Workbook
Name FirmaUnvan: AYARLAR!$B$6
Name RaporTarihi: AYARLAR!$B$7
Name RaporHazirlayan: AYARLAR!$B$8
Name DosyaSurumu: AYARLAR!$B$9
Name SerbestNakit: AYARLAR!$B$10
Name AylikFaaliyetNakdi: AYARLAR!$B$11
Name YillikFaaliyetKari: AYARLAR!$B$12
Name YillikDovizGeliri: AYARLAR!$B$13
Name LikiditeEsigi: AYARLAR!$B$14
Name DovizGeliriEsigi: AYARLAR!$B$15
Name KaldiracEsigi: AYARLAR!$B$16
Name VeriKaliteYuksek: AYARLAR!$B$17
Name VeriKaliteOrta: AYARLAR!$B$18
Name UyariPuanKesintisi: AYARLAR!$B$19
Name DuyarliOran: AYARLAR!$B$20
Name AySayisi: AYARLAR!$B$21
Name ListeBankaDurum: LISTELER!$A$6:$A$8
Name ListeUrunTuru: LISTELER!$C$6:$C$11
Name ListeParaBirimi: LISTELER!$E$6:$E$8
Name ListeOdemeDurumu: LISTELER!$G$6:$G$8
Name ListeMasrafTuru: LISTELER!$I$6:$I$9
Name ListeTeminatTuru: LISTELER!$K$6:$K$9
Name ListeKrediId: LISTELER!$M$6:$M$9
Name ToplamFinansalBorc: KARAR_MOTORU!$B$5
Name AylikBorcServisi: KARAR_MOTORU!$B$6
Name KararBildirimi: KARAR_MOTORU!$B$15
Name RiskSeviyesi: KARAR_MOTORU!$B$16
Name VeriKaliteSkor: KONTROLLER!$B$6

Sheet KAPAK
A1: KAPAK — BANKA, KREDİ VE TAKSİT TAKİP SİSTEMİ
A6: BANKA, KREDİ VE TAKSİT TAKİP SİSTEMİ
A7: Borç yükü, yaklaşan taksit ve refinansman ihtiyacını tek ekranda yönetin.
A9: Bu ürün kimin için?
A10: KOBİ sahipleri, finans yöneticileri, muhasebe ekipleri ve finans danışmanları.
A12: Bu ürün neyi çözer?
A13: Banka limitlerini, kredi portföyünü, taksit ödeme baskısını ve refinansman fırsatlarını tek doğruluk kaynağında izler; borç yapısı sürdürülemez olduğunda uyarı ve aksiyon üretir.
A15: Kullanıcıya ne kazandırır?
A16: • Borcun toplam büyüklüğünü ve ağırlıklı maliyetini anında görürsünüz.
A17: • 30 / 60 / 90 gün içinde ödenmesi gereken taksitleri önceden bilirsiniz.
A18: • Refinansman tekliflerini taksit ve toplam maliyet üzerinden karşılaştırırsınız.
A20: Nasıl başlanır?
... A23: ExcelArşiv — Sürüm 1.0 | Tek kullanıcılı ticari lisans.

Sheet HIZLI_BASLANGIC
A1: HIZLI BASLANGIC — BANKA, KREDİ VE TAKSİT TAKİP SİSTEMİ
A3: 3 ADIMDA SİSTEM
A5: ADIM 1 — AYARLAR
A6: Firma unvanı, rapor tarihi, serbest nakit, aylık faaliyet nakdi ve risk eşiklerini girin. Tüm eşikler tek yerden yönetilir; formüllere sabit sayı gömülmez.
A8: ADIM 2 — GİRİŞ VERİLERİ
A9: BANKALAR, LIMITLER ve KREDILER sayfalarına banka ilişkilerini, limitleri ve kredi portföyünü girin. TAKSIT_PLANI'na dönem bazında ödeme planını işleyin; MASRAF_KOMISYON, TEMINATLAR ve YENI_TEKLIFLER alanlarını tamamlayın.
A11: ADIM 3 — KARAR VE RAPOR
A12: KONTROLLER veri kalitesini, KARAR_MOTORU borç yükü ve likidite kararını üretir; PANO tek ekranda özeti gösterir; RAPOR sayfası yönetim sunumuna hazırdır.
A16: Renk kodu: Açık sarı = manuel giriş | Yeşil yazı = hesaplanan değer | Kırmızı = risk.

Sheet BANKALAR
A1: BANKALAR — BANKA, KREDİ VE TAKSİT TAKİP SİSTEMİ
A3: BANKA TANIMLARI — ilişki, operasyonel durum ve iletişim tek merkezde.
A5: Banka ID | B5: Banka | C5: Şube | D5: Müşteri Numarası | E5: IBAN | F5: Durum | G5: İlişki Yöneticisi | H5: Telefon | I5: Kontrol
A6: BNK-001 | B6: Türkiye İş Bankası | C6: Maslak Ticari | D6: 1002345 | E6: TR110006400000123456789001 | F6: Aktif | G6: Ayşe Yılmaz | H6: 0212 000 00 01 | I6: =IF(ISBLANK($A6),"",IF(OR(ISBLANK($B6),ISBLANK($C6),ISBLANK($D6),ISBLANK($E6),ISBLANK($F6),ISBLANK($G6),ISBLANK($H6)),"EKSİK","OK"))
A7: BNK-002 | B7: Akbank | C7: Levent Ticari | D7: 2001456 | E7: TR220004600000234567890002 | F7: Aktif | G7: Mehmet Kaya | H7: 0212 000 00 02 | I7: =IF(ISBLANK($A7),"",IF(OR(ISBLANK($B7),ISBLANK($C7),ISBLANK($D7),ISBLANK($E7),ISBLANK($F7),ISBLANK($G7),ISBLANK($H7)),"EKSİK","OK"))
A8: BNK-003 | B8: Garanti BBVA | C8: İkitelli Ticari | D8: 3001789 | E8: TR330006200000345678901003 | F8: Aktif | G8: Selin Demir | H8: 0212 000 00 03 | I8: =IF(ISBLANK($A8),"",IF(OR(ISBLANK($B8),ISBLANK($C8),ISBLANK($D8),ISBLANK($E8),ISBLANK($F8),ISBLANK($G8),ISBLANK($H8)),"EKSİK","OK"))
A9: BNK-004 | B9: Yapı Kredi | C9: Kozyatağı Ticari | D9: 4001678 | E9: TR440006700000456789012004 | F9: İzle | G9: Can Arslan | H9: 0212 000 00 04 | I9: =IF(ISBLANK($A9),"",IF(OR(ISBLANK($B9),ISBLANK($C9),ISBLANK($D9),ISBLANK($E9),ISBLANK($F9),ISBLANK($G9),ISBLANK($H9)),"EKSİK","OK"))
I10: =IF(ISBLANK($A10),"",IF(OR(ISBLANK($B10),ISBLANK($C10),ISBLANK($D10),ISBLANK($E10),ISBLANK($F10),ISBLANK($G10),ISBLANK($H10)),"EKSİK","OK"))
I11: =IF(ISBLANK($A11),"",IF(OR(ISBLANK($B11),ISBLANK($C11),ISBLANK($D11),ISBLANK($E11),ISBLANK($F11),ISBLANK($G11),ISBLANK($H11)),"EKSİK","OK"))
I12: =IF(ISBLANK($A12),"",IF(OR(ISBLANK($B12),ISBLANK($C12),ISBLANK($D12),ISBLANK($E12),ISBLANK($F12),ISBLANK($G12),ISBLANK($H12)),"EKSİK","OK"))
I13: =IF(ISBLANK($A13),"",IF(OR(ISBLANK($B13),ISBLANK($C13),ISBLANK($D13),ISBLANK($E13),ISBLANK($F13),ISBLANK($G13),ISBLANK($H13)),"EKSİK","OK"))
I14: =IF(ISBLANK($A14),"",IF(OR(ISBLANK($B14),ISBLANK($C14),ISBLANK($D14),ISBLANK($E14),ISBLANK($F14),ISBLANK($G14),ISBLANK($H14)),"EKSİK","OK"))
I15: =IF(ISBLANK($A15),"",IF(OR(ISBLANK($B15),ISBLANK($C15),ISBLANK($D15),ISBLANK($E15),ISBLANK($F15),ISBLANK($G15),ISBLANK($H15)),"EKSİK","OK"))
I16: =IF(ISBLANK($A16),"",IF(OR(ISBLANK($B16),ISBLANK($C16),ISBLANK($D16),ISBLANK($E16),ISBLANK($F16),ISBLANK($G16),ISBLANK($H16)),"EKSİK","OK"))
I17: =IF(ISBLANK($A17),"",IF(OR(ISBLANK($B17),ISBLANK($C17),ISBLANK($D17),ISBLANK($E17),ISBLANK($F17),ISBLANK($G17),ISBLANK($H17)),"EKSİK","OK"))
I18: =IF(ISBLANK($A18),"",IF(OR(ISBLANK($B18),ISBLANK($C18),ISBLANK($D18),ISBLANK($E18),ISBLANK($F18),ISBLANK($G18),ISBLANK($H18)),"EKSİK","OK"))
I19: =IF(ISBLANK($A19),"",IF(OR(ISBLANK($B19),ISBLANK($C19),ISBLANK($D19),ISBLANK($E19),ISBLANK($F19),ISBLANK($G19),ISBLANK($H19)),"EKSİK","OK"))
I20: =IF(ISBLANK($A20),"",IF(OR(ISBLANK($B20),ISBLANK($C20),ISBLANK($D20),ISBLANK($E20),ISBLANK($F20),ISBLANK($G20),ISBLANK($H20)),"EKSİK","OK"))
I21: =IF(ISBLANK($A21),"",IF(OR(ISBLANK($B21),ISBLANK($C21),ISBLANK($D21),ISBLANK($E21),ISBLANK($F21),ISBLANK($G21),ISBLANK($H21)),"EKSİK","OK"))
... I999: =IF(ISBLANK($A999),"",IF(OR(ISBLANK($B999),ISBLANK($C999),ISBLANK($D999),ISBLANK($E999),ISBLANK($F999),ISBLANK($G999),ISBLANK($H999)),"EKSİK","OK"))

Sheet LIMITLER
A1: LIMITLER — BANKA, KREDİ VE TAKSİT TAKİP SİSTEMİ
A3: BANKA LİMİTLERİ — toplam, kullanılan ve kalan limit ile kullanım oranı.
A5: Limit ID | B5: Banka | C5: Ürün Türü | D5: Para Birimi | E5: Toplam Limit | F5: Kullanılan Limit | G5: Kalan Limit | H5: Kullanım Oranı | I5: Kontrol
A6: LMT-001 | B6: Türkiye İş Bankası | C6: Taksitli Ticari Kredi | D6: TRY | E6: 15000000 | F6: 10500000 | G6: =IF(ISBLANK($A6),"",IF($E6="","",$E6-$F6)) | H6: =IF(ISBLANK($A6),"",IF($E6=0,"",$F6/$E6)) | I6: =IF(ISBLANK($A6),"",IF(OR(ISBLANK($B6),ISBLANK($C6),ISBLANK($D6),ISBLANK($E6),ISBLANK($F6)),"EKSİK","OK"))
A7: LMT-002 | B7: Akbank | C7: Leasing | D7: TRY | E7: 8000000 | F7: 6200000 | G7: =IF(ISBLANK($A7),"",IF($E7="","",$E7-$F7)) | H7: =IF(ISBLANK($A7),"",IF($E7=0,"",$F7/$E7)) | I7: =IF(ISBLANK($A7),"",IF(OR(ISBLANK($B7),ISBLANK($C7),ISBLANK($D7),ISBLANK($E7),ISBLANK($F7)),"EKSİK","OK"))
A8: LMT-003 | B8: Garanti BBVA | C8: Rotatif Kredi | D8: USD | E8: 250000 | F8: 180000 | G8: =IF(ISBLANK($A8),"",IF($E8="","",$E8-$F8)) | H8: =IF(ISBLANK($A8),"",IF($E8=0,"",$F8/$E8)) | I8: =IF(ISBLANK($A8),"",IF(OR(ISBLANK($B8),ISBLANK($C8),ISBLANK($D8),ISBLANK($E8),ISBLANK($F8)),"EKSİK","OK"))
A9: LMT-004 | B9: Yapı Kredi | C9: Spot Kredi | D9: TRY | E9: 5000000 | F9: 0 | G9: =IF(ISBLANK($A9),"",IF($E9="","",$E9-$F9)) | H9: =IF(ISBLANK($A9),"",IF($E9=0,"",$F9/$E9)) | I9: =IF(ISBLANK($A9),"",IF(OR(ISBLANK($B9),ISBLANK($C9),ISBLANK($D9),ISBLANK($E9),ISBLANK($F9)),"EKSİK","OK"))
G10: =IF(ISBLANK($A10),"",IF($E10="","",$E10-$F10)) | H10: =IF(ISBLANK($A10),"",IF($E10=0,"",$F10/$E10)) | I10: =IF(ISBLANK($A10),"",IF(OR(ISBLANK($B10),ISBLANK($C10),ISBLANK($D10),ISBLANK($E10),ISBLANK($F10)),"EKSİK","OK"))
G11: =IF(ISBLANK($A11),"",IF($E11="","",$E11-$F11)) | H11: =IF(ISBLANK($A11),"",IF($E11=0,"",$F11/$E11)) | I11: =IF(ISBLANK($A11),"",IF(OR(ISBLANK($B11),ISBLANK($C11),ISBLANK($D11),ISBLANK($E11),ISBLANK($F11)),"EKSİK","OK"))
G12: =IF(ISBLANK($A12),"",IF($E12="","",$E12-$F12)) | H12: =IF(ISBLANK($A12),"",IF($E12=0,"",$F12/$E12)) | I12: =IF(ISBLANK($A12),"",IF(OR(ISBLANK($B12),ISBLANK($C12),ISBLANK($D12),ISBLANK($E12),ISBLANK($F12)),"EKSİK","OK"))
G13: =IF(ISBLANK($A13),"",IF($E13="","",$E13-$F13)) | H13: =IF(ISBLANK($A13),"",IF($E13=0,"",$F13/$E13)) | I13: =IF(ISBLANK($A13),"",IF(OR(ISBLANK($B13),ISBLANK($C13),ISBLANK($D13),ISBLANK($E13),ISBLANK($F13)),"EKSİK","OK"))
G14: =IF(ISBLANK($A14),"",IF($E14="","",$E14-$F14)) | H14: =IF(ISBLANK($A14),"",IF($E14=0,"",$F14/$E14)) | I14: =IF(ISBLANK($A14),"",IF(OR(ISBLANK($B14),ISBLANK($C14),ISBLANK($D14),ISBLANK($E14),ISBLANK($F14)),"EKSİK","OK"))
G15: =IF(ISBLANK($A15),"",IF($E15="","",$E15-$F15)) | H15: =IF(ISBLANK($A15),"",IF($E15=0,"",$F15/$E15)) | I15: =IF(ISBLANK($A15),"",IF(OR(ISBLANK($B15),ISBLANK($C15),ISBLANK($D15),ISBLANK($E15),ISBLANK($F15)),"EKSİK","OK"))
G16: =IF(ISBLANK($A16),"",IF($E16="","",$E16-$F16)) | H16: =IF(ISBLANK($A16),"",IF($E16=0,"",$F16/$E16)) | I16: =IF(ISBLANK($A16),"",IF(OR(ISBLANK($B16),ISBLANK($C16),ISBLANK($D16),ISBLANK($E16),ISBLANK($F16)),"EKSİK","OK"))
G17: =IF(ISBLANK($A17),"",IF($E17="","",$E17-$F17)) | H17: =IF(ISBLANK($A17),"",IF($E17=0,"",$F17/$E17)) | I17: =IF(ISBLANK($A17),"",IF(OR(ISBLANK($B17),ISBLANK($C17),ISBLANK($D17),ISBLANK($E17),ISBLANK($F17)),"EKSİK","OK"))
G18: =IF(ISBLANK($A18),"",IF($E18="","",$E18-$F18)) | H18: =IF(ISBLANK($A18),"",IF($E18=0,"",$F18/$E18)) | I18: =IF(ISBLANK($A18),"",IF(OR(ISBLANK($B18),ISBLANK($C18),ISBLANK($D18),ISBLANK($E18),ISBLANK($F18)),"EKSİK","OK"))
G19: =IF(ISBLANK($A19),"",IF($E19="","",$E19-$F19)) | H19: =IF(ISBLANK($A19),"",IF($E19=0,"",$F19/$E19)) | I19: =IF(ISBLANK($A19),"",IF(OR(ISBLANK($B19),ISBLANK($C19),ISBLANK($D19),ISBLANK($E19),ISBLANK($F19)),"EKSİK","OK"))
G20: =IF(ISBLANK($A20),"",IF($E20="","",$E20-$F20)) | H20: =IF(ISBLANK($A20),"",IF($E20=0,"",$F20/$E20)) | I20: =IF(ISBLANK($A20),"",IF(OR(ISBLANK($B20),ISBLANK($C20),ISBLANK($D20),ISBLANK($E20),ISBLANK($F20)),"EKSİK","OK"))
G21: =IF(ISBLANK($A21),"",IF($E21="","",$E21-$F21)) | H21: =IF(ISBLANK($A21),"",IF($E21=0,"",$F21/$E21)) | I21: =IF(ISBLANK($A21),"",IF(OR(ISBLANK($B21),ISBLANK($C21),ISBLANK($D21),ISBLANK($E21),ISBLANK($F21)),"EKSİK","OK"))
... G999: =IF(ISBLANK($A999),"",IF($E999="","",$E999-$F999)) | H999: =IF(ISBLANK($A999),"",IF($E999=0,"",$F999/$E999)) | I999: =IF(ISBLANK($A999),"",IF(OR(ISBLANK($B999),ISBLANK($C999),ISBLANK($D999),ISBLANK($E999),ISBLANK($F999)),"EKSİK","OK"))

Sheet KREDILER
A1: KREDILER — BANKA, KREDİ VE TAKSİT TAKİP SİSTEMİ
A3: KREDİ PORTFÖYÜ — sözleşme, bakiye, maliyet, vade ve taksit bilgileri.
A5: Kredi ID | B5: Banka | C5: Şube | D5: Ürün Türü | E5: Para Birimi | F5: Kullandırım Tarihi | G5: Anapara | H5: Güncel Bakiye | I5: Yıllık Faiz | J5: Vade Ay | K5: Aylık Taksit | L5: Bitiş Tarihi | M5: Açıklama | N5: Kontrol
A6: KRD-001 | B6: Türkiye İş Bankası | C6: Maslak Ticari | D6: Taksitli Ticari Kredi | E6: TRY | F6: 45597 | G6: 12000000 | H6: 8400000 | I6: 0.32 | J6: 24 | K6: Yatırım kredisi | L6: =IF(ISBLANK($A6),"",IF($F6="","",EOMONTH($F6,$J6))) | N6: =IF(ISBLANK($A6),"",IF(OR(ISBLANK($B6),ISBLANK($C6),ISBLANK($D6),ISBLANK($E6),ISBLANK($F6),ISBLANK($G6),ISBLANK($H6),ISBLANK($I6),ISBLANK($J6),ISBLANK($K6),ISBLANK($L6)),"EKSİK","OK"))
A7: KRD-002 | B7: Akbank | C7: Levent Ticari | D7: Leasing | E7: TRY | F7: 45717 | G7: 7500000 | H7: 6100000 | I7: 0.34 | J7: 36 | K7: Makine leasing | L7: =IF(ISBLANK($A7),"",IF($F7="","",EOMONTH($F7,$J7))) | N7: =IF(ISBLANK($A7),"",IF(OR(ISBLANK($B7),ISBLANK($C7),ISBLANK($D7),ISBLANK($E7),ISBLANK($F7),ISBLANK($G7),ISBLANK($H7),ISBLANK($I7),ISBLANK($J7),ISBLANK($K7),ISBLANK($L7)),"EKSİK","OK"))
A8: KRD-003 | B8: Garanti BBVA | C8: İkitelli Ticari | D8: Rotatif Kredi | E8: USD | F8: 45809 | G8: 200000 | H8: 180000 | I8: 0.085 | J8: 12 | K8: İhracat rotatifi | L8: =IF(ISBLANK($A8),"",IF($F8="","",EOMONTH($F8,$J8))) | N8: =IF(ISBLANK($A8),"",IF(OR(ISBLANK($B8),ISBLANK($C8),ISBLANK($D8),ISBLANK($E8),ISBLANK($F8),ISBLANK($G8),ISBLANK($H8),ISBLANK($I8),ISBLANK($J8),ISBLANK($K8),ISBLANK($L8)),"EKSİK","OK"))
A9: KRD-004 | B9: Türkiye İş Bankası | C9: Maslak Ticari | D9: Spot Kredi | E9: TRY | F9: 46023 | G9: 2200000 | H9: 2200000 | I9: 0.36 | J9: 12 | K9: İşletme sermayesi | L9: =IF(ISBLANK($A9),"",IF($F9="","",EOMONTH($F9,$J9))) | N9: =IF(ISBLANK($A9),"",IF(OR(ISBLANK($B9),ISBLANK($C9),ISBLANK($D9),ISBLANK($E9),ISBLANK($F9),ISBLANK($G9),ISBLANK($H9),ISBLANK($I9),ISBLANK($J9),ISBLANK($K9),ISBLANK($L9)),"EKSİK","OK"))
K10: =IF(ISBLANK($A10),"",IF($I10="","",$I10/AySayisi)) | L10: =IF(ISBLANK($A10),"",IF($F10="","",EOMONTH($F10,$J10))) | N10: =IF(ISBLANK($A10),"",IF(OR(ISBLANK($B10),ISBLANK($C10),ISBLANK($D10),ISBLANK($E10),ISBLANK($F10),ISBLANK($G10),ISBLANK($H10),ISBLANK($I10),ISBLANK($J10),ISBLANK($K10),ISBLANK($L10)),"EKSİK","OK"))
K11: =IF(ISBLANK($A11),"",IF($I11="","",$I11/AySayisi)) | L11: =IF(ISBLANK($A11),"",IF($F11="","",EOMONTH($F11,$J11))) | N11: =IF(ISBLANK($A11),"",IF(OR(ISBLANK($B11),ISBLANK($C11),ISBLANK($D11),ISBLANK($E11),ISBLANK($F11),ISBLANK($G11),ISBLANK($H11),ISBLANK($I11),ISBLANK($J11),ISBLANK($K11),ISBLANK($L11)),"EKSİK","OK"))
K12: =IF(ISBLANK($A12),"",IF($I12="","",$I12/AySayisi)) | L12: =IF(ISBLANK($A12),"",IF($F12="","",EOMONTH($F12,$J12))) | N12: =IF(ISBLANK($A12),"",IF(OR(ISBLANK($B12),ISBLANK($C12),ISBLANK($D12),ISBLANK($E12),ISBLANK($F12),ISBLANK($G12),ISBLANK($H12),ISBLANK($I12),ISBLANK($J12),ISBLANK($K12),ISBLANK($L12)),"EKSİK","OK"))
K13: =IF(ISBLANK($A13),"",IF($I13="","",$I13/AySayisi)) | L13: =IF(ISBLANK($A13),"",IF($F13="","",EOMONTH($F13,$J13))) | N13: =IF(ISBLANK($A13),"",IF(OR(ISBLANK($B13),ISBLANK($C13),ISBLANK($D13),ISBLANK($E13),ISBLANK($F13),ISBLANK($G13),ISBLANK($H13),ISBLANK($I13),ISBLANK($J13),ISBLANK($K13),ISBLANK($L13)),"EKSİK","OK"))
K14: =IF(ISBLANK($A14),"",IF($I14="","",$I14/AySayisi)) | L14: =IF(ISBLANK($A14),"",IF($F14="","",EOMONTH($F14,$J14))) | N14: =IF(ISBLANK($A14),"",IF(OR(ISBLANK($B14),ISBLANK($C14),ISBLANK($D14),ISBLANK($E14),ISBLANK($F14),ISBLANK($G14),ISBLANK($H14),ISBLANK($I14),ISBLANK($J14),ISBLANK($K14),ISBLANK($L14)),"EKSİK","OK"))
K15: =IF(ISBLANK($A15),"",IF($I15="","",$I15/AySayisi)) | L15: =IF(ISBLANK($A15),"",IF($F15="","",EOMONTH($F15,$J15))) | N15: =IF(ISBLANK($A15),"",IF(OR(ISBLANK($B15),ISBLANK($C15),ISBLANK($D15),ISBLANK($E15),ISBLANK($F15),ISBLANK($G15),ISBLANK($H15),ISBLANK($I15),ISBLANK($J15),ISBLANK($K15),ISBLANK($L15)),"EKSİK","OK"))
K16: =IF(ISBLANK($A16),"",IF($I16="","",$I16/AySayisi)) | L16: =IF(ISBLANK($A16),"",IF($F16="","",EOMONTH($F16,$J16))) | N16: =IF(ISBLANK($A16),"",IF(OR(ISBLANK($B16),ISBLANK($C16),ISBLANK($D16),ISBLANK($E16),ISBLANK($F16),ISBLANK($G16),ISBLANK($H16),ISBLANK($I16),ISBLANK($J16),ISBLANK($K16),ISBLANK($L16)),"EKSİK","OK"))
K17: =IF(ISBLANK($A17),"",IF($I17="","",$I17/AySayisi)) | L17: =IF(ISBLANK($A17),"",IF($F17="","",EOMONTH($F17,$J17))) | N17: =IF(ISBLANK($A17),"",IF(OR(ISBLANK($B17),ISBLANK($C17),ISBLANK($D17),ISBLANK($E17),ISBLANK($F17),ISBLANK($G17),ISBLANK($H17),ISBLANK($I17),ISBLANK($J17),ISBLANK($K17),ISBLANK($L17)),"EKSİK","OK"))
K18: =IF(ISBLANK($A18),"",IF($I18="","",$I18/AySayisi)) | L18: =IF(ISBLANK($A18),"",IF($F18="","",EOMONTH($F18,$J18))) | N18: =IF(ISBLANK($A18),"",IF(OR(ISBLANK($B18),ISBLANK($C18),ISBLANK($D18),ISBLANK($E18),ISBLANK($F18),ISBLANK($G18),ISBLANK($H18),ISBLANK($I18),ISBLANK($J18),ISBLANK($K18),ISBLANK($L18)),"EKSİK","OK"))
K19: =IF(ISBLANK($A19),"",IF($I19="","",$I19/AySayisi)) | L19: =IF(ISBLANK($A19),"",IF($F19="","",EOMONTH($F19,$J19))) | N19: =IF(ISBLANK($A19),"",IF(OR(ISBLANK($B19),ISBLANK($C19),ISBLANK($D19),ISBLANK($E19),ISBLANK($F19),ISBLANK($G19),ISBLANK($H19),ISBLANK($I19),ISBLANK($J19),ISBLANK($K19),ISBLANK($L19)),"EKSİK","OK"))
K20: =IF(ISBLANK($A20),"",IF($I20="","",$I20/AySayisi)) | L20: =IF(ISBLANK($A20),"",IF($F20="","",EOMONTH($F20,$J20))) | N20: =IF(ISBLANK($A20),"",IF(OR(ISBLANK($B20),ISBLANK($C20),ISBLANK($D20),ISBLANK($E20),ISBLANK($F20),ISBLANK($G20),ISBLANK($H20),ISBLANK($I20),ISBLANK($J20),ISBLANK($K20),ISBLANK($L20)),"EKSİK","OK"))
K21: =IF(ISBLANK($A21),"",IF($I21="","",$I21/AySayisi)) | L21: =IF(ISBLANK($A21),"",IF($F21="","",EOMONTH($F21,$J21))) | N21: =IF(ISBLANK($A21),"",IF(OR(ISBLANK($B21),ISBLANK($C21),ISBLANK($D21),ISBLANK($E21),ISBLANK($F21),ISBLANK($G21),ISBLANK($H21),ISBLANK($I21),ISBLANK($J21),ISBLANK($K21),ISBLANK($L21)),"EKSİK","OK"))
... K999: =IF(ISBLANK($A999),"",IF($I999="","",$I999/AySayisi)) | L999: =IF(ISBLANK($A999),"",IF($F999="","",EOMONTH($F999,$J999))) | N999: =IF(ISBLANK($A999),"",IF(OR(ISBLANK($B999),ISBLANK($C999),ISBLANK($D999),ISBLANK($E999),ISBLANK($F999),ISBLANK($G999),ISBLANK($H999),ISBLANK($I999),ISBLANK($J999),ISBLANK($K999),ISBLANK($L999)),"EKSİK","OK"))

Sheet TAKSIT_PLANI
A1: TAKSIT PLANI — BANKA, KREDİ VE TAKSİT TAKİP SİSTEMİ
A3: TAKSİT PLANI — dönem bazında anapara, faiz, vergi ve ödeme tarihi.
A5: Plan ID | B5: Kredi ID | C5: Dönem | D5: Ödeme Tarihi | E5: Anapara | F5: Faiz | G5: Vergi/Fon | H5: Komisyon | I5: Toplam Ödeme | J5: Ödeme Durumu | K5: Kalan Gün | L5: Kontrol
A6: PLN-001 | B6: KRD-001 | C6: 1 | D6: 46244 | E6: 326000 | F6: 280000 | G6: 14000 | H6: 0 | I6: =IF(ISBLANK($A6),"",IF(COUNTA($E6:$H6)=4,$E6+$F6+$G6+$H6,"")) | J6: Bekliyor | K6: =IF(ISBLANK($D6),"",$D6-RaporTarihi) | L6: =IF(ISBLANK($A6),"",IF(OR(ISBLANK($B6),ISBLANK($C6),ISBLANK($D6),ISBLANK($E6),ISBLANK($F6),ISBLANK($G6),ISBLANK($H6),ISBLANK($I6),ISBLANK($J6)),"EKSİK","OK"))
A7: PLN-002 | B7: KRD-001 | C7: 2 | D7: 46275 | E7: 337000 | F7: 269000 | G7: 14000 | H7: 0 | I7: =IF(ISBLANK($A7),"",IF(COUNTA($E7:$H7)=4,$E7+$F7+$G7+$H7,"")) | J7: Bekliyor | K7: =IF(ISBLANK($D7),"",$D7-RaporTarihi) | L7: =IF(ISBLANK($A7),"",IF(OR(ISBLANK($B7),ISBLANK($C7),ISBLANK($D7),ISBLANK($E7),ISBLANK($F7),ISBLANK($G7),ISBLANK($H7),ISBLANK($I7),ISBLANK($J7)),"EKSİK","OK"))
A8: PLN-003 | B8: KRD-002 | C8: 1 | D8: 46249 | E8: 117000 | F8: 183000 | G8: 10000 | H8: 0 | I8: =IF(ISBLANK($A8),"",IF(COUNTA($E8:$H8)=4,$E8+$F8+$G8+$H8,"")) | J8: Bekliyor | K8: =IF(ISBLANK($D8),"",$D8-RaporTarihi) | L8: =IF(ISBLANK($A8),"",IF(OR(ISBLANK($B8),ISBLANK($C8),ISBLANK($D8),ISBLANK($E8),ISBLANK($F8),ISBLANK($G8),ISBLANK($H8),ISBLANK($I8),ISBLANK($J8)),"EKSİK","OK"))
A9: PLN-004 | B9: KRD-002 | C9: 2 | D9: 46280 | E9: 121000 | F9: 179000 | G9: 10000 | H9: 0 | I9: =IF(ISBLANK($A9),"",IF(COUNTA($E9:$H9)=4,$E9+$F9+$G9+$H9,"")) | J9: Bekliyor | K9: =IF(ISBLANK($D9),"",$D9-RaporTarihi) | L9: =IF(ISBLANK($A9),"",IF(OR(ISBLANK($B9),ISBLANK($C9),ISBLANK($D9),ISBLANK($E9),ISBLANK($F9),ISBLANK($G9),ISBLANK($H9),ISBLANK($I9),ISBLANK($J9)),"EKSİK","OK"))
A10: PLN-005 | B10: KRD-003 | C10: 1 | D10: 46254 | E10: 0 | F10: 4275 | G10: 214 | H10: 375 | I10: =IF(ISBLANK($A10),"",IF(COUNTA($E10:$H10)=4,$E10+$F10+$G10+$H10,"")) | J10: Bekliyor | K10: =IF(ISBLANK($D10),"",$D10-RaporTarihi) | L10: =IF(ISBLANK($A10),"",IF(OR(ISBLANK($B10),ISBLANK($C10),ISBLANK($D10),ISBLANK($E10),ISBLANK($F10),ISBLANK($G10),ISBLANK($H10),ISBLANK($I10),ISBLANK($J10)),"EKSİK","OK"))
A11: PLN-006 | B11: KRD-004 | C11: 1 | D11: 46387 | E11: 2200000 | F11: 1034000 | G11: 51700 | H11: 0 | I11: =IF(ISBLANK($A11),"",IF(COUNTA($E11:$H11)=4,$E11+$F11+$G11+$H11,"")) | J11: Bekliyor | K11: =IF(ISBLANK($D11),"",$D11-RaporTarihi) | L11: =IF(ISBLANK($A11),"",IF(OR(ISBLANK($B11),ISBLANK($C11),ISBLANK($D11),ISBLANK($E11),ISBLANK($F11),ISBLANK($G11),ISBLANK($H11),ISBLANK($I11),ISBLANK($J11)),"EKSİK","OK"))
I12: =IF(ISBLANK($A12),"",IF(COUNTA($E12:$H12)=4,$E12+$F12+$G12+$H12,"")) | K12: =IF(ISBLANK($D12),"",$D12-RaporTarihi) | L12: =IF(ISBLANK($A12),"",IF(OR(ISBLANK($B12),ISBLANK($C12),ISBLANK($D12),ISBLANK($E12),ISBLANK($F12),ISBLANK($G12),ISBLANK($H12),ISBLANK($I12),ISBLANK($J12)),"EKSİK","OK"))
I13: =IF(ISBLANK($A13),"",IF(COUNTA($E13:$H13)=4,$E13+$F13+$G13+$H13,"")) | K13: =IF(ISBLANK($D13),"",$D13-RaporTarihi) | L13: =IF(ISBLANK($A13),"",IF(OR(ISBLANK($B13),ISBLANK($C13),ISBLANK($D13),ISBLANK($E13),ISBLANK($F13),ISBLANK($G13),ISBLANK($H13),ISBLANK($I13),ISBLANK($J13)),"EKSİK","OK"))
I14: =IF(ISBLANK($A14),"",IF(COUNTA($E14:$H14)=4,$E14+$F14+$G14+$H14,"")) | K14: =IF(ISBLANK($D14),"",$D14-RaporTarihi) | L14: =IF(ISBLANK($A14),"",IF(OR(ISBLANK($B14),ISBLANK($C14),ISBLANK($D14),ISBLANK($E14),ISBLANK($F14),ISBLANK($G14),ISBLANK($H14),ISBLANK($I14),ISBLANK($J14)),"EKSİK","OK"))
I15: =IF(ISBLANK($A15),"",IF(COUNTA($E15:$H15)=4,$E15+$F15+$G15+$H15,"")) | K15: =IF(ISBLANK($D15),"",$D15-RaporTarihi) | L15: =IF(ISBLANK($A15),"",IF(OR(ISBLANK($B15),ISBLANK($C15),ISBLANK($D15),ISBLANK($E15),ISBLANK($F15),ISBLANK($G15),ISBLANK($H15),ISBLANK($I15),ISBLANK($J15)),"EKSİK","OK"))
I16: =IF(ISBLANK($A16),"",IF(COUNTA($E16:$H16)=4,$E16+$F16+$G16+$H16,"")) | K16: =IF(ISBLANK($D16),"",$D16-RaporTarihi) | L16: =IF(ISBLANK($A16),"",IF(OR(ISBLANK($B16),ISBLANK($C16),ISBLANK($D16),ISBLANK($E16),ISBLANK($F16),ISBLANK($G16),ISBLANK($H16),ISBLANK($I16),ISBLANK($J16)),"EKSİK","OK"))
I17: =IF(ISBLANK($A17),"",IF(COUNTA($E17:$H17)=4,$E17+$F17+$G17+$H17,"")) | K17: =IF(ISBLANK($D17),"",$D17-RaporTarihi) | L17: =IF(ISBLANK($A17),"",IF(OR(ISBLANK($B17),ISBLANK($C17),ISBLANK($D17),ISBLANK($E17),ISBLANK($F17),ISBLANK($G17),ISBLANK($H17),ISBLANK($I17),ISBLANK($J17)),"EKSİK","OK"))
I18: =IF(ISBLANK($A18),"",IF(COUNTA($E18:$H18)=4,$E18+$F18+$G18+$H18,"")) | K18: =IF(ISBLANK($D18),"",$D18-RaporTarihi) | L18: =IF(ISBLANK($A18),"",IF(OR(ISBLANK($B18),ISBLANK($C18),ISBLANK($D18),ISBLANK($E18),ISBLANK($F18),ISBLANK($G18),ISBLANK($H18),ISBLANK($I18),ISBLANK($J18)),"EKSİK","OK"))
I19: =IF(ISBLANK($A19),"",IF(COUNTA($E19:$H19)=4,$E19+$F19+$G19+$H19,"")) | K19: =IF(ISBLANK($D19),"",$D19-RaporTarihi) | L19: =IF(ISBLANK($A19),"",IF(OR(ISBLANK($B19),ISBLANK($C19),ISBLANK($D19),ISBLANK($E19),ISBLANK($F19),ISBLANK($G19),ISBLANK($H19),ISBLANK($I19),ISBLANK($J19)),"EKSİK","OK"))
I20: =IF(ISBLANK($A20),"",IF(COUNTA($E20:$H20)=4,$E20+$F20+$G20+$H20,"")) | K20: =IF(ISBLANK($D20),"",$D20-RaporTarihi) | L20: =IF(ISBLANK($A20),"",IF(OR(ISBLANK($B20),ISBLANK($C20),ISBLANK($D20),ISBLANK($E20),ISBLANK($F20),ISBLANK($G20),ISBLANK($H20),ISBLANK($I20),ISBLANK($J20)),"EKSİK","OK"))
I21: =IF(ISBLANK($A21),"",IF(COUNTA($E21:$H21)=4,$E21+$F21+$G21+$H21,"")) | K21: =IF(ISBLANK($D21),"",$D21-RaporTarihi) | L21: =IF(ISBLANK($A21),"",IF(OR(ISBLANK($B21),ISBLANK($C21),ISBLANK($D21),ISBLANK($E21),ISBLANK($F21),ISBLANK($G21),ISBLANK($H21),ISBLANK($I21),ISBLANK($J21)),"EKSİK","OK"))
I22: =IF(ISBLANK($A22),"",IF(COUNTA($E22:$H22)=4,$E22+$F22+$G22+$H22,"")) | K22: =IF(ISBLANK($D22),"",$D22-RaporTarihi) | L22: =IF(ISBLANK($A22),"",IF(OR(ISBLANK($B22),ISBLANK($C22),ISBLANK($D22),ISBLANK($E22),ISBLANK($F22),ISBLANK($G22),ISBLANK($H22),ISBLANK($I22),ISBLANK($J22)),"EKSİK","OK"))
I23: =IF(ISBLANK($A23),"",IF(COUNTA($E23:$H23)=4,$E23+$F23+$G23+$H23,"")) | K23: =IF(ISBLANK($D23),"",$D23-RaporTarihi) | L23: =IF(ISBLANK($A23),"",IF(OR(ISBLANK($B23),ISBLANK($C23),ISBLANK($D23),ISBLANK($E23),ISBLANK($F23),ISBLANK($G23),ISBLANK($H23),ISBLANK($I23),ISBLANK($J23)),"EKSİK","OK"))
... I999: =IF(ISBLANK($A999),"",IF(COUNTA($E999:$H999)=4,$E999+$F999+$G999+$H999,"")) | K999: =IF(ISBLANK($D999),"",$D999-RaporTarihi) | L999: =IF(ISBLANK($A999),"",IF(OR(ISBLANK($B999),ISBLANK($C999),ISBLANK($D999),ISBLANK($E999),ISBLANK($F999),ISBLANK($G999),ISBLANK($H999),ISBLANK($I999),ISBLANK($J999)),"EKSİK","OK"))

Sheet MASRAF_KOMISYON
A1: MASRAF KOMISYON — BANKA, KREDİ VE TAKSİT TAKİP SİSTEMİ
A3: MASRAF VE KOMİSYONLAR — tahsis, sigorta, komisyon ve diğer finansman maliyetleri.
A5: Masraf ID | B5: Kredi ID | C5: Banka | D5: Masraf Türü | E5: İşlem Tarihi | F5: Belge Numarası | G5: Tutar | H5: Para Birimi | I5: Kontrol
A6: MSF-001 | B6: KRD-001 | C6: Türkiye İş Bankası | D6: Tahsis Ücreti | E6: 45597 | F6: FTR-1001 | G6: 60000 | H6: TRY | I6: =IF(ISBLANK($A6),"",IF(OR(ISBLANK($B6),ISBLANK($C6),ISBLANK($D6),ISBLANK($E6),ISBLANK($F6),ISBLANK($G6),ISBLANK($H6)),"EKSİK","OK"))
A7: MSF-002 | B7: KRD-002 | C7: Akbank | D7: Sigorta | E7: 45717 | F7: POL-2001 | G7: 70000 | H7: TRY | I7: =IF(ISBLANK($A7),"",IF(OR(ISBLANK($B7),ISBLANK($C7),ISBLANK($D7),ISBLANK($E7),ISBLANK($F7),ISBLANK($G7),ISBLANK($H7)),"EKSİK","OK"))
A8: MSF-003 | B8: KRD-003 | C8: Garanti BBVA | D8: Komisyon | E8: 45809 | F8: FTR-3001 | G8: 1500 | H8: USD | I8: =IF(ISBLANK($A8),"",IF(OR(ISBLANK($B8),ISBLANK($C8),ISBLANK($D8),ISBLANK($E8),ISBLANK($F8),ISBLANK($G8),ISBLANK($H8)),"EKSİK","OK"))
I9: =IF(ISBLANK($A9),"",IF(OR(ISBLANK($B9),ISBLANK($C9),ISBLANK($D9),ISBLANK($E9),ISBLANK($F9),ISBLANK($G9),ISBLANK($H9)),"EKSİK","OK"))
I10: =IF(ISBLANK($A10),"",IF(OR(ISBLANK($B10),ISBLANK($C10),ISBLANK($D10),ISBLANK($E10),ISBLANK($F10),ISBLANK($G10),ISBLANK($H10)),"EKSİK","OK"))
I11: =IF(ISBLANK($A11),"",IF(OR(ISBLANK($B11),ISBLANK($C11),ISBLANK($D11),ISBLANK($E11),ISBLANK($F11),ISBLANK($G11),ISBLANK($H11)),"EKSİK","OK"))
I12: =IF(ISBLANK($A12),"",IF(OR(ISBLANK($B12),ISBLANK($C12),ISBLANK($D12),ISBLANK($E12),ISBLANK($F12),ISBLANK($G12),ISBLANK($H12)),"EKSİK","OK"))
I13: =IF(ISBLANK($A13),"",IF(OR(ISBLANK($B13),ISBLANK($C13),ISBLANK($D13),ISBLANK($E13),ISBLANK($F13),ISBLANK($G13),ISBLANK($H13)),"EKSİK","OK"))
I14: =IF(ISBLANK($A14),"",IF(OR(ISBLANK($B14),ISBLANK($C14),ISBLANK($D14),ISBLANK($E14),ISBLANK($F14),ISBLANK($G14),ISBLANK($H14)),"EKSİK","OK"))
I15: =IF(ISBLANK($A15),"",IF(OR(ISBLANK($B15),ISBLANK($C15),ISBLANK($D15),ISBLANK($E15),ISBLANK($F15),ISBLANK($G15),ISBLANK($H15)),"EKSİK","OK"))
I16: =IF(ISBLANK($A16),"",IF(OR(ISBLANK($B16),ISBLANK($C16),ISBLANK($D16),ISBLANK($E16),ISBLANK($F16),ISBLANK($G16),ISBLANK($H16)),"EKSİK","OK"))
I17: =IF(ISBLANK($A17),"",IF(OR(ISBLANK($B17),ISBLANK($C17),ISBLANK($D17),ISBLANK($E17),ISBLANK($F17),ISBLANK($G17),ISBLANK($H17)),"EKSİK","OK"))
I18: =IF(ISBLANK($A18),"",IF(OR(ISBLANK($B18),ISBLANK($C18),ISBLANK($D18),ISBLANK($E18),ISBLANK($F18),ISBLANK($G18),ISBLANK($H18)),"EKSİK","OK"))
I19: =IF(ISBLANK($A19),"",IF(OR(ISBLANK($B19),ISBLANK($C19),ISBLANK($D19),ISBLANK($E19),ISBLANK($F19),ISBLANK($G19),ISBLANK($H19)),"EKSİK","OK"))
I20: =IF(ISBLANK($A20),"",IF(OR(ISBLANK($B20),ISBLANK($C20),ISBLANK($D20),ISBLANK($E20),ISBLANK($F20),ISBLANK($G20),ISBLANK($H20)),"EKSİK","OK"))
... I999: =IF(ISBLANK($A999),"",IF(OR(ISBLANK($B999),ISBLANK($C999),ISBLANK($D999),ISBLANK($E999),ISBLANK($F999),ISBLANK($G999),ISBLANK($H999)),"EKSİK","OK"))

Sheet TEMINATLAR
A1: TEMINATLAR — BANKA, KREDİ VE TAKSİT TAKİP SİSTEMİ
A3: TEMİNAT YÖNETİMİ — değer, geçerlilik ve kredi bağlantısı.
A5: Teminat ID | B5: Kredi ID | C5: Banka | D5: Teminat Türü | E5: Açıklama | F5: Ekspertiz Değeri | G5: Para Birimi | H5: Değerleme Tarihi | I5: Geçerlilik Bitişi | J5: Kontrol
A6: TMN-001 | B6: KRD-001 | C6: Türkiye İş Bankası | D6: Gayrimenkul İpoteği | E6: İstanbul fabrika binası | F6: 15000000 | G6: TRY | H6: 45992 | I6: 47088 | J6: =IF(ISBLANK($A6),"",IF(OR(ISBLANK($B6),ISBLANK($C6),ISBLANK($D6),ISBLANK($E6),ISBLANK($F6),ISBLANK($G6),ISBLANK($H6),ISBLANK($I6)),"EKSİK","OK"))
A7: TMN-002 | B7: KRD-002 | C7: Akbank | D7: Taşıt Rehni | E7: Üretim makineleri | F7: 8500000 | G7: TRY | H7: 45992 | I7: 46722 | J7: =IF(ISBLANK($A7),"",IF(OR(ISBLANK($B7),ISBLANK($C7),ISBLANK($D7),ISBLANK($E7),ISBLANK($F7),ISBLANK($G7),ISBLANK($H7),ISBLANK($I7)),"EKSİK","OK"))
A8: TMN-003 | B8: KRD-003 | C8: Garanti BBVA | D8: Alacak Temliki | E8: İhracat alacak havuzu | F8: 3500000 | G8: TRY | H8: 46023 | I8: 46388 | J8: =IF(ISBLANK($A8),"",IF(OR(ISBLANK($B8),ISBLANK($C8),ISBLANK($D8),ISBLANK($E8),ISBLANK($F8),ISBLANK($G8),ISBLANK($H8),ISBLANK($I8)),"EKSİK","OK"))
J9: =IF(ISBLANK($A9),"",IF(OR(ISBLANK($B9),ISBLANK($C9),ISBLANK($D9),ISBLANK($E9),ISBLANK($F9),ISBLANK($G9),ISBLANK($H9),ISBLANK($I9)),"EKSİK","OK"))
J10: =IF(ISBLANK($A10),"",IF(OR(ISBLANK($B10),ISBLANK($C10),ISBLANK($D10),ISBLANK($E10),ISBLANK($F10),ISBLANK($G10),ISBLANK($H10),ISBLANK($I10)),"EKSİK","OK"))
J11: =IF(ISBLANK($A11),"",IF(OR(ISBLANK($B11),ISBLANK($C11),ISBLANK($D11),ISBLANK($E11),ISBLANK($F11),ISBLANK($G11),ISBLANK($H11),ISBLANK($I11)),"EKSİK","OK"))
J12: =IF(ISBLANK($A12),"",IF(OR(ISBLANK($B12),ISBLANK($C12),ISBLANK($D12),ISBLANK($E12),ISBLANK($F12),ISBLANK($G12),ISBLANK($H12),ISBLANK($I12)),"EKSİK","OK"))
J13: =IF(ISBLANK($A13),"",IF(OR(ISBLANK($B13),ISBLANK($C13),ISBLANK($D13),ISBLANK($E13),ISBLANK($F13),ISBLANK($G13),ISBLANK($H13),ISBLANK($I13)),"EKSİK","OK"))
J14: =IF(ISBLANK($A14),"",IF(OR(ISBLANK($B14),ISBLANK($C14),ISBLANK($D14),ISBLANK($E14),ISBLANK($F14),ISBLANK($G14),ISBLANK($H14),ISBLANK($I14)),"EKSİK","OK"))
J15: =IF(ISBLANK($A15),"",IF(OR(ISBLANK($B15),ISBLANK($C15),ISBLANK($D15),ISBLANK($E15),ISBLANK($F15),ISBLANK($G15),ISBLANK($H15),ISBLANK($I15)),"EKSİK","OK"))
J16: =IF(ISBLANK($A16),"",IF(OR(ISBLANK($B16),ISBLANK($C16),ISBLANK($D16),ISBLANK($E16),ISBLANK($F16),ISBLANK($G16),ISBLANK($H16),ISBLANK($I16)),"EKSİK","OK"))
J17: =IF(ISBLANK($A17),"",IF(OR(ISBLANK($B17),ISBLANK($C17),ISBLANK($D17),ISBLANK($E17),ISBLANK($F17),ISBLANK($G17),ISBLANK($H17),ISBLANK($I17)),"EKSİK","OK"))
J18: =IF(ISBLANK($A18),"",IF(OR(ISBLANK($B18),ISBLANK($C18),ISBLANK($D18),ISBLANK($E18),ISBLANK($F18),ISBLANK($G18),ISBLANK($H18),ISBLANK($I18)),"EKSİK","OK"))
J19: =IF(ISBLANK($A19),"",IF(OR(ISBLANK($B19),ISBLANK($C19),ISBLANK($D19),ISBLANK($E19),ISBLANK($F19),ISBLANK($G19),ISBLANK($H19),ISBLANK($I19)),"EKSİK","OK"))
J20: =IF(ISBLANK($A20),"",IF(OR(ISBLANK($B20),ISBLANK($C20),ISBLANK($D20),ISBLANK($E20),ISBLANK($F20),ISBLANK($G20),ISBLANK($H20),ISBLANK($I20)),"EKSİK","OK"))
... J999: =IF(ISBLANK($A999),"",IF(OR(ISBLANK($B999),ISBLANK($C999),ISBLANK($D999),ISBLANK($E999),ISBLANK($F999),ISBLANK($G999),ISBLANK($H999),ISBLANK($I999)),"EKSİK","OK"))

Sheet YENI_TEKLIFLER
A1: YENI TEKLIFLER — BANKA, KREDİ VE TAKSİT TAKİP SİSTEMİ
A3: YENİ KREDİ TEKLİFLERİ — tutar, faiz, masraf ve aylık taksit karşılaştırması.
A5: Teklif ID | B5: Hedef Kredi ID | C5: Banka | D5: Tutar | E5: Para Birimi | F5: Vade Ay | G5: Nominal Faiz | H5: Toplam Masraf | I5: Aylık Taksit | J5: Öngörülen Maliyet | K5: Kontrol
A6: TKL-001 | B6: KRD-001 | C6: Yapı Kredi | D6: 8600000 | E6: TRY | F6: 30 | G6: 0.36 | H6: 180000 | I6: =IF(ISBLANK($A6),"",IF($D6="","",ROUND($D6/MAX(1,$F6),0))) | J6: =IF(ISBLANK($A6),"",IF($D6="","",$D6+$H6)) | K6: =IF(ISBLANK($A6),"",IF(OR(ISBLANK($B6),ISBLANK($C6),ISBLANK($D6),ISBLANK($E6),ISBLANK($F6),ISBLANK($G6),ISBLANK($H6)),"EKSİK","OK"))
A7: TKL-002 | B7: KRD-002 | C7: Türkiye İş Bankası | D7: 6200000 | E7: TRY | F7: 42 | G7: 0.34 | H7: 160000 | I7: =IF(ISBLANK($A7),"",IF($D7="","",ROUND($D7/MAX(1,$F7),0))) | J7: =IF(ISBLANK($A7),"",IF($D7="","",$D7+$H7)) | K7: =IF(ISBLANK($A7),"",IF(OR(ISBLANK($B7),ISBLANK($C7),ISBLANK($D7),ISBLANK($E7),ISBLANK($F7),ISBLANK($G7),ISBLANK($H7)),"EKSİK","OK"))
A8: TKL-003 | B8: KRD-003 | C8: Akbank | D8: 190000 | E8: USD | F8: 24 | G8: 0.085 | H8: 6000 | I8: =IF(ISBLANK($A8),"",IF($D8="","",ROUND($D8/MAX(1,$F8),0))) | J8: =IF(ISBLANK($A8),"",IF($D8="","",$D8+$H8)) | K8: =IF(ISBLANK($A8),"",IF(OR(ISBLANK($B8),ISBLANK($C8),ISBLANK($D8),ISBLANK($E8),ISBLANK($F8),ISBLANK($G8),ISBLANK($H8)),"EKSİK","OK"))
I9: =IF(ISBLANK($A9),"",IF($D9="","",ROUND($D9/MAX(1,$F9),0))) | J9: =IF(ISBLANK($A9),"",IF($D9="","",$D9+$H9)) | K9: =IF(ISBLANK($A9),"",IF(OR(ISBLANK($B9),ISBLANK($C9),ISBLANK($D9),ISBLANK($E9),ISBLANK($F9),ISBLANK($G9),ISBLANK($H9)),"EKSİK","OK"))
I10: =IF(ISBLANK($A10),"",IF($D10="","",ROUND($D10/MAX(1,$F10),0))) | J10: =IF(ISBLANK($A10),"",IF($D10="","",$D10+$H10)) | K10: =IF(ISBLANK($A10),"",IF(OR(ISBLANK($B10),ISBLANK($C10),ISBLANK($D10),ISBLANK($E10),ISBLANK($F10),ISBLANK($G10),ISBLANK($H10)),"EKSİK","OK"))
I11: =IF(ISBLANK($A11),"",IF($D11="","",ROUND($D11/MAX(1,$F11),0))) | J11: =IF(ISBLANK($A11),"",IF($D11="","",$D11+$H11)) | K11: =IF(ISBLANK($A11),"",IF(OR(ISBLANK($B11),ISBLANK($C11),ISBLANK($D11),ISBLANK($E11),ISBLANK($F11),ISBLANK($G11),ISBLANK($H11)),"EKSİK","OK"))
I12: =IF(ISBLANK($A12),"",IF($D12="","",ROUND($D12/MAX(1,$F12),0))) | J12: =IF(ISBLANK($A12),"",IF($D12="","",$D12+$H12)) | K12: =IF(ISBLANK($A12),"",IF(OR(ISBLANK($B12),ISBLANK($C12),ISBLANK($D12),ISBLANK($E12),ISBLANK($F12),ISBLANK($G12),ISBLANK($H12)),"EKSİK","OK"))
I13: =IF(ISBLANK($A13),"",IF($D13="","",ROUND($D13/MAX(1,$F13),0))) | J13: =IF(ISBLANK($A13),"",IF($D13="","",$D13+$H13)) | K13: =IF(ISBLANK($A13),"",IF(OR(ISBLANK($B13),ISBLANK($C13),ISBLANK($D13),ISBLANK($E13),ISBLANK($F13),ISBLANK($G13),ISBLANK($H13)),"EKSİK","OK"))
I14: =IF(ISBLANK($A14),"",IF($D14="","",ROUND($D14/MAX(1,$F14),0))) | J14: =IF(ISBLANK($A14),"",IF($D14="","",$D14+$H14)) | K14: =IF(ISBLANK($A14),"",IF(OR(ISBLANK($B14),ISBLANK($C14),ISBLANK($D14),ISBLANK($E14),ISBLANK($F14),ISBLANK($G14),ISBLANK($H14)),"EKSİK","OK"))
I15: =IF(ISBLANK($A15),"",IF($D15="","",ROUND($D15/MAX(1,$F15),0))) | J15: =IF(ISBLANK($A15),"",IF($D15="","",$D15+$H15)) | K15: =IF(ISBLANK($A15),"",IF(OR(ISBLANK($B15),ISBLANK($C15),ISBLANK($D15),ISBLANK($E15),ISBLANK($F15),ISBLANK($G15),ISBLANK($H15)),"EKSİK","OK"))
I16: =IF(ISBLANK($A16),"",IF($D16="","",ROUND($D16/MAX(1,$F16),0))) | J16: =IF(ISBLANK($A16),"",IF($D16="","",$D16+$H16)) | K16: =IF(ISBLANK($A16),"",IF(OR(ISBLANK($B16),ISBLANK($C16),ISBLANK($D16),ISBLANK($E16),ISBLANK($F16),ISBLANK($G16),ISBLANK($H16)),"EKSİK","OK"))
I17: =IF(ISBLANK($A17),"",IF($D17="","",ROUND($D17/MAX(1,$F17),0))) | J17: =IF(ISBLANK($A17),"",IF($D17="","",$D17+$H17)) | K17: =IF(ISBLANK($A17),"",IF(OR(ISBLANK($B17),ISBLANK($C17),ISBLANK($D17),ISBLANK($E17),ISBLANK($F17),ISBLANK($G17),ISBLANK($H17)),"EKSİK","OK"))
I18: =IF(ISBLANK($A18),"",IF($D18="","",ROUND($D18/MAX(1,$F18),0))) | J18: =IF(ISBLANK($A18),"",IF($D18="","",$D18+$H18)) | K18: =IF(ISBLANK($A18),"",IF(OR(ISBLANK($B18),ISBLANK($C18),ISBLANK($D18),ISBLANK($E18),ISBLANK($F18),ISBLANK($G18),ISBLANK($H18)),"EKSİK","OK"))
I19: =IF(ISBLANK($A19),"",IF($D19="","",ROUND($D19/MAX(1,$F19),0))) | J19: =IF(ISBLANK($A19),"",IF($D19="","",$D19+$H19)) | K19: =IF(ISBLANK($A19),"",IF(OR(ISBLANK($B19),ISBLANK($C19),ISBLANK($D19),ISBLANK($E19),ISBLANK($F19),ISBLANK($G19),ISBLANK($H19)),"EKSİK","OK"))
I20: =IF(ISBLANK($A20),"",IF($D20="","",ROUND($D20/MAX(1,$F20),0))) | J20: =IF(ISBLANK($A20),"",IF($D20="","",$D20+$H20)) | K20: =IF(ISBLANK($A20),"",IF(OR(ISBLANK($B20),ISBLANK($C20),ISBLANK($D20),ISBLANK($E20),ISBLANK($F20),ISBLANK($G20),ISBLANK($H20)),"EKSİK","OK"))
... I999: =IF(ISBLANK($A999),"",IF($D999="","",ROUND($D999/MAX(1,$F999),0))) | J999: =IF(ISBLANK($A999),"",IF($D999="","",$D999+$H999)) | K999: =IF(ISBLANK($A999),"",IF(OR(ISBLANK($B999),ISBLANK($C999),ISBLANK($D999),ISBLANK($E999),ISBLANK($F999),ISBLANK($G999),ISBLANK($H999)),"EKSİK","OK"))

Sheet ODEME_TAKVIMI
A1: ODEME TAKVIMI — BANKA, KREDİ VE TAKSİT TAKİP SİSTEMİ
A3: ÖDEME TAKVİMİ — yaklaşan taksitler 30 / 60 / 90 gün penceresinde.
A5: Kredi ID | B5: Banka | C5: Ödeme Tarihi | D5: Toplam Ödeme | E5: Kalan Gün | F5: Zaman Dilimi | G5: Ödeme Durumu
A6: =IF(ISBLANK(TAKSIT_PLANI!$A6),"",TAKSIT_PLANI!$B6) | B6: =IF(ISBLANK(TAKSIT_PLANI!$A6),"",INDEX(KREDILER!$B$6:$B$1000,MATCH(TAKSIT_PLANI!$B6,KREDILER!$A$6:$A$1000,0))) | C6: =IF(ISBLANK(TAKSIT_PLANI!$A6),"",TAKSIT_PLANI!$D6) | D6: =IF(ISBLANK(TAKSIT_PLANI!$A6),"",TAKSIT_PLANI!$I6) | E6: =IF(ISBLANK(TAKSIT_PLANI!$A6),"",TAKSIT_PLANI!$K6) | F6: =IF(ISBLANK(TAKSIT_PLANI!$A6),"",IF(TAKSIT_PLANI!$K6<0,"Vadesi Geçmiş",IF(TAKSIT_PLANI!$K6<=30,"0-30 Gün",IF(TAKSIT_PLANI!$K6<=60,"31-60 Gün","61 Gün ve Üzeri")))) | G6: =IF(ISBLANK(TAKSIT_PLANI!$A6),"",TAKSIT_PLANI!$J6)
A7: =IF(ISBLANK(TAKSIT_PLANI!$A7),"",TAKSIT_PLANI!$B7) | B7: =IF(ISBLANK(TAKSIT_PLANI!$A7),"",INDEX(KREDILER!$B$6:$B$1000,MATCH(TAKSIT_PLANI!$B7,KREDILER!$A$6:$A$1000,0))) | C7: =IF(ISBLANK(TAKSIT_PLANI!$A7),"",TAKSIT_PLANI!$D7) | D7: =IF(ISBLANK(TAKSIT_PLANI!$A7),"",TAKSIT_PLANI!$I7) | E7: =IF(ISBLANK(TAKSIT_PLANI!$A7),"",TAKSIT_PLANI!$K7) | F7: =IF(ISBLANK(TAKSIT_PLANI!$A7),"",IF(TAKSIT_PLANI!$K7<0,"Vadesi Geçmiş",IF(TAKSIT_PLANI!$K7<=30,"0-30 Gün",IF(TAKSIT_PLANI!$K7<=60,"31-60 Gün","61 Gün ve Üzeri")))) | G7: =IF(ISBLANK(TAKSIT_PLANI!$A7),"",TAKSIT_PLANI!$J7)
A8: =IF(ISBLANK(TAKSIT_PLANI!$A8),"",TAKSIT_PLANI!$B8) | B8: =IF(ISBLANK(TAKSIT_PLANI!$A8),"",INDEX(KREDILER!$B$6:$B$1000,MATCH(TAKSIT_PLANI!$B8,KREDILER!$A$6:$A$1000,0))) | C8: =IF(ISBLANK(TAKSIT_PLANI!$A8),"",TAKSIT_PLANI!$D8) | D8: =IF(ISBLANK(TAKSIT_PLANI!$A8),"",TAKSIT_PLANI!$I8) | E8: =IF(ISBLANK(TAKSIT_PLANI!$A8),"",TAKSIT_PLANI!$K8) | F8: =IF(ISBLANK(TAKSIT_PLANI!$A8),"",IF(TAKSIT_PLANI!$K8<0,"Vadesi Geçmiş",IF(TAKSIT_PLANI!$K8<=30,"0-30 Gün",IF(TAKSIT_PLANI!$K8<=60,"31-60 Gün","61 Gün ve Üzeri")))) | G8: =IF(ISBLANK(TAKSIT_PLANI!$A8),"",TAKSIT_PLANI!$J8)
A9: =IF(ISBLANK(TAKSIT_PLANI!$A9),"",TAKSIT_PLANI!$B9) | B9: =IF(ISBLANK(TAKSIT_PLANI!$A9),"",INDEX(KREDILER!$B$6:$B$1000,MATCH(TAKSIT_PLANI!$B9,KREDILER!$A$6:$A$1000,0))) | C9: =IF(ISBLANK(TAKSIT_PLANI!$A9),"",TAKSIT_PLANI!$D9) | D9: =IF(ISBLANK(TAKSIT_PLANI!$A9),"",TAKSIT_PLANI!$I9) | E9: =IF(ISBLANK(TAKSIT_PLANI!$A9),"",TAKSIT_PLANI!$K9) | F9: =IF(ISBLANK(TAKSIT_PLANI!$A9),"",IF(TAKSIT_PLANI!$K9<0,"Vadesi Geçmiş",IF(TAKSIT_PLANI!$K9<=30,"0-30 Gün",IF(TAKSIT_PLANI!$K9<=60,"31-60 Gün","61 Gün ve Üzeri")))) | G9: =IF(ISBLANK(TAKSIT_PLANI!$A9),"",TAKSIT_PLANI!$J9)
A10: =IF(ISBLANK(TAKSIT_PLANI!$A10),"",TAKSIT_PLANI!$B10) | B10: =IF(ISBLANK(TAKSIT_PLANI!$A10),"",INDEX(KREDILER!$B$6:$B$1000,MATCH(TAKSIT_PLANI!$B10,KREDILER!$A$6:$A$1000,0))) | C10: =IF(ISBLANK(TAKSIT_PLANI!$A10),"",TAKSIT_PLANI!$D10) | D10: =IF(ISBLANK(TAKSIT_PLANI!$A10),"",TAKSIT_PLANI!$I10) | E10: =IF(ISBLANK(TAKSIT_PLANI!$A10),"",TAKSIT_PLANI!$K10) | F10: =IF(ISBLANK(TAKSIT_PLANI!$A10),"",IF(TAKSIT_PLANI!$K10<0,"Vadesi Geçmiş",IF(TAKSIT_PLANI!$K10<=30,"0-30 Gün",IF(TAKSIT_PLANI!$K10<=60,"31-60 Gün","61 Gün ve Üzeri")))) | G10: =IF(ISBLANK(TAKSIT_PLANI!$A10),"",TAKSIT_PLANI!$J10)
A11: =IF(ISBLANK(TAKSIT_PLANI!$A11),"",TAKSIT_PLANI!$B11) | B11: =IF(ISBLANK(TAKSIT_PLANI!$A11),"",INDEX(KREDILER!$B$6:$B$1000,MATCH(TAKSIT_PLANI!$B11,KREDILER!$A$6:$A$1000,0))) | C11: =IF(ISBLANK(TAKSIT_PLANI!$A11),"",TAKSIT_PLANI!$D11) | D11: =IF(ISBLANK(TAKSIT_PLANI!$A11),"",TAKSIT_PLANI!$I11) | E11: =IF(ISBLANK(TAKSIT_PLANI!$A11),"",TAKSIT_PLANI!$K11) | F11: =IF(ISBLANK(TAKSIT_PLANI!$A11),"",IF(TAKSIT_PLANI!$K11<0,"Vadesi Geçmiş",IF(TAKSIT_PLANI!$K11<=30,"0-30 Gün",IF(TAKSIT_PLANI!$K11<=60,"31-60 Gün","61 Gün ve Üzeri")))) | G11: =IF(ISBLANK(TAKSIT_PLANI!$A11),"",TAKSIT_PLANI!$J11)
A12: =IF(ISBLANK(TAKSIT_PLANI!$A12),"",TAKSIT_PLANI!$B12) | B12: =IF(ISBLANK(TAKSIT_PLANI!$A12),"",INDEX(KREDILER!$B$6:$B$1000,MATCH(TAKSIT_PLANI!$B12,KREDILER!$A$6:$A$1000,0))) | C12: =IF(ISBLANK(TAKSIT_PLANI!$A12),"",TAKSIT_PLANI!$D12) | D12: =IF(ISBLANK(TAKSIT_PLANI!$A12),"",TAKSIT_PLANI!$I12) | E12: =IF(ISBLANK(TAKSIT_PLANI!$A12),"",TAKSIT_PLANI!$K12) | F12: =IF(ISBLANK(TAKSIT_PLANI!$A12),"",IF(TAKSIT_PLANI!$K12<0,"Vadesi Geçmiş",IF(TAKSIT_PLANI!$K12<=30,"0-30 Gün",IF(TAKSIT_PLANI!$K12<=60,"31-60 Gün","61 Gün ve Üzeri")))) | G12: =IF(ISBLANK(TAKSIT_PLANI!$A12),"",TAKSIT_PLANI!$J12)
A13: =IF(ISBLANK(TAKSIT_PLANI!$A13),"",TAKSIT_PLANI!$B13) | B13: =IF(ISBLANK(TAKSIT_PLANI!$A13),"",INDEX(KREDILER!$B$6:$B$1000,MATCH(TAKSIT_PLANI!$B13,KREDILER!$A$6:$A$1000,0))) | C13: =IF(ISBLANK(TAKSIT_PLANI!$A13),"",TAKSIT_PLANI!$D13) | D13: =IF(ISBLANK(TAKSIT_PLANI!$A13),"",TAKSIT_PLANI!$I13) | E13: =IF(ISBLANK(TAKSIT_PLANI!$A13),"",TAKSIT_PLANI!$K13) | F13: =IF(ISBLANK(TAKSIT_PLANI!$A13),"",IF(TAKSIT_PLANI!$K13<0,"Vadesi Geçmiş",IF(TAKSIT_PLANI!$K13<=30,"0-30 Gün",IF(TAKSIT_PLANI!$K13<=60,"31-60 Gün","61 Gün ve Üzeri")))) | G13: =IF(ISBLANK(TAKSIT_PLANI!$A13),"",TAKSIT_PLANI!$J13)
A14: =IF(ISBLANK(TAKSIT_PLANI!$A14),"",TAKSIT_PLANI!$B14) | B14: =IF(ISBLANK(TAKSIT_PLANI!$A14),"",INDEX(KREDILER!$B$6:$B$1000,MATCH(TAKSIT_PLANI!$B14,KREDILER!$A$6:$A$1000,0))) | C14: =IF(ISBLANK(TAKSIT_PLANI!$A14),"",TAKSIT_PLANI!$D14) | D14: =IF(ISBLANK(TAKSIT_PLANI!$A14),"",TAKSIT_PLANI!$I14) | E14: =IF(ISBLANK(TAKSIT_PLANI!$A14),"",TAKSIT_PLANI!$K14) | F14: =IF(ISBLANK(TAKSIT_PLANI!$A14),"",IF(TAKSIT_PLANI!$K14<0,"Vadesi Geçmiş",IF(TAKSIT_PLANI!$K14<=30,"0-30 Gün",IF(TAKSIT_PLANI!$K14<=60,"31-60 Gün","61 Gün ve Üzeri")))) | G14: =IF(ISBLANK(TAKSIT_PLANI!$A14),"",TAKSIT_PLANI!$J14)
A15: =IF(ISBLANK(TAKSIT_PLANI!$A15),"",TAKSIT_PLANI!$B15) | B15: =IF(ISBLANK(TAKSIT_PLANI!$A15),"",INDEX(KREDILER!$B$6:$B$1000,MATCH(TAKSIT_PLANI!$B15,KREDILER!$A$6:$A$1000,0))) | C15: =IF(ISBLANK(TAKSIT_PLANI!$A15),"",TAKSIT_PLANI!$D15) | D15: =IF(ISBLANK(TAKSIT_PLANI!$A15),"",TAKSIT_PLANI!$I15) | E15: =IF(ISBLANK(TAKSIT_PLANI!$A15),"",TAKSIT_PLANI!$K15) | F15: =IF(ISBLANK(TAKSIT_PLANI!$A15),"",IF(TAKSIT_PLANI!$K15<0,"Vadesi Geçmiş",IF(TAKSIT_PLANI!$K15<=30,"0-30 Gün",IF(TAKSIT_PLANI!$K15<=60,"31-60 Gün","61 Gün ve Üzeri")))) | G15: =IF(ISBLANK(TAKSIT_PLANI!$A15),"",TAKSIT_PLANI!$J15)
A16: =IF(ISBLANK(TAKSIT_PLANI!$A16),"",TAKSIT_PLANI!$B16) | B16: =IF(ISBLANK(TAKSIT_PLANI!$A16),"",INDEX(KREDILER!$B$6:$B$1000,MATCH(TAKSIT_PLANI!$B16,KREDILER!$A$6:$A$1000,0))) | C16: =IF(ISBLANK(TAKSIT_PLANI!$A16),"",TAKSIT_PLANI!$D16) | D16: =IF(ISBLANK(TAKSIT_PLANI!$A16),"",TAKSIT_PLANI!$I16) | E16: =IF(ISBLANK(TAKSIT_PLANI!$A16),"",TAKSIT_PLANI!$K16) | F16: =IF(ISBLANK(TAKSIT_PLANI!$A16),"",IF(TAKSIT_PLANI!$K16<0,"Vadesi Geçmiş",IF(TAKSIT_PLANI!$K16<=30,"0-30 Gün",IF(TAKSIT_PLANI!$K16<=60,"31-60 Gün","61 Gün ve Üzeri")))) | G16: =IF(ISBLANK(TAKSIT_PLANI!$A16),"",TAKSIT_PLANI!$J16)
A17: =IF(ISBLANK(TAKSIT_PLANI!$A17),"",TAKSIT_PLANI!$B17) | B17: =IF(ISBLANK(TAKSIT_PLANI!$A17),"",INDEX(KREDILER!$B$6:$B$1000,MATCH(TAKSIT_PLANI!$B17,KREDILER!$A$6:$A$1000,0))) | C17: =IF(ISBLANK(TAKSIT_PLANI!$A17),"",TAKSIT_PLANI!$D17) | D17: =IF(ISBLANK(TAKSIT_PLANI!$A17),"",TAKSIT_PLANI!$I17) | E17: =IF(ISBLANK(TAKSIT_PLANI!$A17),"",TAKSIT_PLANI!$K17) | F17: =IF(ISBLANK(TAKSIT_PLANI!$A17),"",IF(TAKSIT_PLANI!$K17<0,"Vadesi Geçmiş",IF(TAKSIT_PLANI!$K17<=30,"0-30 Gün",IF(TAKSIT_PLANI!$K17<=60,"31-60 Gün","61 Gün ve Üzeri")))) | G17: =IF(ISBLANK(TAKSIT_PLANI!$A17),"",TAKSIT_PLANI!$J17)
... A999: =IF(ISBLANK(TAKSIT_PLANI!$A999),"",TAKSIT_PLANI!$B999) | B999: =IF(ISBLANK(TAKSIT_PLANI!$A999),"",INDEX(KREDILER!$B$6:$B$1000,MATCH(TAKSIT_PLANI!$B999,KREDILER!$A$6:$A$1000,0))) | C999: =IF(ISBLANK(TAKSIT_PLANI!$A999),"",TAKSIT_PLANI!$D999) | D999: =IF(ISBLANK(TAKSIT_PLANI!$A999),"",TAKSIT_PLANI!$I999) | E999: =IF(ISBLANK(TAKSIT_PLANI!$A999),"",TAKSIT_PLANI!$K999) | F999: =IF(ISBLANK(TAKSIT_PLANI!$A999),"",IF(TAKSIT_PLANI!$K999<0,"Vadesi Geçmiş",IF(TAKSIT_PLANI!$K999<=30,"0-30 Gün",IF(TAKSIT_PLANI!$K999<=60,"31-60 Gün","61 Gün ve Üzeri")))) | G999: =IF(ISBLANK(TAKSIT_PLANI!$A999),"",TAKSIT_PLANI!$J999)

Sheet REFINANSMAN
A1: REFINANSMAN — BANKA, KREDİ VE TAKSİT TAKİP SİSTEMİ
A3: REFİNANSMAN ANALİZİ — aylık taksit rahatlaması ve toplam maliyet.
A5: Teklif ID | B5: Hedef Kredi ID | C5: Mevcut Aylık Taksit | D5: Yeni Aylık Taksit | E5: Aylık Taksit Farkı | F5: Nakit Rahatlaması | G5: Yeni Toplam Maliyet | H5: Mevcut Kalan Anapara | I5: Karar | J5: Kontrol
A6: =IF(ISBLANK(YENI_TEKLIFLER!$A6),"",YENI_TEKLIFLER!$A6) | B6: =IF(ISBLANK(YENI_TEKLIFLER!$A6),"",YENI_TEKLIFLER!$B6) | C6: =IF(ISBLANK(YENI_TEKLIFLER!$A6),"",SUMIFS(TAKSIT_PLANI!$I$6:$I$1000,TAKSIT_PLANI!$B$6:$B$1000,YENI_TEKLIFLER!$B6,TAKSIT_PLANI!$C$6:$C$1000,1)) | D6: =IF(ISBLANK(YENI_TEKLIFLER!$A6),"",YENI_TEKLIFLER!$I6) | E6: =IF(ISBLANK(YENI_TEKLIFLER!$A6),"",$C6-$D6) | F6: =IF(ISBLANK(YENI_TEKLIFLER!$A6),"",MAX(0,$E6)) | G6: =IF(ISBLANK(YENI_TEKLIFLER!$A6),"",YENI_TEKLIFLER!$J6) | H6: =IF(ISBLANK(YENI_TEKLIFLER!$A6),"",INDEX(KREDILER!$H$6:$H$1000,MATCH(YENI_TEKLIFLER!$B6,KREDILER!$A$6:$A$1000,0))) | I6: =IF(ISBLANK(YENI_TEKLIFLER!$A6),"",IF($E6>0,"ADAY","DEĞİL")) | J6: =IF(ISBLANK(YENI_TEKLIFLER!$A6),"",IF(OR(ISBLANK($B6),ISBLANK($C6),ISBLANK($D6),ISBLANK($E6),ISBLANK($F6),ISBLANK($G6),ISBLANK($H6)),"EKSİK","OK"))
A7: =IF(ISBLANK(YENI_TEKLIFLER!$A7),"",YENI_TEKLIFLER!$A7) | B7: =IF(ISBLANK(YENI_TEKLIFLER!$A7),"",YENI_TEKLIFLER!$B7) | C7: =IF(ISBLANK(YENI_TEKLIFLER!$A7),"",SUMIFS(TAKSIT_PLANI!$I$6:$I$1000,TAKSIT_PLANI!$B$6:$B$1000,YENI_TEKLIFLER!$B7,TAKSIT_PLANI!$C$6:$C$1000,1)) | D7: =IF(ISBLANK(YENI_TEKLIFLER!$A7),"",YENI_TEKLIFLER!$I7) | E7: =IF(ISBLANK(YENI_TEKLIFLER!$A7),"",$C7-$D7) | F7: =IF(ISBLANK(YENI_TEKLIFLER!$A7),"",MAX(0,$E7)) | G7: =IF(ISBLANK(YENI_TEKLIFLER!$A7),"",YENI_TEKLIFLER!$J7) | H7: =IF(ISBLANK(YENI_TEKLIFLER!$A7),"",INDEX(KREDILER!$H$6:$H$1000,MATCH(YENI_TEKLIFLER!$B7,KREDILER!$A$6:$A$1000,0))) | I7: =IF(ISBLANK(YENI_TEKLIFLER!$A7),"",IF($E7>0,"ADAY","DEĞİL")) | J7: =IF(ISBLANK(YENI_TEKLIFLER!$A7),"",IF(OR(ISBLANK($B7),ISBLANK($C7),ISBLANK($D7),ISBLANK($E7),ISBLANK($F7),ISBLANK($G7),ISBLANK($H7)),"EKSİK","OK"))
A8: =IF(ISBLANK(YENI_TEKLIFLER!$A8),"",YENI_TEKLIFLER!$A8) | B8: =IF(ISBLANK(YENI_TEKLIFLER!$A8),"",YENI_TEKLIFLER!$B8) | C8: =IF(ISBLANK(YENI_TEKLIFLER!$A8),"",SUMIFS(TAKSIT_PLANI!$I$6:$I$1000,TAKSIT_PLANI!$B$6:$B$1000,YENI_TEKLIFLER!$B8,TAKSIT_PLANI!$C$6:$C$1000,1)) | D8: =IF(ISBLANK(YENI_TEKLIFLER!$A8),"",YENI_TEKLIFLER!$I8) | E8: =IF(ISBLANK(YENI_TEKLIFLER!$A8),"",$C8-$D8) | F8: =IF(ISBLANK(YENI_TEKLIFLER!$A8),"",MAX(0,$E8)) | G8: =IF(ISBLANK(YENI_TEKLIFLER!$A8),"",YENI_TEKLIFLER!$J8) | H8: =IF(ISBLANK(YENI_TEKLIFLER!$A8),"",INDEX(KREDILER!$H$6:$H$1000,MATCH(YENI_TEKLIFLER!$B8,KREDILER!$A$6:$A$1000,0))) | I8: =IF(ISBLANK(YENI_TEKLIFLER!$A8),"",IF($E8>0,"ADAY","DEĞİL")) | J8: =IF(ISBLANK(YENI_TEKLIFLER!$A8),"",IF(OR(ISBLANK($B8),ISBLANK($C8),ISBLANK($D8),ISBLANK($E8),ISBLANK($F8),ISBLANK($G8),ISBLANK($H8)),"EKSİK","OK"))
A9: =IF(ISBLANK(YENI_TEKLIFLER!$A9),"",YENI_TEKLIFLER!$A9) | B9: =IF(ISBLANK(YENI_TEKLIFLER!$A9),"",YENI_TEKLIFLER!$B9) | C9: =IF(ISBLANK(YENI_TEKLIFLER!$A9),"",SUMIFS(TAKSIT_PLANI!$I$6:$I$1000,TAKSIT_PLANI!$B$6:$B$1000,YENI_TEKLIFLER!$B9,TAKSIT_PLANI!$C$6:$C$1000,1)) | D9: =IF(ISBLANK(YENI_TEKLIFLER!$A9),"",YENI_TEKLIFLER!$I9) | E9: =IF(ISBLANK(YENI_TEKLIFLER!$A9),"",$C9-$D9) | F9: =IF(ISBLANK(YENI_TEKLIFLER!$A9),"",MAX(0,$E9)) | G9: =IF(ISBLANK(YENI_TEKLIFLER!$A9),"",YENI_TEKLIFLER!$J9) | H9: =IF(ISBLANK(YENI_TEKLIFLER!$A9),"",INDEX(KREDILER!$H$6:$H$1000,MATCH(YENI_TEKLIFLER!$B9,KREDILER!$A$6:$A$1000,0))) | I9: =IF(ISBLANK(YENI_TEKLIFLER!$A9),"",IF($E9>0,"ADAY","DEĞİL")) | J9: =IF(ISBLANK(YENI_TEKLIFLER!$A9),"",IF(OR(ISBLANK($B9),ISBLANK($C9),ISBLANK($D9),ISBLANK($E9),ISBLANK($F9),ISBLANK($G9),ISBLANK($H9)),"EKSİK","OK"))
A10: =IF(ISBLANK(YENI_TEKLIFLER!$A10),"",YENI_TEKLIFLER!$A10) | B10: =IF(ISBLANK(YENI_TEKLIFLER!$A10),"",YENI_TEKLIFLER!$B10) | C10: =IF(ISBLANK(YENI_TEKLIFLER!$A10),"",SUMIFS(TAKSIT_PLANI!$I$6:$I$1000,TAKSIT_PLANI!$B$6:$B$1000,YENI_TEKLIFLER!$B10,TAKSIT_PLANI!$C$6:$C$1000,1)) | D10: =IF(ISBLANK(YENI_TEKLIFLER!$A10),"",YENI_TEKLIFLER!$I10) | E10: =IF(ISBLANK(YENI_TEKLIFLER!$A10),"",$C10-$D10) | F10: =IF(ISBLANK(YENI_TEKLIFLER!$A10),"",MAX(0,$E10)) | G10: =IF(ISBLANK(YENI_TEKLIFLER!$A10),"",YENI_TEKLIFLER!$J10) | H10: =IF(ISBLANK(YENI_TEKLIFLER!$A10),"",INDEX(KREDILER!$H$6:$H$1000,MATCH(YENI_TEKLIFLER!$B10,KREDILER!$A$6:$A$1000,0))) | I10: =IF(ISBLANK(YENI_TEKLIFLER!$A10),"",IF($E10>0,"ADAY","DEĞİL")) | J10: =IF(ISBLANK(YENI_TEKLIFLER!$A10),"",IF(OR(ISBLANK($B10),ISBLANK($C10),ISBLANK($D10),ISBLANK($E10),ISBLANK($F10),ISBLANK($G10),ISBLANK($H10)),"EKSİK","OK"))
A11: =IF(ISBLANK(YENI_TEKLIFLER!$A11),"",YENI_TEKLIFLER!$A11) | B11: =IF(ISBLANK(YENI_TEKLIFLER!$A11),"",YENI_TEKLIFLER!$B11) | C11: =IF(ISBLANK(YENI_TEKLIFLER!$A11),"",SUMIFS(TAKSIT_PLANI!$I$6:$I$1000,TAKSIT_PLANI!$B$6:$B$1000,YENI_TEKLIFLER!$B11,TAKSIT_PLANI!$C$6:$C$1000,1)) | D11: =IF(ISBLANK(YENI_TEKLIFLER!$A11),"",YENI_TEKLIFLER!$I11) | E11: =IF(ISBLANK(YENI_TEKLIFLER!$A11),"",$C11-$D11) | F11: =IF(ISBLANK(YENI_TEKLIFLER!$A11),"",MAX(0,$E11)) | G11: =IF(ISBLANK(YENI_TEKLIFLER!$A11),"",YENI_TEKLIFLER!$J11) | H11: =IF(ISBLANK(YENI_TEKLIFLER!$A11),"",INDEX(KREDILER!$H$6:$H$1000,MATCH(YENI_TEKLIFLER!$B11,KREDILER!$A$6:$A$1000,0))) | I11: =IF(ISBLANK(YENI_TEKLIFLER!$A11),"",IF($E11>0,"ADAY","DEĞİL")) | J11: =IF(ISBLANK(YENI_TEKLIFLER!$A11),"",IF(OR(ISBLANK($B11),ISBLANK($C11),ISBLANK($D11),ISBLANK($E11),ISBLANK($F11),ISBLANK($G11),ISBLANK($H11)),"EKSİK","OK"))
A12: =IF(ISBLANK(YENI_TEKLIFLER!$A12),"",YENI_TEKLIFLER!$A12) | B12: =IF(ISBLANK(YENI_TEKLIFLER!$A12),"",YENI_TEKLIFLER!$B12) | C12: =IF(ISBLANK(YENI_TEKLIFLER!$A12),"",SUMIFS(TAKSIT_PLANI!$I$6:$I$1000,TAKSIT_PLANI!$B$6:$B$1000,YENI_TEKLIFLER!$B12,TAKSIT_PLANI!$C$6:$C$1000,1)) | D12: =IF(ISBLANK(YENI_TEKLIFLER!$A12),"",YENI_TEKLIFLER!$I12) | E12: =IF(ISBLANK(YENI_TEKLIFLER!$A12),"",$C12-$D12) | F12: =IF(ISBLANK(YENI_TEKLIFLER!$A12),"",MAX(0,$E12)) | G12: =IF(ISBLANK(YENI_TEKLIFLER!$A12),"",YENI_TEKLIFLER!$J12) | H12: =IF(ISBLANK(YENI_TEKLIFLER!$A12),"",INDEX(KREDILER!$H$6:$H$1000,MATCH(YENI_TEKLIFLER!$B12,KREDILER!$A$6:$A$1000,0))) | I12: =IF(ISBLANK(YENI_TEKLIFLER!$A12),"",IF($E12>0,"ADAY","DEĞİL")) | J12: =IF(ISBLANK(YENI_TEKLIFLER!$A12),"",IF(OR(ISBLANK($B12),ISBLANK($C12),ISBLANK($D12),ISBLANK($E12),ISBLANK($F12),ISBLANK($G12),ISBLANK($H12)),"EKSİK","OK"))
A13: =IF(ISBLANK(YENI_TEKLIFLER!$A13),"",YENI_TEKLIFLER!$A13) | B13: =IF(ISBLANK(YENI_TEKLIFLER!$A13),"",YENI_TEKLIFLER!$B13) | C13: =IF(ISBLANK(YENI_TEKLIFLER!$A13),"",SUMIFS(TAKSIT_PLANI!$I$6:$I$1000,TAKSIT_PLANI!$B$6:$B$1000,YENI_TEKLIFLER!$B13,TAKSIT_PLANI!$C$6:$C$1000,1)) | D13: =IF(ISBLANK(YENI_TEKLIFLER!$A13),"",YENI_TEKLIFLER!$I13) | E13: =IF(ISBLANK(YENI_TEKLIFLER!$A13),"",$C13-$D13) | F13: =IF(ISBLANK(YENI_TEKLIFLER!$A13),"",MAX(0,$E13)) | G13: =IF(ISBLANK(YENI_TEKLIFLER!$A13),"",YENI_TEKLIFLER!$J13) | H13: =IF(ISBLANK(YENI_TEKLIFLER!$A13),"",INDEX(KREDILER!$H$6:$H$1000,MATCH(YENI_TEKLIFLER!$B13,KREDILER!$A$6:$A$1000,0))) | I13: =IF(ISBLANK(YENI_TEKLIFLER!$A13),"",IF($E13>0,"ADAY","DEĞİL")) | J13: =IF(ISBLANK(YENI_TEKLIFLER!$A13),"",IF(OR(ISBLANK($B13),ISBLANK($C13),ISBLANK($D13),ISBLANK($E13),ISBLANK($F13),ISBLANK($G13),ISBLANK($H13)),"EKSİK","OK"))
A14: =IF(ISBLANK(YENI_TEKLIFLER!$A14),"",YENI_TEKLIFLER!$A14) | B14: =IF(ISBLANK(YENI_TEKLIFLER!$A14),"",YENI_TEKLIFLER!$B14) | C14: =IF(ISBLANK(YENI_TEKLIFLER!$A14),"",SUMIFS(TAKSIT_PLANI!$I$6:$I$1000,TAKSIT_PLANI!$B$6:$B$1000,YENI_TEKLIFLER!$B14,TAKSIT_PLANI!$C$6:$C$1000,1)) | D14: =IF(ISBLANK(YENI_TEKLIFLER!$A14),"",YENI_TEKLIFLER!$I14) | E14: =IF(ISBLANK(YENI_TEKLIFLER!$A14),"",$C14-$D14) | F14: =IF(ISBLANK(YENI_TEKLIFLER!$A14),"",MAX(0,$E14)) | G14: =IF(ISBLANK(YENI_TEKLIFLER!$A14),"",YENI_TEKLIFLER!$J14) | H14: =IF(ISBLANK(YENI_TEKLIFLER!$A14),"",INDEX(KREDILER!$H$6:$H$1000,MATCH(YENI_TEKLIFLER!$B14,KREDILER!$A$6:$A$1000,0))) | I14: =IF(ISBLANK(YENI_TEKLIFLER!$A14),"",IF($E14>0,"ADAY","DEĞİL")) | J14: =IF(ISBLANK(YENI_TEKLIFLER!$A14),"",IF(OR(ISBLANK($B14),ISBLANK($C14),ISBLANK($D14),ISBLANK($E14),ISBLANK($F14),ISBLANK($G14),ISBLANK($H14)),"EKSİK","OK"))
A15: =IF(ISBLANK(YENI_TEKLIFLER!$A15),"",YENI_TEKLIFLER!$A15) | B15: =IF(ISBLANK(YENI_TEKLIFLER!$A15),"",YENI_TEKLIFLER!$B15) | C15: =IF(ISBLANK(YENI_TEKLIFLER!$A15),"",SUMIFS(TAKSIT_PLANI!$I$6:$I$1000,TAKSIT_PLANI!$B$6:$B$1000,YENI_TEKLIFLER!$B15,TAKSIT_PLANI!$C$6:$C$1000,1)) | D15: =IF(ISBLANK(YENI_TEKLIFLER!$A15),"",YENI_TEKLIFLER!$I15) | E15: =IF(ISBLANK(YENI_TEKLIFLER!$A15),"",$C15-$D15) | F15: =IF(ISBLANK(YENI_TEKLIFLER!$A15),"",MAX(0,$E15)) | G15: =IF(ISBLANK(YENI_TEKLIFLER!$A15),"",YENI_TEKLIFLER!$J15) | H15: =IF(ISBLANK(YENI_TEKLIFLER!$A15),"",INDEX(KREDILER!$H$6:$H$1000,MATCH(YENI_TEKLIFLER!$B15,KREDILER!$A$6:$A$1000,0))) | I15: =IF(ISBLANK(YENI_TEKLIFLER!$A15),"",IF($E15>0,"ADAY","DEĞİL")) | J15: =IF(ISBLANK(YENI_TEKLIFLER!$A15),"",IF(OR(ISBLANK($B15),ISBLANK($C15),ISBLANK($D15),ISBLANK($E15),ISBLANK($F15),ISBLANK($G15),ISBLANK($H15)),"EKSİK","OK"))
A16: =IF(ISBLANK(YENI_TEKLIFLER!$A16),"",YENI_TEKLIFLER!$A16) | B16: =IF(ISBLANK(YENI_TEKLIFLER!$A16),"",YENI_TEKLIFLER!$B16) | C16: =IF(ISBLANK(YENI_TEKLIFLER!$A16),"",SUMIFS(TAKSIT_PLANI!$I$6:$I$1000,TAKSIT_PLANI!$B$6:$B$1000,YENI_TEKLIFLER!$B16,TAKSIT_PLANI!$C$6:$C$1000,1)) | D16: =IF(ISBLANK(YENI_TEKLIFLER!$A16),"",YENI_TEKLIFLER!$I16) | E16: =IF(ISBLANK(YENI_TEKLIFLER!$A16),"",$C16-$D16) | F16: =IF(ISBLANK(YENI_TEKLIFLER!$A16),"",MAX(0,$E16)) | G16: =IF(ISBLANK(YENI_TEKLIFLER!$A16),"",YENI_TEKLIFLER!$J16) | H16: =IF(ISBLANK(YENI_TEKLIFLER!$A16),"",INDEX(KREDILER!$H$6:$H$1000,MATCH(YENI_TEKLIFLER!$B16,KREDILER!$A$6:$A$1000,0))) | I16: =IF(ISBLANK(YENI_TEKLIFLER!$A16),"",IF($E16>0,"ADAY","DEĞİL")) | J16: =IF(ISBLANK(YENI_TEKLIFLER!$A16),"",IF(OR(ISBLANK($B16),ISBLANK($C16),ISBLANK($D16),ISBLANK($E16),ISBLANK($F16),ISBLANK($G16),ISBLANK($H16)),"EKSİK","OK"))
A17: =IF(ISBLANK(YENI_TEKLIFLER!$A17),"",YENI_TEKLIFLER!$A17) | B17: =IF(ISBLANK(YENI_TEKLIFLER!$A17),"",YENI_TEKLIFLER!$B17) | C17: =IF(ISBLANK(YENI_TEKLIFLER!$A17),"",SUMIFS(TAKSIT_PLANI!$I$6:$I$1000,TAKSIT_PLANI!$B$6:$B$1000,YENI_TEKLIFLER!$B17,TAKSIT_PLANI!$C$6:$C$1000,1)) | D17: =IF(ISBLANK(YENI_TEKLIFLER!$A17),"",YENI_TEKLIFLER!$I17) | E17: =IF(ISBLANK(YENI_TEKLIFLER!$A17),"",$C17-$D17) | F17: =IF(ISBLANK(YENI_TEKLIFLER!$A17),"",MAX(0,$E17)) | G17: =IF(ISBLANK(YENI_TEKLIFLER!$A17),"",YENI_TEKLIFLER!$J17) | H17: =IF(ISBLANK(YENI_TEKLIFLER!$A17),"",INDEX(KREDILER!$H$6:$H$1000,MATCH(YENI_TEKLIFLER!$B17,KREDILER!$A$6:$A$1000,0))) | I17: =IF(ISBLANK(YENI_TEKLIFLER!$A17),"",IF($E17>0,"ADAY","DEĞİL")) | J17: =IF(ISBLANK(YENI_TEKLIFLER!$A17),"",IF(OR(ISBLANK($B17),ISBLANK($C17),ISBLANK($D17),ISBLANK($E17),ISBLANK($F17),ISBLANK($G17),ISBLANK($H17)),"EKSİK","OK"))
... A999: =IF(ISBLANK(YENI_TEKLIFLER!$A999),"",YENI_TEKLIFLER!$A999) | B999: =IF(ISBLANK(YENI_TEKLIFLER!$A999),"",YENI_TEKLIFLER!$B999) | C999: =IF(ISBLANK(YENI_TEKLIFLER!$A999),"",SUMIFS(TAKSIT_PLANI!$I$6:$I$1000,TAKSIT_PLANI!$B$6:$B$1000,YENI_TEKLIFLER!$B999,TAKSIT_PLANI!$C$6:$C$1000,1)) | D999: =IF(ISBLANK(YENI_TEKLIFLER!$A999),"",YENI_TEKLIFLER!$I999) | E999: =IF(ISBLANK(YENI_TEKLIFLER!$A999),"",$C999-$D999) | F999: =IF(ISBLANK(YENI_TEKLIFLER!$A999),"",MAX(0,$E999)) | G999: =IF(ISBLANK(YENI_TEKLIFLER!$A999),"",YENI_TEKLIFLER!$J999) | H999: =IF(ISBLANK(YENI_TEKLIFLER!$A999),"",INDEX(KREDILER!$H$6:$H$1000,MATCH(YENI_TEKLIFLER!$B999,KREDILER!$A$6:$A$1000,0))) | I999: =IF(ISBLANK(YENI_TEKLIFLER!$A999),"",IF($E999>0,"ADAY","DEĞİL")) | J999: =IF(ISBLANK(YENI_TEKLIFLER!$A999),"",IF(OR(ISBLANK($B999),ISBLANK($C999),ISBLANK($D999),ISBLANK($E999),ISBLANK($F999),ISBLANK($G999),ISBLANK($H999)),"EKSİK","OK"))

Sheet KONTROLLER
A1: KONTROLLER — BANKA, KREDİ VE TAKSİT TAKİP SİSTEMİ
A3: VERİ KALİTESİ VE SİSTEM SAĞLIĞI
A6: Veri Kalite Skoru | B6: =ROUND(100-(B9+B10+B11)*UyariPuanKesintisi,0)
A7: Durum | B7: =IF(B6>=VeriKaliteYuksek,"SAĞLIKLI",IF(B6>=VeriKaliteOrta,"İZLEME GEREKLİ","DÜZELTME GEREKLİ"))
A8: Genel Karar | B8: =IF(B6>=VeriKaliteYuksek,"UYGUN",IF(B6>=VeriKaliteOrta,"İNCELE","DURDUR"))
A9: Eksik Zorunlu Alan | B9: =COUNTIF(BANKALAR!$I$6:$I$1000,"EKSİK")+COUNTIF(LIMITLER!$I$6:$I$1000,"EKSİK")+COUNTIF(KREDILER!$N$6:$N$1000,"EKSİK")+COUNTIF(TAKSIT_PLANI!$L$6:$L$1000,"EKSİK")
A10: Sıfır/Negatif Tutar | B10: =COUNTIF(LIMITLER!$G$6:$G$1000,"<0")+COUNTIF(KREDILER!$H$6:$H$1000,"<=0")+COUNTIF(TAKSIT_PLANI!$I$6:$I$1000,"<=0")
A11: Mükerrer Kredi ID | B11: =COUNTIF(KREDILER!$A$6:$A$1000,KREDILER!$A$6)>1
A12: Kayıt Sayısı (Kredi) | B12: =COUNTA(KREDILER!$A$6:$A$1000)
A13: Kayıt Sayısı (Taksit) | B13: =COUNTA(TAKSIT_PLANI!$A$6:$A$1000)
A14: Mutabakat Tutuyor | B14: =IF(B9+B10+B11=0,"UYGUN","SAĞLAM DEĞİL")
A18: Not: Mutabakat kontrolü, veri kalite skorunu düşüren ihlal sayısını ölçer. Her ihlal skordan düşer.

Sheet KARAR_MOTORU
A1: KARAR MOTORU — BANKA, KREDİ VE TAKSİT TAKİP SİSTEMİ
A3: KARAR MOTORU — borç yükü, yaklaşan taksit ve öncelikli aksiyon
A5: Toplam Finansal Borç | B5: =SUM(KREDILER!$H$6:$H$1000)
A6: Aylık Borç Servisi | B6: =SUMIFS(TAKSIT_PLANI!$I$6:$I$1000,TAKSIT_PLANI!$D$6:$D$1000,">="&RaporTarihi,TAKSIT_PLANI!$D$6:$D$1000,"<"&RaporTarihi+30)
A7: 30 Günlük Ödeme Yükü | B7: =SUMIFS(TAKSIT_PLANI!$I$6:$I$1000,TAKSIT_PLANI!$D$6:$D$1000,">="&RaporTarihi,TAKSIT_PLANI!$D$6:$D$1000,"<="&RaporTarihi+30,TAKSIT_PLANI!$J$6:$J$1000,"<>Ödendi")
A8: 90 Günlük Ödeme Yükü | B8: =SUMIFS(TAKSIT_PLANI!$I$6:$I$1000,TAKSIT_PLANI!$D$6:$D$1000,">="&RaporTarihi,TAKSIT_PLANI!$D$6:$D$1000,"<="&RaporTarihi+AYARLAR!$B$25,TAKSIT_PLANI!$J$6:$J$1000,"<>Ödendi")
A9: Ağırlıklı Maliyet | B9: =SUMPRODUCT(KREDILER!$H$6:$H$1000,KREDILER!$I$6:$I$1000)/MAX(1,SUM(KREDILER!$H$6:$H$1000))
A10: Döviz Borcu | B10: =SUMIFS(KREDILER!$H$6:$H$1000,KREDILER!$E$6:$E$1000,"<>TRY")
A11: Kaldıraç (Borç/Kâr) | B11: =MAX(1,SUM(KREDILER!$H$6:$H$1000))/MAX(1,YillikFaaliyetKari)
A12: Teminat Oranı | B12: =MAX(1,SUM(KREDILER!$H$6:$H$1000))/MAX(1,SUM(TEMINATLAR!$F$6:$F$1000))
A13: Borç Servisi / Nakit | B13: =B6/MAX(1,AylikFaaliyetNakdi)
A14: Likidite Baskısı (30G/Serbest) | B14: =B7/MAX(1,SerbestNakit)
A15: Karar | B15: =IF(B14>LikiditeEsigi,"DURDUR",IF(B10>YillikDovizGeliri,"İNCELE",IF(B11>KaldiracEsigi,"İNCELE","UYGUN")))
A16: Risk Seviyesi | B16: =IF(B15="DURDUR","KRİTİK",IF(B15="İNCELE","YÜKSEK","DÜŞÜK"))
A17: Önerilen Aksiyon | B17: =IF(B15="DURDUR","Ödeme baskısını düşürün: erken kapama, refinansman veya ek limit değerlendirin",IF(B15="İNCELE","Döviz uyumu ve kaldıraç eşiklerini gözden geçirin, aday teklifleri müzakereye alın","Borç yapısı sürdürülebilir: ödeme takvimini düzenli izleyin"))
A18: Refinansman Aday Sayısı | B18: =COUNTIF(REFINANSMAN!$I$6:$I$1000,"ADAY")
A19: Aylık Taksit Rahatlaması | B19: =SUMIFS(REFINANSMAN!$F$6:$F$1000,REFINANSMAN!$I$6:$I$1000,"ADAY")
A22: Not: Karar; likidite baskısı, döviz uyumu ve kaldıraç eşiklerine göre makine tarafından üretilir. Tüm eşikler AYARLAR sayfasından yönetilir.

Sheet PANO
A1: PANO — BANKA, KREDİ VE TAKSİT TAKİP SİSTEMİ
A3: YÖNETİCİ BORÇ VE LİKİDİTE PANELİ — tek ekranda karar
A5: Toplam Finansal Borç | B5: =KARAR_MOTORU!$B$5 | D5: ÖNEMLİ UYARILAR
A6: Aylık Borç Servisi | B6: =KARAR_MOTORU!$B$6 | D6: Bu sistem karar destek aracıdır; kesin finansal tavsiye değildir. Gerçekleşme verilere ve varsayımlara bağlıdır.
A7: 30 Günlük Ödeme Yükü | B7: =KARAR_MOTORU!$B$7
A8: Ağırlıklı Maliyet | B8: =KARAR_MOTORU!$B$9
A9: Döviz Borcu | B9: =KARAR_MOTORU!$B$10
A10: Kaldıraç (Borç/Kâr) | B10: =KARAR_MOTORU!$B$11
A11: Teminat Oranı | B11: =KARAR_MOTORU!$B$12
A12: Veri Kalite Skoru | B12: =KONTROLLER!$B$6
A13: Karar | B13: =KARAR_MOTORU!$B$15
A14: Risk Seviyesi | B14: =KARAR_MOTORU!$B$16
G19: Banka | H19: Bakiye
G20: Türkiye İş Bankası | H20: =SUMIFS(KREDILER!$H$6:$H$1000,KREDILER!$B$6:$B$1000,"Türkiye İş Bankası")
G21: Akbank | H21: =SUMIFS(KREDILER!$H$6:$H$1000,KREDILER!$B$6:$B$1000,"Akbank")
G22: Garanti BBVA | H22: =SUMIFS(KREDILER!$H$6:$H$1000,KREDILER!$B$6:$B$1000,"Garanti BBVA")
G23: Yapı Kredi | H23: =SUMIFS(KREDILER!$H$6:$H$1000,KREDILER!$B$6:$B$1000,"Yapı Kredi")
G25: Ay | H25: Ödeme
G26: Önümüzdeki Ay | H26: =SUMIFS(TAKSIT_PLANI!$I$6:$I$1000,TAKSIT_PLANI!$D$6:$D$1000,">="&RaporTarihi+AYARLAR!$B$22,TAKSIT_PLANI!$D$6:$D$1000,"<"&RaporTarihi+AYARLAR!$B$23)
G27: İkinci Ay | H27: =SUMIFS(TAKSIT_PLANI!$I$6:$I$1000,TAKSIT_PLANI!$D$6:$D$1000,">="&RaporTarihi+AYARLAR!$B$23,TAKSIT_PLANI!$D$6:$D$1000,"<"&RaporTarihi+AYARLAR!$B$24)
G28: Üçüncü Ay | H28: =SUMIFS(TAKSIT_PLANI!$I$6:$I$1000,TAKSIT_PLANI!$D$6:$D$1000,">="&RaporTarihi+AYARLAR!$B$24,TAKSIT_PLANI!$D$6:$D$1000,"<"&RaporTarihi+AYARLAR!$B$25)
G29: Dördüncü Ay | H29: =SUMIFS(TAKSIT_PLANI!$I$6:$I$1000,TAKSIT_PLANI!$D$6:$D$1000,">="&RaporTarihi+AYARLAR!$B$25,TAKSIT_PLANI!$D$6:$D$1000,"<"&RaporTarihi+AYARLAR!$B$26)
G30: Beşinci Ay | H30: =SUMIFS(TAKSIT_PLANI!$I$6:$I$1000,TAKSIT_PLANI!$D$6:$D$1000,">="&RaporTarihi+AYARLAR!$B$26,TAKSIT_PLANI!$D$6:$D$1000,"<"&RaporTarihi+AYARLAR!$B$27)
G31: Altıncı Ay | H31: =SUMIFS(TAKSIT_PLANI!$I$6:$I$1000,TAKSIT_PLANI!$D$6:$D$1000,">="&RaporTarihi+AYARLAR!$B$27,TAKSIT_PLANI!$D$6:$D$1000,"<"&RaporTarihi+AYARLAR!$B$28)
G32: Pencere | H32: Ödeme
G33: 30 Gün | H33: =SUMIFS(TAKSIT_PLANI!$I$6:$I$1000,TAKSIT_PLANI!$D$6:$D$1000,">="&RaporTarihi,TAKSIT_PLANI!$D$6:$D$1000,"<="&RaporTarihi+AYARLAR!$B$23)
G34: 60 Gün | H34: =SUMIFS(TAKSIT_PLANI!$I$6:$I$1000,TAKSIT_PLANI!$D$6:$D$1000,">="&RaporTarihi,TAKSIT_PLANI!$D$6:$D$1000,"<="&RaporTarihi+AYARLAR!$B$24)
G35: 90 Gün | H35: =SUMIFS(TAKSIT_PLANI!$I$6:$I$1000,TAKSIT_PLANI!$D$6:$D$1000,">="&RaporTarihi,TAKSIT_PLANI!$D$6:$D$1000,"<="&RaporTarihi+AYARLAR!$B$25)
G37: Ürün Türü | H37: Bakiye
G38: Taksitli Ticari Kredi | H38: =SUMIFS(KREDILER!$H$6:$H$1000,KREDILER!$D$6:$D$1000,"Taksitli Ticari Kredi")
