Workbook

Sheet KAPAK
A1: KAPAK — Vergi/SGK Borcunu Tecil Etmeli Miyim? (Kredi mi Tecil mi?)
A3: Vergi/SGK Borcunu Tecil Etmeli Miyim? (Kredi mi Tecil mi?)
A4: Vergi ve SGK borçlarınızı girin; tecil, banka kredisi ve peşin ödeme seçeneklerinin toplam maliyetini ve bugünkü değerini karşılaştırın; size en uygun ödeme yoluna karar verin.
A6: Bu ürün ne sağlar?
A7: • Borç aslı, gecikme zammı ve vade yapısını tek tabloda izler; toplam borç ve aylık zam yükünü hesaplar
A8: • Tecil (vadeye yayma), banka kredisi ve peşin ödeme seçeneklerinin toplam maliyetini hesaplar
A9: • Seçenekleri bugünkü değerine (NBD) indirgeyerek en ucuz ödeme yolunu belirler
A10: • Tecil faizi, kredi faizi ve iskonto oranına göre senaryo bant aralığı ve tornado analizi
A11: • Borç türü yoğunlaşması, anomali ve veri kalite skoru ile karar kapısı ve aksiyon önerisi
A14: Kimler için?
A15: • Vergi ve SGK borcu için tecil başvurusu değerlendiren mükellefler
A16: • Borcunu kredi ile kapatmayı düşünen işletme sahipleri ve finans yöneticileri
... A21: Sürüm 1.0.0 | 2026 | ExcelArşiv | Lisans: Tek kullanıcı

Sheet HIZLI_BASLANGIC
A1: HIZLI BASLANGIC — Vergi/SGK Borcunu Tecil Etmeli Miyim? (Kredi mi Tecil mi?)
A3: Nasıl kullanılır?
A5: Adım 1 — Borçlarınızı girin | B5: BORC_LISTESI sayfasındaki sarı hücrelere borç türü, borç aslı, gecikme zammı, vade tarihi ve aylık zam oranını girin.
A6: Adım 2 — Seçenekleri izleyin | B6: HESAP sayfası tecil, kredi ve peşin ödeme seçeneklerinin toplam maliyetini ve NBD'sini hesaplar.
A7: Adım 3 — Kararı değerlendirin | B7: KARAR sayfası en düşük maliyetli ödeme yolunu gerekçesiyle önerir.
A8: Adım 4 — Oranları ayarlayın | B8: Tecil faizi, kredi faizi, iskonto oranı ve terkin oranı AYARLAR sayfasından değiştirilir.
A11: Sık yapılan hatalar
A12: • Gecikme zammını borç aslının dışında eksik girmek (toplam borç eksik çıkar)
A13: • Vade tarihini rapor tarihinden sonra bırakmak (geciken ay sıfır görünür)
A14: • Aylık zam oranını yüzde yerine 1'in üzerinde ondalık girmek (zam yükü şişer)
A15: Bu dosya karar destek aracıdır; tecil başvurusu sonucu bağlayıcı değildir.

Sheet BORC_LISTESI
A1: BORC LISTESI — Vergi/SGK Borcunu Tecil Etmeli Miyim? (Kredi mi Tecil mi?)
A3: Vergi ve SGK Borç Listesi
A4: Sarı hücrelere manuel veri girin. Her satır bir vergi/SGK borç kalemidir; geciken ay, toplam borç ve aylık zam yükü otomatik hesaplanır.
A5: Borç Kodu | B5: Borç Türü | C5: Borç Aslı (TL) | D5: Gecikme Zammı (TL) | E5: Vade Tarihi | F5: Aylık Zam Oranı | G5: Geciken Ay | H5: Toplam Borç (TL) | I5: Aylık Zam Yükü (TL) | J5: Açıklama
A6: V-1001 | B6: KDV | C6: 150000 | D6: 42000 | E6: 45742 | F6: 0.04 | G6: =IF($E6="",0,MAX(0,ROUNDDOWN((TecilRaporTarihi-$E6)/30,0))) -> 16 | H6: =IF($C6="",0,$C6+$D6) -> 192000 | I6: =IF($C6="",0,$C6*$F6) -> 6000 | J6: =IF($B6="","",CONCATENATE("Borç: ",$B6," | Toplam: ",TEXT($H6,"#,##0"))) -> Borç: KDV | Toplam: 192.000
A7: V-1002 | B7: Muhtasar Stopaj | C7: 80000 | D7: 19000 | E7: 45834 | F7: 0.04 | G7: =IF($E7="",0,MAX(0,ROUNDDOWN((TecilRaporTarihi-$E7)/30,0))) -> 13 | H7: =IF($C7="",0,$C7+$D7) -> 99000 | I7: =IF($C7="",0,$C7*$F7) -> 3200 | J7: =IF($B7="","",CONCATENATE("Borç: ",$B7," | Toplam: ",TEXT($H7,"#,##0"))) -> Borç: Muhtasar Stopaj | Toplam: 99.000
A8: V-1003 | B8: Kurumlar Vergisi | C8: 240000 | D8: 61000 | E8: 45808 | F8: 0.04 | G8: =IF($E8="",0,MAX(0,ROUNDDOWN((TecilRaporTarihi-$E8)/30,0))) -> 14 | H8: =IF($C8="",0,$C8+$D8) -> 301000 | I8: =IF($C8="",0,$C8*$F8) -> 9600 | J8: =IF($B8="","",CONCATENATE("Borç: ",$B8," | Toplam: ",TEXT($H8,"#,##0"))) -> Borç: Kurumlar Vergisi | Toplam: 301.000
A9: S-2001 | B9: SGK Primi | C9: 120000 | D9: 31000 | E9: 45900 | F9: 0.03 | G9: =IF($E9="",0,MAX(0,ROUNDDOWN((TecilRaporTarihi-$E9)/30,0))) -> 11 | H9: =IF($C9="",0,$C9+$D9) -> 151000 | I9: =IF($C9="",0,$C9*$F9) -> 3600 | J9: =IF($B9="","",CONCATENATE("Borç: ",$B9," | Toplam: ",TEXT($H9,"#,##0"))) -> Borç: SGK Primi | Toplam: 151.000
A10: S-2002 | B10: SGK Cezası | C10: 40000 | D10: 14000 | E10: 45961 | F10: 0.04 | G10: =IF($E10="",0,MAX(0,ROUNDDOWN((TecilRaporTarihi-$E10)/30,0))) -> 9 | H10: =IF($C10="",0,$C10+$D10) -> 54000 | I10: =IF($C10="",0,$C10*$F10) -> 1600 | J10: =IF($B10="","",CONCATENATE("Borç: ",$B10," | Toplam: ",TEXT($H10,"#,##0"))) -> Borç: SGK Cezası | Toplam: 54.000
A11: V-1004 | B11: Gelir Vergisi | C11: 60000 | D11: 9000 | E11: 45991 | F11: 0.04 | G11: =IF($E11="",0,MAX(0,ROUNDDOWN((TecilRaporTarihi-$E11)/30,0))) -> 8 | H11: =IF($C11="",0,$C11+$D11) -> 69000 | I11: =IF($C11="",0,$C11*$F11) -> 2400 | J11: =IF($B11="","",CONCATENATE("Borç: ",$B11," | Toplam: ",TEXT($H11,"#,##0"))) -> Borç: Gelir Vergisi | Toplam: 69.000
A12: V-1005 | B12: KDV | C12: 90000 | D12: 8000 | E12: 46079 | F12: 0.04 | G12: =IF($E12="",0,MAX(0,ROUNDDOWN((TecilRaporTarihi-$E12)/30,0))) -> 5 | H12: =IF($C12="",0,$C12+$D12) -> 98000 | I12: =IF($C12="",0,$C12*$F12) -> 3600 | J12: =IF($B12="","",CONCATENATE("Borç: ",$B12," | Toplam: ",TEXT($H12,"#,##0"))) -> Borç: KDV | Toplam: 98.000
G13: =IF($E13="",0,MAX(0,ROUNDDOWN((TecilRaporTarihi-$E13)/30,0))) -> 0 | H13: =IF($C13="",0,$C13+$D13) -> 0 | I13: =IF($C13="",0,$C13*$F13) -> 0 | J13: =IF($B13="","",CONCATENATE("Borç: ",$B13," | Toplam: ",TEXT($H13,"#,##0")))
G14: =IF($E14="",0,MAX(0,ROUNDDOWN((TecilRaporTarihi-$E14)/30,0))) -> 0 | H14: =IF($C14="",0,$C14+$D14) -> 0 | I14: =IF($C14="",0,$C14*$F14) -> 0 | J14: =IF($B14="","",CONCATENATE("Borç: ",$B14," | Toplam: ",TEXT($H14,"#,##0")))
G15: =IF($E15="",0,MAX(0,ROUNDDOWN((TecilRaporTarihi-$E15)/30,0))) -> 0 | H15: =IF($C15="",0,$C15+$D15) -> 0 | I15: =IF($C15="",0,$C15*$F15) -> 0 | J15: =IF($B15="","",CONCATENATE("Borç: ",$B15," | Toplam: ",TEXT($H15,"#,##0")))
G16: =IF($E16="",0,MAX(0,ROUNDDOWN((TecilRaporTarihi-$E16)/30,0))) -> 0 | H16: =IF($C16="",0,$C16+$D16) -> 0 | I16: =IF($C16="",0,$C16*$F16) -> 0 | J16: =IF($B16="","",CONCATENATE("Borç: ",$B16," | Toplam: ",TEXT($H16,"#,##0")))
G17: =IF($E17="",0,MAX(0,ROUNDDOWN((TecilRaporTarihi-$E17)/30,0))) -> 0 | H17: =IF($C17="",0,$C17+$D17) -> 0 | I17: =IF($C17="",0,$C17*$F17) -> 0 | J17: =IF($B17="","",CONCATENATE("Borç: ",$B17," | Toplam: ",TEXT($H17,"#,##0")))
G18: =IF($E18="",0,MAX(0,ROUNDDOWN((TecilRaporTarihi-$E18)/30,0))) -> 0 | H18: =IF($C18="",0,$C18+$D18) -> 0 | I18: =IF($C18="",0,$C18*$F18) -> 0 | J18: =IF($B18="","",CONCATENATE("Borç: ",$B18," | Toplam: ",TEXT($H18,"#,##0")))
G19: =IF($E19="",0,MAX(0,ROUNDDOWN((TecilRaporTarihi-$E19)/30,0))) -> 0 | H19: =IF($C19="",0,$C19+$D19) -> 0 | I19: =IF($C19="",0,$C19*$F19) -> 0 | J19: =IF($B19="","",CONCATENATE("Borç: ",$B19," | Toplam: ",TEXT($H19,"#,##0")))
G20: =IF($E20="",0,MAX(0,ROUNDDOWN((TecilRaporTarihi-$E20)/30,0))) -> 0 | H20: =IF($C20="",0,$C20+$D20) -> 0 | I20: =IF($C20="",0,$C20*$F20) -> 0 | J20: =IF($B20="","",CONCATENATE("Borç: ",$B20," | Toplam: ",TEXT($H20,"#,##0")))
G21: =IF($E21="",0,MAX(0,ROUNDDOWN((TecilRaporTarihi-$E21)/30,0))) -> 0 | H21: =IF($C21="",0,$C21+$D21) -> 0 | I21: =IF($C21="",0,$C21*$F21) -> 0 | J21: =IF($B21="","",CONCATENATE("Borç: ",$B21," | Toplam: ",TEXT($H21,"#,##0")))
G22: =IF($E22="",0,MAX(0,ROUNDDOWN((TecilRaporTarihi-$E22)/30,0))) -> 0 | H22: =IF($C22="",0,$C22+$D22) -> 0 | I22: =IF($C22="",0,$C22*$F22) -> 0 | J22: =IF($B22="","",CONCATENATE("Borç: ",$B22," | Toplam: ",TEXT($H22,"#,##0")))
G23: =IF($E23="",0,MAX(0,ROUNDDOWN((TecilRaporTarihi-$E23)/30,0))) -> 0 | H23: =IF($C23="",0,$C23+$D23) -> 0 | I23: =IF($C23="",0,$C23*$F23) -> 0 | J23: =IF($B23="","",CONCATENATE("Borç: ",$B23," | Toplam: ",TEXT($H23,"#,##0")))
G24: =IF($E24="",0,MAX(0,ROUNDDOWN((TecilRaporTarihi-$E24)/30,0))) -> 0 | H24: =IF($C24="",0,$C24+$D24) -> 0 | I24: =IF($C24="",0,$C24*$F24) -> 0 | J24: =IF($B24="","",CONCATENATE("Borç: ",$B24," | Toplam: ",TEXT($H24,"#,##0")))
... G1004: =IF($E1004="",0,MAX(0,ROUNDDOWN((TecilRaporTarihi-$E1004)/30,0))) -> 0 | H1004: =IF($C1004="",0,$C1004+$D1004) -> 0 | I1004: =IF($C1004="",0,$C1004*$F1004) -> 0 | J1004: =IF($B1004="","",CONCATENATE("Borç: ",$B1004," | Toplam: ",TEXT($H1004,"#,##0")))
A1006: Sarı hücreler manuel giriştir; formül hücreleri kilitli ve korumalıdır.

Sheet HESAP
A1: HESAP — Vergi/SGK Borcunu Tecil Etmeli Miyim? (Kredi mi Tecil mi?)
A3: Borç Türü Bazlı Özet ve Ödeme Seçeneği Motoru
A4: Aşağıdaki özet borç listesinden otomatik beslenir; seçenek hesapları AYARLAR'daki oranlarla canlı üretilir.
A5: Borç Türü | B5: Asıl Toplam | C5: Zam Toplam | D5: Toplam Borç | E5: Aylık Zam Yükü | F5: Ortalama Geciken Ay
A6: Gelir Vergisi | B6: =SUMIFS(tblBorc[Borç Aslı (TL)],tblBorc[Borç Türü],$A6) -> 60000 | C6: =SUMIFS(tblBorc[Gecikme Zammı (TL)],tblBorc[Borç Türü],$A6) -> 9000 | D6: =SUMIFS(tblBorc[Toplam Borç (TL)],tblBorc[Borç Türü],$A6) -> 69000 | E6: =SUMIFS(tblBorc[Aylık Zam Yükü (TL)],tblBorc[Borç Türü],$A6) -> 2400 | F6: =IFERROR(AVERAGEIFS(tblBorc[Geciken Ay],tblBorc[Borç Türü],$A6),0) -> 8
A7: Kurumlar Vergisi | B7: =SUMIFS(tblBorc[Borç Aslı (TL)],tblBorc[Borç Türü],$A7) -> 240000 | C7: =SUMIFS(tblBorc[Gecikme Zammı (TL)],tblBorc[Borç Türü],$A7) -> 61000 | D7: =SUMIFS(tblBorc[Toplam Borç (TL)],tblBorc[Borç Türü],$A7) -> 301000 | E7: =SUMIFS(tblBorc[Aylık Zam Yükü (TL)],tblBorc[Borç Türü],$A7) -> 9600 | F7: =IFERROR(AVERAGEIFS(tblBorc[Geciken Ay],tblBorc[Borç Türü],$A7),0) -> 14
A8: KDV | B8: =SUMIFS(tblBorc[Borç Aslı (TL)],tblBorc[Borç Türü],$A8) -> 240000 | C8: =SUMIFS(tblBorc[Gecikme Zammı (TL)],tblBorc[Borç Türü],$A8) -> 50000 | D8: =SUMIFS(tblBorc[Toplam Borç (TL)],tblBorc[Borç Türü],$A8) -> 290000 | E8: =SUMIFS(tblBorc[Aylık Zam Yükü (TL)],tblBorc[Borç Türü],$A8) -> 9600 | F8: =IFERROR(AVERAGEIFS(tblBorc[Geciken Ay],tblBorc[Borç Türü],$A8),0) -> 10.5
A9: Muhtasar Stopaj | B9: =SUMIFS(tblBorc[Borç Aslı (TL)],tblBorc[Borç Türü],$A9) -> 80000 | C9: =SUMIFS(tblBorc[Gecikme Zammı (TL)],tblBorc[Borç Türü],$A9) -> 19000 | D9: =SUMIFS(tblBorc[Toplam Borç (TL)],tblBorc[Borç Türü],$A9) -> 99000 | E9: =SUMIFS(tblBorc[Aylık Zam Yükü (TL)],tblBorc[Borç Türü],$A9) -> 3200 | F9: =IFERROR(AVERAGEIFS(tblBorc[Geciken Ay],tblBorc[Borç Türü],$A9),0) -> 13
A10: SGK Primi | B10: =SUMIFS(tblBorc[Borç Aslı (TL)],tblBorc[Borç Türü],$A10) -> 120000 | C10: =SUMIFS(tblBorc[Gecikme Zammı (TL)],tblBorc[Borç Türü],$A10) -> 31000 | D10: =SUMIFS(tblBorc[Toplam Borç (TL)],tblBorc[Borç Türü],$A10) -> 151000 | E10: =SUMIFS(tblBorc[Aylık Zam Yükü (TL)],tblBorc[Borç Türü],$A10) -> 3600 | F10: =IFERROR(AVERAGEIFS(tblBorc[Geciken Ay],tblBorc[Borç Türü],$A10),0) -> 11
A11: SGK Cezası | B11: =SUMIFS(tblBorc[Borç Aslı (TL)],tblBorc[Borç Türü],$A11) -> 40000 | C11: =SUMIFS(tblBorc[Gecikme Zammı (TL)],tblBorc[Borç Türü],$A11) -> 14000 | D11: =SUMIFS(tblBorc[Toplam Borç (TL)],tblBorc[Borç Türü],$A11) -> 54000 | E11: =SUMIFS(tblBorc[Aylık Zam Yükü (TL)],tblBorc[Borç Türü],$A11) -> 1600 | F11: =IFERROR(AVERAGEIFS(tblBorc[Geciken Ay],tblBorc[Borç Türü],$A11),0) -> 9
A12: Diğer | B12: =SUMIFS(tblBorc[Borç Aslı (TL)],tblBorc[Borç Türü],$A12) -> 0 | C12: =SUMIFS(tblBorc[Gecikme Zammı (TL)],tblBorc[Borç Türü],$A12) -> 0 | D12: =SUMIFS(tblBorc[Toplam Borç (TL)],tblBorc[Borç Türü],$A12) -> 0 | E12: =SUMIFS(tblBorc[Aylık Zam Yükü (TL)],tblBorc[Borç Türü],$A12) -> 0 | F12: =IFERROR(AVERAGEIFS(tblBorc[Geciken Ay],tblBorc[Borç Türü],$A12),0) -> 0
A14: TOPLAM BLOK
A15: Toplam Borç Aslı (TL) | B15: =SUM(B6:B12) -> 780000
A16: Toplam Gecikme Zammı (TL) | B16: =SUM(C6:C12) -> 184000
A17: TOPLAM BORÇ (TL) | B17: =SUM(D6:D12) -> 964000
A18: Toplam Aylık Zam Yükü (TL) | B18: =SUM(E6:E12) -> 30000
A19: Ortalama Geciken Ay | B19: =IFERROR(AVERAGE(tblBorc[Geciken Ay]),0) -> 0.076076076
A20: Borç Kalemi Sayısı | B20: =COUNTA(tblBorc[Borç Kodu]) -> 7
A21: Borç Türü Sayısı (farklı) | B21: =IFERROR(SUMPRODUCT((tblBorc[Borç Türü]<>"")/COUNTIF(tblBorc[Borç Türü],tblBorc[Borç Türü]&"")),0) -> 6
A23: TECİL SEÇENEĞİ (6183/48 kapsamında vadeye yayma)
A24: Peşinat Oranı | B24: =AYARLAR!$B$11 -> 0.1
A25: Peşinat Tutarı (TL) | B25: =B17*B24 -> 96400
A26: Tecil Anaparası (TL) | B26: =B17-B25 -> 867600
A27: Aylık Tecil Faizi | B27: =AYARLAR!$B$13/12 -> 0.015
A28: Tecil Taksit Sayısı | B28: =AYARLAR!$B$12 -> 12
A29: Aylık Taksit (TL) | B29: =IF(OR(B26<=0,B28=0),0,B26*B27/(1-(1+B27)^-B28)) -> 79541.562
A30: Tecil Toplam Maliyet (TL) | B30: =B29*B28+B25 -> 1050898.7
A32: KREDİ SEÇENEĞİ (bankadan borcu kapatacak kredi)
A33: Kredi Komisyon Oranı | B33: =AYARLAR!$B$15 -> 0.02
A34: Komisyon Tutarı (TL) | B34: =B17*B33 -> 19280
A35: Kredi Anaparası (TL) | B35: =B17 -> 964000
A36: Aylık Kredi Faizi | B36: =AYARLAR!$B$14/12 -> 0.029166667
A37: Kredi Taksit Sayısı | B37: =AYARLAR!$B$16 -> 12
A38: Aylık Taksit (TL) | B38: =IF(OR(B35<=0,B37=0),0,B35*B36/(1-(1+B36)^-B37)) -> 96364.32
A39: Kredi Toplam Maliyet (TL) | B39: =B38*B37+B34 -> 1175651.8
A41: PEŞİN ÖDEME SEÇENEĞİ (yapılandırma terkinli)
A42: Gecikme Zammı Terkin Oranı | B42: =AYARLAR!$B$18 -> 0.5
A43: Terkin Tutarı (TL) | B43: =B16*B42 -> 92000
A44: Peşin Ödeme (TL) | B44: =B17-B43 -> 872000
A46: SEÇENEK KARŞILAŞTIRMASI
...

Sheet ANALITIK_MOTOR
A1: ANALITIK MOTOR — Vergi/SGK Borcunu Tecil Etmeli Miyim? (Kredi mi Tecil mi?)
A3: ANALİTİK MOTOR — DERİNLİK KATMANI
A5: Kod | B5: Gösterge | C5: Değer | D5: Makine Yorumu
A6: T1 | B6: Ortalama Gecikme Zammı Oranı | C6: =IFERROR(AVERAGE(tblBorc[Gecikme Zammı (TL)])/AVERAGE(tblBorc[Borç Aslı (TL)]),0) -> 0.23589744 | D6: =_xlfn.TEXTJOIN("; ",TRUE(),"Ortalama gecikme zammı oranı ",TEXT(C6,"0.0%")," — zammın borç aslına oranı vade yapısının ne kadar esnediğini gösterir") -> Ortalama gecikme zammı oranı ; 24%; — zammın borç aslına oranı vade yapısının ne kadar esnediğini gösterir
A7: T2 | B7: Ortalama Toplam Borç | C7: =IFERROR(AVERAGE(tblBorc[Toplam Borç (TL)]),0) -> 964.96496 | D7: =_xlfn.TEXTJOIN("; ",TRUE(),"Ortalama toplam borç kalemi ",TEXT(C7,"₺ #,##0")," TL — borç portföyünün ortalama büyüklüğünü gösterir") -> Ortalama toplam borç kalemi ; ₺ 964,965; TL — borç portföyünün ortalama büyüklüğünü gösterir
A8: O1 | B8: Toplam Borç Sapması (MAD) | C8: =IFERROR(AVEDEV(tblBorc[Toplam Borç (TL)]),0) -> 1916.4069 | D8: =_xlfn.TEXTJOIN("; ",TRUE(),"Toplam borç ortalama mutlak sapması ",TEXT(C8,"₺ #,##0")," TL — sapma yüksekse borç kalemleri heterojendir") -> Toplam borç ortalama mutlak sapması ; ₺ 1916,407; TL — sapma yüksekse borç kalemleri heterojendir
A9: O2 | B9: En Yüksek Borç Kalemi | C9: =IFERROR(MAX(tblBorc[Toplam Borç (TL)]),0) -> 301000 | D9: =_xlfn.TEXTJOIN("; ",TRUE(),"En yüksek toplam borç kalemi ",TEXT(C9,"₺ #,##0")," TL — bu kalem tecil/kredi kararında önceliklidir") -> En yüksek toplam borç kalemi ; ₺ 301000,000; TL — bu kalem tecil/kredi kararında önceliklidir
A10: O3 | B10: Senaryo Bant Genişliği | C10: =SENARYO_DUYARLILIK!C11 -> -115712.15 | D10: =_xlfn.TEXTJOIN("; ",TRUE(),"İyimser ile kritik senaryo tecil maliyet farkı ",TEXT(C10,"₺ #,##0")," TL — faiz belirsizliğinin etkisini gösterir") -> İyimser ile kritik senaryo tecil maliyet farkı ; -₺ 115712,145; TL — faiz belirsizliğinin etkisini gösterir
A11: O6 | B11: Borç Yoğunlaşması (HHI) | C11: =IFERROR(IF(SUM(HESAP!$D$6:$D$12)=0,0,SUMPRODUCT((HESAP!$D$6:$D$12/SUM(HESAP!$D$6:$D$12))^2)),0) -> 0.23133641 | D11: =_xlfn.TEXTJOIN("; ",TRUE(),"Borç yoğunlaşma endeksi ",TEXT(C11,"0.000")," — 1 e yaklaştıkça borç tek türde toplanır") -> Borç yoğunlaşma endeksi ; 0.000; — 1 e yaklaştıkça borç tek türde toplanır
A12: O8 | B12: Veri Kalite Skoru | C12: =KONTROLLER!B19 -> 100 | D12: =_xlfn.TEXTJOIN("; ",TRUE(),"Veri kalite skoru ",TEXT(C12,"0")," puan — ",IF(C12>=TecilKaliteIyi,"yüksek güven","veri girişi tamamlanmalı")) -> Veri kalite skoru ; 100; puan — ; yüksek güven
A13: I1 | B13: Gelecek Dönem Borç Tahmini | C13: =PANO!B30 -> 0 | D13: =_xlfn.TEXTJOIN("; ",TRUE(),"Gelecek dönem toplam borç tahmini ",TEXT(C13,"₺ #,##0")," TL — güven bandı için alt/üst sınır PANO sayfasındadır") -> Gelecek dönem toplam borç tahmini ; ₺ ,000; TL — güven bandı için alt/üst sınır PANO sayfasındadır
A14: I2 | B14: Toplam Borç Yüzdelik P90 | C14: =IFERROR(_xlfn.PERCENTILE.INC(tblBorc[Toplam Borç (TL)],TecilP90Oran),0) -> 0 | D14: =_xlfn.TEXTJOIN("; ",TRUE(),"Toplam borç kalemlerinin %90 ı ",TEXT(C14,"₺ #,##0")," TL altında gerçekleşir — üst sınır planlamada kullanılabilir") -> Toplam borç kalemlerinin %90 ı ; ₺ ,000; TL altında gerçekleşir — üst sınır planlamada kullanılabilir
A15: I3 | B15: NBD Farkı (Tecil − Kredi) | C15: =HESAP!B58 -> -95443.891 | D15: =_xlfn.TEXTJOIN("; ",TRUE(),"NBD farkı ",TEXT(C15,"₺ #,##0")," TL — fark pozitifse tecil bugünkü değerde daha pahalı, kredi avantajlıdır") -> NBD farkı ; -₺ 95443,891; TL — fark pozitifse tecil bugünkü değerde daha pahalı, kredi avantajlıdır

Sheet KONTROLLER
A1: KONTROLLER — Vergi/SGK Borcunu Tecil Etmeli Miyim? (Kredi mi Tecil mi?)
A3: Giriş Kalite Kontrolleri
A4: Aşağıdaki kontroller canlı formüllerle çalışır; sorun varsa uyarı üretir.
A6: Boş borç aslı satırı var mı? | B6: =IF(COUNTBLANK(tblBorc[Borç Aslı (TL)])=0,"TEMİZ","BOŞ VAR") -> BOŞ VAR
A7: Negatif borç aslı var mı? | B7: =IF(COUNTIF(tblBorc[Borç Aslı (TL)],"<0")=0,"TEMİZ","NEGATİF VAR") -> TEMİZ
A8: Negatif gecikme zammı var mı? | B8: =IF(COUNTIF(tblBorc[Gecikme Zammı (TL)],"<0")=0,"TEMİZ","NEGATİF VAR") -> TEMİZ
A9: Vadesi 36 aydan eski borç var mı? | B9: =IF(COUNTIF(tblBorc[Geciken Ay],">36")=0,"TEMİZ","GEÇİKMİŞ") -> TEMİZ
A10: Aylık zam oranı 1'in üzerinde mi? | B10: =IF(COUNTIF(tblBorc[Aylık Zam Oranı],">1")=0,"TEMİZ","ORAN >1 VAR") -> TEMİZ
A11: Toplam borç eşiği aşılıyor mu? | B11: =IF(HESAP!B17>TecilYuksekBorcEsik,"AŞIYOR","NORMAL") -> AŞIYOR
A12: Tecil taksiti aylık nakit akışını aşıyor mu? | B12: =IF(HESAP!B29>AYARLAR!$B$27,"AŞIYOR","NORMAL") -> NORMAL
A13: NBD farkı hangi tarafı işaret ediyor? | B13: =IF(HESAP!B58<0,"KREDİ AVANTAJLI","TECİL AVANTAJLI") -> KREDİ AVANTAJLI
A15: Veri Kalitesi Skoru (0-100)
A16: Temel giriş kolonlarının dolu olma oranına göre üretilen kalite skoru.
A17: Toplam Giriş Hücresi | B17: =COUNTA(tblBorc[Borç Türü])*TecilTemelKolonSayisi -> 35
A18: Dolu Giriş Hücresi | B18: =COUNTA(tblBorc[Borç Türü])+COUNTA(tblBorc[Borç Aslı (TL)])+COUNTA(tblBorc[Gecikme Zammı (TL)])+COUNTA(tblBorc[Vade Tarihi])+COUNTA(tblBorc[Aylık Zam Oranı]) -> 35
A19: Kalite Skoru | B19: =ROUND(IF(TecilToplamGiris=0,0,TecilDoluGiris/TecilToplamGiris*100),0) -> 100
A20: Kalite Seviyesi | B20: =IF(B19>=TecilKaliteIyi,"YÜKSEK",IF(B19>=TecilKaliteOrta,"ORTA","DÜŞÜK")) -> YÜKSEK
A22: Kontroller yalnızca giriş verisini denetler; değerleri değiştirmez.

Sheet KARAR
A1: KARAR — Vergi/SGK Borcunu Tecil Etmeli Miyim? (Kredi mi Tecil mi?)
A3: Karar Kapısı — Tecil mi, Kredi mi, Peşin mi?
A4: Toplam maliyet, bugünkü değer farkı ve kredi erişimine göre üretilen karar.
A6: Toplam Borç (TL) | B6: =HESAP!B17 -> 964000
A7: En Düşük Maliyetli Seçenek | B7: =HESAP!B50 -> PEŞİN
A8: En Düşük Maliyet (TL) | B8: =HESAP!B51 -> 872000
A9: NBD Farkı (Tecil − Kredi) (TL) | B9: =HESAP!B58 -> -95443.891
A11: KARAR | B11: =IF(COUNTA(tblBorc[Borç Aslı (TL)])=0,"VERİ YOK",IF(OR(COUNTIF(tblBorc[Borç Aslı (TL)],"<0")>0,COUNTIF(tblBorc[Gecikme Zammı (TL)],"<0")>0),"DURDUR",IF(HESAP!B17<=0,"VERİ YOK",IF(AYARLAR!$B$17="Hayır",IF(HESAP!B49<=HESAP!B30,"PEŞİN ÖDE","TECİL YAP"),IF(HESAP!B50="TECİL","TECİL YAP",IF(HESAP!B50="PEŞİN","PEŞİN ÖDE","KREDİ KULLAN")))))) -> PEŞİN ÖDE
A12: Gerekçe | B12: =IF(COUNTIF(tblBorc[Borç Aslı (TL)],"<0")>0,"Negatif borç aslı girişi tespit edildi; veriler mutlaka düzeltilmeli.",IF(COUNTIF(tblBorc[Gecikme Zammı (TL)],"<0")>0,"Negatif gecikme zammı girişi tespit edildi; veriler mutlaka düzeltilmeli.",IF(HESAP!B17<=0,"Borç kaydı bulunmuyor; ödeme yolu kararı üretilemiyor.",IF(AYARLAR!$B$17="Hayır",IF(HESAP!B49<=HESAP!B30,"Peşin ödeme toplam maliyeti tecilden düşük; borç peşin kapatılabilir.","Tecil toplam maliyeti peşin ödemenin altında; krediye erişim olmadığından tecil önerilir."),IF(HESAP!B50="TECİL","Tecil toplam maliyeti hem kredi hem peşin ödemeden düşük; tecil en avantajlı yoldur.",IF(HESAP!B50="PEŞİN","Peşin ödeme toplam maliyeti en düşük; terkin avantajıyla borç tek seferde kapatılabilir.","Kredi toplam maliyeti en düşük; borç kredi ile kapatılıp vadeye yayılabilir.")))))) -> Peşin ödeme toplam maliyeti en düşük; terkin avantajıyla borç tek seferde kapatılabilir.
A14: Önerilen Aksiyonlar
A15: Aksiyon 1 | B15: =TecilAksiyon1_ACIKLAMA -> Karara göre önerilen aksiyon.
A16: Aksiyon 2 | B16: =TecilAksiyon2_ACIKLAMA -> Karara göre önerilen aksiyon.
A17: Aksiyon 3 | B17: =TecilAksiyon3_ACIKLAMA -> Karara göre önerilen aksiyon.
A19: Karar yalnızca giriş verisi ve AYARLAR'daki oran/eşiklerden türetilir; tecil başvuru sonucu bağlayıcı değildir.

Sheet PANO
A1: PANO — Vergi/SGK Borcunu Tecil Etmeli Miyim? (Kredi mi Tecil mi?)
A3: Yönetim Paneli | B3: Toplam Borç (TL) | C3: Tecil Toplam (TL) | D3: Kredi Toplam (TL) | E3: Peşin Ödeme (TL) | F3: En Düşük Seçenek | G3: NBD Farkı (TL)
B4: =HESAP!B17 -> 964000 | C4: =HESAP!B30 -> 1050898.7 | D4: =HESAP!B39 -> 1175651.8 | E4: =HESAP!B44 -> 872000 | F4: =HESAP!B50 -> PEŞİN | G4: =HESAP!B58 -> -95443.891
A6: Karar | B6: =KARAR!B11 -> PEŞİN ÖDE | D6: Kalite Skoru | E6: =KONTROLLER!B19 -> 100 | G6: Borç Kalemi | H6: =HESAP!B20 -> 7
A10: Borç Türü | B10: Asıl Toplam (TL) | C10: Zam Toplam (TL) | D10: Toplam Borç (TL) | E10: Aylık Zam Yükü (TL)
A11: Gelir Vergisi | B11: =HESAP!B6 -> 60000 | C11: =HESAP!C6 -> 9000 | D11: =HESAP!D6 -> 69000 | E11: =HESAP!E6 -> 2400
A12: Kurumlar Vergisi | B12: =HESAP!B7 -> 240000 | C12: =HESAP!C7 -> 61000 | D12: =HESAP!D7 -> 301000 | E12: =HESAP!E7 -> 9600
A13: KDV | B13: =HESAP!B8 -> 240000 | C13: =HESAP!C8 -> 50000 | D13: =HESAP!D8 -> 290000 | E13: =HESAP!E8 -> 9600
A14: Muhtasar Stopaj | B14: =HESAP!B9 -> 80000 | C14: =HESAP!C9 -> 19000 | D14: =HESAP!D9 -> 99000 | E14: =HESAP!E9 -> 3200
A15: SGK Primi | B15: =HESAP!B10 -> 120000 | C15: =HESAP!C10 -> 31000 | D15: =HESAP!D10 -> 151000 | E15: =HESAP!E10 -> 3600
A16: SGK Cezası | B16: =HESAP!B11 -> 40000 | C16: =HESAP!C11 -> 14000 | D16: =HESAP!D11 -> 54000 | E16: =HESAP!E11 -> 1600
A17: Diğer | B17: =HESAP!B12 -> 0 | C17: =HESAP!C12 -> 0 | D17: =HESAP!D12 -> 0 | E17: =HESAP!E12 -> 0
G20: Borç Sırası | H20: Toplam Borç (TL)
G21: 1 | H21: =IFERROR(INDEX(tblBorc[Toplam Borç (TL)],AYARLAR!$B$34),0) -> 0
G22: 2 | H22: =IFERROR(INDEX(tblBorc[Toplam Borç (TL)],AYARLAR!$B$35),0) -> 192000
G23: 3 | H23: =IFERROR(INDEX(tblBorc[Toplam Borç (TL)],AYARLAR!$B$36),0) -> 99000
G24: 4 | H24: =IFERROR(INDEX(tblBorc[Toplam Borç (TL)],AYARLAR!$B$37),0) -> 301000
G25: 5 | H25: =IFERROR(INDEX(tblBorc[Toplam Borç (TL)],AYARLAR!$B$38),0) -> 151000
G26: 6 | H26: =IFERROR(INDEX(tblBorc[Toplam Borç (TL)],AYARLAR!$B$39),0) -> 54000
G27: 7 | H27: =IFERROR(INDEX(tblBorc[Toplam Borç (TL)],AYARLAR!$B$40),0) -> 69000
G28: 8 | H28: =IFERROR(INDEX(tblBorc[Toplam Borç (TL)],AYARLAR!$B$41),0) -> 98000
G29: 9 | H29: =IFERROR(INDEX(tblBorc[Toplam Borç (TL)],AYARLAR!$B$42),0) -> 0
G30: 10 | H30: =IFERROR(INDEX(tblBorc[Toplam Borç (TL)],AYARLAR!$B$43),0) -> 0
G31: 11 | H31: =IFERROR(INDEX(tblBorc[Toplam Borç (TL)],AYARLAR!$B$44),0) -> 0
G32: 12 | H32: =IFERROR(INDEX(tblBorc[Toplam Borç (TL)],AYARLAR!$B$45),0) -> 0
A34: Gelecek Dönem Toplam Borç Tahmini | B34: =ROUND(IFERROR(forecast.lınear(TecilPanelSatir12,tblBorc[Toplam Borç (TL)],ROW(tblBorc[Toplam Borç (TL)])-ROW(tblBorc[[#Headers],[Toplam Borç (TL)]])),0),0) -> 0
A35: Ortalama Toplam Borç | B35: =ROUND(IFERROR(AVERAGE(tblBorc[Toplam Borç (TL)]),0),0) -> 965
A36: Toplam Borç Standart Sapması | B36: =ROUND(IFERROR(stdev.p(INDEX(tblBorc[Toplam Borç (TL)],TecilPanelSatir1):INDEX(tblBorc[Toplam Borç (TL)],TecilPanelSatir12)),0),0) -> 0
A37: Alt Tahmin Sınırı | B37: =B35-B36*TecilTahminCarpan -> 965
A38: Üst Tahmin Sınırı | B38: =B35+B36*TecilTahminCarpan -> 965
A40: Seçenek | B40: Toplam Maliyet (TL) | C40: NBD (TL)
A41: TECİL | B41: =HESAP!B30 -> 1050898.7 | C41: =HESAP!B55 -> 912318.62
A42: KREDİ | B42: =HESAP!B39 -> 1175651.8 | C42: =HESAP!B56 -> 1007762.5
A43: PEŞİN | B43: =HESAP!B44 -> 872000 | C43: =HESAP!B57 -> 872000
E45: Senaryo | F45: Tecil Maliyeti (TL)
E46: İyimser | F46: =SENARYO_DUYARLILIK!C7 -> 1021422.5
E47: Baz | F47: =SENARYO_DUYARLILIK!C8 -> 1050898.7
E48: Kötümser | F48: =SENARYO_DUYARLILIK!C9 -> 1085924.2
E49: Kritik | F49: =SENARYO_DUYARLILIK!C10 -> 1137134.7
A50: Paneldeki tüm göstergeler canlı formüllerden beslenir.

Sheet SENARYO_DUYARLILIK
A1: SENARYO DUYARLILIK — Vergi/SGK Borcunu Tecil Etmeli Miyim? (Kredi mi Tecil mi?)
A3: Senaryo ve Duyarlılık Analizi
A4: Farklı tecil faizi senaryolarında toplam maliyet bant aralığı; ardından hangi değişkenin maliyeti en çok etkilediğini gösteren tornado analizi.
A6: Senaryo | B6: Aylık Faiz | C6: Tecil Maliyeti (TL) | D6: Durum
A7: İYİMSER | B7: =AYARLAR!$B$20/12 -> 0.01 | C7: =IFERROR(HESAP!B25+HESAP!B26*(B7/(1-(1+B7)^-HESAP!B28))*HESAP!B28,0) -> 1021422.5 | D7: =IF(C7<=HESAP!B30,"AVANTAJLI","DEĞERLENDİR") -> AVANTAJLI
A8: BAZ | B8: =AYARLAR!$B$21/12 -> 0.015 | C8: =IFERROR(HESAP!B25+HESAP!B26*(B8/(1-(1+B8)^-HESAP!B28))*HESAP!B28,0) -> 1050898.7 | D8: =IF(C8<=HESAP!B30,"AVANTAJLI","DEĞERLENDİR") -> AVANTAJLI
A9: KÖTÜMSER | B9: =AYARLAR!$B$22/12 -> 0.020833333 | C9: =IFERROR(HESAP!B25+HESAP!B26*(B9/(1-(1+B9)^-HESAP!B28))*HESAP!B28,0) -> 1085924.2 | D9: =IF(C9<=HESAP!B30,"AVANTAJLI","DEĞERLENDİR") -> DEĞERLENDİR
A10: KRİTİK | B10: =AYARLAR!$B$23/12 -> 0.029166667 | C10: =IFERROR(HESAP!B25+HESAP!B26*(B10/(1-(1+B10)^-HESAP!B28))*HESAP!B28,0) -> 1137134.7 | D10: =IF(C10<=HESAP!B30,"AVANTAJLI","DEĞERLENDİR") -> DEĞERLENDİR
A11: Senaryo Bant Genişliği (İyi − Kritik) | C11: =C7-C10 -> -115712.15
A13: Tornado: Toplam Maliyete Etki
A14: Tecil Faizi +1 puan Etkisi | B14: =IFERROR(ABS((HESAP!B25+HESAP!B26*((AYARLAR!$B$13+TecilTornadoFaiz)/12)/(1-(1+(AYARLAR!$B$13+TecilTornadoFaiz)/12)^-HESAP!B28)*HESAP!B28)-HESAP!B30),0) -> 4961.8251
A15: Kredi Faizi +1 puan Etkisi | B15: =IFERROR(ABS((HESAP!B34+HESAP!B35*((AYARLAR!$B$14+KrediTornadoFaiz)/12)/(1-(1+(AYARLAR!$B$14+KrediTornadoFaiz)/12)^-HESAP!B37)*HESAP!B37)-HESAP!B39),0) -> 5773.5672
A17: En Etkili Değişken | B17: =IF(B14>=B15,"Tecil Faizi","Kredi Faizi") -> Kredi Faizi
A19: Senaryo faizleri ve tornado çarpanları AYARLAR'dan türetilir.

Sheet RAPOR
A1: VERGİ/SGK BORCU — ÖDEME YOLU YÖNETİCİ ÖZETİ
A2: =_xlfn.CONCAT("Rapor Tarihi: ",TEXT(RaporTarihi,"dd.mm.yyyy")," | Hazırlayan: ",RaporHazirlayan," | Sürüm: ",DosyaSurumu) -> Rapor Tarihi: 10.08.2026 | Hazırlayan: Mali İşler Direktörü | Sürüm: 1.0.0
A4: Karar | B4: =KARAR!B11 -> PEŞİN ÖDE
A6: Toplam Borç (TL) | B6: =HESAP!B17 -> 964000
A7: Toplam Gecikme Zammı (TL) | B7: =HESAP!B16 -> 184000
A8: Tecil Toplam Maliyet (TL) | B8: =HESAP!B30 -> 1050898.7
A9: Kredi Toplam Maliyet (TL) | B9: =HESAP!B39 -> 1175651.8
A10: Peşin Ödeme (TL) | B10: =HESAP!B44 -> 872000
A11: En Düşük Maliyet (TL) | B11: =HESAP!B51 -> 872000
A12: NBD Farkı (Tecil − Kredi) (TL) | B12: =HESAP!B58 -> -95443.891
A13: Ortalama Geciken Ay | B13: =HESAP!B19 -> 0.076076076
A14: Kalite Skoru | B14: =KONTROLLER!B19 -> 100
A16: Varsayımlar ve Önemli Notlar
A17: • Tecil seçeneği 6183 sayılı Kanun 48. madde kapsamında vadeye yaymayı modeller; tecil faizi AYARLAR'dan güncellenir.
A18: • Kredi seçeneği borcu kapatacak banka kredisini modeller; faiz ve komisyon oranı kullanıcı tarafından girilir.
A19: • Peşin ödeme seçeneği yapılandırma kapsamında gecikme zammının terkin edilen kısmını dikkate alır.
A20: • NBD karşılaştırması iskonto oranıyla aylık ödemeleri bugünkü değere indirger; iskonto oranı AYARLAR'dadır.
A21: • Bu dosya karar destek aracıdır; tecil başvuru sonucu ve kredi onayı bağlayıcı değildir.
A22: • Demo veriler gerçek müşteri verisi değildir; kullanımdan önce temizlenmelidir.
A24: Önerilen Aksiyonlar
A25: =TecilAksiyon1_ACIKLAMA -> Karara göre önerilen aksiyon.
A26: =TecilAksiyon2_ACIKLAMA -> Karara göre önerilen aksiyon.
A27: =TecilAksiyon3_ACIKLAMA -> Karara göre önerilen aksiyon.
A29: Bu rapor karar destek amaçlıdır; mali tavsiye niteliği taşımaz.

Sheet ORNEK_VERI
A1: ORNEK VERI — Vergi/SGK Borcunu Tecil Etmeli Miyim? (Kredi mi Tecil mi?)
A3: Örnek Veri (Demo)
A4: Gerçek girişlere başlamadan önce demo veri ile ürünü deneyin. Bu satırlar örnektir; gerçek verilerle değiştirin.
A5: Borç Kodu | B5: Borç Türü | C5: Borç Aslı (TL) | D5: Gecikme Zammı (TL) | E5: Vade Tarihi | F5: Aylık Zam Oranı | G5: Toplam Borç (TL) | H5: Açıklama
A6: V-1001 | B6: KDV | C6: 150000 | D6: 42000 | E6: 45742 | F6: 0.04 | G6: =IF($C6="",0,$C6+$D6) -> 192000 | H6: =IF($B6="","",CONCATENATE("Örnek borç: ",$B6)) -> Örnek borç: KDV
A7: V-1002 | B7: Muhtasar Stopaj | C7: 80000 | D7: 19000 | E7: 45834 | F7: 0.04 | G7: =IF($C7="",0,$C7+$D7) -> 99000 | H7: =IF($B7="","",CONCATENATE("Örnek borç: ",$B7)) -> Örnek borç: Muhtasar Stopaj
A8: V-1003 | B8: Kurumlar Vergisi | C8: 240000 | D8: 61000 | E8: 45808 | F8: 0.04 | G8: =IF($C8="",0,$C8+$D8) -> 301000 | H8: =IF($B8="","",CONCATENATE("Örnek borç: ",$B8)) -> Örnek borç: Kurumlar Vergisi
A9: S-2001 | B9: SGK Primi | C9: 120000 | D9: 31000 | E9: 45900 | F9: 0.03 | G9: =IF($C9="",0,$C9+$D9) -> 151000 | H9: =IF($B9="","",CONCATENATE("Örnek borç: ",$B9)) -> Örnek borç: SGK Primi
A10: S-2002 | B10: SGK Cezası | C10: 40000 | D10: 14000 | E10: 45961 | F10: 0.04 | G10: =IF($C10="",0,$C10+$D10) -> 54000 | H10: =IF($B10="","",CONCATENATE("Örnek borç: ",$B10)) -> Örnek borç: SGK Cezası
A11: V-1004 | B11: Gelir Vergisi | C11: 60000 | D11: 9000 | E11: 45991 | F11: 0.04 | G11: =IF($C11="",0,$C11+$D11) -> 69000 | H11: =IF($B11="","",CONCATENATE("Örnek borç: ",$B11)) -> Örnek borç: Gelir Vergisi
G12: =IF($C12="",0,$C12+$D12) -> 0 | H12: =IF($B12="","",CONCATENATE("Örnek borç: ",$B12))
G13: =IF($C13="",0,$C13+$D13) -> 0 | H13: =IF($B13="","",CONCATENATE("Örnek borç: ",$B13))
G14: =IF($C14="",0,$C14+$D14) -> 0 | H14: =IF($B14="","",CONCATENATE("Örnek borç: ",$B14))
G15: =IF($C15="",0,$C15+$D15) -> 0 | H15: =IF($B15="","",CONCATENATE("Örnek borç: ",$B15))
G16: =IF($C16="",0,$C16+$D16) -> 0 | H16: =IF($B16="","",CONCATENATE("Örnek borç: ",$B16))
G17: =IF($C17="",0,$C17+$D17) -> 0 | H17: =IF($B17="","",CONCATENATE("Örnek borç: ",$B17))
G18: =IF($C18="",0,$C18+$D18) -> 0 | H18: =IF($B18="","",CONCATENATE("Örnek borç: ",$B18))
G19: =IF($C19="",0,$C19+$D19) -> 0 | H19: =IF($B19="","",CONCATENATE("Örnek borç: ",$B19))
G20: =IF($C20="",0,$C20+$D20) -> 0 | H20: =IF($B20="","",CONCATENATE("Örnek borç: ",$B20))
G21: =IF($C21="",0,$C21+$D21) -> 0 | H21: =IF($B21="","",CONCATENATE("Örnek borç: ",$B21))
G22: =IF($C22="",0,$C22+$D22) -> 0 | H22: =IF($B22="","",CONCATENATE("Örnek borç: ",$B22))
G23: =IF($C23="",0,$C23+$D23) -> 0 | H23: =IF($B23="","",CONCATENATE("Örnek borç: ",$B23))
... G1004: =IF($C1004="",0,$C1004+$D1004) -> 0 | H1004: =IF($B1004="","",CONCATENATE("Örnek borç: ",$B1004))
A1006: Demo veriler rapor sonuçlarını örnekler; satın alma sonrası silinerek gerçek veriler girilir.

Sheet DEGISIKLIK_KAYDI
A1: DEGISIKLIK KAYDI — Vergi/SGK Borcunu Tecil Etmeli Miyim? (Kredi mi Tecil mi?)
A3: Değişiklik Kaydı
A4: Tarih | B4: Sürüm | C4: Değişiklik | D4: Neden | E4: Yapan
A5: 10.08.2026 | B5: 1.0.0 | C5: İlk üretim | D5: Ürünün yayına hazırlanması | E5: ExcelArşiv

Sheet LISTELER
A1: LISTELER — Vergi/SGK Borcunu Tecil Etmeli Miyim? (Kredi mi Tecil mi?)
A3: Bağlı Listeler
A4: Bu sayfadaki listeler açılır menüleri besler; yeni seçenek eklemek için sarı hücrelere yazın.
A6: Borç Türü
A7: Gelir Vergisi | B7: Kredi Onayı
A8: Kurumlar Vergisi | B8: Evet
A9: KDV | B9: Hayır
A10: Muhtasar Stopaj
A11: SGK Primi
A12: SGK Cezası
A13: Diğer

Sheet AYARLAR
A1: AYARLAR — Vergi/SGK Borcunu Tecil Etmeli Miyim? (Kredi mi Tecil mi?)
A3: Sistem Ayarları ve Oranlar
A4: Tüm sabitler bu sayfadadır. Tecil faizi, kredi faizi, iskonto oranı ve terkin oranını güncelleyin; değişen her değer tüm hesaplamalara anında yansır.
A6: anahtar | B6: deger | C6: birim | D6: alt | E6: ust | F6: aciklama | G6: kaynak | H6: yururluk_tarihi | I6: dogrulama_tarihi
A7: FirmaUnvan | B7: Örnek Firma A.Ş. | C7: Metin | F7: Firma unvanı rapor başlığında görünür. | G7: Kullanıcı | H7: 45658 | I7: 46244
A8: RaporTarihi | B8: 46244 | C8: Tarih | F8: Geciken ay ve NBD hesabının dayanak tarihi. | G8: Kullanıcı | H8: 45658 | I8: 46244
A9: RaporHazirlayan | B9: Mali İşler Direktörü | C9: Metin | F9: Raporu hazırlayan kişi. | G9: Kullanıcı | H9: 45658 | I9: 46244
A10: DosyaSurumu | B10: 1.0.0 | C10: Metin | F10: Dosya sürümü. | G10: Kullanıcı | H10: 45658 | I10: 46244
A11: TecilPesinatOran | B11: 0.1 | C11: Oran | D11: 0 | E11: 1 | F11: Tecile başlamadan ödenen peşin oranı. | G11: Varsayım | H11: 45658 | I11: 46244
A12: TecilTaksitSayisi | B12: 12 | C12: Adet | D12: 1 | E12: 60 | F12: Tecilin vadeye yayılacağı taksit sayısı. | G12: Varsayım | H12: 45658 | I12: 46244
A13: TecilFaizYillik | B13: 0.18 | C13: Oran | D13: 0 | E13: 1 | F13: Yıllık tecil faizi (6183 kapsamında değişken). | G13: Varsayım | H13: 45658 | I13: 46244
A14: KrediFaizYillik | B14: 0.35 | C14: Oran | D14: 0 | E14: 1 | F14: Borcu kapatacak banka kredisinin yıllık faizi. | G14: Varsayım | H14: 45658 | I14: 46244
A15: KrediKomisyonOran | B15: 0.02 | C15: Oran | D15: 0 | E15: 1 | F15: Kredi komisyon oranı. | G15: Varsayım | H15: 45658 | I15: 46244
A16: KrediTaksitSayisi | B16: 12 | C16: Adet | D16: 1 | E16: 60 | F16: Kredi taksit sayısı. | G16: Varsayım | H16: 45658 | I16: 46244
A17: KrediOnayiVar | B17: Evet | C17: Metin | F17: Kredi onayı var mı? Hayır ise kredi seçeneği devre dışı kalır. | G17: Varsayım | H17: 45658 | I17: 46244
A18: PesinTerkinOran | B18: 0.5 | C18: Oran | D18: 0 | E18: 1 | F18: Peşin ödemede gecikme zammından terkin edilen oran (yapılandırma). | G18: Varsayım | H18: 45658 | I18: 46244
A19: IskontoOrani | B19: 0.3 | C19: Oran | D19: 0 | E19: 1 | F19: NBD için yıllık iskonto oranı. | G19: Varsayım | H19: 45658 | I19: 46244
A20: SenTecilIyi | B20: 0.12 | C20: Oran | D20: 0 | E20: 1 | F20: İyimser senaryo tecil faizi. | G20: Varsayım | H20: 45658 | I20: 46244
A21: SenTecilBaz | B21: 0.18 | C21: Oran | D21: 0 | E21: 1 | F21: Baz senaryo tecil faizi. | G21: Varsayım | H21: 45658 | I21: 46244
A22: SenTecilKotu | B22: 0.25 | C22: Oran | D22: 0 | E22: 1 | F22: Kötümser senaryo tecil faizi. | G22: Varsayım | H22: 45658 | I22: 46244
A23: SenTecilKritik | B23: 0.35 | C23: Oran | D23: 0 | E23: 1 | F23: Kritik senaryo tecil faizi. | G23: Varsayım | H23: 45658 | I23: 46244
A24: TecilTahminCarpan | B24: 1.645 | C24: Çarpan | D24: 0 | E24: 10 | F24: Tahmin güven bandı çarpanı (%90 normal dağılım). | G24: Varsayım | H24: 45658 | I24: 46244
A25: TecilKaliteIyi | B25: 90 | C25: Puan | D25: 0 | E25: 100 | F25: Yüksek kalite skoru eşiği. | G25: Varsayım | H25: 45658 | I25: 46244
A26: TecilKaliteOrta | B26: 70 | C26: Puan | D26: 0 | E26: 100 | F26: Orta kalite skoru eşiği. | G26: Varsayım | H26: 45658 | I26: 46244
A27: TecilAylikNakitAkisi | B27: 100000 | C27: TL | D27: 0 | E27: 100000000000 | F27: Aylık nakit akışı; tecil taksiti bu değerle kıyaslanır. | G27: Varsayım | H27: 45658 | I27: 46244
A28: TecilYuksekBorcEsik | B28: 500000 | C28: TL | D28: 0 | E28: 100000000000 | F28: Yüksek borç eşiği. | G28: Varsayım | H28: 45658 | I28: 46244
A29: TecilP90Oran | B29: 0.9 | C29: Oran | D29: 0 | E29: 1 | F29: Toplam borç dağılımında üst yüzdelik dilimin oranı. | G29: Varsayım | H29: 45658 | I29: 46244
... A32: KrediTornadoFaiz | B32: 0.01 | C32: Oran | D32: 0 | E32: 0.1 | F32: Tornado analizinde kredi faizine uygulanan +1 puan çarpanı. | G32: Varsayım | H32: 45658 | I32: 46244
A35: TecilPanelSatir1 | B35: 1 | C35: Satır | F35: PANO'daki borç kalemi bazlı toplam borç grafiğinin tablodaki veri satırı (1. veri). | G35: Kullanıcı | H35: 45658 | I35: 46244
A36: TecilPanelSatir2 | B36: 2 | C36: Satır | F36: PANO'daki borç kalemi bazlı toplam borç grafiğinin tablodaki veri satırı (2. veri). | G36: Kullanıcı | H36: 45658 | I36: 46244
A37: TecilPanelSatir3 | B37: 3 | C37: Satır | F37: PANO'daki borç kalemi bazlı toplam borç grafiğinin tablodaki veri satırı (3. veri). | G37: Kullanıcı | H37: 45658 | I37: 46244
A38: TecilPanelSatir4 | B38: 4 | C38: Satır | F38: PANO'daki borç kalemi bazlı toplam borç grafiğinin tablodaki veri satırı (4. veri). | G38: Kullanıcı | H38: 45658 | I38: 46244
A39: TecilPanelSatir5 | B39: 5 | C39: Satır | F39: PANO'daki borç kalemi bazlı toplam borç grafiğinin tablodaki veri satırı (5. veri). | G39: Kullanıcı | H39: 45658 | I39: 46244
A40: TecilPanelSatir6 | B40: 6 | C40: Satır | F40: PANO'daki borç kalemi bazlı toplam borç grafiğinin tablodaki veri satırı (6. veri). | G40: Kullanıcı | H40: 45658 | I40: 46244
A41: TecilPanelSatir7 | B41: 7 | C41: Satır | F41: PANO'daki borç kalemi bazlı toplam borç grafiğinin tablodaki veri satırı (7. veri). | G41: Kullanıcı | H41: 45658 | I41: 46244
A42: TecilPanelSatir8 | B42: 8 | C42: Satır | F42: PANO'daki borç kalemi bazlı toplam borç grafiğinin tablodaki veri satırı (8. veri). | G42: Kullanıcı | H42: 45658 | I42: 46244
A43: TecilPanelSatir9 | B43: 9 | C43: Satır | F43: PANO'daki borç kalemi bazlı toplam borç grafiğinin tablodaki veri satırı (9. veri). | G43: Kullanıcı | H43: 45658 | I43: 46244
A44: TecilPanelSatir10 | B44: 10 | C44: Satır | F44: PANO'daki borç kalemi bazlı toplam borç grafiğinin tablodaki veri satırı (10. veri). | G44: Kullanıcı | H44: 45658 | I44: 46244
A45: TecilPanelSatir11 | B45: 11 | C45: Satır | F45: PANO'daki borç kalemi bazlı toplam borç grafiğinin tablodaki veri satırı (11. veri). | G45: Kullanıcı | H45: 45658 | I45: 46244
A46: TecilPanelSatir12 | B46: 12 | C46: Satır | F46: PANO'daki borç kalemi bazlı toplam borç grafiğinin tablodaki veri satırı (12. veri). | G46: Kullanıcı | H46: 45658 | I46: 46244
...

Sheet KILAVUZ
A1: KILAVUZ — Vergi/SGK Borcunu Tecil Etmeli Miyim? (Kredi mi Tecil mi?)
A3: Kullanım Kılavuzu
A5: Veri girişi | B5: BORC_LISTESI sayfasında sarı hücrelere borçlarınızı girin. Borç türünü listeden seçin; borç aslı, gecikme zammı, vade tarihi ve aylık zam oranını girin. Geciken ay, toplam borç ve aylık zam yükü otomatik hesaplanır.
A6: Seçenek hesapları | B6: HESAP sayfası tecil, kredi ve peşin ödeme seçeneklerinin toplam maliyetini ve bugünkü değerini (NBD) hesaplar. Peşinat oranı, taksit sayısı ve faizler AYARLAR'dan gelir.
A7: Karar ve aksiyon | B7: KARAR sayfası en düşük maliyetli ödeme yolunu gerekçesiyle önerir. Kredi onayı yoksa kredi seçeneği karar dışı bırakılır.
A8: Oranlar ve senaryolar | B8: AYARLAR sayfasından tecil faizi, kredi faizi, iskonto oranı, terkin oranı ve senaryo faizlerini güncelleyin; PANO ve SENARYO_DUYARLILIK sayfaları anında güncellenir.
A9: Güven ve karar kalitesi | B9: Veri kalite skoru girişlerin tamlığını ölçer. Borç girişi yokken karar VERİ YOK; negatif girişte DURDUR üretir. Verileriniz cihazınızdan çıkmaz; dosya tamamen çevrimdışıdır.
A10: Uyumluluk | B10: Excel 2016-365 (Windows ve Mac), LibreOffice ve Google Sheets ile uyumludur. Makro içermez; formüller ayrıştırıcı ile denetlenmiştir.
