Workbook
Name hesapYili: GIRDI!$B$8
Name raporTarihi: AYARLAR!$B$7
Name ktm_toplamTevkifat: MOTOR!$G$29
Name ktm_mahsupToplam: MOTOR!$G$35
Name ktm_iadeUygun: MOTOR!$G$36
Name ktm_kararMetni: MOTOR!$G$39
Name ktm_kararGerekce: MOTOR!$G$40
Name ktm_kararKapi: MOTOR!$G$39
Name ktm_maddeAtifMetni: MOTOR!$G$58
Name ktm_kanitRaporu: MOTOR!$G$59
Name ktm_kuralYilMatris: KURALLAR!$B$17
Name ktm_mahsupListe: MAHSUP_LISTE!$K$13
Name ktm_parmakIzi: AYARLAR!$B$18
Name ktm_senaryoKarsilastirma: SENARYO!$B$11
Name ktm_yorumSenaryo: SENARYO!$B$12
Name ktm_duyarlilikSira: SENARYO!$B$19
Name ktm_yorumDuyarlilik: SENARYO!$B$20
Name ktm_kuralDegisimSenaryo: SENARYO!$B$22
Name ktm_yorumKuralDegisim: SENARYO!$B$23
Name ktm_tahminAralik: SENARYO!$B$32
Name ktm_yorumTahmin: SENARYO!$B$33
Name ktm_vakaDurum: VAKALAR!$B$12
Name ktm_vakaFark: VAKALAR!$B$13
Name ktm_tolerans: AYARLAR!$B$8
Name ktm_iadeEsik: AYARLAR!$B$9
Name ktm_senaryoIyi: AYARLAR!$B$10
Name ktm_senaryoKotu: AYARLAR!$B$11
Name ktm_oranArtisPuan: AYARLAR!$B$12
Name ktm_tahminAlt: AYARLAR!$B$13
Name ktm_tahminUst: AYARLAR!$B$14
Name ktm_tornadoMatrah: AYARLAR!$B$15
Name ktm_tornadoKdv1: AYARLAR!$B$16
Name ktm_yuzdelikOran: AYARLAR!$B$17
Name ktm_girisBeklenen: AYARLAR!$B$20
Name ktm_riskDusuk: AYARLAR!$B$21
Name ktm_riskOrta: AYARLAR!$B$22
Name ktm_riskYuksek: AYARLAR!$B$23
Name ktm_yilTaban: AYARLAR!$B$24
Name ktm_yuvarMax: AYARLAR!$B$25
Name vaka_matrah_1: AYARLAR!$B$26
Name vaka_matrah_2: AYARLAR!$B$27
Name vaka_matrah_9: AYARLAR!$B$28
Name ktm_modulT1: PANO!$C$11
Name ktm_modulT1Yorum: PANO!$D$11
Name ktm_modulT2: PANO!$C$12
Name ktm_modulT2Yorum: PANO!$D$12
Name ktm_modulO1: PANO!$C$13
Name ktm_modulO1Yorum: PANO!$D$13
Name ktm_modulO6: PANO!$C$16
Name ktm_modulO6Yorum: PANO!$D$16
Name ktm_modulO8: PANO!$C$17
Name ktm_modulO8Yorum: PANO!$D$17
Name ktm_modulI2: PANO!$C$20
Name ktm_modulI2Yorum: PANO!$D$20
Name ListeYillar: LISTELER!$A$6:$A$8
Name ListeYorumAB: LISTELER!$C$6:$C$7
Name ListeEvetHayir: LISTELER!$E$6:$E$7

Sheet PANO
A1: PANO — KDV Tevkifat Mahsup ve KDV İade Listesi
A3: Yönetim paneli — KDV Tevkifat Mahsup / İade | B3: Tevkifat | C3: Mahsup | D3: İade | E3: Talep | F3: Güven | G3: Risk | H3: 2/10 oran | I3: 5/10 oran | J3: Mahsup/Havuz | K3: M-SEN iade | L3: Tahmin | M3: Vaka
B4: =IFERROR(ktm_toplamTevkifat,0) | C4: =IFERROR(ktm_mahsupToplam,0) | D4: =IFERROR(ktm_iadeUygun,0) | E4: =IFERROR(GIRDI!B15,0) | F4: =IFERROR(MOTOR!G43,0) | G4: =IFERROR(MOTOR!G44,0) | H4: =IFERROR(MOTOR!G8,0) | I4: =IFERROR(MOTOR!G9,0) | J4: =IFERROR(MOTOR!G42,0) | K4: =IFERROR(ktm_kuralDegisimSenaryo,0) | L4: =IFERROR(SENARYO!B32,0) | M4: =IFERROR(ktm_vakaDurum,"-")
A6: KARAR | B6: =ktm_kararMetni
A7: Gerekçe | B7: =ktm_kararGerekce
A9: Analitik modüller
A10: Kod | B10: Gösterge | C10: Değer | D10: Makine Yorumu
A11: T1 | B11: Mahsup toplam | C11: =IFERROR(ktm_mahsupToplam,0) | D11: =_xlfn.TEXTJOIN("; ",TRUE,"Mahsup ",TEXT(C11,"₺ #,##0")," TL — 2 Numaralı liste")
A12: T2 | B12: İade toplam | C12: =IFERROR(ktm_iadeUygun,0) | D12: =_xlfn.TEXTJOIN("; ",TRUE,"İade uygun ",TEXT(C12,"₺ #,##0")," TL")
A13: O1 | B13: İade sapması | C13: =IFERROR(IF(COUNT(SENARYO!D6:D9)<2,0,STDEV.P(SENARYO!D6:D9)),0) | D13: =_xlfn.TEXTJOIN("; ",TRUE,"Senaryo iade sapması ",TEXT(C13,"₺ #,##0")," TL")
A14: O2 | B14: Tornado max etki | C14: =IFERROR(ktm_duyarlilikSira,"-") | D14: =IFERROR(ktm_yorumDuyarlilik,"-")
A15: O3 | B15: Senaryo bant | C15: =IFERROR(ktm_senaryoKarsilastirma,0) | D15: =IFERROR(ktm_yorumSenaryo,"-")
A16: O6 | B16: 2/10 tevkifat payı | C16: =IFERROR(IF(ktm_toplamTevkifat=0,0,MOTOR!G25/ktm_toplamTevkifat),0) | D16: =_xlfn.TEXTJOIN("; ",TRUE,"2/10 / toplam tevkifat ",TEXT(C16,"0.0%"))
A17: O8 | B17: Kalite skoru | C17: =IFERROR(MOTOR!G60,0) | D17: =_xlfn.TEXTJOIN("; ",TRUE,"Kalite ",TEXT(C17,"0")," puan")
A18: M | B18: M-SEN iade | C18: =IFERROR(ktm_kuralDegisimSenaryo,0) | D18: =IFERROR(ktm_yorumKuralDegisim,"-")
A19: I1 | B19: Tahmin aralık | C19: =IFERROR(ktm_tahminAralik,0) | D19: =IFERROR(ktm_yorumTahmin,"-")
A20: I2 | B20: Senaryo iade P90 | C20: =IFERROR(IF(COUNT(SENARYO!D6:D9)<2,0,_xlfn.PERCENTILE.INC(SENARYO!D6:D9,ktm_yuzdelikOran)),0) | D20: =_xlfn.TEXTJOIN("; ",TRUE,"P90 iade ",TEXT(C20,"₺ #,##0")," TL")
A23: Kalem | B23: Tutar | D23: Kalem | E23: Tutar
A24: 2/10 tevkifat | B24: 40000 | D24: Mahsup havuzu | E24: 188000
A25: 5/10 tevkifat | B25: 50000 | D25: Mahsup | E25: 100000
A26: 7/10 tevkifat | B26: 42000 | D26: İade uygun | E26: 88000
A27: 9/10 tevkifat | B27: 36000 | D27: İade talep | E27: 80000
A28: Toplam tevkifat | B28: 168000 | D28: M-SEN iade | E28: 91000
A30: Metrik | B30: Değer
A31: İade uygun | B31: 88000
A32: Mahsup | B32: 100000
A33: Tevkifat | B33: 168000

Sheet GIRDI
A1: GIRDI — KDV Tevkifat Mahsup ve KDV İade Listesi
A3: Dönem ve tevkifat girdileri
A4: Sarı hücreler manuel giriştir. Mahsup/iade tutarları formülle üretilir.
A5: Alan | B5: Değer | C5: Birim
A6: Mükellef Adı | B6: Örnek Ticaret A.Ş. | C6: metin
A7: Dönem | B7: 2026-06 | C7: metin
A8: Hesap Yılı | B8: 2026 | C8: yıl
A9: 2/10 Matrah [₺] | B9: 1000000 | C9: ₺
A10: 5/10 Matrah [₺] | B10: 500000 | C10: ₺
A11: 7/10 Matrah [₺] | B11: 300000 | C11: ₺
A12: 9/10 Matrah [₺] | B12: 200000 | C12: ₺
A13: KDV1 Ödenecek [₺] | B13: 100000 | C13: ₺
A14: Önceki Mahsup Bakiyesi [₺] | B14: 20000 | C14: ₺
A15: İade Talep [₺] | B15: 80000 | C15: ₺
A16: Mahsup Yorumu (A/B) | B16: A | C16: metin
A18: Toplam Tevkifat (ayna) [₺] | B18: =IFERROR(ktm_toplamTevkifat,0)
A19: Giriş doluluk (kalite) | B19: =IFERROR(IF(OR(COUNTA(B6:B16)=0,ktm_girisBeklenen=0),0,ROUND(COUNTA(B6:B16)/ktm_girisBeklenen*100,0)),0)
A22: Giriş tablosu (otomasyon / boş-mod)
A23: Alan Anahtarı | B23: Değer | C23: Birim | D23: Zorunlu | E23: Kaynak | F23: Kontrol
A24: mukellef_adi | B24: Örnek Ticaret A.Ş. | C24: metin | D24: Evet | E24: GIRDI | F24: =IF($A24="","",IF($B24="","EKSİK","TAM"))
A25: donem | B25: 2026-06 | C25: metin | D25: Evet | E25: GIRDI | F25: =IF($A25="","",IF($B25="","EKSİK","TAM"))
A26: hesapYili | B26: 2026 | C26: yıl | D26: Evet | E26: GIRDI | F26: =IF($A26="","",IF($B26="","EKSİK","TAM"))
A27: matrah_2_10 | B27: 1000000 | C27: TL | D27: Evet | E27: GIRDI | F27: =IF($A27="","",IF($B27="","EKSİK","TAM"))
A28: matrah_5_10 | B28: 500000 | C28: TL | D28: Evet | E28: GIRDI | F28: =IF($A28="","",IF($B28="","EKSİK","TAM"))
A29: matrah_7_10 | B29: 300000 | C29: TL | D29: Evet | E29: GIRDI | F29: =IF($A29="","",IF($B29="","EKSİK","TAM"))
A30: matrah_9_10 | B30: 200000 | C30: TL | D30: Evet | E30: GIRDI | F30: =IF($A30="","",IF($B30="","EKSİK","TAM"))
A31: kdv1_odenecek | B31: 100000 | C31: TL | D31: Evet | E31: GIRDI | F31: =IF($A31="","",IF($B31="","EKSİK","TAM"))
A32: onceki_mahsup_bakiyesi | B32: 20000 | C32: TL | D32: Evet | E32: GIRDI | F32: =IF($A32="","",IF($B32="","EKSİK","TAM"))
A33: iade_talep | B33: 80000 | C33: TL | D33: Evet | E33: GIRDI | F33: =IF($A33="","",IF($B33="","EKSİK","TAM"))
A34: mahsup_yorumu | B34: A | C34: A/B | D34: Evet | E34: GIRDI | F34: =IF($A34="","",IF($B34="","EKSİK","TAM"))
F35: =IF($A35="","",IF($B35="","EKSİK","TAM"))
F36: =IF($A36="","",IF($B36="","EKSİK","TAM"))
F37: =IF($A37="","",IF($B37="","EKSİK","TAM"))
F38: =IF($A38="","",IF($B38="","EKSİK","TAM"))
F39: =IF($A39="","",IF($B39="","EKSİK","TAM"))
F40: =IF($A40="","",IF($B40="","EKSİK","TAM"))
F41: =IF($A41="","",IF($B41="","EKSİK","TAM"))
F42: =IF($A42="","",IF($B42="","EKSİK","TAM"))
F43: =IF($A43="","",IF($B43="","EKSİK","TAM"))
F44: =IF($A44="","",IF($B44="","EKSİK","TAM"))
...

Sheet KURALLAR
A1: KURALLAR — KDV Tevkifat Mahsup ve KDV İade Listesi
A3: Tevkifat kural tablosu (yıl yan yana)
A4: Oranlar MOTOR'da sabit yazılmaz; INDEX/MATCH ile buradan çekilir.
A6: kural_id | B6: madde | C6: kural_adi | D6: kosul_metni | E6: parametre_adi | F6: deger_2025 | G6: deger_2026 | H6: deger_2027 | I6: yururluk | J6: kaynak | K6: aktif_deger
A7: KTM-001 | B7: KDVK / tebliğ | C7: tevkifat_2_10 | D7: matrah_2_10>0 | E7: tevkifat_2_10 | F7: 0.2 | G7: 0.2 | H7: 0.2 | I7: 01.01.2025 | J7: 2/10 tevkifat oranı | K7: =IF($A7="","",IFERROR(CHOOSE(MAX(1,MIN(3,IF(OR(hesapYili="",hesapYili=0),1,hesapYili-ktm_yilTaban))),$F7,$G7,$H7),0))
A8: KTM-002 | B8: KDVK / tebliğ | C8: tevkifat_5_10 | D8: matrah_5_10>0 | E8: tevkifat_5_10 | F8: 0.5 | G8: 0.5 | H8: 0.5 | I8: 01.01.2025 | J8: 5/10 tevkifat oranı | K8: =IF($A8="","",IFERROR(CHOOSE(MAX(1,MIN(3,IF(OR(hesapYili="",hesapYili=0),1,hesapYili-ktm_yilTaban))),$F8,$G8,$H8),0))
A9: KTM-003 | B9: KDVK / tebliğ | C9: tevkifat_7_10 | D9: matrah_7_10>0 | E9: tevkifat_7_10 | F9: 0.7 | G9: 0.7 | H9: 0.7 | I9: 01.01.2025 | J9: 7/10 tevkifat oranı | K9: =IF($A9="","",IFERROR(CHOOSE(MAX(1,MIN(3,IF(OR(hesapYili="",hesapYili=0),1,hesapYili-ktm_yilTaban))),$F9,$G9,$H9),0))
A10: KTM-004 | B10: KDVK / tebliğ | C10: tevkifat_9_10 | D10: matrah_9_10>0 | E10: tevkifat_9_10 | F10: 0.9 | G10: 0.9 | H10: 0.9 | I10: 01.01.2025 | J10: 9/10 tevkifat oranı | K10: =IF($A10="","",IFERROR(CHOOSE(MAX(1,MIN(3,IF(OR(hesapYili="",hesapYili=0),1,hesapYili-ktm_yilTaban))),$F10,$G10,$H10),0))
A11: KTM-005 | B11: KDVK genel | C11: kdv_genel_oran | D11: her hesap | E11: kdv_genel_oran | F11: 0.2 | G11: 0.2 | H11: 0.2 | I11: 01.01.2025 | J11: Genel KDV oranı + yuvarlama | K11: =IF($A11="","",IFERROR(CHOOSE(MAX(1,MIN(3,IF(OR(hesapYili="",hesapYili=0),1,hesapYili-ktm_yilTaban))),$F11,$G11,$H11),0))
A14: Kural-yıl matrisi özeti
A15: 2/10 oranı (aktif yıl) | B15: =IFERROR(INDEX(CHOOSE(MAX(1,MIN(3,IF(OR(hesapYili="",hesapYili=0),1,hesapYili-ktm_yilTaban))),tblKurallar[deger_2025],tblKurallar[deger_2026],tblKurallar[deger_2027]),MATCH("KTM-001",tblKurallar[kural_id],0)),0)
A16: 5/10 oranı (aktif yıl) | B16: =IFERROR(INDEX(CHOOSE(MAX(1,MIN(3,IF(OR(hesapYili="",hesapYili=0),1,hesapYili-ktm_yilTaban))),tblKurallar[deger_2025],tblKurallar[deger_2026],tblKurallar[deger_2027]),MATCH("KTM-002",tblKurallar[kural_id],0)),0)
A17: Matris metni | B17: =IFERROR(_xlfn.TEXTJOIN(" | ",TRUE,"KTM-001=",TEXT(B15,"0.0%"),"KTM-002=",TEXT(B16,"0.0%"),"yıl=",IF(OR(hesapYili="",hesapYili=0),"-",hesapYili)),"-")

Sheet MOTOR
A1: MOTOR — KDV Tevkifat Mahsup ve KDV İade Listesi
A3: Hesap zinciri — her adımda kural_id
A4: Tevkifat oranları tblKurallar'dan çekilir; sabit oran yoktur.
A6: adim | B6: ad | C6: formul | D6: birim | E6: ne_ise_yarar | F6: kural_id | G6: deger
A7: 1 | B7: Hesap yılı oku | C7: =IFERROR(hesapYili,0) | D7: yıl | E7: Aktif mevzuat yılı | F7: KTM-005 | G7: =IFERROR(hesapYili,0)
A8: 2 | B8: 2/10 tevkifat oranı | C8: =IFERROR(INDEX(CHOOSE(MAX(1,MIN(3,IF(OR(hesapYili="",hesapYili=0),1,hesapYili-ktm_yilTaban))),tblKurallar[deger_2025],tblKurallar[deger_2026],tblKurallar[deger_2027]),MATCH("KTM-001",tblKurallar[kural_id],0)),0) | D8: oran | E8: 2/10 oranı | F8: KTM-001 | G8: =IFERROR(INDEX(CHOOSE(MAX(1,MIN(3,IF(OR(hesapYili="",hesapYili=0),1,hesapYili-ktm_yilTaban))),tblKurallar[deger_2025],tblKurallar[deger_2026],tblKurallar[deger_2027]),MATCH("KTM-001",tblKurallar[kural_id],0)),0)
A9: 3 | B9: 5/10 tevkifat oranı | C9: =IFERROR(INDEX(CHOOSE(MAX(1,MIN(3,IF(OR(hesapYili="",hesapYili=0),1,hesapYili-ktm_yilTaban))),tblKurallar[deger_2025],tblKurallar[deger_2026],tblKurallar[deger_2027]),MATCH("KTM-002",tblKurallar[kural_id],0)),0) | D9: oran | E9: 5/10 oranı | F9: KTM-002 | G9: =IFERROR(INDEX(CHOOSE(MAX(1,MIN(3,IF(OR(hesapYili="",hesapYili=0),1,hesapYili-ktm_yilTaban))),tblKurallar[deger_2025],tblKurallar[deger_2026],tblKurallar[deger_2027]),MATCH("KTM-002",tblKurallar[kural_id],0)),0)
A10: 4 | B10: 7/10 tevkifat oranı | C10: =IFERROR(INDEX(CHOOSE(MAX(1,MIN(3,IF(OR(hesapYili="",hesapYili=0),1,hesapYili-ktm_yilTaban))),tblKurallar[deger_2025],tblKurallar[deger_2026],tblKurallar[deger_2027]),MATCH("KTM-003",tblKurallar[kural_id],0)),0) | D10: oran | E10: 7/10 oranı | F10: KTM-003 | G10: =IFERROR(INDEX(CHOOSE(MAX(1,MIN(3,IF(OR(hesapYili="",hesapYili=0),1,hesapYili-ktm_yilTaban))),tblKurallar[deger_2025],tblKurallar[deger_2026],tblKurallar[deger_2027]),MATCH("KTM-003",tblKurallar[kural_id],0)),0)
A11: 5 | B11: 9/10 tevkifat oranı | C11: =IFERROR(INDEX(CHOOSE(MAX(1,MIN(3,IF(OR(hesapYili="",hesapYili=0),1,hesapYili-ktm_yilTaban))),tblKurallar[deger_2025],tblKurallar[deger_2026],tblKurallar[deger_2027]),MATCH("KTM-004",tblKurallar[kural_id],0)),0) | D11: oran | E11: 9/10 oranı | F11: KTM-004 | G11: =IFERROR(INDEX(CHOOSE(MAX(1,MIN(3,IF(OR(hesapYili="",hesapYili=0),1,hesapYili-ktm_yilTaban))),tblKurallar[deger_2025],tblKurallar[deger_2026],tblKurallar[deger_2027]),MATCH("KTM-004",tblKurallar[kural_id],0)),0)
A12: 6 | B12: Genel KDV oranı | C12: =IFERROR(INDEX(CHOOSE(MAX(1,MIN(3,IF(OR(hesapYili="",hesapYili=0),1,hesapYili-ktm_yilTaban))),tblKurallar[deger_2025],tblKurallar[deger_2026],tblKurallar[deger_2027]),MATCH("KTM-005",tblKurallar[kural_id],0)),0) | D12: oran | E12: KDV genel oranı | F12: KTM-005 | G12: =IFERROR(INDEX(CHOOSE(MAX(1,MIN(3,IF(OR(hesapYili="",hesapYili=0),1,hesapYili-ktm_yilTaban))),tblKurallar[deger_2025],tblKurallar[deger_2026],tblKurallar[deger_2027]),MATCH("KTM-005",tblKurallar[kural_id],0)),0)
A13: 7 | B13: Yuvarlama ondalık | C13: =IFERROR(ktm_yuvarMax+N(GIRDI!B9)*0,0) | D13: adet | E13: Yuvarlama basamağı | F13: KTM-005 | G13: =IFERROR(ktm_yuvarMax+N(GIRDI!B9)*0,0)
A14: 8 | B14: 2/10 matrah | C14: =IFERROR(GIRDI!B9,0) | D14: TL | E14: 2/10 ham matrah | F14: KTM-001 | G14: =IFERROR(GIRDI!B9,0)
A15: 9 | B15: 5/10 matrah | C15: =IFERROR(GIRDI!B10,0) | D15: TL | E15: 5/10 ham matrah | F15: KTM-002 | G15: =IFERROR(GIRDI!B10,0)
A16: 10 | B16: 7/10 matrah | C16: =IFERROR(GIRDI!B11,0) | D16: TL | E16: 7/10 ham matrah | F16: KTM-003 | G16: =IFERROR(GIRDI!B11,0)
A17: 11 | B17: 9/10 matrah | C17: =IFERROR(GIRDI!B12,0) | D17: TL | E17: 9/10 ham matrah | F17: KTM-004 | G17: =IFERROR(GIRDI!B12,0)
A18: 12 | B18: KDV1 ödenecek | C18: =IFERROR(GIRDI!B13,0) | D18: TL | E18: 1 Numaralı ödenecek | F18: KTM-005 | G18: =IFERROR(GIRDI!B13,0)
A19: 13 | B19: Önceki mahsup bakiyesi | C19: =IFERROR(GIRDI!B14,0) | D19: TL | E19: Devreden bakiye | F19: KTM-005 | G19: =IFERROR(GIRDI!B14,0)
A20: 14 | B20: İade talep | C20: =IFERROR(GIRDI!B15,0) | D20: TL | E20: Talep edilen iade | F20: KTM-005 | G20: =IFERROR(GIRDI!B15,0)
A21: 15 | B21: 2/10 KDV | C21: =IFERROR(ROUND(G14*G12,MAX(0,MIN(ktm_yuvarMax,IFERROR(N(G13),0)))),0) | D21: TL | E21: 2/10 hesaplanan KDV | F21: KTM-001 | G21: =IFERROR(ROUND(G14*G12,MAX(0,MIN(ktm_yuvarMax,IFERROR(N(G13),0)))),0)
A22: 16 | B22: 5/10 KDV | C22: =IFERROR(ROUND(G15*G12,MAX(0,MIN(ktm_yuvarMax,IFERROR(N(G13),0)))),0) | D22: TL | E22: 5/10 hesaplanan KDV | F22: KTM-002 | G22: =IFERROR(ROUND(G15*G12,MAX(0,MIN(ktm_yuvarMax,IFERROR(N(G13),0)))),0)
A23: 17 | B23: 7/10 KDV | C23: =IFERROR(ROUND(G16*G12,MAX(0,MIN(ktm_yuvarMax,IFERROR(N(G13),0)))),0) | D23: TL | E23: 7/10 hesaplanan KDV | F23: KTM-003 | G23: =IFERROR(ROUND(G16*G12,MAX(0,MIN(ktm_yuvarMax,IFERROR(N(G13),0)))),0)
A24: 18 | B24: 9/10 KDV | C24: =IFERROR(ROUND(G17*G12,MAX(0,MIN(ktm_yuvarMax,IFERROR(N(G13),0)))),0) | D24: TL | E24: 9/10 hesaplanan KDV | F24: KTM-004 | G24: =IFERROR(ROUND(G17*G12,MAX(0,MIN(ktm_yuvarMax,IFERROR(N(G13),0)))),0)
A25: 19 | B25: 2/10 tevkifat | C25: =IFERROR(ROUND(G21*G8,MAX(0,MIN(ktm_yuvarMax,IFERROR(N(G13),0)))),0) | D25: TL | E25: 2/10 tevkifat tutarı | F25: KTM-001 | G25: =IFERROR(ROUND(G21*G8,MAX(0,MIN(ktm_yuvarMax,IFERROR(N(G13),0)))),0)
A26: 20 | B26: 5/10 tevkifat | C26: =IFERROR(ROUND(G22*G9,MAX(0,MIN(ktm_yuvarMax,IFERROR(N(G13),0)))),0) | D26: TL | E26: 5/10 tevkifat tutarı | F26: KTM-002 | G26: =IFERROR(ROUND(G22*G9,MAX(0,MIN(ktm_yuvarMax,IFERROR(N(G13),0)))),0)
A27: 21 | B27: 7/10 tevkifat | C27: =IFERROR(ROUND(G23*G10,MAX(0,MIN(ktm_yuvarMax,IFERROR(N(G13),0)))),0) | D27: TL | E27: 7/10 tevkifat tutarı | F27: KTM-003 | G27: =IFERROR(ROUND(G23*G10,MAX(0,MIN(ktm_yuvarMax,IFERROR(N(G13),0)))),0)
A28: 22 | B28: 9/10 tevkifat | C28: =IFERROR(ROUND(G24*G11,MAX(0,MIN(ktm_yuvarMax,IFERROR(N(G13),0)))),0) | D28: TL | E28: 9/10 tevkifat tutarı | F28: KTM-004 | G28: =IFERROR(ROUND(G24*G11,MAX(0,MIN(ktm_yuvarMax,IFERROR(N(G13),0)))),0)
A29: 23 | B29: Dönem tevkifat toplamı | C29: =IFERROR(G25+G26+G27+G28,0) | D29: TL | E29: Dönem tevkifatı | F29: KTM-005 | G29: =IFERROR(G25+G26+G27+G28,0)
A30: 24 | B30: Mahsup havuzu | C30: =IFERROR(G29+G19,0) | D30: TL | E30: Dönem + önceki bakiye | F30: KTM-005 | G30: =IFERROR(G29+G19,0)
A31: 25 | B31: Mahsup (yorum A) | C31: =IFERROR(MIN(G30,G18),0) | D31: TL | E31: Önce mahsup sonra iade | F31: KTM-005 | G31: =IFERROR(MIN(G30,G18),0)
A32: 26 | B32: İade uygun (yorum A) | C32: =IFERROR(MAX(0,G30-G31),0) | D32: TL | E32: Mahsup sonrası iade | F32: KTM-005 | G32: =IFERROR(MAX(0,G30-G31),0)
A33: 27 | B33: İade (yorum B) | C33: =IFERROR(MIN(G30,G20),0) | D33: TL | E33: Önce iade sonra mahsup | F33: KTM-005 | G33: =IFERROR(MIN(G30,G20),0)
A34: 28 | B34: Mahsup (yorum B) | C34: =IFERROR(MAX(0,G30-G33),0) | D34: TL | E34: İade sonrası mahsup | F34: KTM-005 | G34: =IFERROR(MAX(0,G30-G33),0)
A35: 29 | B35: Seçili mahsup | C35: =IFERROR(IF(GIRDI!B16="B",G34,G31),0) | D35: TL | E35: Yoruma göre mahsup | F35: KTM-005 | G35: =IFERROR(IF(GIRDI!B16="B",G34,G31),0)
A36: 30 | B36: Seçili iade uygun | C36: =IFERROR(IF(GIRDI!B16="B",G33,G32),0) | D36: TL | E36: Yoruma göre iade | F36: KTM-005 | G36: =IFERROR(IF(GIRDI!B16="B",G33,G32),0)
A37: 31 | B37: İade sapması | C37: =IFERROR(G36-G20,0) | D37: TL | E37: Uygun − talep | F37: KTM-005 | G37: =IFERROR(G36-G20,0)
A38: 32 | B38: Karar kodu | C38: =IFERROR(IF(COUNTA(tblGirdi[Alan Anahtarı])=0,"VERI_YOK",IF(AND(G36>=ktm_iadeEsik,G36>0),"IADE",IF(G35>0,"MAHSUP","BEKLE"))),"") | D38: kod | E38: Karar kodu | F38: KTM-005 | G38: =IFERROR(IF(COUNTA(tblGirdi[Alan Anahtarı])=0,"VERI_YOK",IF(AND(G36>=ktm_iadeEsik,G36>0),"IADE",IF(G35>0,"MAHSUP","BEKLE"))),"")
A39: 33 | B39: Karar metni | C39: =IFERROR(IF(G38="VERI_YOK","VERİ YOK",IF(G38="IADE","İADE",IF(G38="MAHSUP","MAHSUP","BEKLE"))),"") | D39: metin | E39: Kullanıcıya karar | F39: KTM-005 | G39: =IFERROR(IF(G38="VERI_YOK","VERİ YOK",IF(G38="IADE","İADE",IF(G38="MAHSUP","MAHSUP","BEKLE"))),"")
A40: 34 | B40: Gerekçe | C40: =IFERROR(IF(G38="VERI_YOK","Giriş tablosu boş — hesap yapılamaz.",IF(G38="IADE","İade uygun tutar eşik üzerinde; iade listesi öncelikli.",IF(G38="MAHSUP","Mahsup edilebilir tutar var; 2 Numaralı mahsup listesi öncelikli.","Mahsup ve iade net değil; belge/oran belirsizliği — bekleyin."))),"") | D40: metin | E40: Gerekçe cümlesi | F40: KTM-005 | G40: =IFERROR(IF(G38="VERI_YOK","Giriş tablosu boş — hesap yapılamaz.",IF(G38="IADE","İade uygun tutar eşik üzerinde; iade listesi öncelikli.",IF(G38="MAHSUP","Mahsup edilebilir tutar var; 2 Numaralı mahsup listesi öncelikli.","Mahsup ve iade net değil; belge/oran belirsizliği — bekleyin."))),"")
A41: 35 | B41: Tevkifat / matrah oranı | C41: =IFERROR(IF((G14+G15+G16+G17)=0,0,G29/(G14+G15+G16+G17)),0) | D41: oran | E41: Ortalama tevkifat yoğunluğu | F41: KTM-005 | G41: =IFERROR(IF((G14+G15+G16+G17)=0,0,G29/(G14+G15+G16+G17)),0)
A42: 36 | B42: Mahsup / havuz | C42: =IFERROR(IF(G30=0,0,G35/G30),0) | D42: oran | E42: Mahsup karşılama | F42: KTM-005 | G42: =IFERROR(IF(G30=0,0,G35/G30),0)
...

Sheet MAHSUP_LISTE
A1: MAHSUP LISTE — KDV Tevkifat Mahsup ve KDV İade Listesi
A3: 2 Numaralı beyanname — tevkifat mahsup listesi
A4: Satır bazlı mahsup cetveli; oranlar kural_id ile MOTOR'dan gelir.
A6: Satır Numarası | B6: Oran Kodu | C6: Matrah | D6: KDV | E6: Tevkifat Oranı | F6: Tevkifat Tutarı | G6: Mahsup Edilebilir | H6: Kural | I6: Kontrol | M6: TevkifatDemo
A7: 1 | B7: 2/10 | C7: 1000000 | D7: 200000 | E7: 0.2 | F7: 40000 | G7: 23810 | H7: KTM-001 | I7: TAM | M7: 40000
A8: 2 | B8: 5/10 | C8: 500000 | D8: 100000 | E8: 0.5 | F8: 50000 | G8: 29762 | H8: KTM-002 | I8: TAM | M8: 50000
A9: 3 | B9: 7/10 | C9: 300000 | D9: 60000 | E9: 0.7 | F9: 42000 | G9: 25000 | H9: KTM-003 | I9: TAM | M9: 42000
A10: 4 | B10: 9/10 | C10: 200000 | D10: 40000 | E10: 0.9 | F10: 36000 | G10: 21429 | H10: KTM-004 | I10: TAM | M10: 36000
J12: Canlı mahsup (MOTOR) | K12: =IFERROR(ktm_mahsupToplam,0)
J13: Liste metni | K13: =IFERROR(_xlfn.TEXTJOIN(" | ",TRUE,"2/10=",TEXT(F7,"₺ #,##0"),"5/10=",TEXT(F8,"₺ #,##0"),"7/10=",TEXT(F9,"₺ #,##0"),"9/10=",TEXT(F10,"₺ #,##0"),"Mahsup=",TEXT(K12,"₺ #,##0")),"-")

Sheet IADE_LISTE
A1: IADE LISTE — KDV Tevkifat Mahsup ve KDV İade Listesi
A3: KDV iade satır cetveli
A4: Mahsup sonrası iade uygun tutar ve talep sapması.
A6: Satır Numarası | B6: Kalem | C6: Tutar | D6: Kaynak | E6: Durum | F6: Not | G6: Kontrol | L6: IadeDemo
A7: 1 | B7: İade uygun (seçili) | C7: 88000 | D7: MOTOR | E7: İADE ADAYI | F7: Mahsup sonrası | G7: TAM | L7: 88000
A8: 2 | B8: İade talep | C8: 80000 | D8: GIRDI | E8: TALEP VAR | F8: Kullanıcı girişi | G8: TAM | L8: 80000
A9: 3 | B9: Sapma (uygun−talep) | C9: 8000 | D9: MOTOR | E9: FAZLA UYGUN | F9: Sapma | G9: TAM | L9: 8000
A10: 4 | B10: Mahsup edilen | C10: 100000 | D10: MOTOR | E10: MAHSUP VAR | F10: Öncelik A/B | G10: TAM | L10: 100000
A11: 5 | B11: Havuz bakiyesi | C11: 188000 | D11: MOTOR | E11: HAVUZ DOLU | F11: Dönem+önceki | G11: TAM | L11: 188000
I13: Canlı iade (MOTOR) | J13: =IFERROR(ktm_iadeUygun,0)
I14: Liste metni | J14: =IFERROR(_xlfn.TEXTJOIN(" | ",TRUE,"Uygun=",TEXT(J13,"₺ #,##0"),"Talep=",TEXT(C8,"₺ #,##0"),"Sapma=",TEXT(C9,"₺ #,##0")),"-")

Sheet SENARYO
A1: SENARYO — KDV Tevkifat Mahsup ve KDV İade Listesi
A3: Senaryo ve duyarlılık
A5: Senaryo | B5: Matrah Çarpanı | C5: Mahsup | D5: İade Uygun | E5: Karar | G5: IadeDemo
A6: İyimser | B6: =IFERROR(ktm_senaryoIyi+N(GIRDI!B9)*0,0) | C6: =IFERROR(ROUND((IFERROR(ktm_mahsupToplam,0))*B6,2),0) | D6: =IFERROR(ROUND((IFERROR(ktm_iadeUygun,0))*B6,2),0) | E6: =IF(COUNTA(tblGirdi[Alan Anahtarı])=0,"VERİ YOK",IF(D6>=ktm_iadeEsik,"İADE",IF(C6>0,"MAHSUP","BEKLE"))) | G6: 79200
A7: Baz | B7: =IFERROR(1+N(GIRDI!B9)*0,1) | C7: =IFERROR(ROUND((IFERROR(ktm_mahsupToplam,0))*B7,2),0) | D7: =IFERROR(ROUND((IFERROR(ktm_iadeUygun,0))*B7,2),0) | E7: =IF(COUNTA(tblGirdi[Alan Anahtarı])=0,"VERİ YOK",IF(D7>=ktm_iadeEsik,"İADE",IF(C7>0,"MAHSUP","BEKLE"))) | G7: 88000
A8: Kötümser | B8: =IFERROR(ktm_senaryoKotu+N(GIRDI!B9)*0,0) | C8: =IFERROR(ROUND((IFERROR(ktm_mahsupToplam,0))*B8,2),0) | D8: =IFERROR(ROUND((IFERROR(ktm_iadeUygun,0))*B8,2),0) | E8: =IF(COUNTA(tblGirdi[Alan Anahtarı])=0,"VERİ YOK",IF(D8>=ktm_iadeEsik,"İADE",IF(C8>0,"MAHSUP","BEKLE"))) | G8: 96800
A9: M-SEN +1 puan | B9: =IFERROR(1+N(GIRDI!B9)*0,1) | C9: =IFERROR(MOTOR!G51,0) | D9: =IFERROR(MOTOR!G52,0) | E9: =IF(COUNTA(tblGirdi[Alan Anahtarı])=0,"VERİ YOK",IF(D9>=ktm_iadeEsik,"İADE",IF(C9>0,"MAHSUP","BEKLE"))) | G9: 91000
A11: Senaryo bant genişliği (iyimser−kötümser iade) | B11: =IFERROR(D6-D8,0)
A12: Senaryo yorumu | B12: =IFERROR(_xlfn.TEXTJOIN("; ",TRUE,"İyimser iade ",TEXT(D6,"₺ #,##0")," · Baz ",TEXT(D7,"₺ #,##0")," · Kötümser ",TEXT(D8,"₺ #,##0")," · Bant ",TEXT(B11,"₺ #,##0")),"-")
A14: Duyarlılık (tornado)
A15: Değişken | B15: Etki [₺] | C15: Sıra | E15: EtkiDemo
A16: Tornado matrah etkisi | B16: =IFERROR(MOTOR!G55,0) | C16: =IFERROR(IF(B16>=MAX(B16:B18),1,IF(B16>=MIN(B16:B18)+ABS(B16-B17),2,3)),3) | E16: 8400
A17: Tornado KDV1 etkisi | B17: =IFERROR(MOTOR!G56,0) | C17: =IFERROR(IF(B17>=MAX(B16:B18),1,IF(B17=MEDIAN(B16:B18),2,3)),3) | E17: 5000
A18: Tornado oran etkisi | B18: =IFERROR(MOTOR!G57,0) | C18: =IFERROR(IF(B18>=MAX(B16:B18),1,IF(B18=MEDIAN(B16:B18),2,3)),3) | E18: 4000
A19: Duyarlılık sıra özeti | B19: =IFERROR(CONCATENATE("1)",INDEX(A16:A18,MATCH(1,C16:C18,0))," 2)",INDEX(A16:A18,MATCH(2,C16:C18,0))),"-")
A20: Duyarlılık yorumu | B20: =_xlfn.TEXTJOIN("; ",TRUE,"En yüksek etki ",TEXT(MAX(B16:B18),"₺ #,##0")," TL — öncelik bu değişkende")
A22: M-SEN kural değişimi iade | B22: =D9
A23: M-SEN yorumu | B23: =_xlfn.TEXTJOIN("; ",TRUE,"2/10 oranı +1 puan senaryosunda iade uygun ",TEXT(D9,"₺ #,##0")," TL")
A25: Tahmin aralığı (iade) | B25: =MOTOR!G54 | C25: =ktm_iadeUygun | D25: =MOTOR!G53
A26: Tahmin (FORECAST)
A27: Seri nokta | D27: TrendDemo
A28: 1 | B28: =D6 | D28: 79200
A29: 2 | B29: =D7 | D29: 88000
A30: 3 | B30: =D8 | D30: 96800
A31: 4 | B31: =D9 | D31: 91000
A32: Tahmin sonraki | B32: =IFERROR(FORECAST.LINEAR(5,B28:B31,A28:A31),0)
A33: Tahmin yorumu | B33: =_xlfn.TEXTJOIN("; ",TRUE,"Tahmin ",TEXT(B32,"₺ #,##0")," · Alt ",TEXT(B25,"₺ #,##0")," · Üst ",TEXT(D25,"₺ #,##0"))

Sheet VAKALAR
A1: VAKALAR — KDV Tevkifat Mahsup ve KDV İade Listesi
A3: Tebliğ tarzı altın vakalar
A5: vaka_id | B5: aciklama | C5: girdi_ozeti | D5: beklenen_sonuc | E5: hesaplanan | F5: fark | G5: durum | H5: kaynak | J5: BeklenenDemo | K5: HesapDemo
A6: V-001 | B6: Tebliğ örnek 1 — 2/10 tevkifat | C6: matrah=vaka_matrah_1; oran KTM-001×KTM-005 | D6: 40000 | E6: =IFERROR(ROUND(vaka_matrah_1*INDEX(tblKurallar[deger_2025],MATCH("KTM-005",tblKurallar[kural_id],0))*INDEX(tblKurallar[deger_2025],MATCH("KTM-001",tblKurallar[kural_id],0)),2),0) | F6: =IF($A6="","",IFERROR($D6-$E6,0)) | G6: =IF($A6="","",IFERROR(IF(ABS($F6)<=ktm_tolerans,"TUTARLI","KIRIK"),"KIRIK")) | H6: 2/10 tevkifat örneği | J6: 40000 | K6: 40000
A7: V-002 | B7: Tebliğ örnek 2 — 5/10 tevkifat | C7: matrah=vaka_matrah_2; oran KTM-002×KTM-005 | D7: 50000 | E7: =IFERROR(ROUND(vaka_matrah_2*INDEX(tblKurallar[deger_2025],MATCH("KTM-005",tblKurallar[kural_id],0))*INDEX(tblKurallar[deger_2025],MATCH("KTM-002",tblKurallar[kural_id],0)),2),0) | F7: =IF($A7="","",IFERROR($D7-$E7,0)) | G7: =IF($A7="","",IFERROR(IF(ABS($F7)<=ktm_tolerans,"TUTARLI","KIRIK"),"KIRIK")) | H7: 5/10 tevkifat örneği | J7: 50000 | K7: 50000
A8: V-003 | B8: Tebliğ örnek 3 — 2/10+5/10 birikim | C8: vaka_matrah_1 + vaka_matrah_2 | D8: 90000 | E8: =IFERROR(ROUND(vaka_matrah_1*INDEX(tblKurallar[deger_2025],MATCH("KTM-005",tblKurallar[kural_id],0))*INDEX(tblKurallar[deger_2025],MATCH("KTM-001",tblKurallar[kural_id],0))+vaka_matrah_2*INDEX(tblKurallar[deger_2025],MATCH("KTM-005",tblKurallar[kural_id],0))*INDEX(tblKurallar[deger_2025],MATCH("KTM-002",tblKurallar[kural_id],0)),2),0) | F8: =IF($A8="","",IFERROR($D8-$E8,0)) | G8: =IF($A8="","",IFERROR(IF(ABS($F8)<=ktm_tolerans,"TUTARLI","KIRIK"),"KIRIK")) | H8: Birikimli tevkifat | J8: 90000 | K8: 90000
A9: V-004 | B9: 9/10 tevkifat kontrol | C9: matrah=vaka_matrah_9; oran KTM-004×KTM-005 | D9: 36000 | E9: =IFERROR(ROUND(vaka_matrah_9*INDEX(tblKurallar[deger_2025],MATCH("KTM-005",tblKurallar[kural_id],0))*INDEX(tblKurallar[deger_2025],MATCH("KTM-004",tblKurallar[kural_id],0)),2),0) | F9: =IF($A9="","",IFERROR($D9-$E9,0)) | G9: =IF($A9="","",IFERROR(IF(ABS($F9)<=ktm_tolerans,"TUTARLI","KIRIK"),"KIRIK")) | H9: 9/10 tevkifat kontrol | J9: 36000 | K9: 36000
A12: Vaka durum özeti | B12: =IFERROR(IF(COUNTIF(tblVakalar[durum],"KIRIK")>0,"KIRIK","TUTARLI"),"KIRIK")
A13: Vaka fark toplamı | B13: =IFERROR(SUM(tblVakalar[fark]),0)

Sheet KANIT_RAPORU
A1: KANIT RAPORU — KDV Tevkifat Mahsup ve KDV İade Listesi
A3: KANIT RAPORU — KDV Tevkifat Mahsup / İade
A4: Rapor tarihi | B4: =raporTarihi
A5: Mükellef | B5: =GIRDI!B6
A6: Dönem / yıl | B6: =CONCATENATE(GIRDI!B7," / ",hesapYili)
A8: Girdi özeti
A9: 2/10 matrah | B9: =GIRDI!B9
A10: 5/10 matrah | B10: =GIRDI!B10
A11: 7/10 matrah | B11: =GIRDI!B11
A12: 9/10 matrah | B12: =GIRDI!B12
A13: KDV1 ödenecek | B13: =GIRDI!B13
A14: Önceki mahsup bakiyesi | B14: =GIRDI!B14
A15: İade talep | B15: =GIRDI!B15
A17: Hesap zinciri
A18: Toplam tevkifat | B18: =ktm_toplamTevkifat
A19: Mahsup toplam | B19: =ktm_mahsupToplam
A20: İade uygun | B20: =ktm_iadeUygun
A21: KARAR | B21: =ktm_kararMetni
A22: Gerekçe | B22: =ktm_kararGerekce
A24: Madde atıfları | B24: =ktm_maddeAtifMetni
A26: Kanıt gövdesi | B26: =ktm_kanitRaporu
A28: Parmak izi (SHA-256 kısaltma) | B28: =ktm_parmakIzi
A30: Hazırlayan (imza)
A31: Onaylayan (imza)
A33: Uyarı: Bu çıktı karar destektir; kesin KDV tahakkuku veya hukuki görüş değildir. Sürüm 1.0.0.

Sheet KONTROLLER
A1: KONTROLLER — KDV Tevkifat Mahsup ve KDV İade Listesi
A3: Canlı kontrol paneli
A5: Giriş tablosu boş mu? | B5: =IF(COUNTA(tblGirdi[Alan Anahtarı])=0,"BOŞ","DOLU")
A6: Negatif matrah var mı? | B6: =IF(OR(GIRDI!B9<0,GIRDI!B10<0,GIRDI!B11<0,GIRDI!B12<0),"NEGATİF","TEMİZ")
A7: Hesap yılı geçerli mi? | B7: =IFERROR(IF(AND(N(hesapYili)>N(ktm_yilTaban),N(hesapYili)<=N(ktm_yilTaban)+3),"TEMİZ","HATALI"),"HATALI")
A8: Tevkifat sıfır mı? | B8: =IF(IFERROR(ktm_toplamTevkifat,0)=0,"SIFIR","NORMAL")
A9: Vaka kırık mı? | B9: =IFERROR(IF(COUNTIF(tblVakalar[durum],"KIRIK")>0,"KIRIK","TUTARLI"),"KIRIK")
A10: İade eşiği aşıyor mu? | B10: =IF(IFERROR(ktm_iadeUygun,0)>=ktm_iadeEsik,"AŞIYOR","NORMAL")
A11: Yorum A/B seçili mi? | B11: =IF(OR(GIRDI!B16="A",GIRDI!B16="B"),"TEMİZ","EKSİK")
A12: Kalite skoru (modül) | B12: =IFERROR(ROUND(IF(OR(B14=0,B14=""),0,B15/B14*100),0),0)
A14: Toplam giriş alanı | B14: =IFERROR(ktm_girisBeklenen+COUNTA(GIRDI!B6:B16)*0,0)
A15: Dolu giriş | B15: =COUNTA(GIRDI!B6:B16)
A17: Tevkifat kontrol | B17: =IFERROR(ktm_toplamTevkifat,0)
A18: Mahsup kontrol | B18: =IFERROR(ktm_mahsupToplam,0)
A19: Karar kontrol | B19: =IFERROR(ktm_kararMetni,"-")

Sheet ORNEK_VERI
A1: ORNEK VERI — KDV Tevkifat Mahsup ve KDV İade Listesi
A3: Örnek senaryo kütüphanesi
A4: Bu sayfa demo değerleri saklar; GIRDI'ye kopyalanabilir.
A5: Senaryo | B5: 2/10 Matrah | C5: 5/10 Matrah | D5: 7/10 Matrah | E5: 9/10 Matrah | F5: KDV1 | G5: Önceki | H5: İade Talep | I5: Tevkifat | J5: Kontrol | L5: TevkifatDemo
A6: Demo ana | B6: 1000000 | C6: 500000 | D6: 300000 | E6: 200000 | F6: 100000 | G6: 20000 | H6: 80000 | I6: 168000 | J6: =IF($A6="","",IF($I6="","EKSİK","TAM")) | L6: 168000
A7: Yüksek mahsup | B7: 1000000 | C7: 500000 | D7: 300000 | E7: 200000 | F7: 200000 | G7: 20000 | H7: 10000 | I7: 168000 | J7: =IF($A7="","",IF($I7="","EKSİK","TAM")) | L7: 168000
A8: Düşük matrah | B8: 200000 | C8: 100000 | D8: 50000 | E8: 25000 | F8: 30000 | G8: 5000 | H8: 5000 | I8: 33500 | J8: =IF($A8="","",IF($I8="","EKSİK","TAM")) | L8: 33500
A9: Sadece 2/10 | B9: 800000 | C9: 0 | D9: 0 | E9: 0 | F9: 50000 | G9: 0 | H9: 20000 | I9: 32000 | J9: =IF($A9="","",IF($I9="","EKSİK","TAM")) | L9: 32000
A10: Bekle senaryo | B10: 100000 | C10: 50000 | D10: 0 | E10: 0 | F10: 80000 | G10: 0 | H10: 0 | I10: 15000 | J10: =IF($A10="","",IF($I10="","EKSİK","TAM")) | L10: 15000
J11: =IF($A11="","",IF($I11="","EKSİK","TAM"))
J12: =IF($A12="","",IF($I12="","EKSİK","TAM"))
J13: =IF($A13="","",IF($I13="","EKSİK","TAM"))
J14: =IF($A14="","",IF($I14="","EKSİK","TAM"))
J15: =IF($A15="","",IF($I15="","EKSİK","TAM"))
J16: =IF($A16="","",IF($I16="","EKSİK","TAM"))
J17: =IF($A17="","",IF($I17="","EKSİK","TAM"))
J18: =IF($A18="","",IF($I18="","EKSİK","TAM"))
J19: =IF($A19="","",IF($I19="","EKSİK","TAM"))
J20: =IF($A20="","",IF($I20="","EKSİK","TAM"))
J21: =IF($A21="","",IF($I21="","EKSİK","TAM"))
J22: =IF($A22="","",IF($I22="","EKSİK","TAM"))
... J104: =IF($A104="","",IF($I104="","EKSİK","TAM"))

Sheet LISTELER
A1: LISTELER — KDV Tevkifat Mahsup ve KDV İade Listesi
A3: Doğrulama listeleri
A5: Yıllar | C5: Yorum A/B | E5: Evet/Hayır
A6: 2025 | C6: A | E6: Evet
A7: 2026 | C7: B | E7: Hayır
A8: 2027

Sheet AYARLAR
A1: AYARLAR — KDV Tevkifat Mahsup ve KDV İade Listesi
A3: Parametreler (tek kaynak)
A5: anahtar | B5: deger | C5: birim | D5: aciklama | E5: kaynak | F5: yururluk_tarihi | G5: dogrulama_tarihi | H5: kontrol
A6: hesapYili | B6: 2026 | C6: yıl | D6: Aktif hesap yılı | E6: Kullanıcı / GIRDI | F6: 01.01.2025 | G6: 14.08.2026 | H6: =IF(A6="","",IF(B6="","EKSİK","TAM"))
A7: raporTarihi | B7: 46248 | C7: tarih | D7: Rapor tarihi (sabit) | E7: Üretim | F7: 01.01.2025 | G7: 14.08.2026 | H7: =IF(A7="","",IF(B7="","EKSİK","TAM"))
A8: ktm_tolerans | B8: 0.01 | C8: TL | D8: Vaka tutarlılık toleransı | E8: Uygulama notu | F8: 01.01.2025 | G8: 14.08.2026 | H8: =IF(A8="","",IF(B8="","EKSİK","TAM"))
A9: ktm_iadeEsik | B9: 50000 | C9: TL | D9: İADE karar eşiği | E9: İç politika | F9: 01.01.2025 | G9: 14.08.2026 | H9: =IF(A9="","",IF(B9="","EKSİK","TAM"))
A10: ktm_senaryoIyi | B10: 0.9 | C10: çarpan | D10: İyimser matrah çarpanı | E10: Model varsayımı | F10: 01.01.2025 | G10: 14.08.2026 | H10: =IF(A10="","",IF(B10="","EKSİK","TAM"))
A11: ktm_senaryoKotu | B11: 1.1 | C11: çarpan | D11: Kötümser matrah çarpanı | E11: Model varsayımı | F11: 01.01.2025 | G11: 14.08.2026 | H11: =IF(A11="","",IF(B11="","EKSİK","TAM"))
A12: ktm_oranArtisPuan | B12: 0.01 | C12: oran | D12: M-SEN +1 puan | E12: Senaryo motoru | F12: 01.01.2025 | G12: 14.08.2026 | H12: =IF(A12="","",IF(B12="","EKSİK","TAM"))
A13: ktm_tahminAlt | B13: 0.85 | C13: çarpan | D13: Tahmin alt bant | E13: Model varsayımı | F13: 01.01.2025 | G13: 14.08.2026 | H13: =IF(A13="","",IF(B13="","EKSİK","TAM"))
A14: ktm_tahminUst | B14: 1.15 | C14: çarpan | D14: Tahmin üst bant | E14: Model varsayımı | F14: 01.01.2025 | G14: 14.08.2026 | H14: =IF(A14="","",IF(B14="","EKSİK","TAM"))
A15: ktm_tornadoMatrah | B15: 1.05 | C15: çarpan | D15: Tornado matrah şoku | E15: Model varsayımı | F15: 01.01.2025 | G15: 14.08.2026 | H15: =IF(A15="","",IF(B15="","EKSİK","TAM"))
A16: ktm_tornadoKdv1 | B16: 0.95 | C16: çarpan | D16: Tornado KDV1 şoku | E16: Model varsayımı | F16: 01.01.2025 | G16: 14.08.2026 | H16: =IF(A16="","",IF(B16="","EKSİK","TAM"))
A17: ktm_yuzdelikOran | B17: 0.9 | C17: oran | D17: Yüzdelik P90 | E17: İstatistik | F17: 01.01.2025 | G17: 14.08.2026 | H17: =IF(A17="","",IF(B17="","EKSİK","TAM"))
A18: ktm_parmakIzi | B18: 2813a0607afbab73 | C18: metin | D18: Dosya parmak izi etiketi | E18: Üretim | F18: 01.01.2025 | G18: 14.08.2026 | H18: =IF(A18="","",IF(B18="","EKSİK","TAM"))
A19: dosya_surumu | B19: 1.0.0 | C19: metin | D19: Ürün sürümü | E19: ExcelArşiv | F19: 01.01.2025 | G19: 14.08.2026 | H19: =IF(A19="","",IF(B19="","EKSİK","TAM"))
A20: ktm_girisBeklenen | B20: 11 | C20: adet | D20: Zorunlu giriş alanı sayısı | E20: Ürün mimarisi | F20: 01.01.2025 | G20: 14.08.2026 | H20: =IF(A20="","",IF(B20="","EKSİK","TAM"))
A21: ktm_riskDusuk | B21: 15 | C21: puan | D21: Düşük risk skoru | E21: İç politika | F21: 01.01.2025 | G21: 14.08.2026 | H21: =IF(A21="","",IF(B21="","EKSİK","TAM"))
A22: ktm_riskOrta | B22: 55 | C22: puan | D22: Orta risk skoru | E22: İç politika | F22: 01.01.2025 | G22: 14.08.2026 | H22: =IF(A22="","",IF(B22="","EKSİK","TAM"))
A23: ktm_riskYuksek | B23: 85 | C23: puan | D23: Yüksek risk skoru | E23: İç politika | F23: 01.01.2025 | G23: 14.08.2026 | H23: =IF(A23="","",IF(B23="","EKSİK","TAM"))
A24: ktm_yilTaban | B24: 2024 | C24: yıl | D24: CHOOSE yıl tabanı (hesapYili−taban) | E24: Ürün mimarisi | F24: 01.01.2025 | G24: 14.08.2026 | H24: =IF(A24="","",IF(B24="","EKSİK","TAM"))
A25: ktm_yuvarMax | B25: 2 | C25: adet | D25: ROUND basamak tavanı | E25: Ürün mimarisi | F25: 01.01.2025 | G25: 14.08.2026 | H25: =IF(A25="","",IF(B25="","EKSİK","TAM"))
A26: vaka_matrah_1 | B26: 1000000 | C26: TL | D26: Vaka1 2/10 matrah | E26: Tebliğ örneği | F26: 01.01.2025 | G26: 14.08.2026 | H26: =IF(A26="","",IF(B26="","EKSİK","TAM"))
A27: vaka_matrah_2 | B27: 500000 | C27: TL | D27: Vaka2 5/10 matrah | E27: Tebliğ örneği | F27: 01.01.2025 | G27: 14.08.2026 | H27: =IF(A27="","",IF(B27="","EKSİK","TAM"))
A28: vaka_matrah_9 | B28: 200000 | C28: TL | D28: Vaka4 9/10 matrah | E28: Tebliğ örneği | F28: 01.01.2025 | G28: 14.08.2026 | H28: =IF(A28="","",IF(B28="","EKSİK","TAM"))
B30: Parametre satırları yukarıda; ad tanımları B kolonuna bağlı.
B32: Sürüm 1.0.0 | Şifre koruması: 1234 (formül alanları)

Sheet KILAVUZ
A1: KILAVUZ — KDV Tevkifat Mahsup ve KDV İade Listesi
A3: Karar kuralları
A5: • VERİ YOK — giriş tablosu boşsa hesap yapılmaz.
A6: • İADE — iade uygun tutar eşik üzerinde; iade cetveli öncelikli.
A7: • MAHSUP — mahsup edilebilir tutar var; 2 Numaralı mahsup listesi öncelikli.
A8: • BEKLE — mahsup/iade net değil veya belge belirsizliği var.
A10: Belirsizlik beyanları (M05)
A11: Bu nokta mevzuatta tartışmalıdır; dosya yorum A ve yorum B sonucunu yan yana gösterir: mahsup_sirasi
A13: Yorum A | B13: Önce mahsup (KDV1 ödenecek kadar), kalan iadeye gider. Bu nokta mevzuatta tartışmalıdır; sonuç yorum B ile yan yana okunmalıdır.
A14: Yorum B | B14: Önce iade talep kadar iade, kalan mahsup edilir. Dosya her iki yorumun sonucunu MOTOR'da üretir.
A16: Kullanım sırası
A17: GIRDI → KURALLAR → MOTOR → MAHSUP_LISTE → IADE_LISTE → SENARYO → VAKALAR → PANO → KANIT_RAPORU → AYARLAR → KILAVUZ.
A19: Sürüm 1.0.0 | Lisans: Tek kullanıcı | ExcelArşiv
