Workbook

Sheet KAPAK
A1: KAPAK — CARİ HESAP, TAHSİLAT VE MÜŞTERİ RİSK TAKİP SİSTEMİ
A5: CARİ RİSK UZMAN
A6: Cari Hesap, Tahsilat ve Müşteri Risk Takip Sistemi
A8: Vadeli satış kararlarını, tahsilat önceliklerini ve müşteri limitlerini
A9: makine üretimi risk skoru ve karar kapısı ile yönetin.
A11: KİMLER İÇİN?
A12: • Finans ve kredi yöneticileri
A13: • Tahsilat ekipleri ve muhasebe uzmanları
A14: • Vadeli satış riskini ölçen satış yöneticileri
A16: NE KAZANDIRIR?
A17: • Açık alacak ve vadesi geçmiş bakiyeyi anında görürsünüz
A18: • Risk skoru ile kiminle vadeli çalışacağınızı netleştirirsiniz
... A28: Başlamak için HIZLI_BAŞLANGIÇ sayfasına gidin.

Sheet HIZLI_BASLANGIC
A1: HIZLI BASLANGIC — CARİ HESAP, TAHSİLAT VE MÜŞTERİ RİSK TAKİP SİSTEMİ
A3: 3 ADIMDA KULLANIM
A5: ADIM 1 — MÜŞTERİ VE FATURA
A6: MUSTERI_KARTLARI'na müşterileri, FATURALAR'a faturaları girin; TAHSILATLAR'a ödemeleri işleyin.
A7: ADIM 2 — TEMİNAT VE İLETİŞİM
A8: TEMINATLAR'ı ve ILETISIM_TAKIP'i tamamlayın; yaşlandırma otomatik hesaplanır.
A9: ADIM 3 — KARAR VE RAPOR
A10: MUSTERI_RISK_SKORU ve KARAR_MOTORU'ndaki kararları inceleyin; RAPOR'u yöneticiye sunun.
A14: ÖNEMLİ NOTLAR
A15: • Sarı hücreler manuel giriş alanlarıdır; diğer hücreler formül üretir ve 1234 şifresiyle korunur.
A16: • Rapor tarihi AYARLAR sayfasındandır; gecikme günleri bu tarihe göre hesaplanır.
A17: • Örnek veri ile deneme için ORNEK_VERI sayfasına bakın; verileri kendi verinizle değiştirin.

Sheet MUSTERI_KARTLARI
A1: MUSTERI KARTLARI — CARİ HESAP, TAHSİLAT VE MÜŞTERİ RİSK TAKİP SİSTEMİ
A3: MÜŞTERİ PORTFÖYÜ VE LİMİT MERKEZİ
A5: Müşteri Kodu | B5: Unvan | C5: Vergi Numarası | D5: Sektör | E5: Bölge | F5: Satış Sorumlusu | G5: İlk Çalışma Tarihi | H5: Varsayılan Vade | I5: Onaylı Risk Limiti | J5: Geçici Ek Limit | K5: Limit Bitiş Tarihi | L5: Teminat Türü | M5: Teminat Değeri | N5: Teminat Geçerlilik Tarihi | O5: Grup Şirketi | P5: Kritik Müşteri mi? | Q5: Durum | R5: Kontrol
A6: M001 | B6: Atlas Yapı A.Ş. | C6: 1111111111 | D6: İnşaat | E6: Marmara | F6: Ayşe Yılmaz | G6: 44576 | H6: 60 | I6: 1250000 | J6: 250000 | K6: 46387 | L6: Banka Teminat Mektubu | M6: 900000 | N6: 46387 | O6: Anadolu Grubu | P6: Hayır | Q6: Aktif | R6: =IF($A6="","",IF(COUNTA($A6:$Q6)>=ZorunluAlanSayisi,"OK","EKSİK")) -> OK
A7: M002 | B7: Bora Perakende Ltd. | C7: 2222222222 | D7: Perakende | E7: Ege | F7: Mehmet Kaya | G7: 44995 | H7: 45 | I7: 800000 | J7: 0 | K7: 46387 | L7: İpotek | M7: 550000 | N7: 46203 | O7: Bağımsız | P7: Hayır | Q7: Aktif | R7: =IF($A6="","",IF(COUNTA($A6:$Q6)>=ZorunluAlanSayisi,"OK","EKSİK")) -> OK
A8: M003 | B8: Cemre Gıda A.Ş. | C8: 3333333333 | D8: Gıda | E8: İç Anadolu | F8: Selin Demir | G8: 44367 | H8: 30 | I8: 650000 | J8: 100000 | K8: 46387 | L8: Çek ve Senet | M8: 300000 | N8: 46235 | O8: Bağımsız | P8: Hayır | Q8: İzlemede | R8: =IF($A6="","",IF(COUNTA($A6:$Q6)>=ZorunluAlanSayisi,"OK","EKSİK")) -> OK
A9: M004 | B9: Delta Tekstil Ltd. | C9: 4444444444 | D9: Tekstil | E9: Ege | F9: Can Arslan | G9: 43866 | H9: 90 | I9: 2000000 | J9: 0 | K9: 46387 | L9: Teminatsız | M9: 0 | N9: 46387 | O9: Bağımsız | P9: Evet | Q9: Askıda | R9: =IF($A6="","",IF(COUNTA($A6:$Q6)>=ZorunluAlanSayisi,"OK","EKSİK")) -> OK
R10: =IF($A6="","",IF(COUNTA($A6:$Q6)>=ZorunluAlanSayisi,"OK","EKSİK")) -> OK
R11: =IF($A6="","",IF(COUNTA($A6:$Q6)>=ZorunluAlanSayisi,"OK","EKSİK")) -> OK
R12: =IF($A6="","",IF(COUNTA($A6:$Q6)>=ZorunluAlanSayisi,"OK","EKSİK")) -> OK
R13: =IF($A6="","",IF(COUNTA($A6:$Q6)>=ZorunluAlanSayisi,"OK","EKSİK")) -> OK
R14: =IF($A6="","",IF(COUNTA($A6:$Q6)>=ZorunluAlanSayisi,"OK","EKSİK")) -> OK
R15: =IF($A6="","",IF(COUNTA($A6:$Q6)>=ZorunluAlanSayisi,"OK","EKSİK")) -> OK
R16: =IF($A6="","",IF(COUNTA($A6:$Q6)>=ZorunluAlanSayisi,"OK","EKSİK")) -> OK
R17: =IF($A6="","",IF(COUNTA($A6:$Q6)>=ZorunluAlanSayisi,"OK","EKSİK")) -> OK
R18: =IF($A6="","",IF(COUNTA($A6:$Q6)>=ZorunluAlanSayisi,"OK","EKSİK")) -> OK
R19: =IF($A6="","",IF(COUNTA($A6:$Q6)>=ZorunluAlanSayisi,"OK","EKSİK")) -> OK
R20: =IF($A6="","",IF(COUNTA($A6:$Q6)>=ZorunluAlanSayisi,"OK","EKSİK")) -> OK
R21: =IF($A6="","",IF(COUNTA($A6:$Q6)>=ZorunluAlanSayisi,"OK","EKSİK")) -> OK
R22: =IF($A6="","",IF(COUNTA($A6:$Q6)>=ZorunluAlanSayisi,"OK","EKSİK")) -> OK
R23: =IF($A6="","",IF(COUNTA($A6:$Q6)>=ZorunluAlanSayisi,"OK","EKSİK")) -> OK
R24: =IF($A6="","",IF(COUNTA($A6:$Q6)>=ZorunluAlanSayisi,"OK","EKSİK")) -> OK
R25: =IF($A6="","",IF(COUNTA($A6:$Q6)>=ZorunluAlanSayisi,"OK","EKSİK")) -> OK
R26: =IF($A6="","",IF(COUNTA($A6:$Q6)>=ZorunluAlanSayisi,"OK","EKSİK")) -> OK
R27: =IF($A6="","",IF(COUNTA($A6:$Q6)>=ZorunluAlanSayisi,"OK","EKSİK")) -> OK
R28: =IF($A6="","",IF(COUNTA($A6:$Q6)>=ZorunluAlanSayisi,"OK","EKSİK")) -> OK
R29: =IF($A6="","",IF(COUNTA($A6:$Q6)>=ZorunluAlanSayisi,"OK","EKSİK")) -> OK
R30: =IF($A6="","",IF(COUNTA($A6:$Q6)>=ZorunluAlanSayisi,"OK","EKSİK")) -> OK
R31: =IF($A6="","",IF(COUNTA($A6:$Q6)>=ZorunluAlanSayisi,"OK","EKSİK")) -> OK
R32: =IF($A6="","",IF(COUNTA($A6:$Q6)>=ZorunluAlanSayisi,"OK","EKSİK")) -> OK
R33: =IF($A6="","",IF(COUNTA($A6:$Q6)>=ZorunluAlanSayisi,"OK","EKSİK")) -> OK
R34: =IF($A6="","",IF(COUNTA($A6:$Q6)>=ZorunluAlanSayisi,"OK","EKSİK")) -> OK
R35: =IF($A6="","",IF(COUNTA($A6:$Q6)>=ZorunluAlanSayisi,"OK","EKSİK")) -> OK
R36: =IF($A6="","",IF(COUNTA($A6:$Q6)>=ZorunluAlanSayisi,"OK","EKSİK")) -> OK
R37: =IF($A6="","",IF(COUNTA($A6:$Q6)>=ZorunluAlanSayisi,"OK","EKSİK")) -> OK
R38: =IF($A6="","",IF(COUNTA($A6:$Q6)>=ZorunluAlanSayisi,"OK","EKSİK")) -> OK
R39: =IF($A6="","",IF(COUNTA($A6:$Q6)>=ZorunluAlanSayisi,"OK","EKSİK")) -> OK
R40: =IF($A6="","",IF(COUNTA($A6:$Q6)>=ZorunluAlanSayisi,"OK","EKSİK")) -> OK
R41: =IF($A6="","",IF(COUNTA($A6:$Q6)>=ZorunluAlanSayisi,"OK","EKSİK")) -> OK
R42: =IF($A6="","",IF(COUNTA($A6:$Q6)>=ZorunluAlanSayisi,"OK","EKSİK")) -> OK
...

Sheet FATURALAR
A1: FATURALAR — CARİ HESAP, TAHSİLAT VE MÜŞTERİ RİSK TAKİP SİSTEMİ
A3: FATURA VE VADE YÖNETİM MERKEZİ
A5: Fatura Kayıt Numarası | B5: Fatura Numarası | C5: Müşteri Kodu | D5: Fatura Tarihi | E5: Vade Tarihi | F5: Fatura Tutarı | G5: Para Birimi | H5: Kur | I5: TL Tutarı | J5: İade/İskonto | K5: Net Fatura | L5: İtirazlı Tutar | M5: Teminat Kapsamı | N5: Proje/Sipariş | O5: Satış Sorumlusu | P5: Belge Durumu | Q5: Mükerrer Kontrol
A6: F001 | B6: 2026-001 | C6: M001 | D6: 46091 | E6: 46151 | F6: 780000 | G6: TRY | H6: 1 | I6: =IF($B6="","",$F6*$H6) -> 780000 | J6: 30000 | K6: =IF($B6="","",$I6-$J6) -> 750000 | L6: 0 | M6: 0 | N6: Proje A-2026 | O6: Ayşe Yılmaz | P6: Onaylı | Q6: =IF($B6="","",IF(COUNTIFS(tblFaturalar[Fatura Numarası],$B6,tblFaturalar[Müşteri Kodu],$C6)>1,"MÜKERRER","UYGUN")) -> UYGUN
A7: F002 | B7: 2026-002 | C7: M001 | D7: 46188 | E7: 46248 | F7: 520000 | G7: TRY | H7: 1 | I7: =IF($B7="","",$F7*$H7) -> 520000 | J7: 0 | K7: =IF($B7="","",$I7-$J7) -> 520000 | L7: 0 | M7: 0 | N7: Proje B-2026 | O7: Ayşe Yılmaz | P7: Onaylı | Q7: =IF($B7="","",IF(COUNTIFS(tblFaturalar[Fatura Numarası],$B7,tblFaturalar[Müşteri Kodu],$C7)>1,"MÜKERRER","UYGUN")) -> UYGUN
A8: F003 | B8: 2026-003 | C8: M002 | D8: 46204 | E8: 46249 | F8: 420000 | G8: TRY | H8: 1 | I8: =IF($B8="","",$F8*$H8) -> 420000 | J8: 20000 | K8: =IF($B8="","",$I8-$J8) -> 400000 | L8: 0 | M8: 0 | N8: Perakende dönem | O8: Mehmet Kaya | P8: Onaylı | Q8: =IF($B8="","",IF(COUNTIFS(tblFaturalar[Fatura Numarası],$B8,tblFaturalar[Müşteri Kodu],$C8)>1,"MÜKERRER","UYGUN")) -> UYGUN
A9: F004 | B9: 2026-004 | C9: M003 | D9: 46162 | E9: 46192 | F9: 680000 | G9: TRY | H9: 1 | I9: =IF($B9="","",$F9*$H9) -> 680000 | J9: 0 | K9: =IF($B9="","",$I9-$J9) -> 680000 | L9: 150000 | M9: 0 | N9: Gıda dönem | O9: Selin Demir | P9: İtirazlı | Q9: =IF($B9="","",IF(COUNTIFS(tblFaturalar[Fatura Numarası],$B9,tblFaturalar[Müşteri Kodu],$C9)>1,"MÜKERRER","UYGUN")) -> UYGUN
A10: F005 | B10: 2026-005 | C10: M004 | D10: 46063 | E10: 46153 | F10: 1500000 | G10: TRY | H10: 1 | I10: =IF($B10="","",$F10*$H10) -> 1500000 | J10: 0 | K10: =IF($B10="","",$I10-$J10) -> 1500000 | L10: 0 | M10: 0 | N10: Tekstil ihracat | O10: Can Arslan | P10: Onaylı | Q10: =IF($B10="","",IF(COUNTIFS(tblFaturalar[Fatura Numarası],$B10,tblFaturalar[Müşteri Kodu],$C10)>1,"MÜKERRER","UYGUN")) -> UYGUN
A11: F006 | B11: 2026-006 | C11: M003 | D11: 46213 | E11: 46243 | F11: 260000 | G11: TRY | H11: 1 | I11: =IF($B11="","",$F11*$H11) -> 260000 | J11: 0 | K11: =IF($B11="","",$I11-$J11) -> 260000 | L11: 0 | M11: 0 | N11: Gıda dönem 2 | O11: Selin Demir | P11: Onaylı | Q11: =IF($B11="","",IF(COUNTIFS(tblFaturalar[Fatura Numarası],$B11,tblFaturalar[Müşteri Kodu],$C11)>1,"MÜKERRER","UYGUN")) -> UYGUN
I12: =IF($B12="","",$F12*$H12) | K12: =IF($B12="","",$I12-$J12) | Q12: =IF($B12="","",IF(COUNTIFS(tblFaturalar[Fatura Numarası],$B12,tblFaturalar[Müşteri Kodu],$C12)>1,"MÜKERRER","UYGUN"))
I13: =IF($B13="","",$F13*$H13) | K13: =IF($B13="","",$I13-$J13) | Q13: =IF($B13="","",IF(COUNTIFS(tblFaturalar[Fatura Numarası],$B13,tblFaturalar[Müşteri Kodu],$C13)>1,"MÜKERRER","UYGUN"))
I14: =IF($B14="","",$F14*$H14) | K14: =IF($B14="","",$I14-$J14) | Q14: =IF($B14="","",IF(COUNTIFS(tblFaturalar[Fatura Numarası],$B14,tblFaturalar[Müşteri Kodu],$C14)>1,"MÜKERRER","UYGUN"))
I15: =IF($B15="","",$F15*$H15) | K15: =IF($B15="","",$I15-$J15) | Q15: =IF($B15="","",IF(COUNTIFS(tblFaturalar[Fatura Numarası],$B15,tblFaturalar[Müşteri Kodu],$C15)>1,"MÜKERRER","UYGUN"))
I16: =IF($B16="","",$F16*$H16) | K16: =IF($B16="","",$I16-$J16) | Q16: =IF($B16="","",IF(COUNTIFS(tblFaturalar[Fatura Numarası],$B16,tblFaturalar[Müşteri Kodu],$C16)>1,"MÜKERRER","UYGUN"))
I17: =IF($B17="","",$F17*$H17) | K17: =IF($B17="","",$I17-$J17) | Q17: =IF($B17="","",IF(COUNTIFS(tblFaturalar[Fatura Numarası],$B17,tblFaturalar[Müşteri Kodu],$C17)>1,"MÜKERRER","UYGUN"))
I18: =IF($B18="","",$F18*$H18) | K18: =IF($B18="","",$I18-$J18) | Q18: =IF($B18="","",IF(COUNTIFS(tblFaturalar[Fatura Numarası],$B18,tblFaturalar[Müşteri Kodu],$C18)>1,"MÜKERRER","UYGUN"))
I19: =IF($B19="","",$F19*$H19) | K19: =IF($B19="","",$I19-$J19) | Q19: =IF($B19="","",IF(COUNTIFS(tblFaturalar[Fatura Numarası],$B19,tblFaturalar[Müşteri Kodu],$C19)>1,"MÜKERRER","UYGUN"))
I20: =IF($B20="","",$F20*$H20) | K20: =IF($B20="","",$I20-$J20) | Q20: =IF($B20="","",IF(COUNTIFS(tblFaturalar[Fatura Numarası],$B20,tblFaturalar[Müşteri Kodu],$C20)>1,"MÜKERRER","UYGUN"))
I21: =IF($B21="","",$F21*$H21) | K21: =IF($B21="","",$I21-$J21) | Q21: =IF($B21="","",IF(COUNTIFS(tblFaturalar[Fatura Numarası],$B21,tblFaturalar[Müşteri Kodu],$C21)>1,"MÜKERRER","UYGUN"))
I22: =IF($B22="","",$F22*$H22) | K22: =IF($B22="","",$I22-$J22) | Q22: =IF($B22="","",IF(COUNTIFS(tblFaturalar[Fatura Numarası],$B22,tblFaturalar[Müşteri Kodu],$C22)>1,"MÜKERRER","UYGUN"))
I23: =IF($B23="","",$F23*$H23) | K23: =IF($B23="","",$I23-$J23) | Q23: =IF($B23="","",IF(COUNTIFS(tblFaturalar[Fatura Numarası],$B23,tblFaturalar[Müşteri Kodu],$C23)>1,"MÜKERRER","UYGUN"))
... I45: =IF($B45="","",$F45*$H45) | K45: =IF($B45="","",$I45-$J45) | Q45: =IF($B45="","",IF(COUNTIFS(tblFaturalar[Fatura Numarası],$B45,tblFaturalar[Müşteri Kodu],$C45)>1,"MÜKERRER","UYGUN"))

Sheet TAHSILATLAR
A1: TAHSILATLAR — CARİ HESAP, TAHSİLAT VE MÜŞTERİ RİSK TAKİP SİSTEMİ
A3: TAHSİLAT KAYIT VE EŞLEŞTİRME MERKEZİ
A5: Tahsilat Kayıt Numarası | B5: Tarih | C5: Müşteri Kodu | D5: Fatura Numarası | E5: Tahsilat Tutarı | F5: Ödeme Türü | G5: Banka/Kasa | H5: Çek/Senet Numarası | I5: Valör Tarihi | J5: Kesinleşti mi? | K5: Açıklama
A6: T001 | B6: 46162 | C6: M001 | D6: 2026-001 | E6: 300000 | F6: Havale/EFT | G6: Akbank | I6: 46162 | J6: =IF($B6="","",IF(ISNUMBER($E6),IF(OR($F6="Çek/Senet",$F6=""),"Hayır","Evet"),"Hayır")) -> Evet
A7: T002 | B7: 46218 | C7: M001 | D7: 2026-001 | E7: 250000 | F7: Havale/EFT | G7: İş Bankası | I7: 46218 | J7: =IF($B7="","",IF(ISNUMBER($E7),IF(OR($F7="Çek/Senet",$F7=""),"Hayır","Evet"),"Hayır")) -> Evet
A8: T003 | B8: 46236 | C8: M002 | D8: 2026-003 | E8: 180000 | F8: Havale/EFT | G8: Garanti | I8: 46236 | J8: =IF($B8="","",IF(ISNUMBER($E8),IF(OR($F8="Çek/Senet",$F8=""),"Hayır","Evet"),"Hayır")) -> Evet
A9: T004 | B9: 46183 | C9: M003 | D9: 2026-004 | E9: 120000 | F9: Çek/Senet | H9: ÇEK-4412 | I9: 46244 | J9: =IF($B9="","",IF(ISNUMBER($E9),IF(OR($F9="Çek/Senet",$F9=""),"Hayır","Evet"),"Hayır")) -> Hayır | K9: Vade bekleniyor
J10: =IF($B10="","",IF(ISNUMBER($E10),IF(OR($F10="Çek/Senet",$F10=""),"Hayır","Evet"),"Hayır"))
J11: =IF($B11="","",IF(ISNUMBER($E11),IF(OR($F11="Çek/Senet",$F11=""),"Hayır","Evet"),"Hayır"))
J12: =IF($B12="","",IF(ISNUMBER($E12),IF(OR($F12="Çek/Senet",$F12=""),"Hayır","Evet"),"Hayır"))
J13: =IF($B13="","",IF(ISNUMBER($E13),IF(OR($F13="Çek/Senet",$F13=""),"Hayır","Evet"),"Hayır"))
J14: =IF($B14="","",IF(ISNUMBER($E14),IF(OR($F14="Çek/Senet",$F14=""),"Hayır","Evet"),"Hayır"))
J15: =IF($B15="","",IF(ISNUMBER($E15),IF(OR($F15="Çek/Senet",$F15=""),"Hayır","Evet"),"Hayır"))
J16: =IF($B16="","",IF(ISNUMBER($E16),IF(OR($F16="Çek/Senet",$F16=""),"Hayır","Evet"),"Hayır"))
J17: =IF($B17="","",IF(ISNUMBER($E17),IF(OR($F17="Çek/Senet",$F17=""),"Hayır","Evet"),"Hayır"))
J18: =IF($B18="","",IF(ISNUMBER($E18),IF(OR($F18="Çek/Senet",$F18=""),"Hayır","Evet"),"Hayır"))
J19: =IF($B19="","",IF(ISNUMBER($E19),IF(OR($F19="Çek/Senet",$F19=""),"Hayır","Evet"),"Hayır"))
J20: =IF($B20="","",IF(ISNUMBER($E20),IF(OR($F20="Çek/Senet",$F20=""),"Hayır","Evet"),"Hayır"))
J21: =IF($B21="","",IF(ISNUMBER($E21),IF(OR($F21="Çek/Senet",$F21=""),"Hayır","Evet"),"Hayır"))
... J45: =IF($B45="","",IF(ISNUMBER($E45),IF(OR($F45="Çek/Senet",$F45=""),"Hayır","Evet"),"Hayır"))

Sheet TEMINATLAR
A1: TEMINATLAR — CARİ HESAP, TAHSİLAT VE MÜŞTERİ RİSK TAKİP SİSTEMİ
A3: TEMİNAT PORTFÖYÜ
A5: Teminat Kayıt Numarası | B5: Müşteri Kodu | C5: Teminat Türü | D5: Belge Numarası | E5: Başlangıç Tarihi | F5: Geçerlilik Tarihi | G5: Nominal Değer | H5: Değerleme İndirimi | I5: Kabul Edilen Değer | J5: Para Birimi | K5: Durum | L5: Kontrol
A6: T001 | B6: M001 | C6: Banka Teminat Mektubu | D6: BTM-24018 | E6: 45366 | F6: 46461 | G6: 900000 | H6: 0.1 | I6: =$G6*(1-$H6) -> 810000 | J6: TRY | K6: =IF($F6="","",IF($F6<RaporTarihi,"SÜRESİ GEÇTİ",IF($F6-RaporTarihi<=YenilemeUyariGunu,"30 GÜN İÇİNDE BİTİYOR","GEÇERLİ"))) -> GEÇERLİ | L6: =IF($A6="","",IF(COUNTA($A6:$J6)>=ZorunluTeminatAlanSayisi,"OK","EKSİK")) -> OK
A7: T002 | B7: M002 | C7: İpotek | D7: IP-8831 | E7: 45108 | F7: 46203 | G7: 550000 | H7: 0.25 | I7: =$G7*(1-$H7) -> 412500 | J7: TRY | K7: =IF($F7="","",IF($F7<RaporTarihi,"SÜRESİ GEÇTİ",IF($F7-RaporTarihi<=YenilemeUyariGunu,"30 GÜN İÇİNDE BİTİYOR","GEÇERLİ"))) -> SÜRESİ GEÇTİ | L7: =IF($A6="","",IF(COUNTA($A6:$J6)>=ZorunluTeminatAlanSayisi,"OK","EKSİK")) -> OK
A8: T003 | B8: M003 | C8: Çek ve Senet | D8: ÇEK-4412 | E8: 46023 | F8: 46235 | G8: 300000 | H8: 0.2 | I8: =$G8*(1-$H8) -> 240000 | J8: TRY | K8: =IF($F8="","",IF($F8<RaporTarihi,"SÜRESİ GEÇTİ",IF($F8-RaporTarihi<=YenilemeUyariGunu,"30 GÜN İÇİNDE BİTİYOR","GEÇERLİ"))) -> SÜRESİ GEÇTİ | L8: =IF($A6="","",IF(COUNTA($A6:$J6)>=ZorunluTeminatAlanSayisi,"OK","EKSİK")) -> OK
I9: =$G9*(1-$H9) -> 0 | K9: =IF($F9="","",IF($F9<RaporTarihi,"SÜRESİ GEÇTİ",IF($F9-RaporTarihi<=YenilemeUyariGunu,"30 GÜN İÇİNDE BİTİYOR","GEÇERLİ"))) | L9: =IF($A6="","",IF(COUNTA($A6:$J6)>=ZorunluTeminatAlanSayisi,"OK","EKSİK")) -> OK
I10: =$G10*(1-$H10) -> 0 | K10: =IF($F10="","",IF($F10<RaporTarihi,"SÜRESİ GEÇTİ",IF($F10-RaporTarihi<=YenilemeUyariGunu,"30 GÜN İÇİNDE BİTİYOR","GEÇERLİ"))) | L10: =IF($A6="","",IF(COUNTA($A6:$J6)>=ZorunluTeminatAlanSayisi,"OK","EKSİK")) -> OK
I11: =$G11*(1-$H11) -> 0 | K11: =IF($F11="","",IF($F11<RaporTarihi,"SÜRESİ GEÇTİ",IF($F11-RaporTarihi<=YenilemeUyariGunu,"30 GÜN İÇİNDE BİTİYOR","GEÇERLİ"))) | L11: =IF($A6="","",IF(COUNTA($A6:$J6)>=ZorunluTeminatAlanSayisi,"OK","EKSİK")) -> OK
I12: =$G12*(1-$H12) -> 0 | K12: =IF($F12="","",IF($F12<RaporTarihi,"SÜRESİ GEÇTİ",IF($F12-RaporTarihi<=YenilemeUyariGunu,"30 GÜN İÇİNDE BİTİYOR","GEÇERLİ"))) | L12: =IF($A6="","",IF(COUNTA($A6:$J6)>=ZorunluTeminatAlanSayisi,"OK","EKSİK")) -> OK
I13: =$G13*(1-$H13) -> 0 | K13: =IF($F13="","",IF($F13<RaporTarihi,"SÜRESİ GEÇTİ",IF($F13-RaporTarihi<=YenilemeUyariGunu,"30 GÜN İÇİNDE BİTİYOR","GEÇERLİ"))) | L13: =IF($A6="","",IF(COUNTA($A6:$J6)>=ZorunluTeminatAlanSayisi,"OK","EKSİK")) -> OK
I14: =$G14*(1-$H14) -> 0 | K14: =IF($F14="","",IF($F14<RaporTarihi,"SÜRESİ GEÇTİ",IF($F14-RaporTarihi<=YenilemeUyariGunu,"30 GÜN İÇİNDE BİTİYOR","GEÇERLİ"))) | L14: =IF($A6="","",IF(COUNTA($A6:$J6)>=ZorunluTeminatAlanSayisi,"OK","EKSİK")) -> OK
I15: =$G15*(1-$H15) -> 0 | K15: =IF($F15="","",IF($F15<RaporTarihi,"SÜRESİ GEÇTİ",IF($F15-RaporTarihi<=YenilemeUyariGunu,"30 GÜN İÇİNDE BİTİYOR","GEÇERLİ"))) | L15: =IF($A6="","",IF(COUNTA($A6:$J6)>=ZorunluTeminatAlanSayisi,"OK","EKSİK")) -> OK
I16: =$G16*(1-$H16) -> 0 | K16: =IF($F16="","",IF($F16<RaporTarihi,"SÜRESİ GEÇTİ",IF($F16-RaporTarihi<=YenilemeUyariGunu,"30 GÜN İÇİNDE BİTİYOR","GEÇERLİ"))) | L16: =IF($A6="","",IF(COUNTA($A6:$J6)>=ZorunluTeminatAlanSayisi,"OK","EKSİK")) -> OK
I17: =$G17*(1-$H17) -> 0 | K17: =IF($F17="","",IF($F17<RaporTarihi,"SÜRESİ GEÇTİ",IF($F17-RaporTarihi<=YenilemeUyariGunu,"30 GÜN İÇİNDE BİTİYOR","GEÇERLİ"))) | L17: =IF($A6="","",IF(COUNTA($A6:$J6)>=ZorunluTeminatAlanSayisi,"OK","EKSİK")) -> OK
I18: =$G18*(1-$H18) -> 0 | K18: =IF($F18="","",IF($F18<RaporTarihi,"SÜRESİ GEÇTİ",IF($F18-RaporTarihi<=YenilemeUyariGunu,"30 GÜN İÇİNDE BİTİYOR","GEÇERLİ"))) | L18: =IF($A6="","",IF(COUNTA($A6:$J6)>=ZorunluTeminatAlanSayisi,"OK","EKSİK")) -> OK
I19: =$G19*(1-$H19) -> 0 | K19: =IF($F19="","",IF($F19<RaporTarihi,"SÜRESİ GEÇTİ",IF($F19-RaporTarihi<=YenilemeUyariGunu,"30 GÜN İÇİNDE BİTİYOR","GEÇERLİ"))) | L19: =IF($A6="","",IF(COUNTA($A6:$J6)>=ZorunluTeminatAlanSayisi,"OK","EKSİK")) -> OK
I20: =$G20*(1-$H20) -> 0 | K20: =IF($F20="","",IF($F20<RaporTarihi,"SÜRESİ GEÇTİ",IF($F20-RaporTarihi<=YenilemeUyariGunu,"30 GÜN İÇİNDE BİTİYOR","GEÇERLİ"))) | L20: =IF($A6="","",IF(COUNTA($A6:$J6)>=ZorunluTeminatAlanSayisi,"OK","EKSİK")) -> OK
I21: =$G21*(1-$H21) -> 0 | K21: =IF($F21="","",IF($F21<RaporTarihi,"SÜRESİ GEÇTİ",IF($F21-RaporTarihi<=YenilemeUyariGunu,"30 GÜN İÇİNDE BİTİYOR","GEÇERLİ"))) | L21: =IF($A6="","",IF(COUNTA($A6:$J6)>=ZorunluTeminatAlanSayisi,"OK","EKSİK")) -> OK
I22: =$G22*(1-$H22) -> 0 | K22: =IF($F22="","",IF($F22<RaporTarihi,"SÜRESİ GEÇTİ",IF($F22-RaporTarihi<=YenilemeUyariGunu,"30 GÜN İÇİNDE BİTİYOR","GEÇERLİ"))) | L22: =IF($A6="","",IF(COUNTA($A6:$J6)>=ZorunluTeminatAlanSayisi,"OK","EKSİK")) -> OK
I23: =$G23*(1-$H23) -> 0 | K23: =IF($F23="","",IF($F23<RaporTarihi,"SÜRESİ GEÇTİ",IF($F23-RaporTarihi<=YenilemeUyariGunu,"30 GÜN İÇİNDE BİTİYOR","GEÇERLİ"))) | L23: =IF($A6="","",IF(COUNTA($A6:$J6)>=ZorunluTeminatAlanSayisi,"OK","EKSİK")) -> OK
I24: =$G24*(1-$H24) -> 0 | K24: =IF($F24="","",IF($F24<RaporTarihi,"SÜRESİ GEÇTİ",IF($F24-RaporTarihi<=YenilemeUyariGunu,"30 GÜN İÇİNDE BİTİYOR","GEÇERLİ"))) | L24: =IF($A6="","",IF(COUNTA($A6:$J6)>=ZorunluTeminatAlanSayisi,"OK","EKSİK")) -> OK
I25: =$G25*(1-$H25) -> 0 | K25: =IF($F25="","",IF($F25<RaporTarihi,"SÜRESİ GEÇTİ",IF($F25-RaporTarihi<=YenilemeUyariGunu,"30 GÜN İÇİNDE BİTİYOR","GEÇERLİ"))) | L25: =IF($A6="","",IF(COUNTA($A6:$J6)>=ZorunluTeminatAlanSayisi,"OK","EKSİK")) -> OK
I26: =$G26*(1-$H26) -> 0 | K26: =IF($F26="","",IF($F26<RaporTarihi,"SÜRESİ GEÇTİ",IF($F26-RaporTarihi<=YenilemeUyariGunu,"30 GÜN İÇİNDE BİTİYOR","GEÇERLİ"))) | L26: =IF($A6="","",IF(COUNTA($A6:$J6)>=ZorunluTeminatAlanSayisi,"OK","EKSİK")) -> OK
I27: =$G27*(1-$H27) -> 0 | K27: =IF($F27="","",IF($F27<RaporTarihi,"SÜRESİ GEÇTİ",IF($F27-RaporTarihi<=YenilemeUyariGunu,"30 GÜN İÇİNDE BİTİYOR","GEÇERLİ"))) | L27: =IF($A6="","",IF(COUNTA($A6:$J6)>=ZorunluTeminatAlanSayisi,"OK","EKSİK")) -> OK
I28: =$G28*(1-$H28) -> 0 | K28: =IF($F28="","",IF($F28<RaporTarihi,"SÜRESİ GEÇTİ",IF($F28-RaporTarihi<=YenilemeUyariGunu,"30 GÜN İÇİNDE BİTİYOR","GEÇERLİ"))) | L28: =IF($A6="","",IF(COUNTA($A6:$J6)>=ZorunluTeminatAlanSayisi,"OK","EKSİK")) -> OK
I29: =$G29*(1-$H29) -> 0 | K29: =IF($F29="","",IF($F29<RaporTarihi,"SÜRESİ GEÇTİ",IF($F29-RaporTarihi<=YenilemeUyariGunu,"30 GÜN İÇİNDE BİTİYOR","GEÇERLİ"))) | L29: =IF($A6="","",IF(COUNTA($A6:$J6)>=ZorunluTeminatAlanSayisi,"OK","EKSİK")) -> OK
I30: =$G30*(1-$H30) -> 0 | K30: =IF($F30="","",IF($F30<RaporTarihi,"SÜRESİ GEÇTİ",IF($F30-RaporTarihi<=YenilemeUyariGunu,"30 GÜN İÇİNDE BİTİYOR","GEÇERLİ"))) | L30: =IF($A6="","",IF(COUNTA($A6:$J6)>=ZorunluTeminatAlanSayisi,"OK","EKSİK")) -> OK
I31: =$G31*(1-$H31) -> 0 | K31: =IF($F31="","",IF($F31<RaporTarihi,"SÜRESİ GEÇTİ",IF($F31-RaporTarihi<=YenilemeUyariGunu,"30 GÜN İÇİNDE BİTİYOR","GEÇERLİ"))) | L31: =IF($A6="","",IF(COUNTA($A6:$J6)>=ZorunluTeminatAlanSayisi,"OK","EKSİK")) -> OK
I32: =$G32*(1-$H32) -> 0 | K32: =IF($F32="","",IF($F32<RaporTarihi,"SÜRESİ GEÇTİ",IF($F32-RaporTarihi<=YenilemeUyariGunu,"30 GÜN İÇİNDE BİTİYOR","GEÇERLİ"))) | L32: =IF($A6="","",IF(COUNTA($A6:$J6)>=ZorunluTeminatAlanSayisi,"OK","EKSİK")) -> OK
I33: =$G33*(1-$H33) -> 0 | K33: =IF($F33="","",IF($F33<RaporTarihi,"SÜRESİ GEÇTİ",IF($F33-RaporTarihi<=YenilemeUyariGunu,"30 GÜN İÇİNDE BİTİYOR","GEÇERLİ"))) | L33: =IF($A6="","",IF(COUNTA($A6:$J6)>=ZorunluTeminatAlanSayisi,"OK","EKSİK")) -> OK
I34: =$G34*(1-$H34) -> 0 | K34: =IF($F34="","",IF($F34<RaporTarihi,"SÜRESİ GEÇTİ",IF($F34-RaporTarihi<=YenilemeUyariGunu,"30 GÜN İÇİNDE BİTİYOR","GEÇERLİ"))) | L34: =IF($A6="","",IF(COUNTA($A6:$J6)>=ZorunluTeminatAlanSayisi,"OK","EKSİK")) -> OK
I35: =$G35*(1-$H35) -> 0 | K35: =IF($F35="","",IF($F35<RaporTarihi,"SÜRESİ GEÇTİ",IF($F35-RaporTarihi<=YenilemeUyariGunu,"30 GÜN İÇİNDE BİTİYOR","GEÇERLİ"))) | L35: =IF($A6="","",IF(COUNTA($A6:$J6)>=ZorunluTeminatAlanSayisi,"OK","EKSİK")) -> OK
I36: =$G36*(1-$H36) -> 0 | K36: =IF($F36="","",IF($F36<RaporTarihi,"SÜRESİ GEÇTİ",IF($F36-RaporTarihi<=YenilemeUyariGunu,"30 GÜN İÇİNDE BİTİYOR","GEÇERLİ"))) | L36: =IF($A6="","",IF(COUNTA($A6:$J6)>=ZorunluTeminatAlanSayisi,"OK","EKSİK")) -> OK
I37: =$G37*(1-$H37) -> 0 | K37: =IF($F37="","",IF($F37<RaporTarihi,"SÜRESİ GEÇTİ",IF($F37-RaporTarihi<=YenilemeUyariGunu,"30 GÜN İÇİNDE BİTİYOR","GEÇERLİ"))) | L37: =IF($A6="","",IF(COUNTA($A6:$J6)>=ZorunluTeminatAlanSayisi,"OK","EKSİK")) -> OK
I38: =$G38*(1-$H38) -> 0 | K38: =IF($F38="","",IF($F38<RaporTarihi,"SÜRESİ GEÇTİ",IF($F38-RaporTarihi<=YenilemeUyariGunu,"30 GÜN İÇİNDE BİTİYOR","GEÇERLİ"))) | L38: =IF($A6="","",IF(COUNTA($A6:$J6)>=ZorunluTeminatAlanSayisi,"OK","EKSİK")) -> OK
I39: =$G39*(1-$H39) -> 0 | K39: =IF($F39="","",IF($F39<RaporTarihi,"SÜRESİ GEÇTİ",IF($F39-RaporTarihi<=YenilemeUyariGunu,"30 GÜN İÇİNDE BİTİYOR","GEÇERLİ"))) | L39: =IF($A6="","",IF(COUNTA($A6:$J6)>=ZorunluTeminatAlanSayisi,"OK","EKSİK")) -> OK
I40: =$G40*(1-$H40) -> 0 | K40: =IF($F40="","",IF($F40<RaporTarihi,"SÜRESİ GEÇTİ",IF($F40-RaporTarihi<=YenilemeUyariGunu,"30 GÜN İÇİNDE BİTİYOR","GEÇERLİ"))) | L40: =IF($A6="","",IF(COUNTA($A6:$J6)>=ZorunluTeminatAlanSayisi,"OK","EKSİK")) -> OK
I41: =$G41*(1-$H41) -> 0 | K41: =IF($F41="","",IF($F41<RaporTarihi,"SÜRESİ GEÇTİ",IF($F41-RaporTarihi<=YenilemeUyariGunu,"30 GÜN İÇİNDE BİTİYOR","GEÇERLİ"))) | L41: =IF($A6="","",IF(COUNTA($A6:$J6)>=ZorunluTeminatAlanSayisi,"OK","EKSİK")) -> OK
I42: =$G42*(1-$H42) -> 0 | K42: =IF($F42="","",IF($F42<RaporTarihi,"SÜRESİ GEÇTİ",IF($F42-RaporTarihi<=YenilemeUyariGunu,"30 GÜN İÇİNDE BİTİYOR","GEÇERLİ"))) | L42: =IF($A6="","",IF(COUNTA($A6:$J6)>=ZorunluTeminatAlanSayisi,"OK","EKSİK")) -> OK
...

Sheet ILETISIM_TAKIP
A1: ILETISIM TAKIP — CARİ HESAP, TAHSİLAT VE MÜŞTERİ RİSK TAKİP SİSTEMİ
A3: İLETİŞİM VE ÖDEME SÖZÜ TAKİBİ
A5: Takip Kayıt Numarası | B5: Tarih | C5: Müşteri Kodu | D5: Yetkili Kişi | E5: Kanal | F5: Görüşme Sonucu | G5: Söz Verilen Tarih | H5: Söz Verilen Tutar | I5: Sonraki Aksiyon | J5: Sorumlu | K5: Söz Gecikme Günü | L5: Söz Durumu
A6: IT001 | B6: 46235 | C6: M003 | D6: Mali İşler Müdürü | E6: Telefon | F6: Kısmi ödeme sözü | G6: 46237 | H6: 150000 | I6: Ödeme dekontunu teyit et | J6: Zeynep Kaya | K6: =IF($B6="","",IF($G6="","",MAX(0,RaporTarihi-$G6))) -> 2 | L6: =IF($B6="","",IF($G6="","BEKLİYOR",IF(RaporTarihi-$G6>0,"SÖZ GECİKTİ",IF($F6="Yerine getirildi","YERİNE GETİRİLDİ","BEKLİYOR")))) -> SÖZ GECİKTİ
A7: IT002 | B7: 46236 | C7: M004 | D7: Finans Uzmanı | E7: E-posta | F7: İtiraz dosyası bekleniyor | G7: 46242 | H7: 400000 | I7: Mutabakat toplantısı planla | J7: Kemal Şahin | K7: =IF($B7="","",IF($G7="","",MAX(0,RaporTarihi-$G7))) -> 0 | L7: =IF($B7="","",IF($G7="","BEKLİYOR",IF(RaporTarihi-$G7>0,"SÖZ GECİKTİ",IF($F7="Yerine getirildi","YERİNE GETİRİLDİ","BEKLİYOR")))) -> BEKLİYOR
K8: =IF($B8="","",IF($G8="","",MAX(0,RaporTarihi-$G8))) | L8: =IF($B8="","",IF($G8="","BEKLİYOR",IF(RaporTarihi-$G8>0,"SÖZ GECİKTİ",IF($F8="Yerine getirildi","YERİNE GETİRİLDİ","BEKLİYOR"))))
K9: =IF($B9="","",IF($G9="","",MAX(0,RaporTarihi-$G9))) | L9: =IF($B9="","",IF($G9="","BEKLİYOR",IF(RaporTarihi-$G9>0,"SÖZ GECİKTİ",IF($F9="Yerine getirildi","YERİNE GETİRİLDİ","BEKLİYOR"))))
K10: =IF($B10="","",IF($G10="","",MAX(0,RaporTarihi-$G10))) | L10: =IF($B10="","",IF($G10="","BEKLİYOR",IF(RaporTarihi-$G10>0,"SÖZ GECİKTİ",IF($F10="Yerine getirildi","YERİNE GETİRİLDİ","BEKLİYOR"))))
K11: =IF($B11="","",IF($G11="","",MAX(0,RaporTarihi-$G11))) | L11: =IF($B11="","",IF($G11="","BEKLİYOR",IF(RaporTarihi-$G11>0,"SÖZ GECİKTİ",IF($F11="Yerine getirildi","YERİNE GETİRİLDİ","BEKLİYOR"))))
K12: =IF($B12="","",IF($G12="","",MAX(0,RaporTarihi-$G12))) | L12: =IF($B12="","",IF($G12="","BEKLİYOR",IF(RaporTarihi-$G12>0,"SÖZ GECİKTİ",IF($F12="Yerine getirildi","YERİNE GETİRİLDİ","BEKLİYOR"))))
K13: =IF($B13="","",IF($G13="","",MAX(0,RaporTarihi-$G13))) | L13: =IF($B13="","",IF($G13="","BEKLİYOR",IF(RaporTarihi-$G13>0,"SÖZ GECİKTİ",IF($F13="Yerine getirildi","YERİNE GETİRİLDİ","BEKLİYOR"))))
K14: =IF($B14="","",IF($G14="","",MAX(0,RaporTarihi-$G14))) | L14: =IF($B14="","",IF($G14="","BEKLİYOR",IF(RaporTarihi-$G14>0,"SÖZ GECİKTİ",IF($F14="Yerine getirildi","YERİNE GETİRİLDİ","BEKLİYOR"))))
K15: =IF($B15="","",IF($G15="","",MAX(0,RaporTarihi-$G15))) | L15: =IF($B15="","",IF($G15="","BEKLİYOR",IF(RaporTarihi-$G15>0,"SÖZ GECİKTİ",IF($F15="Yerine getirildi","YERİNE GETİRİLDİ","BEKLİYOR"))))
K16: =IF($B16="","",IF($G16="","",MAX(0,RaporTarihi-$G16))) | L16: =IF($B16="","",IF($G16="","BEKLİYOR",IF(RaporTarihi-$G16>0,"SÖZ GECİKTİ",IF($F16="Yerine getirildi","YERİNE GETİRİLDİ","BEKLİYOR"))))
K17: =IF($B17="","",IF($G17="","",MAX(0,RaporTarihi-$G17))) | L17: =IF($B17="","",IF($G17="","BEKLİYOR",IF(RaporTarihi-$G17>0,"SÖZ GECİKTİ",IF($F17="Yerine getirildi","YERİNE GETİRİLDİ","BEKLİYOR"))))
K18: =IF($B18="","",IF($G18="","",MAX(0,RaporTarihi-$G18))) | L18: =IF($B18="","",IF($G18="","BEKLİYOR",IF(RaporTarihi-$G18>0,"SÖZ GECİKTİ",IF($F18="Yerine getirildi","YERİNE GETİRİLDİ","BEKLİYOR"))))
K19: =IF($B19="","",IF($G19="","",MAX(0,RaporTarihi-$G19))) | L19: =IF($B19="","",IF($G19="","BEKLİYOR",IF(RaporTarihi-$G19>0,"SÖZ GECİKTİ",IF($F19="Yerine getirildi","YERİNE GETİRİLDİ","BEKLİYOR"))))
... K45: =IF($B45="","",IF($G45="","",MAX(0,RaporTarihi-$G45))) | L45: =IF($B45="","",IF($G45="","BEKLİYOR",IF(RaporTarihi-$G45>0,"SÖZ GECİKTİ",IF($F45="Yerine getirildi","YERİNE GETİRİLDİ","BEKLİYOR"))))

Sheet YASLANDIRMA
A1: YASLANDIRMA — CARİ HESAP, TAHSİLAT VE MÜŞTERİ RİSK TAKİP SİSTEMİ
A3: ALACAK YAŞLANDIRMA ANALİZİ
A5: Fatura Numarası | B5: Müşteri Kodu | C5: Vade Tarihi | D5: Net Fatura | E5: Kesin Tahsilat | F5: Açık Tutar | G5: Gecikme Günü | H5: Yaşlandırma | I5: İtirazlı Tutar | J5: Teminat Kapsamı
A6: =FATURALAR!$B6 -> 2026-001 | B6: =FATURALAR!$C6 -> M001 | C6: =FATURALAR!$E6 -> 46151 | D6: =FATURALAR!$K6 -> 750000 | E6: =SUMIFS(tblTahsilatlar[Tahsilat Tutarı],tblTahsilatlar[Fatura Numarası],$A6,tblTahsilatlar[Kesinleşti mi?],"Evet") -> 550000 | F6: =IF($D6="","",MAX(0,$D6-$E6)) -> 200000 | G6: =IF($F6="","",IF($F6=0,0,MAX(0,RaporTarihi-$C6))) -> 88 | H6: =IF($F6="","",IF($F6=0,"KAPALI",IF($G6<=0,"VADESİ GELMEMİŞ",IF($G6<=YaslamaDilim1,"1-"&TEXT(YaslamaDilim1,"0"),IF($G6<=YaslamaDilim2,TEXT(YaslamaDilim1+1,"0")&"-"&TEXT(YaslamaDilim2,"0"),IF($G6<=YaslamaDilim3,TEXT(YaslamaDilim2+1,"0")&"-"&TEXT(YaslamaDilim3,"0"),TEXT(YaslamaDilim3+1,"0")&"+")))))) -> 61+ | I6: =IF(FATURALAR!$L6=0,"",FATURALAR!$L6) | J6: =IF(FATURALAR!$M6=0,"",FATURALAR!$M6)
A7: =FATURALAR!$B7 -> 2026-002 | B7: =FATURALAR!$C7 -> M001 | C7: =FATURALAR!$E7 -> 46248 | D7: =FATURALAR!$K7 -> 520000 | E7: =SUMIFS(tblTahsilatlar[Tahsilat Tutarı],tblTahsilatlar[Fatura Numarası],$A7,tblTahsilatlar[Kesinleşti mi?],"Evet") -> 0 | F7: =IF($D7="","",MAX(0,$D7-$E7)) -> 520000 | G7: =IF($F7="","",IF($F7=0,0,MAX(0,RaporTarihi-$C7))) -> 0 | H7: =IF($F7="","",IF($F7=0,"KAPALI",IF($G7<=0,"VADESİ GELMEMİŞ",IF($G7<=YaslamaDilim1,"1-"&TEXT(YaslamaDilim1,"0"),IF($G7<=YaslamaDilim2,TEXT(YaslamaDilim1+1,"0")&"-"&TEXT(YaslamaDilim2,"0"),IF($G7<=YaslamaDilim3,TEXT(YaslamaDilim2+1,"0")&"-"&TEXT(YaslamaDilim3,"0"),TEXT(YaslamaDilim3+1,"0")&"+")))))) -> VADESİ GELMEMİŞ | I7: =IF(FATURALAR!$L7=0,"",FATURALAR!$L7) | J7: =IF(FATURALAR!$M7=0,"",FATURALAR!$M7)
A8: =FATURALAR!$B8 -> 2026-003 | B8: =FATURALAR!$C8 -> M002 | C8: =FATURALAR!$E8 -> 46249 | D8: =FATURALAR!$K8 -> 400000 | E8: =SUMIFS(tblTahsilatlar[Tahsilat Tutarı],tblTahsilatlar[Fatura Numarası],$A8,tblTahsilatlar[Kesinleşti mi?],"Evet") -> 180000 | F8: =IF($D8="","",MAX(0,$D8-$E8)) -> 220000 | G8: =IF($F8="","",IF($F8=0,0,MAX(0,RaporTarihi-$C8))) -> 0 | H8: =IF($F8="","",IF($F8=0,"KAPALI",IF($G8<=0,"VADESİ GELMEMİŞ",IF($G8<=YaslamaDilim1,"1-"&TEXT(YaslamaDilim1,"0"),IF($G8<=YaslamaDilim2,TEXT(YaslamaDilim1+1,"0")&"-"&TEXT(YaslamaDilim2,"0"),IF($G8<=YaslamaDilim3,TEXT(YaslamaDilim2+1,"0")&"-"&TEXT(YaslamaDilim3,"0"),TEXT(YaslamaDilim3+1,"0")&"+")))))) -> VADESİ GELMEMİŞ | I8: =IF(FATURALAR!$L8=0,"",FATURALAR!$L8) | J8: =IF(FATURALAR!$M8=0,"",FATURALAR!$M8)
A9: =FATURALAR!$B9 -> 2026-004 | B9: =FATURALAR!$C9 -> M003 | C9: =FATURALAR!$E9 -> 46192 | D9: =FATURALAR!$K9 -> 680000 | E9: =SUMIFS(tblTahsilatlar[Tahsilat Tutarı],tblTahsilatlar[Fatura Numarası],$A9,tblTahsilatlar[Kesinleşti mi?],"Evet") -> 0 | F9: =IF($D9="","",MAX(0,$D9-$E9)) -> 680000 | G9: =IF($F9="","",IF($F9=0,0,MAX(0,RaporTarihi-$C9))) -> 47 | H9: =IF($F9="","",IF($F9=0,"KAPALI",IF($G9<=0,"VADESİ GELMEMİŞ",IF($G9<=YaslamaDilim1,"1-"&TEXT(YaslamaDilim1,"0"),IF($G9<=YaslamaDilim2,TEXT(YaslamaDilim1+1,"0")&"-"&TEXT(YaslamaDilim2,"0"),IF($G9<=YaslamaDilim3,TEXT(YaslamaDilim2+1,"0")&"-"&TEXT(YaslamaDilim3,"0"),TEXT(YaslamaDilim3+1,"0")&"+")))))) -> 31-60 | I9: =IF(FATURALAR!$L9=0,"",FATURALAR!$L9) -> 150000 | J9: =IF(FATURALAR!$M9=0,"",FATURALAR!$M9)
A10: =FATURALAR!$B10 -> 2026-005 | B10: =FATURALAR!$C10 -> M004 | C10: =FATURALAR!$E10 -> 46153 | D10: =FATURALAR!$K10 -> 1500000 | E10: =SUMIFS(tblTahsilatlar[Tahsilat Tutarı],tblTahsilatlar[Fatura Numarası],$A10,tblTahsilatlar[Kesinleşti mi?],"Evet") -> 0 | F10: =IF($D10="","",MAX(0,$D10-$E10)) -> 1500000 | G10: =IF($F10="","",IF($F10=0,0,MAX(0,RaporTarihi-$C10))) -> 86 | H10: =IF($F10="","",IF($F10=0,"KAPALI",IF($G10<=0,"VADESİ GELMEMİŞ",IF($G10<=YaslamaDilim1,"1-"&TEXT(YaslamaDilim1,"0"),IF($G10<=YaslamaDilim2,TEXT(YaslamaDilim1+1,"0")&"-"&TEXT(YaslamaDilim2,"0"),IF($G10<=YaslamaDilim3,TEXT(YaslamaDilim2+1,"0")&"-"&TEXT(YaslamaDilim3,"0"),TEXT(YaslamaDilim3+1,"0")&"+")))))) -> 61+ | I10: =IF(FATURALAR!$L10=0,"",FATURALAR!$L10) | J10: =IF(FATURALAR!$M10=0,"",FATURALAR!$M10)
A11: =FATURALAR!$B11 -> 2026-006 | B11: =FATURALAR!$C11 -> M003 | C11: =FATURALAR!$E11 -> 46243 | D11: =FATURALAR!$K11 -> 260000 | E11: =SUMIFS(tblTahsilatlar[Tahsilat Tutarı],tblTahsilatlar[Fatura Numarası],$A11,tblTahsilatlar[Kesinleşti mi?],"Evet") -> 0 | F11: =IF($D11="","",MAX(0,$D11-$E11)) -> 260000 | G11: =IF($F11="","",IF($F11=0,0,MAX(0,RaporTarihi-$C11))) -> 0 | H11: =IF($F11="","",IF($F11=0,"KAPALI",IF($G11<=0,"VADESİ GELMEMİŞ",IF($G11<=YaslamaDilim1,"1-"&TEXT(YaslamaDilim1,"0"),IF($G11<=YaslamaDilim2,TEXT(YaslamaDilim1+1,"0")&"-"&TEXT(YaslamaDilim2,"0"),IF($G11<=YaslamaDilim3,TEXT(YaslamaDilim2+1,"0")&"-"&TEXT(YaslamaDilim3,"0"),TEXT(YaslamaDilim3+1,"0")&"+")))))) -> VADESİ GELMEMİŞ | I11: =IF(FATURALAR!$L11=0,"",FATURALAR!$L11) | J11: =IF(FATURALAR!$M11=0,"",FATURALAR!$M11)
A12: =FATURALAR!$B12 -> 0 | B12: =FATURALAR!$C12 -> 0 | C12: =FATURALAR!$E12 -> 0 | D12: =FATURALAR!$K12 | E12: =SUMIFS(tblTahsilatlar[Tahsilat Tutarı],tblTahsilatlar[Fatura Numarası],$A12,tblTahsilatlar[Kesinleşti mi?],"Evet") -> 0 | F12: =IF($D12="","",MAX(0,$D12-$E12)) | G12: =IF($F12="","",IF($F12=0,0,MAX(0,RaporTarihi-$C12))) | H12: =IF($F12="","",IF($F12=0,"KAPALI",IF($G12<=0,"VADESİ GELMEMİŞ",IF($G12<=YaslamaDilim1,"1-"&TEXT(YaslamaDilim1,"0"),IF($G12<=YaslamaDilim2,TEXT(YaslamaDilim1+1,"0")&"-"&TEXT(YaslamaDilim2,"0"),IF($G12<=YaslamaDilim3,TEXT(YaslamaDilim2+1,"0")&"-"&TEXT(YaslamaDilim3,"0"),TEXT(YaslamaDilim3+1,"0")&"+")))))) | I12: =IF(FATURALAR!$L12=0,"",FATURALAR!$L12) | J12: =IF(FATURALAR!$M12=0,"",FATURALAR!$M12)
A13: =FATURALAR!$B13 -> 0 | B13: =FATURALAR!$C13 -> 0 | C13: =FATURALAR!$E13 -> 0 | D13: =FATURALAR!$K13 | E13: =SUMIFS(tblTahsilatlar[Tahsilat Tutarı],tblTahsilatlar[Fatura Numarası],$A13,tblTahsilatlar[Kesinleşti mi?],"Evet") -> 0 | F13: =IF($D13="","",MAX(0,$D13-$E13)) | G13: =IF($F13="","",IF($F13=0,0,MAX(0,RaporTarihi-$C13))) | H13: =IF($F13="","",IF($F13=0,"KAPALI",IF($G13<=0,"VADESİ GELMEMİŞ",IF($G13<=YaslamaDilim1,"1-"&TEXT(YaslamaDilim1,"0"),IF($G13<=YaslamaDilim2,TEXT(YaslamaDilim1+1,"0")&"-"&TEXT(YaslamaDilim2,"0"),IF($G13<=YaslamaDilim3,TEXT(YaslamaDilim2+1,"0")&"-"&TEXT(YaslamaDilim3,"0"),TEXT(YaslamaDilim3+1,"0")&"+")))))) | I13: =IF(FATURALAR!$L13=0,"",FATURALAR!$L13) | J13: =IF(FATURALAR!$M13=0,"",FATURALAR!$M13)
A14: =FATURALAR!$B14 -> 0 | B14: =FATURALAR!$C14 -> 0 | C14: =FATURALAR!$E14 -> 0 | D14: =FATURALAR!$K14 | E14: =SUMIFS(tblTahsilatlar[Tahsilat Tutarı],tblTahsilatlar[Fatura Numarası],$A14,tblTahsilatlar[Kesinleşti mi?],"Evet") -> 0 | F14: =IF($D14="","",MAX(0,$D14-$E14)) | G14: =IF($F14="","",IF($F14=0,0,MAX(0,RaporTarihi-$C14))) | H14: =IF($F14="","",IF($F14=0,"KAPALI",IF($G14<=0,"VADESİ GELMEMİŞ",IF($G14<=YaslamaDilim1,"1-"&TEXT(YaslamaDilim1,"0"),IF($G14<=YaslamaDilim2,TEXT(YaslamaDilim1+1,"0")&"-"&TEXT(YaslamaDilim2,"0"),IF($G14<=YaslamaDilim3,TEXT(YaslamaDilim2+1,"0")&"-"&TEXT(YaslamaDilim3,"0"),TEXT(YaslamaDilim3+1,"0")&"+")))))) | I14: =IF(FATURALAR!$L14=0,"",FATURALAR!$L14) | J14: =IF(FATURALAR!$M14=0,"",FATURALAR!$M14)
A15: =FATURALAR!$B15 -> 0 | B15: =FATURALAR!$C15 -> 0 | C15: =FATURALAR!$E15 -> 0 | D15: =FATURALAR!$K15 | E15: =SUMIFS(tblTahsilatlar[Tahsilat Tutarı],tblTahsilatlar[Fatura Numarası],$A15,tblTahsilatlar[Kesinleşti mi?],"Evet") -> 0 | F15: =IF($D15="","",MAX(0,$D15-$E15)) | G15: =IF($F15="","",IF($F15=0,0,MAX(0,RaporTarihi-$C15))) | H15: =IF($F15="","",IF($F15=0,"KAPALI",IF($G15<=0,"VADESİ GELMEMİŞ",IF($G15<=YaslamaDilim1,"1-"&TEXT(YaslamaDilim1,"0"),IF($G15<=YaslamaDilim2,TEXT(YaslamaDilim1+1,"0")&"-"&TEXT(YaslamaDilim2,"0"),IF($G15<=YaslamaDilim3,TEXT(YaslamaDilim2+1,"0")&"-"&TEXT(YaslamaDilim3,"0"),TEXT(YaslamaDilim3+1,"0")&"+")))))) | I15: =IF(FATURALAR!$L15=0,"",FATURALAR!$L15) | J15: =IF(FATURALAR!$M15=0,"",FATURALAR!$M15)
A16: =FATURALAR!$B16 -> 0 | B16: =FATURALAR!$C16 -> 0 | C16: =FATURALAR!$E16 -> 0 | D16: =FATURALAR!$K16 | E16: =SUMIFS(tblTahsilatlar[Tahsilat Tutarı],tblTahsilatlar[Fatura Numarası],$A16,tblTahsilatlar[Kesinleşti mi?],"Evet") -> 0 | F16: =IF($D16="","",MAX(0,$D16-$E16)) | G16: =IF($F16="","",IF($F16=0,0,MAX(0,RaporTarihi-$C16))) | H16: =IF($F16="","",IF($F16=0,"KAPALI",IF($G16<=0,"VADESİ GELMEMİŞ",IF($G16<=YaslamaDilim1,"1-"&TEXT(YaslamaDilim1,"0"),IF($G16<=YaslamaDilim2,TEXT(YaslamaDilim1+1,"0")&"-"&TEXT(YaslamaDilim2,"0"),IF($G16<=YaslamaDilim3,TEXT(YaslamaDilim2+1,"0")&"-"&TEXT(YaslamaDilim3,"0"),TEXT(YaslamaDilim3+1,"0")&"+")))))) | I16: =IF(FATURALAR!$L16=0,"",FATURALAR!$L16) | J16: =IF(FATURALAR!$M16=0,"",FATURALAR!$M16)
A17: =FATURALAR!$B17 -> 0 | B17: =FATURALAR!$C17 -> 0 | C17: =FATURALAR!$E17 -> 0 | D17: =FATURALAR!$K17 | E17: =SUMIFS(tblTahsilatlar[Tahsilat Tutarı],tblTahsilatlar[Fatura Numarası],$A17,tblTahsilatlar[Kesinleşti mi?],"Evet") -> 0 | F17: =IF($D17="","",MAX(0,$D17-$E17)) | G17: =IF($F17="","",IF($F17=0,0,MAX(0,RaporTarihi-$C17))) | H17: =IF($F17="","",IF($F17=0,"KAPALI",IF($G17<=0,"VADESİ GELMEMİŞ",IF($G17<=YaslamaDilim1,"1-"&TEXT(YaslamaDilim1,"0"),IF($G17<=YaslamaDilim2,TEXT(YaslamaDilim1+1,"0")&"-"&TEXT(YaslamaDilim2,"0"),IF($G17<=YaslamaDilim3,TEXT(YaslamaDilim2+1,"0")&"-"&TEXT(YaslamaDilim3,"0"),TEXT(YaslamaDilim3+1,"0")&"+")))))) | I17: =IF(FATURALAR!$L17=0,"",FATURALAR!$L17) | J17: =IF(FATURALAR!$M17=0,"",FATURALAR!$M17)
... A45: =FATURALAR!$B45 -> 0 | B45: =FATURALAR!$C45 -> 0 | C45: =FATURALAR!$E45 -> 0 | D45: =FATURALAR!$K45 | E45: =SUMIFS(tblTahsilatlar[Tahsilat Tutarı],tblTahsilatlar[Fatura Numarası],$A45,tblTahsilatlar[Kesinleşti mi?],"Evet") -> 0 | F45: =IF($D45="","",MAX(0,$D45-$E45)) | G45: =IF($F45="","",IF($F45=0,0,MAX(0,RaporTarihi-$C45))) | H45: =IF($F45="","",IF($F45=0,"KAPALI",IF($G45<=0,"VADESİ GELMEMİŞ",IF($G45<=YaslamaDilim1,"1-"&TEXT(YaslamaDilim1,"0"),IF($G45<=YaslamaDilim2,TEXT(YaslamaDilim1+1,"0")&"-"&TEXT(YaslamaDilim2,"0"),IF($G45<=YaslamaDilim3,TEXT(YaslamaDilim2+1,"0")&"-"&TEXT(YaslamaDilim3,"0"),TEXT(YaslamaDilim3+1,"0")&"+")))))) | I45: =IF(FATURALAR!$L45=0,"",FATURALAR!$L45) | J45: =IF(FATURALAR!$M45=0,"",FATURALAR!$M45)

Sheet ANALITIK_MOTOR
A1: ANALITIK MOTOR — CARİ HESAP, TAHSİLAT VE MÜŞTERİ RİSK TAKİP SİSTEMİ
A3: ANALİTİK MOTOR — DERİNLİK KATMANI
A5: Kod | B5: Gösterge | C5: Değer | D5: Makine Yorumu
A6: T1 | B6: Vadesi Geçmiş Alacak | C6: =SUMIFS(tblYaslandirma[Açık Tutar],tblYaslandirma[Gecikme Günü],">0") -> 2380000 | D6: =_xlfn.TEXTJOIN("; ",TRUE(),"Vadesi geçmiş alacak ",TEXT(C6,"₺ #,##0")," — bu tutar tahsilat planının birincil hedefidir") -> Vadesi geçmiş alacak ; ₺ 2380000,000; — bu tutar tahsilat planının birincil hedefidir
A7: T2 | B7: Tahsilat Trend Ortalaması | C7: =AVERAGE(PANO!$H$16:$H$19) -> 182500 | D7: =_xlfn.TEXTJOIN("; ",TRUE(),"Aylık tahsilat ortalaması ",TEXT(C7,"₺ #,##0")," TL — eğilim bu seviyede seyrediyor") -> Aylık tahsilat ortalaması ; ₺ 182500,000; TL — eğilim bu seviyede seyrediyor
A8: T3 | B8: En Yüksek Müşteri Yoğunlaşması | C8: =MAX(tblRisk[Yoğunlaşma Oranı]) -> 0.44378698 | D8: =_xlfn.TEXTJOIN("; ",TRUE(),"En yüksek müşteri yoğunlaşması ",TEXT(C8,"0,0%")," — tek müşteriye aşırı bağımlılık risk taşır") -> En yüksek müşteri yoğunlaşması ; 44,4%; — tek müşteriye aşırı bağımlılık risk taşır
A9: T4 | B9: Dönemler Arası Tahsilat Farkı | C9: =PANO!$H$19-PANO!$H$16 -> -120000 | D9: =_xlfn.TEXTJOIN("; ",TRUE(),"Dönemler arası tahsilat farkı ",TEXT(C9,"₺ #,##0")," TL — artış nakit gücünü gösterir") -> Dönemler arası tahsilat farkı ; -₺ 120000,000; TL — artış nakit gücünü gösterir
A10: T5 | B10: Mutabakat Farkı (Fatura-Tahsilat) | C10: =SUM(tblFaturalar[Net Fatura])-SUMIFS(tblTahsilatlar[Tahsilat Tutarı],tblTahsilatlar[Kesinleşti mi?],"Evet") -> 3380000 | D10: =_xlfn.TEXTJOIN("; ",TRUE(),"Fatura ile kesin tahsilat arasındaki fark ",TEXT(C10,"₺ #,##0")," TL — bu tutar açık alacağın kaynağıdır") -> Fatura ile kesin tahsilat arasındaki fark ; ₺ 3380000,000; TL — bu tutar açık alacağın kaynağıdır
A11: T6 | B11: Vadesi Geçmiş Kırılım Oranı | C11: =IF(SUM(tblYaslandirma[Açık Tutar])=0,0,SUMIFS(tblYaslandirma[Açık Tutar],tblYaslandirma[Gecikme Günü],">0")/SUM(tblYaslandirma[Açık Tutar])) -> 0.70414201 | D11: =_xlfn.TEXTJOIN("; ",TRUE(),"Açık bakiyenin ",TEXT(C11,"0,0%")," i vadesi geçmiş — oran ",IF(C11>VadeGecikmeEsik,"yüksek, öncelikli aksiyon gerekli","kontrol altında")) -> Açık bakiyenin ; 70,4%; i vadesi geçmiş — oran ; yüksek, öncelikli aksiyon gerekli
A12: O1 | B12: Aylık Tahsilat Sapması (MAD) | C12: =_xlfn.STDEV.P(PANO!$H$16:$H$19) -> 113660.68 | D12: =_xlfn.TEXTJOIN("; ",TRUE(),"Aylık tahsilat sapması ",TEXT(C12,"₺ #,##0")," TL — sapma yüksekse tahsilat öngörülemezdir") -> Aylık tahsilat sapması ; ₺ 113660,679; TL — sapma yüksekse tahsilat öngörülemezdir
A13: O2 | B13: Riskli Müşteri Sayısı | C13: =COUNTIF(tblRisk[Risk Skoru],">69") -> 2 | D13: =_xlfn.TEXTJOIN("; ",TRUE(),"Risk skoru 70 üzeri ",C13," müşteri var — bu müşterilerin satışı teminata bağlanmalı") -> Risk skoru 70 üzeri ; 2; müşteri var — bu müşterilerin satışı teminata bağlanmalı
A14: O3 | B14: Kötümser Senaryo Açık Bakiye | C14: =PANO!$B$6*(1+DuyarliOran) -> 0 | D14: =_xlfn.TEXTJOIN("; ",TRUE(),"Kötümser senaryoda açık bakiye ",TEXT(C14,"₺ #,##0")," TL olur — tahsilat başarısı düşerse") -> Kötümser senaryoda açık bakiye ; ₺ ,000; TL olur — tahsilat başarısı düşerse
A15: O4 | B15: Nakit Dönüşüm Oranı | C15: =IF(SUM(tblFaturalar[Net Fatura])=0,0,SUMIFS(tblTahsilatlar[Tahsilat Tutarı],tblTahsilatlar[Kesinleşti mi?],"Evet")/SUM(tblFaturalar[Net Fatura])) -> 0.17761557 | D15: =_xlfn.TEXTJOIN("; ",TRUE(),"Faturaların ",TEXT(C15,"0,0%")," i nakit tahsilata dönmüş — düşükse vade süresi uzun demektir") -> Faturaların ; 17,8%; i nakit tahsilata dönmüş — düşükse vade süresi uzun demektir
A16: O5 | B16: Gecikme Maliyeti | C16: =IFERROR(SUMIFS(tblYaslandirma[Açık Tutar],tblYaslandirma[Gecikme Günü],">0")*FinansmanMaliyeti/365*AVERAGEIFS(tblYaslandirma[Gecikme Günü],tblYaslandirma[Gecikme Günü],">0"),0) -> 144104.11 | D16: =_xlfn.TEXTJOIN("; ",TRUE(),"Vadesi geçen alacakların finansman maliyeti ",TEXT(C16,"₺ #,##0")," TL — bu kayıp tahsilat hızlandırılarak azaltılabilir") -> Vadesi geçen alacakların finansman maliyeti ; ₺ 144104,110; TL — bu kayıp tahsilat hızlandırılarak azaltılabilir
A17: O6 | B17: Yoğunlaşma Riski (HHI) | C17: =SUMPRODUCT(tblRisk[Yoğunlaşma Oranı],tblRisk[Yoğunlaşma Oranı]) -> 0.32390322 | D17: =_xlfn.TEXTJOIN("; ",TRUE(),"HHI yoğunlaşma endeksi ",TEXT(C17,"0.000")," — 0,18 üzeri tek müşteri grubuna bağımlılık riskini gösterir") -> HHI yoğunlaşma endeksi ; 0.000; — 0,18 üzeri tek müşteri grubuna bağımlılık riskini gösterir
A18: O8 | B18: Ortalama Veri Kalitesi Skoru | C18: =AVERAGE(tblRisk[Veri Kalitesi]) -> 100 | D18: =_xlfn.TEXTJOIN("; ",TRUE(),"Ortalama veri kalitesi ",TEXT(C18,"0")," puan — ",IF(C18>=KaliteSkorEsik,"yüksek güven","veri girişi tamamlanmalı")) -> Ortalama veri kalitesi ; 100; puan — ; yüksek güven
A19: I1 | B19: Tahsilat Trend Tahmini | C19: =TREND(PANO!$H$16:$H$19) -> 199000 | D19: =_xlfn.TEXTJOIN("; ",TRUE(),"Trend eğilim değeri ",TEXT(C19,"₺ #,##0")," TL — eğilim sürerse gelecek dönem tahsilatı bu yönde şekillenir") -> Trend eğilim değeri ; ₺ 199000,000; TL — eğilim sürerse gelecek dönem tahsilatı bu yönde şekillenir
A20: I2 | B20: Tahsilat Yüzdelik P90 | C20: =_xlfn.PERCENTILE.INC(PANO!$H$16:$H$19,P90Oran) -> 285000 | D20: =_xlfn.TEXTJOIN("; ",TRUE(),"Tahsilatların %90 i ",TEXT(C20,"₺ #,##0")," TL altında gerçekleşir — üst sınır bütçe için kullanılabilir") -> Tahsilatların %90 i ; ₺ 285000,000; TL altında gerçekleşir — üst sınır bütçe için kullanılabilir
A21: I7 | B21: Nakit Açığı (Tahsilat Hedefi) | C21: =SUM(tblYaslandirma[Açık Tutar])-SUMIFS(tblTahsilatlar[Tahsilat Tutarı],tblTahsilatlar[Kesinleşti mi?],"Evet") -> 2650000 | D21: =_xlfn.TEXTJOIN("; ",TRUE(),"Kapatılması gereken nakit açığı ",TEXT(C21,"₺ #,##0")," TL — tahsilat hedefi bu tutarın tamamıdır") -> Kapatılması gereken nakit açığı ; ₺ 2650000,000; TL — tahsilat hedefi bu tutarın tamamıdır

Sheet MUSTERI_RISK_SKORU
A1: MUSTERI RISK SKORU — CARİ HESAP, TAHSİLAT VE MÜŞTERİ RİSK TAKİP SİSTEMİ
A3: MÜŞTERİ RİSK SKORU
A5: Müşteri Kodu | B5: Unvan | C5: Açık Bakiye | D5: Risk Limiti | E5: Kullanılabilir Limit | F5: Limit Kullanım Oranı | G5: Vadesi Geçmiş | H5: Vadesi Geçmiş Oranı | I5: Maks Gecikme Günü | J5: Teminat Değeri | K5: Net Risk | L5: Yoğunlaşma Oranı | M5: İtirazlı Tutar | N5: Gecikme Katkısı | O5: Vade Katkısı | P5: Limit Katkısı | Q5: Teminat Katkısı | R5: İtiraz Katkısı | S5: Statü Katkısı | T5: Veri Kalitesi | U5: Güven | V5: Karar | W5: Aksiyon | X5: Risk Skoru
A6: =MUSTERI_KARTLARI!$A6 -> M001 | B6: =MUSTERI_KARTLARI!$B6 -> Atlas Yapı A.Ş. | C6: =SUMIFS(tblYaslandirma[Açık Tutar],tblYaslandirma[Müşteri Kodu],$A6) -> 720000 | D6: =MUSTERI_KARTLARI!$I6+MUSTERI_KARTLARI!$J6 -> 1500000 | E6: =$D6-$C6 -> 780000 | F6: =IFERROR($C6/$D6,1) -> 0.48 | G6: =SUMIFS(tblYaslandirma[Açık Tutar],tblYaslandirma[Müşteri Kodu],$A6,tblYaslandirma[Gecikme Günü],">0") -> 200000 | H6: =IF($C6=0,0,$G6/$C6) -> 0.27777778 | I6: =_xlfn.MAXIFS(tblYaslandirma[Gecikme Günü],tblYaslandirma[Müşteri Kodu],$A6) -> 88 | J6: =SUMIFS(tblTeminatlar[Kabul Edilen Değer],tblTeminatlar[Müşteri Kodu],$A6) -> 810000 | K6: =MAX(0,$C6-$J6) -> 0 | L6: =IF(SUM(tblRisk[Açık Bakiye])=0,0,$C6/SUM(tblRisk[Açık Bakiye])) -> 0.21301775 | M6: =SUMIFS(tblYaslandirma[İtirazlı Tutar],tblYaslandirma[Müşteri Kodu],$A6) -> 0 | N6: =MIN(GecikmeMaxPuan,$I6/YaslamaDilim3*GecikmeMaxPuan) -> 25 | O6: =MIN(VadeMaxPuan,$H6*VadeMaxPuan) -> 5.5555556 | P6: =MIN(LimitMaxPuan,$F6*LimitMaxPuan) -> 9.6 | Q6: =IF($C6=0,0,MIN(TeminatMaxPuan,$K6/$C6*TeminatMaxPuan)) -> 0 | R6: =IF($C6=0,0,MIN(ItirazMaxPuan,$M6/$C6*ItirazMaxPuan)) -> 0 | S6: =IF(MUSTERI_KARTLARI!$Q6="Askıda",StatufAskida,IF(MUSTERI_KARTLARI!$Q6="İzlemede",StatufIzleme,0)) -> 0 | T6: =IF(MUSTERI_KARTLARI!$R6="OK",100,IF(MUSTERI_KARTLARI!$R6="EKSİK",VeriKalitesiEksik,0)) -> 100 | U6: =IF($T6>=GuvenYuksek,"YÜKSEK",IF($T6>=GuvenOrta,"ORTA","DÜŞÜK")) -> YÜKSEK | V6: =IF($X6<=EsikDevam,"DEVAM",IF($X6<=EsikIzle,"İZLE",IF($X6<=EsikLimitAzalt,"LİMİTİ AZALT",IF($X6<=EsikPesin,"PEŞİN / TEMİNATLI","VADELİ SATIŞI DURDUR")))) -> İZLE | W6: =IF($X6>EsikKritik,"Yönetim onayı ve acil tahsilat planı",IF($X6>EsikYuksek,"Yeni satışı teminata bağla",IF($X6>EsikIzle,"Limit revizyonu ve tahsilatı hızlandır","Planlı izleme"))) -> Planlı izleme | X6: =ROUND(MIN(100,SUM($N6+$O6+$P6+$Q6+$R6+$S6)),0) -> 40
A7: =MUSTERI_KARTLARI!$A7 -> M002 | B7: =MUSTERI_KARTLARI!$B7 -> Bora Perakende Ltd. | C7: =SUMIFS(tblYaslandirma[Açık Tutar],tblYaslandirma[Müşteri Kodu],$A7) -> 220000 | D7: =MUSTERI_KARTLARI!$I7+MUSTERI_KARTLARI!$J7 -> 800000 | E7: =$D7-$C7 -> 580000 | F7: =IFERROR($C7/$D7,1) -> 0.275 | G7: =SUMIFS(tblYaslandirma[Açık Tutar],tblYaslandirma[Müşteri Kodu],$A7,tblYaslandirma[Gecikme Günü],">0") -> 0 | H7: =IF($C7=0,0,$G7/$C7) -> 0 | I7: =_xlfn.MAXIFS(tblYaslandirma[Gecikme Günü],tblYaslandirma[Müşteri Kodu],$A7) -> 0 | J7: =SUMIFS(tblTeminatlar[Kabul Edilen Değer],tblTeminatlar[Müşteri Kodu],$A7) -> 412500 | K7: =MAX(0,$C7-$J7) -> 0 | L7: =IF(SUM(tblRisk[Açık Bakiye])=0,0,$C7/SUM(tblRisk[Açık Bakiye])) -> 0.065088757 | M7: =SUMIFS(tblYaslandirma[İtirazlı Tutar],tblYaslandirma[Müşteri Kodu],$A7) -> 0 | N7: =MIN(GecikmeMaxPuan,$I7/YaslamaDilim3*GecikmeMaxPuan) -> 0 | O7: =MIN(VadeMaxPuan,$H7*VadeMaxPuan) -> 0 | P7: =MIN(LimitMaxPuan,$F7*LimitMaxPuan) -> 5.5 | Q7: =IF($C7=0,0,MIN(TeminatMaxPuan,$K7/$C7*TeminatMaxPuan)) -> 0 | R7: =IF($C7=0,0,MIN(ItirazMaxPuan,$M7/$C7*ItirazMaxPuan)) -> 0 | S7: =IF(MUSTERI_KARTLARI!$Q7="Askıda",StatufAskida,IF(MUSTERI_KARTLARI!$Q7="İzlemede",StatufIzleme,0)) -> 0 | T7: =IF(MUSTERI_KARTLARI!$R7="OK",100,IF(MUSTERI_KARTLARI!$R7="EKSİK",VeriKalitesiEksik,0)) -> 100 | U7: =IF($T7>=GuvenYuksek,"YÜKSEK",IF($T7>=GuvenOrta,"ORTA","DÜŞÜK")) -> YÜKSEK | V7: =IF($X7<=EsikDevam,"DEVAM",IF($X7<=EsikIzle,"İZLE",IF($X7<=EsikLimitAzalt,"LİMİTİ AZALT",IF($X7<=EsikPesin,"PEŞİN / TEMİNATLI","VADELİ SATIŞI DURDUR")))) -> DEVAM | W7: =IF($X7>EsikKritik,"Yönetim onayı ve acil tahsilat planı",IF($X7>EsikYuksek,"Yeni satışı teminata bağla",IF($X7>EsikIzle,"Limit revizyonu ve tahsilatı hızlandır","Planlı izleme"))) -> Planlı izleme | X7: =ROUND(MIN(100,SUM($N7+$O7+$P7+$Q7+$R7+$S7)),0) -> 6
A8: =MUSTERI_KARTLARI!$A8 -> M003 | B8: =MUSTERI_KARTLARI!$B8 -> Cemre Gıda A.Ş. | C8: =SUMIFS(tblYaslandirma[Açık Tutar],tblYaslandirma[Müşteri Kodu],$A8) -> 940000 | D8: =MUSTERI_KARTLARI!$I8+MUSTERI_KARTLARI!$J8 -> 750000 | E8: =$D8-$C8 -> -190000 | F8: =IFERROR($C8/$D8,1) -> 1.2533333 | G8: =SUMIFS(tblYaslandirma[Açık Tutar],tblYaslandirma[Müşteri Kodu],$A8,tblYaslandirma[Gecikme Günü],">0") -> 680000 | H8: =IF($C8=0,0,$G8/$C8) -> 0.72340426 | I8: =_xlfn.MAXIFS(tblYaslandirma[Gecikme Günü],tblYaslandirma[Müşteri Kodu],$A8) -> 47 | J8: =SUMIFS(tblTeminatlar[Kabul Edilen Değer],tblTeminatlar[Müşteri Kodu],$A8) -> 240000 | K8: =MAX(0,$C8-$J8) -> 700000 | L8: =IF(SUM(tblRisk[Açık Bakiye])=0,0,$C8/SUM(tblRisk[Açık Bakiye])) -> 0.27810651 | M8: =SUMIFS(tblYaslandirma[İtirazlı Tutar],tblYaslandirma[Müşteri Kodu],$A8) -> 150000 | N8: =MIN(GecikmeMaxPuan,$I8/YaslamaDilim3*GecikmeMaxPuan) -> 19.583333 | O8: =MIN(VadeMaxPuan,$H8*VadeMaxPuan) -> 14.468085 | P8: =MIN(LimitMaxPuan,$F8*LimitMaxPuan) -> 20 | Q8: =IF($C8=0,0,MIN(TeminatMaxPuan,$K8/$C8*TeminatMaxPuan)) -> 14.893617 | R8: =IF($C8=0,0,MIN(ItirazMaxPuan,$M8/$C8*ItirazMaxPuan)) -> 1.5957447 | S8: =IF(MUSTERI_KARTLARI!$Q8="Askıda",StatufAskida,IF(MUSTERI_KARTLARI!$Q8="İzlemede",StatufIzleme,0)) -> 3 | T8: =IF(MUSTERI_KARTLARI!$R8="OK",100,IF(MUSTERI_KARTLARI!$R8="EKSİK",VeriKalitesiEksik,0)) -> 100 | U8: =IF($T8>=GuvenYuksek,"YÜKSEK",IF($T8>=GuvenOrta,"ORTA","DÜŞÜK")) -> YÜKSEK | V8: =IF($X8<=EsikDevam,"DEVAM",IF($X8<=EsikIzle,"İZLE",IF($X8<=EsikLimitAzalt,"LİMİTİ AZALT",IF($X8<=EsikPesin,"PEŞİN / TEMİNATLI","VADELİ SATIŞI DURDUR")))) -> PEŞİN / TEMİNATLI | W8: =IF($X8>EsikKritik,"Yönetim onayı ve acil tahsilat planı",IF($X8>EsikYuksek,"Yeni satışı teminata bağla",IF($X8>EsikIzle,"Limit revizyonu ve tahsilatı hızlandır","Planlı izleme"))) -> Yeni satışı teminata bağla | X8: =ROUND(MIN(100,SUM($N8+$O8+$P8+$Q8+$R8+$S8)),0) -> 74
A9: =MUSTERI_KARTLARI!$A9 -> M004 | B9: =MUSTERI_KARTLARI!$B9 -> Delta Tekstil Ltd. | C9: =SUMIFS(tblYaslandirma[Açık Tutar],tblYaslandirma[Müşteri Kodu],$A9) -> 1500000 | D9: =MUSTERI_KARTLARI!$I9+MUSTERI_KARTLARI!$J9 -> 2000000 | E9: =$D9-$C9 -> 500000 | F9: =IFERROR($C9/$D9,1) -> 0.75 | G9: =SUMIFS(tblYaslandirma[Açık Tutar],tblYaslandirma[Müşteri Kodu],$A9,tblYaslandirma[Gecikme Günü],">0") -> 1500000 | H9: =IF($C9=0,0,$G9/$C9) -> 1 | I9: =_xlfn.MAXIFS(tblYaslandirma[Gecikme Günü],tblYaslandirma[Müşteri Kodu],$A9) -> 86 | J9: =SUMIFS(tblTeminatlar[Kabul Edilen Değer],tblTeminatlar[Müşteri Kodu],$A9) -> 0 | K9: =MAX(0,$C9-$J9) -> 1500000 | L9: =IF(SUM(tblRisk[Açık Bakiye])=0,0,$C9/SUM(tblRisk[Açık Bakiye])) -> 0.44378698 | M9: =SUMIFS(tblYaslandirma[İtirazlı Tutar],tblYaslandirma[Müşteri Kodu],$A9) -> 0 | N9: =MIN(GecikmeMaxPuan,$I9/YaslamaDilim3*GecikmeMaxPuan) -> 25 | O9: =MIN(VadeMaxPuan,$H9*VadeMaxPuan) -> 20 | P9: =MIN(LimitMaxPuan,$F9*LimitMaxPuan) -> 15 | Q9: =IF($C9=0,0,MIN(TeminatMaxPuan,$K9/$C9*TeminatMaxPuan)) -> 20 | R9: =IF($C9=0,0,MIN(ItirazMaxPuan,$M9/$C9*ItirazMaxPuan)) -> 0 | S9: =IF(MUSTERI_KARTLARI!$Q9="Askıda",StatufAskida,IF(MUSTERI_KARTLARI!$Q9="İzlemede",StatufIzleme,0)) -> 5 | T9: =IF(MUSTERI_KARTLARI!$R9="OK",100,IF(MUSTERI_KARTLARI!$R9="EKSİK",VeriKalitesiEksik,0)) -> 100 | U9: =IF($T9>=GuvenYuksek,"YÜKSEK",IF($T9>=GuvenOrta,"ORTA","DÜŞÜK")) -> YÜKSEK | V9: =IF($X9<=EsikDevam,"DEVAM",IF($X9<=EsikIzle,"İZLE",IF($X9<=EsikLimitAzalt,"LİMİTİ AZALT",IF($X9<=EsikPesin,"PEŞİN / TEMİNATLI","VADELİ SATIŞI DURDUR")))) -> VADELİ SATIŞI DURDUR | W9: =IF($X9>EsikKritik,"Yönetim onayı ve acil tahsilat planı",IF($X9>EsikYuksek,"Yeni satışı teminata bağla",IF($X9>EsikIzle,"Limit revizyonu ve tahsilatı hızlandır","Planlı izleme"))) -> Yeni satışı teminata bağla | X9: =ROUND(MIN(100,SUM($N9+$O9+$P9+$Q9+$R9+$S9)),0) -> 85
A10: =MUSTERI_KARTLARI!$A10 -> 0 | B10: =MUSTERI_KARTLARI!$B10 -> 0 | C10: =SUMIFS(tblYaslandirma[Açık Tutar],tblYaslandirma[Müşteri Kodu],$A10) -> 0 | D10: =MUSTERI_KARTLARI!$I10+MUSTERI_KARTLARI!$J10 -> 0 | E10: =$D10-$C10 -> 0 | F10: =IFERROR($C10/$D10,1) -> 1 | G10: =SUMIFS(tblYaslandirma[Açık Tutar],tblYaslandirma[Müşteri Kodu],$A10,tblYaslandirma[Gecikme Günü],">0") -> 0 | H10: =IF($C10=0,0,$G10/$C10) -> 0 | I10: =_xlfn.MAXIFS(tblYaslandirma[Gecikme Günü],tblYaslandirma[Müşteri Kodu],$A10) -> 0 | J10: =SUMIFS(tblTeminatlar[Kabul Edilen Değer],tblTeminatlar[Müşteri Kodu],$A10) -> 0 | K10: =MAX(0,$C10-$J10) -> 0 | L10: =IF(SUM(tblRisk[Açık Bakiye])=0,0,$C10/SUM(tblRisk[Açık Bakiye])) -> 0 | M10: =SUMIFS(tblYaslandirma[İtirazlı Tutar],tblYaslandirma[Müşteri Kodu],$A10) -> 0 | N10: =MIN(GecikmeMaxPuan,$I10/YaslamaDilim3*GecikmeMaxPuan) -> 0 | O10: =MIN(VadeMaxPuan,$H10*VadeMaxPuan) -> 0 | P10: =MIN(LimitMaxPuan,$F10*LimitMaxPuan) -> 20 | Q10: =IF($C10=0,0,MIN(TeminatMaxPuan,$K10/$C10*TeminatMaxPuan)) -> 0 | R10: =IF($C10=0,0,MIN(ItirazMaxPuan,$M10/$C10*ItirazMaxPuan)) -> 0 | S10: =IF(MUSTERI_KARTLARI!$Q10="Askıda",StatufAskida,IF(MUSTERI_KARTLARI!$Q10="İzlemede",StatufIzleme,0)) -> 0 | T10: =IF(MUSTERI_KARTLARI!$R10="OK",100,IF(MUSTERI_KARTLARI!$R10="EKSİK",VeriKalitesiEksik,0)) -> 100 | U10: =IF($T10>=GuvenYuksek,"YÜKSEK",IF($T10>=GuvenOrta,"ORTA","DÜŞÜK")) -> YÜKSEK | V10: =IF($X10<=EsikDevam,"DEVAM",IF($X10<=EsikIzle,"İZLE",IF($X10<=EsikLimitAzalt,"LİMİTİ AZALT",IF($X10<=EsikPesin,"PEŞİN / TEMİNATLI","VADELİ SATIŞI DURDUR")))) -> DEVAM | W10: =IF($X10>EsikKritik,"Yönetim onayı ve acil tahsilat planı",IF($X10>EsikYuksek,"Yeni satışı teminata bağla",IF($X10>EsikIzle,"Limit revizyonu ve tahsilatı hızlandır","Planlı izleme"))) -> Planlı izleme | X10: =ROUND(MIN(100,SUM($N10+$O10+$P10+$Q10+$R10+$S10)),0) -> 20
A11: =MUSTERI_KARTLARI!$A11 -> 0 | B11: =MUSTERI_KARTLARI!$B11 -> 0 | C11: =SUMIFS(tblYaslandirma[Açık Tutar],tblYaslandirma[Müşteri Kodu],$A11) -> 0 | D11: =MUSTERI_KARTLARI!$I11+MUSTERI_KARTLARI!$J11 -> 0 | E11: =$D11-$C11 -> 0 | F11: =IFERROR($C11/$D11,1) -> 1 | G11: =SUMIFS(tblYaslandirma[Açık Tutar],tblYaslandirma[Müşteri Kodu],$A11,tblYaslandirma[Gecikme Günü],">0") -> 0 | H11: =IF($C11=0,0,$G11/$C11) -> 0 | I11: =_xlfn.MAXIFS(tblYaslandirma[Gecikme Günü],tblYaslandirma[Müşteri Kodu],$A11) -> 0 | J11: =SUMIFS(tblTeminatlar[Kabul Edilen Değer],tblTeminatlar[Müşteri Kodu],$A11) -> 0 | K11: =MAX(0,$C11-$J11) -> 0 | L11: =IF(SUM(tblRisk[Açık Bakiye])=0,0,$C11/SUM(tblRisk[Açık Bakiye])) -> 0 | M11: =SUMIFS(tblYaslandirma[İtirazlı Tutar],tblYaslandirma[Müşteri Kodu],$A11) -> 0 | N11: =MIN(GecikmeMaxPuan,$I11/YaslamaDilim3*GecikmeMaxPuan) -> 0 | O11: =MIN(VadeMaxPuan,$H11*VadeMaxPuan) -> 0 | P11: =MIN(LimitMaxPuan,$F11*LimitMaxPuan) -> 20 | Q11: =IF($C11=0,0,MIN(TeminatMaxPuan,$K11/$C11*TeminatMaxPuan)) -> 0 | R11: =IF($C11=0,0,MIN(ItirazMaxPuan,$M11/$C11*ItirazMaxPuan)) -> 0 | S11: =IF(MUSTERI_KARTLARI!$Q11="Askıda",StatufAskida,IF(MUSTERI_KARTLARI!$Q11="İzlemede",StatufIzleme,0)) -> 0 | T11: =IF(MUSTERI_KARTLARI!$R11="OK",100,IF(MUSTERI_KARTLARI!$R11="EKSİK",VeriKalitesiEksik,0)) -> 100 | U11: =IF($T11>=GuvenYuksek,"YÜKSEK",IF($T11>=GuvenOrta,"ORTA","DÜŞÜK")) -> YÜKSEK | V11: =IF($X11<=EsikDevam,"DEVAM",IF($X11<=EsikIzle,"İZLE",IF($X11<=EsikLimitAzalt,"LİMİTİ AZALT",IF($X11<=EsikPesin,"PEŞİN / TEMİNATLI","VADELİ SATIŞI DURDUR")))) -> DEVAM | W11: =IF($X11>EsikKritik,"Yönetim onayı ve acil tahsilat planı",IF($X11>EsikYuksek,"Yeni satışı teminata bağla",IF($X11>EsikIzle,"Limit revizyonu ve tahsilatı hızlandır","Planlı izleme"))) -> Planlı izleme | X11: =ROUND(MIN(100,SUM($N11+$O11+$P11+$Q11+$R11+$S11)),0) -> 20
A12: =MUSTERI_KARTLARI!$A12 -> 0 | B12: =MUSTERI_KARTLARI!$B12 -> 0 | C12: =SUMIFS(tblYaslandirma[Açık Tutar],tblYaslandirma[Müşteri Kodu],$A12) -> 0 | D12: =MUSTERI_KARTLARI!$I12+MUSTERI_KARTLARI!$J12 -> 0 | E12: =$D12-$C12 -> 0 | F12: =IFERROR($C12/$D12,1) -> 1 | G12: =SUMIFS(tblYaslandirma[Açık Tutar],tblYaslandirma[Müşteri Kodu],$A12,tblYaslandirma[Gecikme Günü],">0") -> 0 | H12: =IF($C12=0,0,$G12/$C12) -> 0 | I12: =_xlfn.MAXIFS(tblYaslandirma[Gecikme Günü],tblYaslandirma[Müşteri Kodu],$A12) -> 0 | J12: =SUMIFS(tblTeminatlar[Kabul Edilen Değer],tblTeminatlar[Müşteri Kodu],$A12) -> 0 | K12: =MAX(0,$C12-$J12) -> 0 | L12: =IF(SUM(tblRisk[Açık Bakiye])=0,0,$C12/SUM(tblRisk[Açık Bakiye])) -> 0 | M12: =SUMIFS(tblYaslandirma[İtirazlı Tutar],tblYaslandirma[Müşteri Kodu],$A12) -> 0 | N12: =MIN(GecikmeMaxPuan,$I12/YaslamaDilim3*GecikmeMaxPuan) -> 0 | O12: =MIN(VadeMaxPuan,$H12*VadeMaxPuan) -> 0 | P12: =MIN(LimitMaxPuan,$F12*LimitMaxPuan) -> 20 | Q12: =IF($C12=0,0,MIN(TeminatMaxPuan,$K12/$C12*TeminatMaxPuan)) -> 0 | R12: =IF($C12=0,0,MIN(ItirazMaxPuan,$M12/$C12*ItirazMaxPuan)) -> 0 | S12: =IF(MUSTERI_KARTLARI!$Q12="Askıda",StatufAskida,IF(MUSTERI_KARTLARI!$Q12="İzlemede",StatufIzleme,0)) -> 0 | T12: =IF(MUSTERI_KARTLARI!$R12="OK",100,IF(MUSTERI_KARTLARI!$R12="EKSİK",VeriKalitesiEksik,0)) -> 100 | U12: =IF($T12>=GuvenYuksek,"YÜKSEK",IF($T12>=GuvenOrta,"ORTA","DÜŞÜK")) -> YÜKSEK | V12: =IF($X12<=EsikDevam,"DEVAM",IF($X12<=EsikIzle,"İZLE",IF($X12<=EsikLimitAzalt,"LİMİTİ AZALT",IF($X12<=EsikPesin,"PEŞİN / TEMİNATLI","VADELİ SATIŞI DURDUR")))) -> DEVAM | W12: =IF($X12>EsikKritik,"Yönetim onayı ve acil tahsilat planı",IF($X12>EsikYuksek,"Yeni satışı teminata bağla",IF($X12>EsikIzle,"Limit revizyonu ve tahsilatı hızlandır","Planlı izleme"))) -> Planlı izleme | X12: =ROUND(MIN(100,SUM($N12+$O12+$P12+$Q12+$R12+$S12)),0) -> 20
A13: =MUSTERI_KARTLARI!$A13 -> 0 | B13: =MUSTERI_KARTLARI!$B13 -> 0 | C13: =SUMIFS(tblYaslandirma[Açık Tutar],tblYaslandirma[Müşteri Kodu],$A13) -> 0 | D13: =MUSTERI_KARTLARI!$I13+MUSTERI_KARTLARI!$J13 -> 0 | E13: =$D13-$C13 -> 0 | F13: =IFERROR($C13/$D13,1) -> 1 | G13: =SUMIFS(tblYaslandirma[Açık Tutar],tblYaslandirma[Müşteri Kodu],$A13,tblYaslandirma[Gecikme Günü],">0") -> 0 | H13: =IF($C13=0,0,$G13/$C13) -> 0 | I13: =_xlfn.MAXIFS(tblYaslandirma[Gecikme Günü],tblYaslandirma[Müşteri Kodu],$A13) -> 0 | J13: =SUMIFS(tblTeminatlar[Kabul Edilen Değer],tblTeminatlar[Müşteri Kodu],$A13) -> 0 | K13: =MAX(0,$C13-$J13) -> 0 | L13: =IF(SUM(tblRisk[Açık Bakiye])=0,0,$C13/SUM(tblRisk[Açık Bakiye])) -> 0 | M13: =SUMIFS(tblYaslandirma[İtirazlı Tutar],tblYaslandirma[Müşteri Kodu],$A13) -> 0 | N13: =MIN(GecikmeMaxPuan,$I13/YaslamaDilim3*GecikmeMaxPuan) -> 0 | O13: =MIN(VadeMaxPuan,$H13*VadeMaxPuan) -> 0 | P13: =MIN(LimitMaxPuan,$F13*LimitMaxPuan) -> 20 | Q13: =IF($C13=0,0,MIN(TeminatMaxPuan,$K13/$C13*TeminatMaxPuan)) -> 0 | R13: =IF($C13=0,0,MIN(ItirazMaxPuan,$M13/$C13*ItirazMaxPuan)) -> 0 | S13: =IF(MUSTERI_KARTLARI!$Q13="Askıda",StatufAskida,IF(MUSTERI_KARTLARI!$Q13="İzlemede",StatufIzleme,0)) -> 0 | T13: =IF(MUSTERI_KARTLARI!$R13="OK",100,IF(MUSTERI_KARTLARI!$R13="EKSİK",VeriKalitesiEksik,0)) -> 100 | U13: =IF($T13>=GuvenYuksek,"YÜKSEK",IF($T13>=GuvenOrta,"ORTA","DÜŞÜK")) -> YÜKSEK | V13: =IF($X13<=EsikDevam,"DEVAM",IF($X13<=EsikIzle,"İZLE",IF($X13<=EsikLimitAzalt,"LİMİTİ AZALT",IF($X13<=EsikPesin,"PEŞİN / TEMİNATLI","VADELİ SATIŞI DURDUR")))) -> DEVAM | W13: =IF($X13>EsikKritik,"Yönetim onayı ve acil tahsilat planı",IF($X13>EsikYuksek,"Yeni satışı teminata bağla",IF($X13>EsikIzle,"Limit revizyonu ve tahsilatı hızlandır","Planlı izleme"))) -> Planlı izleme | X13: =ROUND(MIN(100,SUM($N13+$O13+$P13+$Q13+$R13+$S13)),0) -> 20
