Workbook

Sheet KAPAK
A1: KAPAK — Pazaryeri Net Kâr & Eksik Hakediş Yakalayıcı
A3: Pazaryeri Net Kâr & Eksik Hakediş Yakalayıcı
A4: Pazaryerinde sattığınız ürünlerin komisyon, kargo, reklam, iade ve ek gider sonrası gerçek net kârını hesaplayın; pazaryerinden gelen tahsilatı beklenen hakedişle karşılaştırarak eksik hakedişleri otomatik yakalayın.
A6: Bu ürün ne sağlar?
A7: • Kalem bazında satış, komisyon, kargo, reklam, iade ve ek gider sonrası net kâr ve kâr marjı hesabı
A8: • Beklenen hakediş (pazaryerinin ödemesi gereken) ile gerçek hakediş farkını yakalar; eksik tahsilatı eşiklerle işaretler
A9: • Pazaryeri bazında satış, kâr ve marj özeti; yoğunlaşma (HHI) ve anomali analizi
A10: • Satış fiyatı senaryoları ve komisyon duyarlılığı (tornado) ile kâr bant aralığı
A11: • Karar kapısı ve aksiyon önerisi ile portföy yönlendirmesi
A14: Kimler için?
A15: • Pazaryerinde satış yapan e-ticaret işletmeleri
A16: • Ürün bazında gerçek kârlılığını izlemek isteyen operasyon yöneticileri
... A21: Sürüm 1.0.0 | 2026 | ExcelArşiv | Lisans: Tek kullanıcı

Sheet HIZLI_BASLANGIC
A1: HIZLI BASLANGIC — Pazaryeri Net Kâr & Eksik Hakediş Yakalayıcı
A3: Nasıl kullanılır?
A5: Adım 1 — Kalemlerinizi girin | B5: KALEM_LISTESI sayfasındaki sarı hücrelere satış kalemi bilgilerini girin: satış fiyatı, miktar, ürün maliyeti, komisyon/kargo/reklam/iade oranları, ek gider.
A6: Adım 2 — Gerçek hakedişi girin | B6: Pazaryerinden gelen ödemeyi (hakediş) 'Gerçek Hakediş' sütununa girin; sistem beklenenle farkı hesaplar ve eksik hakedişi işaretler.
A7: Adım 3 — Kârı izleyin | B7: HESAP ve PANO sayfaları pazaryeri bazlı satış, kâr, marj ve eksik hakediş özetini üretir.
A8: Adım 4 — Kararı değerlendirin | B8: KARAR sayfası marj ve eksik hakediş durumuna göre GÜÇLÜ/NORMAL/İNCELE kararı üretir.
A11: Sık yapılan hatalar
A12: • Gerçek hakedişe KDV dahil tutar girmek (hakedişler KDV hariç karşılaştırılır)
A13: • Komisyon oranını yüzde olarak 25 değil 0,25 girmek
A14: • Miktar girilmeden satış fiyatı girmek (hesap sıfırlanır)
A16: Sık sorulan sorular
A17: Soru: Komisyon oranını yüzde olarak nasıl girerim? Cevap: 0,25 olarak (onluk kesir). %25 yazmak hesabı 25 kat büyütür.
A18: Soru: Gerçek hakediş KDV dahil mi? Cevap: Hakediş mutabakatı KDV hariç yapılır; KDV dahil tutar girmeyin.
A19: Soru: Beklenen hakedişten hangi tutarlar düşülür? Cevap: Komisyon, kargo/operasyon ve reklam tutarları düşülür; iade maliyeti kâr/marjda etkilidir.
A20: Soru: Hangi pazaryeri listesinde yoksa ne yapmalıyım? Cevap: LISTELER sayfasındaki sarı hücreye yeni pazaryeri adını ekleyin.
A22: Bu dosya karar destek aracıdır; vergi ve muhasebe hesabı mali müşavir görüşü yerine geçmez.

Sheet KALEM_LISTESI
A1: KALEM LISTESI — Pazaryeri Net Kâr & Eksik Hakediş Yakalayıcı
A3: Satış Kalemleri ve Hakediş Takibi
A4: Sarı hücrelere manuel veri girin. Satış, komisyon, kargo, reklam, iade, toplam maliyet, net kâr, marj ve hakediş farkı otomatik hesaplanır.
A5: Kalem Kodu | B5: Ürün Adı | C5: Birim Satış Fiyatı (TL) | D5: Miktar (Adet) | E5: Birim Ürün Maliyeti (TL) | F5: Komisyon Oranı | G5: Kargo/Operasyon Oranı | H5: Reklam Oranı | I5: İade Oranı | J5: Birim Ek Gider (TL) | K5: Toplam Satış (TL) | L5: Komisyon Tutarı (TL) | M5: Kargo Tutarı (TL) | N5: Reklam Tutarı (TL) | O5: İade Maliyeti (TL) | P5: Toplam Maliyet (TL) | Q5: NET KÂR (TL) | R5: KÂR MARJI | S5: Beklenen Hakediş (TL) | T5: Gerçek Hakediş (TL) | U5: Hakediş Farkı (TL) | V5: Fark Oranı | W5: Durum | X5: Açıklama | Y5: Pazaryeri
A6: P-1001 | B6: Kulaklık Bluetooth | C6: 899 | D6: 25 | E6: 420 | F6: 0.18 | G6: 0.04 | H6: 0.06 | I6: 0.05 | J6: 12 | K6: =IF($D6="",0,$C6*$D6) -> 22475 | L6: =IF($D6="",0,$F6*$K6) -> 4045.5 | M6: =IF($D6="",0,$G6*$K6) -> 899 | N6: =IF($D6="",0,$H6*$K6) -> 1348.5 | O6: =IF($D6="",0,$I6*$K6*(1-$F6)) -> 921.475 | P6: =IF($D6="",0,$E6*$D6+$L6+$M6+$N6+$O6+$J6*$D6) -> 18014.475 | Q6: =IF($D6="",0,$K6-$P6) -> 4460.525 | R6: =IF($K6=0,0,$Q6/$K6) -> 0.19846607 | S6: =IF($D6="",0,$K6-$L6-$M6-$N6) -> 16182 | U6: =IF($T6="",0,MAX(0,$S6-$T6)) -> 0 | V6: =IF($S6=0,0,$U6/$S6) -> 0 | W6: =IF($D6="","",IF($T6="","BEKLİYOR",IF(OR($U6=0,$S6=0),"DOĞRU",IF(AND($V6>PazaryeriEksikHakedisEsik,$U6>PazaryeriEksikHakedisTutarEsik),"EKSİK HAKEDİŞ","DOĞRU")))) -> BEKLİYOR | X6: =IF($B6="","",CONCATENATE("Ürün: ",$B6," | Kâr: ",TEXT($Q6,"₺ #,##0")," | Durum: ",$W6)) -> Ürün: Kulaklık Bluetooth | Kâr: ₺ 4460,525 | Durum: BEKLİYOR | Y6: Trendyol
A7: P-1002 | B7: Powerbank 20.000mAh | C7: 549 | D7: 60 | E7: 260 | F7: 0.22 | G7: 0.05 | H7: 0.05 | I7: 0.04 | J7: 9 | K7: =IF($D7="",0,$C7*$D7) -> 32940 | L7: =IF($D7="",0,$F7*$K7) -> 7246.8 | M7: =IF($D7="",0,$G7*$K7) -> 1647 | N7: =IF($D7="",0,$H7*$K7) -> 1647 | O7: =IF($D7="",0,$I7*$K7*(1-$F7)) -> 1027.728 | P7: =IF($D7="",0,$E7*$D7+$L7+$M7+$N7+$O7+$J7*$D7) -> 27708.528 | Q7: =IF($D7="",0,$K7-$P7) -> 5231.472 | R7: =IF($K7=0,0,$Q7/$K7) -> 0.15881821 | S7: =IF($D7="",0,$K7-$L7-$M7-$N7) -> 22399.2 | T7: 16500 | U7: =IF($T7="",0,MAX(0,$S7-$T7)) -> 5899.2 | V7: =IF($S7=0,0,$U7/$S7) -> 0.26336655 | W7: =IF($D7="","",IF($T7="","BEKLİYOR",IF(OR($U7=0,$S7=0),"DOĞRU",IF(AND($V7>PazaryeriEksikHakedisEsik,$U7>PazaryeriEksikHakedisTutarEsik),"EKSİK HAKEDİŞ","DOĞRU")))) -> EKSİK HAKEDİŞ | X7: =IF($B7="","",CONCATENATE("Ürün: ",$B7," | Kâr: ",TEXT($Q7,"₺ #,##0")," | Durum: ",$W7)) -> Ürün: Powerbank 20.000mAh | Kâr: ₺ 5231,472 | Durum: EKSİK HAKEDİŞ | Y7: Hepsiburada
A8: P-1003 | B8: Akıllı Saat | C8: 1499 | D8: 18 | E8: 820 | F8: 0.2 | G8: 0.04 | H8: 0.08 | I8: 0.06 | J8: 18 | K8: =IF($D8="",0,$C8*$D8) -> 26982 | L8: =IF($D8="",0,$F8*$K8) -> 5396.4 | M8: =IF($D8="",0,$G8*$K8) -> 1079.28 | N8: =IF($D8="",0,$H8*$K8) -> 2158.56 | O8: =IF($D8="",0,$I8*$K8*(1-$F8)) -> 1295.136 | P8: =IF($D8="",0,$E8*$D8+$L8+$M8+$N8+$O8+$J8*$D8) -> 25013.376 | Q8: =IF($D8="",0,$K8-$P8) -> 1968.624 | R8: =IF($K8=0,0,$Q8/$K8) -> 0.07296064 | S8: =IF($D8="",0,$K8-$L8-$M8-$N8) -> 18347.76 | T8: 19600 | U8: =IF($T8="",0,MAX(0,$S8-$T8)) -> 0 | V8: =IF($S8=0,0,$U8/$S8) -> 0 | W8: =IF($D8="","",IF($T8="","BEKLİYOR",IF(OR($U8=0,$S8=0),"DOĞRU",IF(AND($V8>PazaryeriEksikHakedisEsik,$U8>PazaryeriEksikHakedisTutarEsik),"EKSİK HAKEDİŞ","DOĞRU")))) -> DOĞRU | X8: =IF($B8="","",CONCATENATE("Ürün: ",$B8," | Kâr: ",TEXT($Q8,"₺ #,##0")," | Durum: ",$W8)) -> Ürün: Akıllı Saat | Kâr: ₺ 1968,624 | Durum: DOĞRU | Y8: Trendyol
A9: P-1004 | B9: Şarj Aleti 65W | C9: 349 | D9: 120 | E9: 160 | F9: 0.24 | G9: 0.06 | H9: 0.07 | I9: 0.03 | J9: 6 | K9: =IF($D9="",0,$C9*$D9) -> 41880 | L9: =IF($D9="",0,$F9*$K9) -> 10051.2 | M9: =IF($D9="",0,$G9*$K9) -> 2512.8 | N9: =IF($D9="",0,$H9*$K9) -> 2931.6 | O9: =IF($D9="",0,$I9*$K9*(1-$F9)) -> 954.864 | P9: =IF($D9="",0,$E9*$D9+$L9+$M9+$N9+$O9+$J9*$D9) -> 36370.464 | Q9: =IF($D9="",0,$K9-$P9) -> 5509.536 | R9: =IF($K9=0,0,$Q9/$K9) -> 0.1315553 | S9: =IF($D9="",0,$K9-$L9-$M9-$N9) -> 26384.4 | U9: =IF($T9="",0,MAX(0,$S9-$T9)) -> 0 | V9: =IF($S9=0,0,$U9/$S9) -> 0 | W9: =IF($D9="","",IF($T9="","BEKLİYOR",IF(OR($U9=0,$S9=0),"DOĞRU",IF(AND($V9>PazaryeriEksikHakedisEsik,$U9>PazaryeriEksikHakedisTutarEsik),"EKSİK HAKEDİŞ","DOĞRU")))) -> BEKLİYOR | X9: =IF($B9="","",CONCATENATE("Ürün: ",$B9," | Kâr: ",TEXT($Q9,"₺ #,##0")," | Durum: ",$W9)) -> Ürün: Şarj Aleti 65W | Kâr: ₺ 5509,536 | Durum: BEKLİYOR | Y9: Amazon
A10: P-1005 | B10: Kablo USB-C | C10: 129 | D10: 300 | E10: 55 | F10: 0.15 | G10: 0.08 | H10: 0.04 | I10: 0.06 | J10: 3 | K10: =IF($D10="",0,$C10*$D10) -> 38700 | L10: =IF($D10="",0,$F10*$K10) -> 5805 | M10: =IF($D10="",0,$G10*$K10) -> 3096 | N10: =IF($D10="",0,$H10*$K10) -> 1548 | O10: =IF($D10="",0,$I10*$K10*(1-$F10)) -> 1973.7 | P10: =IF($D10="",0,$E10*$D10+$L10+$M10+$N10+$O10+$J10*$D10) -> 29822.7 | Q10: =IF($D10="",0,$K10-$P10) -> 8877.3 | R10: =IF($K10=0,0,$Q10/$K10) -> 0.2293876 | S10: =IF($D10="",0,$K10-$L10-$M10-$N10) -> 28251 | T10: 28300 | U10: =IF($T10="",0,MAX(0,$S10-$T10)) -> 0 | V10: =IF($S10=0,0,$U10/$S10) -> 0 | W10: =IF($D10="","",IF($T10="","BEKLİYOR",IF(OR($U10=0,$S10=0),"DOĞRU",IF(AND($V10>PazaryeriEksikHakedisEsik,$U10>PazaryeriEksikHakedisTutarEsik),"EKSİK HAKEDİŞ","DOĞRU")))) -> DOĞRU | X10: =IF($B10="","",CONCATENATE("Ürün: ",$B10," | Kâr: ",TEXT($Q10,"₺ #,##0")," | Durum: ",$W10)) -> Ürün: Kablo USB-C | Kâr: ₺ 8877,300 | Durum: DOĞRU | Y10: N11
A11: P-1006 | B11: Mouse Kablosuz | C11: 279 | D11: 80 | E11: 130 | F11: 0.25 | G11: 0.06 | H11: 0.09 | I11: 0.05 | J11: 5 | K11: =IF($D11="",0,$C11*$D11) -> 22320 | L11: =IF($D11="",0,$F11*$K11) -> 5580 | M11: =IF($D11="",0,$G11*$K11) -> 1339.2 | N11: =IF($D11="",0,$H11*$K11) -> 2008.8 | O11: =IF($D11="",0,$I11*$K11*(1-$F11)) -> 837 | P11: =IF($D11="",0,$E11*$D11+$L11+$M11+$N11+$O11+$J11*$D11) -> 20565 | Q11: =IF($D11="",0,$K11-$P11) -> 1755 | R11: =IF($K11=0,0,$Q11/$K11) -> 0.078629032 | S11: =IF($D11="",0,$K11-$L11-$M11-$N11) -> 13392 | T11: 12750 | U11: =IF($T11="",0,MAX(0,$S11-$T11)) -> 642 | V11: =IF($S11=0,0,$U11/$S11) -> 0.047939068 | W11: =IF($D11="","",IF($T11="","BEKLİYOR",IF(OR($U11=0,$S11=0),"DOĞRU",IF(AND($V11>PazaryeriEksikHakedisEsik,$U11>PazaryeriEksikHakedisTutarEsik),"EKSİK HAKEDİŞ","DOĞRU")))) -> EKSİK HAKEDİŞ | X11: =IF($B11="","",CONCATENATE("Ürün: ",$B11," | Kâr: ",TEXT($Q11,"₺ #,##0")," | Durum: ",$W11)) -> Ürün: Mouse Kablosuz | Kâr: ₺ 1755,000 | Durum: EKSİK HAKEDİŞ | Y11: Amazon
K12: =IF($D12="",0,$C12*$D12) -> 0 | L12: =IF($D12="",0,$F12*$K12) -> 0 | M12: =IF($D12="",0,$G12*$K12) -> 0 | N12: =IF($D12="",0,$H12*$K12) -> 0 | O12: =IF($D12="",0,$I12*$K12*(1-$F12)) -> 0 | P12: =IF($D12="",0,$E12*$D12+$L12+$M12+$N12+$O12+$J12*$D12) -> 0 | Q12: =IF($D12="",0,$K12-$P12) -> 0 | R12: =IF($K12=0,0,$Q12/$K12) -> 0 | S12: =IF($D12="",0,$K12-$L12-$M12-$N12) -> 0 | U12: =IF($T12="",0,MAX(0,$S12-$T12)) -> 0 | V12: =IF($S12=0,0,$U12/$S12) -> 0 | W12: =IF($D12="","",IF($T12="","BEKLİYOR",IF(OR($U12=0,$S12=0),"DOĞRU",IF(AND($V12>PazaryeriEksikHakedisEsik,$U12>PazaryeriEksikHakedisTutarEsik),"EKSİK HAKEDİŞ","DOĞRU")))) | X12: =IF($B12="","",CONCATENATE("Ürün: ",$B12," | Kâr: ",TEXT($Q12,"₺ #,##0")," | Durum: ",$W12))
K13: =IF($D13="",0,$C13*$D13) -> 0 | L13: =IF($D13="",0,$F13*$K13) -> 0 | M13: =IF($D13="",0,$G13*$K13) -> 0 | N13: =IF($D13="",0,$H13*$K13) -> 0 | O13: =IF($D13="",0,$I13*$K13*(1-$F13)) -> 0 | P13: =IF($D13="",0,$E13*$D13+$L13+$M13+$N13+$O13+$J13*$D13) -> 0 | Q13: =IF($D13="",0,$K13-$P13) -> 0 | R13: =IF($K13=0,0,$Q13/$K13) -> 0 | S13: =IF($D13="",0,$K13-$L13-$M13-$N13) -> 0 | U13: =IF($T13="",0,MAX(0,$S13-$T13)) -> 0 | V13: =IF($S13=0,0,$U13/$S13) -> 0 | W13: =IF($D13="","",IF($T13="","BEKLİYOR",IF(OR($U13=0,$S13=0),"DOĞRU",IF(AND($V13>PazaryeriEksikHakedisEsik,$U13>PazaryeriEksikHakedisTutarEsik),"EKSİK HAKEDİŞ","DOĞRU")))) | X13: =IF($B13="","",CONCATENATE("Ürün: ",$B13," | Kâr: ",TEXT($Q13,"₺ #,##0")," | Durum: ",$W13))
K14: =IF($D14="",0,$C14*$D14) -> 0 | L14: =IF($D14="",0,$F14*$K14) -> 0 | M14: =IF($D14="",0,$G14*$K14) -> 0 | N14: =IF($D14="",0,$H14*$K14) -> 0 | O14: =IF($D14="",0,$I14*$K14*(1-$F14)) -> 0 | P14: =IF($D14="",0,$E14*$D14+$L14+$M14+$N14+$O14+$J14*$D14) -> 0 | Q14: =IF($D14="",0,$K14-$P14) -> 0 | R14: =IF($K14=0,0,$Q14/$K14) -> 0 | S14: =IF($D14="",0,$K14-$L14-$M14-$N14) -> 0 | U14: =IF($T14="",0,MAX(0,$S14-$T14)) -> 0 | V14: =IF($S14=0,0,$U14/$S14) -> 0 | W14: =IF($D14="","",IF($T14="","BEKLİYOR",IF(OR($U14=0,$S14=0),"DOĞRU",IF(AND($V14>PazaryeriEksikHakedisEsik,$U14>PazaryeriEksikHakedisTutarEsik),"EKSİK HAKEDİŞ","DOĞRU")))) | X14: =IF($B14="","",CONCATENATE("Ürün: ",$B14," | Kâr: ",TEXT($Q14,"₺ #,##0")," | Durum: ",$W14))
K15: =IF($D15="",0,$C15*$D15) -> 0 | L15: =IF($D15="",0,$F15*$K15) -> 0 | M15: =IF($D15="",0,$G15*$K15) -> 0 | N15: =IF($D15="",0,$H15*$K15) -> 0 | O15: =IF($D15="",0,$I15*$K15*(1-$F15)) -> 0 | P15: =IF($D15="",0,$E15*$D15+$L15+$M15+$N15+$O15+$J15*$D15) -> 0 | Q15: =IF($D15="",0,$K15-$P15) -> 0 | R15: =IF($K15=0,0,$Q15/$K15) -> 0 | S15: =IF($D15="",0,$K15-$L15-$M15-$N15) -> 0 | U15: =IF($T15="",0,MAX(0,$S15-$T15)) -> 0 | V15: =IF($S15=0,0,$U15/$S15) -> 0 | W15: =IF($D15="","",IF($T15="","BEKLİYOR",IF(OR($U15=0,$S15=0),"DOĞRU",IF(AND($V15>PazaryeriEksikHakedisEsik,$U15>PazaryeriEksikHakedisTutarEsik),"EKSİK HAKEDİŞ","DOĞRU")))) | X15: =IF($B15="","",CONCATENATE("Ürün: ",$B15," | Kâr: ",TEXT($Q15,"₺ #,##0")," | Durum: ",$W15))
K16: =IF($D16="",0,$C16*$D16) -> 0 | L16: =IF($D16="",0,$F16*$K16) -> 0 | M16: =IF($D16="",0,$G16*$K16) -> 0 | N16: =IF($D16="",0,$H16*$K16) -> 0 | O16: =IF($D16="",0,$I16*$K16*(1-$F16)) -> 0 | P16: =IF($D16="",0,$E16*$D16+$L16+$M16+$N16+$O16+$J16*$D16) -> 0 | Q16: =IF($D16="",0,$K16-$P16) -> 0 | R16: =IF($K16=0,0,$Q16/$K16) -> 0 | S16: =IF($D16="",0,$K16-$L16-$M16-$N16) -> 0 | U16: =IF($T16="",0,MAX(0,$S16-$T16)) -> 0 | V16: =IF($S16=0,0,$U16/$S16) -> 0 | W16: =IF($D16="","",IF($T16="","BEKLİYOR",IF(OR($U16=0,$S16=0),"DOĞRU",IF(AND($V16>PazaryeriEksikHakedisEsik,$U16>PazaryeriEksikHakedisTutarEsik),"EKSİK HAKEDİŞ","DOĞRU")))) | X16: =IF($B16="","",CONCATENATE("Ürün: ",$B16," | Kâr: ",TEXT($Q16,"₺ #,##0")," | Durum: ",$W16))
K17: =IF($D17="",0,$C17*$D17) -> 0 | L17: =IF($D17="",0,$F17*$K17) -> 0 | M17: =IF($D17="",0,$G17*$K17) -> 0 | N17: =IF($D17="",0,$H17*$K17) -> 0 | O17: =IF($D17="",0,$I17*$K17*(1-$F17)) -> 0 | P17: =IF($D17="",0,$E17*$D17+$L17+$M17+$N17+$O17+$J17*$D17) -> 0 | Q17: =IF($D17="",0,$K17-$P17) -> 0 | R17: =IF($K17=0,0,$Q17/$K17) -> 0 | S17: =IF($D17="",0,$K17-$L17-$M17-$N17) -> 0 | U17: =IF($T17="",0,MAX(0,$S17-$T17)) -> 0 | V17: =IF($S17=0,0,$U17/$S17) -> 0 | W17: =IF($D17="","",IF($T17="","BEKLİYOR",IF(OR($U17=0,$S17=0),"DOĞRU",IF(AND($V17>PazaryeriEksikHakedisEsik,$U17>PazaryeriEksikHakedisTutarEsik),"EKSİK HAKEDİŞ","DOĞRU")))) | X17: =IF($B17="","",CONCATENATE("Ürün: ",$B17," | Kâr: ",TEXT($Q17,"₺ #,##0")," | Durum: ",$W17))
K18: =IF($D18="",0,$C18*$D18) -> 0 | L18: =IF($D18="",0,$F18*$K18) -> 0 | M18: =IF($D18="",0,$G18*$K18) -> 0 | N18: =IF($D18="",0,$H18*$K18) -> 0 | O18: =IF($D18="",0,$I18*$K18*(1-$F18)) -> 0 | P18: =IF($D18="",0,$E18*$D18+$L18+$M18+$N18+$O18+$J18*$D18) -> 0 | Q18: =IF($D18="",0,$K18-$P18) -> 0 | R18: =IF($K18=0,0,$Q18/$K18) -> 0 | S18: =IF($D18="",0,$K18-$L18-$M18-$N18) -> 0 | U18: =IF($T18="",0,MAX(0,$S18-$T18)) -> 0 | V18: =IF($S18=0,0,$U18/$S18) -> 0 | W18: =IF($D18="","",IF($T18="","BEKLİYOR",IF(OR($U18=0,$S18=0),"DOĞRU",IF(AND($V18>PazaryeriEksikHakedisEsik,$U18>PazaryeriEksikHakedisTutarEsik),"EKSİK HAKEDİŞ","DOĞRU")))) | X18: =IF($B18="","",CONCATENATE("Ürün: ",$B18," | Kâr: ",TEXT($Q18,"₺ #,##0")," | Durum: ",$W18))
K19: =IF($D19="",0,$C19*$D19) -> 0 | L19: =IF($D19="",0,$F19*$K19) -> 0 | M19: =IF($D19="",0,$G19*$K19) -> 0 | N19: =IF($D19="",0,$H19*$K19) -> 0 | O19: =IF($D19="",0,$I19*$K19*(1-$F19)) -> 0 | P19: =IF($D19="",0,$E19*$D19+$L19+$M19+$N19+$O19+$J19*$D19) -> 0 | Q19: =IF($D19="",0,$K19-$P19) -> 0 | R19: =IF($K19=0,0,$Q19/$K19) -> 0 | S19: =IF($D19="",0,$K19-$L19-$M19-$N19) -> 0 | U19: =IF($T19="",0,MAX(0,$S19-$T19)) -> 0 | V19: =IF($S19=0,0,$U19/$S19) -> 0 | W19: =IF($D19="","",IF($T19="","BEKLİYOR",IF(OR($U19=0,$S19=0),"DOĞRU",IF(AND($V19>PazaryeriEksikHakedisEsik,$U19>PazaryeriEksikHakedisTutarEsik),"EKSİK HAKEDİŞ","DOĞRU")))) | X19: =IF($B19="","",CONCATENATE("Ürün: ",$B19," | Kâr: ",TEXT($Q19,"₺ #,##0")," | Durum: ",$W19))
K20: =IF($D20="",0,$C20*$D20) -> 0 | L20: =IF($D20="",0,$F20*$K20) -> 0 | M20: =IF($D20="",0,$G20*$K20) -> 0 | N20: =IF($D20="",0,$H20*$K20) -> 0 | O20: =IF($D20="",0,$I20*$K20*(1-$F20)) -> 0 | P20: =IF($D20="",0,$E20*$D20+$L20+$M20+$N20+$O20+$J20*$D20) -> 0 | Q20: =IF($D20="",0,$K20-$P20) -> 0 | R20: =IF($K20=0,0,$Q20/$K20) -> 0 | S20: =IF($D20="",0,$K20-$L20-$M20-$N20) -> 0 | U20: =IF($T20="",0,MAX(0,$S20-$T20)) -> 0 | V20: =IF($S20=0,0,$U20/$S20) -> 0 | W20: =IF($D20="","",IF($T20="","BEKLİYOR",IF(OR($U20=0,$S20=0),"DOĞRU",IF(AND($V20>PazaryeriEksikHakedisEsik,$U20>PazaryeriEksikHakedisTutarEsik),"EKSİK HAKEDİŞ","DOĞRU")))) | X20: =IF($B20="","",CONCATENATE("Ürün: ",$B20," | Kâr: ",TEXT($Q20,"₺ #,##0")," | Durum: ",$W20))
K21: =IF($D21="",0,$C21*$D21) -> 0 | L21: =IF($D21="",0,$F21*$K21) -> 0 | M21: =IF($D21="",0,$G21*$K21) -> 0 | N21: =IF($D21="",0,$H21*$K21) -> 0 | O21: =IF($D21="",0,$I21*$K21*(1-$F21)) -> 0 | P21: =IF($D21="",0,$E21*$D21+$L21+$M21+$N21+$O21+$J21*$D21) -> 0 | Q21: =IF($D21="",0,$K21-$P21) -> 0 | R21: =IF($K21=0,0,$Q21/$K21) -> 0 | S21: =IF($D21="",0,$K21-$L21-$M21-$N21) -> 0 | U21: =IF($T21="",0,MAX(0,$S21-$T21)) -> 0 | V21: =IF($S21=0,0,$U21/$S21) -> 0 | W21: =IF($D21="","",IF($T21="","BEKLİYOR",IF(OR($U21=0,$S21=0),"DOĞRU",IF(AND($V21>PazaryeriEksikHakedisEsik,$U21>PazaryeriEksikHakedisTutarEsik),"EKSİK HAKEDİŞ","DOĞRU")))) | X21: =IF($B21="","",CONCATENATE("Ürün: ",$B21," | Kâr: ",TEXT($Q21,"₺ #,##0")," | Durum: ",$W21))
K22: =IF($D22="",0,$C22*$D22) -> 0 | L22: =IF($D22="",0,$F22*$K22) -> 0 | M22: =IF($D22="",0,$G22*$K22) -> 0 | N22: =IF($D22="",0,$H22*$K22) -> 0 | O22: =IF($D22="",0,$I22*$K22*(1-$F22)) -> 0 | P22: =IF($D22="",0,$E22*$D22+$L22+$M22+$N22+$O22+$J22*$D22) -> 0 | Q22: =IF($D22="",0,$K22-$P22) -> 0 | R22: =IF($K22=0,0,$Q22/$K22) -> 0 | S22: =IF($D22="",0,$K22-$L22-$M22-$N22) -> 0 | U22: =IF($T22="",0,MAX(0,$S22-$T22)) -> 0 | V22: =IF($S22=0,0,$U22/$S22) -> 0 | W22: =IF($D22="","",IF($T22="","BEKLİYOR",IF(OR($U22=0,$S22=0),"DOĞRU",IF(AND($V22>PazaryeriEksikHakedisEsik,$U22>PazaryeriEksikHakedisTutarEsik),"EKSİK HAKEDİŞ","DOĞRU")))) | X22: =IF($B22="","",CONCATENATE("Ürün: ",$B22," | Kâr: ",TEXT($Q22,"₺ #,##0")," | Durum: ",$W22))
K23: =IF($D23="",0,$C23*$D23) -> 0 | L23: =IF($D23="",0,$F23*$K23) -> 0 | M23: =IF($D23="",0,$G23*$K23) -> 0 | N23: =IF($D23="",0,$H23*$K23) -> 0 | O23: =IF($D23="",0,$I23*$K23*(1-$F23)) -> 0 | P23: =IF($D23="",0,$E23*$D23+$L23+$M23+$N23+$O23+$J23*$D23) -> 0 | Q23: =IF($D23="",0,$K23-$P23) -> 0 | R23: =IF($K23=0,0,$Q23/$K23) -> 0 | S23: =IF($D23="",0,$K23-$L23-$M23-$N23) -> 0 | U23: =IF($T23="",0,MAX(0,$S23-$T23)) -> 0 | V23: =IF($S23=0,0,$U23/$S23) -> 0 | W23: =IF($D23="","",IF($T23="","BEKLİYOR",IF(OR($U23=0,$S23=0),"DOĞRU",IF(AND($V23>PazaryeriEksikHakedisEsik,$U23>PazaryeriEksikHakedisTutarEsik),"EKSİK HAKEDİŞ","DOĞRU")))) | X23: =IF($B23="","",CONCATENATE("Ürün: ",$B23," | Kâr: ",TEXT($Q23,"₺ #,##0")," | Durum: ",$W23))
... K1004: =IF($D1004="",0,$C1004*$D1004) -> 0 | L1004: =IF($D1004="",0,$F1004*$K1004) -> 0 | M1004: =IF($D1004="",0,$G1004*$K1004) -> 0 | N1004: =IF($D1004="",0,$H1004*$K1004) -> 0 | O1004: =IF($D1004="",0,$I1004*$K1004*(1-$F1004)) -> 0 | P1004: =IF($D1004="",0,$E1004*$D1004+$L1004+$M1004+$N1004+$O1004+$J1004*$D1004) -> 0 | Q1004: =IF($D1004="",0,$K1004-$P1004) -> 0 | R1004: =IF($K1004=0,0,$Q1004/$K1004) -> 0 | S1004: =IF($D1004="",0,$K1004-$L1004-$M1004-$N1004) -> 0 | U1004: =IF($T1004="",0,MAX(0,$S1004-$T1004)) -> 0 | V1004: =IF($S1004=0,0,$U1004/$S1004) -> 0 | W1004: =IF($D1004="","",IF($T1004="","BEKLİYOR",IF(OR($U1004=0,$S1004=0),"DOĞRU",IF(AND($V1004>PazaryeriEksikHakedisEsik,$U1004>PazaryeriEksikHakedisTutarEsik),"EKSİK HAKEDİŞ","DOĞRU")))) | X1004: =IF($B1004="","",CONCATENATE("Ürün: ",$B1004," | Kâr: ",TEXT($Q1004,"₺ #,##0")," | Durum: ",$W1004))
A1006: Sarı hücreler manuel giriştir; formül hücreleri kilitli ve korumalıdır.

Sheet HESAP
A1: HESAP — Pazaryeri Net Kâr & Eksik Hakediş Yakalayıcı
A3: Pazaryeri Bazlı Özet ve Net Kâr Motoru
A4: Özet kalem listesinden otomatik beslenir; pazaryeri bazında satış, maliyet, net kâr, marj ve hakediş farkı canlı üretilir.
A5: Pazaryeri | B5: Adet | C5: Toplam Satış (TL) | D5: Komisyon (TL) | E5: Kargo (TL) | F5: Reklam (TL) | G5: İade (TL) | H5: Toplam Maliyet (TL) | I5: NET KÂR (TL) | J5: KÂR MARJI | K5: Beklenen Hakediş (TL) | L5: Hakediş Farkı (TL)
A6: Trendyol | B6: =IFERROR(COUNTIFS(tblKalem[Pazaryeri],$A6,tblKalem[Miktar (Adet)],"<>0"),0) -> 2 | C6: =SUMIFS(tblKalem[Toplam Satış (TL)],tblKalem[Pazaryeri],$A6) -> 49457 | D6: =SUMIFS(tblKalem[Komisyon Tutarı (TL)],tblKalem[Pazaryeri],$A6) -> 9441.9 | E6: =SUMIFS(tblKalem[Kargo Tutarı (TL)],tblKalem[Pazaryeri],$A6) -> 1978.28 | F6: =SUMIFS(tblKalem[Reklam Tutarı (TL)],tblKalem[Pazaryeri],$A6) -> 3507.06 | G6: =SUMIFS(tblKalem[İade Maliyeti (TL)],tblKalem[Pazaryeri],$A6) -> 2216.611 | H6: =SUMIFS(tblKalem[Toplam Maliyet (TL)],tblKalem[Pazaryeri],$A6) -> 43027.851 | I6: =SUMIFS(tblKalem[NET KÂR (TL)],tblKalem[Pazaryeri],$A6) -> 6429.149 | J6: =IFERROR(C6/B6,0) -> 24728.5 | K6: =SUMIFS(tblKalem[Beklenen Hakediş (TL)],tblKalem[Pazaryeri],$A6) -> 34529.76 | L6: =SUMIFS(tblKalem[Hakediş Farkı (TL)],tblKalem[Pazaryeri],$A6) -> 0
A7: Hepsiburada | B7: =IFERROR(COUNTIFS(tblKalem[Pazaryeri],$A7,tblKalem[Miktar (Adet)],"<>0"),0) -> 1 | C7: =SUMIFS(tblKalem[Toplam Satış (TL)],tblKalem[Pazaryeri],$A7) -> 32940 | D7: =SUMIFS(tblKalem[Komisyon Tutarı (TL)],tblKalem[Pazaryeri],$A7) -> 7246.8 | E7: =SUMIFS(tblKalem[Kargo Tutarı (TL)],tblKalem[Pazaryeri],$A7) -> 1647 | F7: =SUMIFS(tblKalem[Reklam Tutarı (TL)],tblKalem[Pazaryeri],$A7) -> 1647 | G7: =SUMIFS(tblKalem[İade Maliyeti (TL)],tblKalem[Pazaryeri],$A7) -> 1027.728 | H7: =SUMIFS(tblKalem[Toplam Maliyet (TL)],tblKalem[Pazaryeri],$A7) -> 27708.528 | I7: =SUMIFS(tblKalem[NET KÂR (TL)],tblKalem[Pazaryeri],$A7) -> 5231.472 | J7: =IFERROR(C7/B7,0) -> 32940 | K7: =SUMIFS(tblKalem[Beklenen Hakediş (TL)],tblKalem[Pazaryeri],$A7) -> 22399.2 | L7: =SUMIFS(tblKalem[Hakediş Farkı (TL)],tblKalem[Pazaryeri],$A7) -> 5899.2
A8: Amazon | B8: =IFERROR(COUNTIFS(tblKalem[Pazaryeri],$A8,tblKalem[Miktar (Adet)],"<>0"),0) -> 2 | C8: =SUMIFS(tblKalem[Toplam Satış (TL)],tblKalem[Pazaryeri],$A8) -> 64200 | D8: =SUMIFS(tblKalem[Komisyon Tutarı (TL)],tblKalem[Pazaryeri],$A8) -> 15631.2 | E8: =SUMIFS(tblKalem[Kargo Tutarı (TL)],tblKalem[Pazaryeri],$A8) -> 3852 | F8: =SUMIFS(tblKalem[Reklam Tutarı (TL)],tblKalem[Pazaryeri],$A8) -> 4940.4 | G8: =SUMIFS(tblKalem[İade Maliyeti (TL)],tblKalem[Pazaryeri],$A8) -> 1791.864 | H8: =SUMIFS(tblKalem[Toplam Maliyet (TL)],tblKalem[Pazaryeri],$A8) -> 56935.464 | I8: =SUMIFS(tblKalem[NET KÂR (TL)],tblKalem[Pazaryeri],$A8) -> 7264.536 | J8: =IFERROR(C8/B8,0) -> 32100 | K8: =SUMIFS(tblKalem[Beklenen Hakediş (TL)],tblKalem[Pazaryeri],$A8) -> 39776.4 | L8: =SUMIFS(tblKalem[Hakediş Farkı (TL)],tblKalem[Pazaryeri],$A8) -> 642
A9: N11 | B9: =IFERROR(COUNTIFS(tblKalem[Pazaryeri],$A9,tblKalem[Miktar (Adet)],"<>0"),0) -> 1 | C9: =SUMIFS(tblKalem[Toplam Satış (TL)],tblKalem[Pazaryeri],$A9) -> 38700 | D9: =SUMIFS(tblKalem[Komisyon Tutarı (TL)],tblKalem[Pazaryeri],$A9) -> 5805 | E9: =SUMIFS(tblKalem[Kargo Tutarı (TL)],tblKalem[Pazaryeri],$A9) -> 3096 | F9: =SUMIFS(tblKalem[Reklam Tutarı (TL)],tblKalem[Pazaryeri],$A9) -> 1548 | G9: =SUMIFS(tblKalem[İade Maliyeti (TL)],tblKalem[Pazaryeri],$A9) -> 1973.7 | H9: =SUMIFS(tblKalem[Toplam Maliyet (TL)],tblKalem[Pazaryeri],$A9) -> 29822.7 | I9: =SUMIFS(tblKalem[NET KÂR (TL)],tblKalem[Pazaryeri],$A9) -> 8877.3 | J9: =IFERROR(C9/B9,0) -> 38700 | K9: =SUMIFS(tblKalem[Beklenen Hakediş (TL)],tblKalem[Pazaryeri],$A9) -> 28251 | L9: =SUMIFS(tblKalem[Hakediş Farkı (TL)],tblKalem[Pazaryeri],$A9) -> 0
A10: Diğer | B10: =IFERROR(COUNTIFS(tblKalem[Pazaryeri],$A10,tblKalem[Miktar (Adet)],"<>0"),0) -> 0 | C10: =SUMIFS(tblKalem[Toplam Satış (TL)],tblKalem[Pazaryeri],$A10) -> 0 | D10: =SUMIFS(tblKalem[Komisyon Tutarı (TL)],tblKalem[Pazaryeri],$A10) -> 0 | E10: =SUMIFS(tblKalem[Kargo Tutarı (TL)],tblKalem[Pazaryeri],$A10) -> 0 | F10: =SUMIFS(tblKalem[Reklam Tutarı (TL)],tblKalem[Pazaryeri],$A10) -> 0 | G10: =SUMIFS(tblKalem[İade Maliyeti (TL)],tblKalem[Pazaryeri],$A10) -> 0 | H10: =SUMIFS(tblKalem[Toplam Maliyet (TL)],tblKalem[Pazaryeri],$A10) -> 0 | I10: =SUMIFS(tblKalem[NET KÂR (TL)],tblKalem[Pazaryeri],$A10) -> 0 | J10: =IFERROR(C10/B10,0) -> 0 | K10: =SUMIFS(tblKalem[Beklenen Hakediş (TL)],tblKalem[Pazaryeri],$A10) -> 0 | L10: =SUMIFS(tblKalem[Hakediş Farkı (TL)],tblKalem[Pazaryeri],$A10) -> 0
A13: TOPLAM BLOK
A14: Toplam Satış (TL) | B14: =SUM(C6:C10) -> 185297
A15: Toplam Komisyon (TL) | B15: =SUM(D6:D10) -> 38124.9
A16: Toplam Kargo/Operasyon (TL) | B16: =SUM(E6:E10) -> 10573.28
A17: Toplam Reklam (TL) | B17: =SUM(F6:F10) -> 11642.46
A18: Toplam İade Maliyeti (TL) | B18: =SUM(G6:G10) -> 7009.903
A19: Toplam Maliyet (TL) | B19: =SUM(H6:H10) -> 157494.54
A20: TOPLAM NET KÂR (TL) | B20: =SUM(I6:I10) -> 27802.457
A21: Genel Kâr Marjı | B21: =IFERROR(B20/B14,0) -> 0.15004267
A22: Ortalama Kesinti Oranı | B22: =IFERROR((B15+B16+B17+B18)/B14,0) -> 0.36347347
A23: Toplam Beklenen Hakediş (TL) | B23: =SUM(K6:K10) -> 124956.36
A24: TOPLAM HAKEDİŞ FARKI (TL) | B24: =SUM(L6:L10) -> 6541.2
A25: Eksik Hakediş Kalem Sayısı | B25: =COUNTIF(tblKalem[Durum],"EKSİK HAKEDİŞ") -> 2
A26: Ortalama Kâr Marjı | B26: =IFERROR(AVERAGE(tblKalem[KÂR MARJI]),0) -> 0.00087068755
A27: En İyi Pazaryeri | B27: =IFERROR(INDEX(A6:A10,MATCH(MAX(J6:J10),J6:J10,0)),"") -> N11
A28: En İyi Pazaryeri Marjı | B28: =IFERROR(MAX(J6:J10),0) -> 38700
A30: Kalem Sırası | B30: NET KÂR (TL) | D30: Hakediş Farkı (TL)
A31: 1 | B31: =IFERROR(INDEX(tblKalem[NET KÂR (TL)],PazaryeriPanelSatir_1),0) -> 4460.525 | D31: =IFERROR(INDEX(tblKalem[Hakediş Farkı (TL)],PazaryeriPanelSatir_1),0) -> 0
A32: 2 | B32: =IFERROR(INDEX(tblKalem[NET KÂR (TL)],PazaryeriPanelSatir_2),0) -> 5231.472 | D32: =IFERROR(INDEX(tblKalem[Hakediş Farkı (TL)],PazaryeriPanelSatir_2),0) -> 5899.2
A33: 3 | B33: =IFERROR(INDEX(tblKalem[NET KÂR (TL)],PazaryeriPanelSatir_3),0) -> 1968.624 | D33: =IFERROR(INDEX(tblKalem[Hakediş Farkı (TL)],PazaryeriPanelSatir_3),0) -> 0
A34: 4 | B34: =IFERROR(INDEX(tblKalem[NET KÂR (TL)],PazaryeriPanelSatir_4),0) -> 5509.536 | D34: =IFERROR(INDEX(tblKalem[Hakediş Farkı (TL)],PazaryeriPanelSatir_4),0) -> 0
A35: 5 | B35: =IFERROR(INDEX(tblKalem[NET KÂR (TL)],PazaryeriPanelSatir_5),0) -> 8877.3 | D35: =IFERROR(INDEX(tblKalem[Hakediş Farkı (TL)],PazaryeriPanelSatir_5),0) -> 0
A36: 6 | B36: =IFERROR(INDEX(tblKalem[NET KÂR (TL)],PazaryeriPanelSatir_6),0) -> 1755 | D36: =IFERROR(INDEX(tblKalem[Hakediş Farkı (TL)],PazaryeriPanelSatir_6),0) -> 642
A37: 7 | B37: =IFERROR(INDEX(tblKalem[NET KÂR (TL)],PazaryeriPanelSatir_7),0) -> 0 | D37: =IFERROR(INDEX(tblKalem[Hakediş Farkı (TL)],PazaryeriPanelSatir_7),0) -> 0
A38: 8 | B38: =IFERROR(INDEX(tblKalem[NET KÂR (TL)],PazaryeriPanelSatir_8),0) -> 0 | D38: =IFERROR(INDEX(tblKalem[Hakediş Farkı (TL)],PazaryeriPanelSatir_8),0) -> 0
A39: 9 | B39: =IFERROR(INDEX(tblKalem[NET KÂR (TL)],PazaryeriPanelSatir_9),0) -> 0 | D39: =IFERROR(INDEX(tblKalem[Hakediş Farkı (TL)],PazaryeriPanelSatir_9),0) -> 0
A40: 10 | B40: =IFERROR(INDEX(tblKalem[NET KÂR (TL)],PazaryeriPanelSatir_10),0) -> 0 | D40: =IFERROR(INDEX(tblKalem[Hakediş Farkı (TL)],PazaryeriPanelSatir_10),0) -> 0
A41: 11 | B41: =IFERROR(INDEX(tblKalem[NET KÂR (TL)],PazaryeriPanelSatir_11),0) -> 0 | D41: =IFERROR(INDEX(tblKalem[Hakediş Farkı (TL)],PazaryeriPanelSatir_11),0) -> 0
A42: 12 | B42: =IFERROR(INDEX(tblKalem[NET KÂR (TL)],PazaryeriPanelSatir_12),0) -> 0 | D42: =IFERROR(INDEX(tblKalem[Hakediş Farkı (TL)],PazaryeriPanelSatir_12),0) -> 0
A44: Ortalama NET KÂR (TL) | B44: =ROUND(IFERROR(AVERAGE(INDEX(tblKalem[NET KÂR (TL)],PazaryeriPanelSatir_1):INDEX(tblKalem[NET KÂR (TL)],PazaryeriPanelSatir_12)),0),0) -> 2317
A45: Gelecek Dönem NET KÂR Tahmini (TL) | B45: =ROUND(IFERROR(forecast.lınear(PazaryeriPanelSatir_12,tblKalem[NET KÂR (TL)],ROW(tblKalem[NET KÂR (TL)])-ROW(tblKalem[[#Headers],[NET KÂR (TL)]])),0),0) -> 0
...

Sheet ANALITIK_MOTOR
A1: ANALITIK MOTOR — Pazaryeri Net Kâr & Eksik Hakediş Yakalayıcı
A3: ANALİTİK MOTOR — DERİNLİK KATMANI
A5: Kod | B5: Gösterge | C5: Değer | D5: Makine Yorumu
A6: T1 | B6: Ortalama Kâr Marjı | C6: =IFERROR(AVERAGE(tblKalem[KÂR MARJI]),0) -> 0.00087068755 | D6: =_xlfn.TEXTJOIN("; ",TRUE(),"Ortalama kâr marjı ",TEXT(C6,"0.0%")," — portföyün genel kârlılık düzeyini gösterir") -> Ortalama kâr marjı ; 00%; — portföyün genel kârlılık düzeyini gösterir
A7: T2 | B7: Ortalama Komisyon Oranı | C7: =IFERROR(AVERAGE(tblKalem[Komisyon Oranı]),0) -> 0.20666667 | D7: =_xlfn.TEXTJOIN("; ",TRUE(),"Ortalama komisyon oranı ",TEXT(C7,"0.0%")," — pazaryeri maliyet yükünü gösterir") -> Ortalama komisyon oranı ; 21%; — pazaryeri maliyet yükünü gösterir
A8: O1 | B8: Net Kâr Sapması (MAD) | C8: =IFERROR(AVEDEV(tblKalem[NET KÂR (TL)]),0) -> 55.326277 | D8: =_xlfn.TEXTJOIN("; ",TRUE(),"Net kâr ortalama mutlak sapması ",TEXT(C8,"₺ #,##0")," TL — kalemler arası kâr heterojenliğini ölçer") -> Net kâr ortalama mutlak sapması ; ₺ 55,326; TL — kalemler arası kâr heterojenliğini ölçer
A9: O2 | B9: En Yüksek Net Kâr | C9: =IFERROR(MAX(tblKalem[NET KÂR (TL)]),0) -> 8877.3 | D9: =_xlfn.TEXTJOIN("; ",TRUE(),"En yüksek net kâr ",TEXT(C9,"₺ #,##0")," TL — bu kalem portföyün kâr lideridir") -> En yüksek net kâr ; ₺ 8877,300; TL — bu kalem portföyün kâr lideridir
A10: O3 | B10: Senaryo Bant Genişliği | C10: =SENARYO_DUYARLILIK!C11 -> 17691.969 | D10: =_xlfn.TEXTJOIN("; ",TRUE(),"İyimser ile kritik senaryo net kâr farkı ",TEXT(C10,"₺ #,##0")," TL — satış fiyatı belirsizliğinin etkisini gösterir") -> İyimser ile kritik senaryo net kâr farkı ; ₺ 17691,969; TL — satış fiyatı belirsizliğinin etkisini gösterir
A11: O6 | B11: Pazaryeri Yoğunlaşması (HHI) | C11: =IFERROR(IF(SUM(HESAP!$C$6:$C$10)=0,0,SUMPRODUCT((HESAP!$C$6:$C$10/SUM(HESAP!$C$6:$C$10))^2)),0) -> 0.26650282 | D11: =_xlfn.TEXTJOIN("; ",TRUE(),"Pazaryeri yoğunlaşma endeksi ",TEXT(C11,"0.000")," — 1 e yaklaştıkça satış tek pazaryerinde toplanır") -> Pazaryeri yoğunlaşma endeksi ; 0.000; — 1 e yaklaştıkça satış tek pazaryerinde toplanır
A12: O8 | B12: Veri Kalite Skoru | C12: =KONTROLLER!B19 -> 95 | D12: =_xlfn.TEXTJOIN("; ",TRUE(),"Veri kalite skoru ",TEXT(C12,"0")," puan — ",IF(C12>=PazaryeriKaliteIyi,"yüksek güven","veri girişi tamamlanmalı")) -> Veri kalite skoru ; 95; puan — ; yüksek güven
A13: I1 | B13: Gelecek Dönem NET KÂR Tahmini | C13: =HESAP!B45 -> 0 | D13: =_xlfn.TEXTJOIN("; ",TRUE(),"Gelecek dönem net kâr tahmini ",TEXT(C13,"₺ #,##0")," TL — güven bandı için alt/üst sınır HESAP sayfasındadır") -> Gelecek dönem net kâr tahmini ; ₺ ,000; TL — güven bandı için alt/üst sınır HESAP sayfasındadır
A14: I2 | B14: Satış Fiyatı Yüzdelik P90 | C14: =IFERROR(_xlfn.PERCENTILE.INC(tblKalem[Birim Satış Fiyatı (TL)],PazaryeriP90Oran),0) -> 1199 | D14: =_xlfn.TEXTJOIN("; ",TRUE(),"Kalemlerin %90 ı ",TEXT(C14,"₺ #,##0")," TL altında satış fiyatına sahiptir — fiyat dağılımı üst sınırını gösterir") -> Kalemlerin %90 ı ; ₺ 1199,000; TL altında satış fiyatına sahiptir — fiyat dağılımı üst sınırını gösterir
A15: I8 | B15: Toplam Eksik Hakediş Etkisi | C15: =HESAP!B24 -> 6541.2 | D15: =_xlfn.TEXTJOIN("; ",TRUE(),"Tespit edilen toplam eksik hakediş ",TEXT(C15,"₺ #,##0")," TL — pazaryerinden talep edilmesi gereken tutar") -> Tespit edilen toplam eksik hakediş ; ₺ 6541,200; TL — pazaryerinden talep edilmesi gereken tutar

Sheet KONTROLLER
A1: KONTROLLER — Pazaryeri Net Kâr & Eksik Hakediş Yakalayıcı
A3: Giriş Kalite Kontrolleri
A4: Aşağıdaki kontroller canlı formüllerle çalışır; sorun varsa uyarı üretir.
A6: Negatif satış fiyatı var mı? | B6: =IF(COUNTIF(tblKalem[Birim Satış Fiyatı (TL)],"<0")=0,"TEMİZ","NEGATİF VAR") -> TEMİZ
A7: Negatif ürün maliyeti var mı? | B7: =IF(COUNTIF(tblKalem[Birim Ürün Maliyeti (TL)],"<0")=0,"TEMİZ","NEGATİF VAR") -> TEMİZ
A8: Komisyon oranı 0,50 üzerinde mi? | B8: =IF(COUNTIF(tblKalem[Komisyon Oranı],">0.5")=0,"TEMİZ","ORAN >0,5 VAR") -> TEMİZ
A9: İade oranı 0,50 üzerinde mi? | B9: =IF(COUNTIF(tblKalem[İade Oranı],">0.5")=0,"TEMİZ","ORAN >0,5 VAR") -> TEMİZ
A10: Toplam hakediş farkı eşiği aşıyor mu? | B10: =IF(HESAP!B24>PazaryeriToplamFarkEsik,"AŞIYOR","NORMAL") -> AŞIYOR
A11: Eksik hakediş kalemi var mı? | B11: =IF(COUNTIF(tblKalem[Durum],"EKSİK HAKEDİŞ")>0,"VAR","YOK") -> VAR
A12: Genel marj kritik altında mı? | B12: =IF(HESAP!B21<PazaryeriNetKarMarjiKritik,"KRİTİK","NORMAL") -> NORMAL
A13: Kalem sayısı yeterli mi? | B13: =IF(COUNTA(tblKalem[Ürün Adı])>=3,"YETERLİ","AZ") -> YETERLİ
A15: Veri Kalitesi Skoru (0-100)
A16: Temel giriş kolonlarının dolu olma oranına göre üretilen kalite skoru.
A17: Toplam Giriş Hücresi | B17: =COUNTA(tblKalem[Ürün Adı])*PazaryeriTemelKolonSayisi -> 42
A18: Dolu Giriş Hücresi | B18: =COUNTA(tblKalem[Ürün Adı])+COUNTA(tblKalem[Birim Satış Fiyatı (TL)])+COUNTA(tblKalem[Miktar (Adet)])+COUNTA(tblKalem[Birim Ürün Maliyeti (TL)])+COUNTA(tblKalem[Komisyon Oranı])+COUNTA(tblKalem[Birim Ek Gider (TL)])+COUNTA(tblKalem[Gerçek Hakediş (TL)]) -> 40
A19: Kalite Skoru | B19: =ROUND(IF(PazaryeriToplamGiris=0,0,PazaryeriDoluGiris/PazaryeriToplamGiris*100),0) -> 95
A20: Kalite Seviyesi | B20: =IF(B19>=PazaryeriKaliteIyi,"YÜKSEK",IF(B19>=PazaryeriKaliteOrta,"ORTA","DÜŞÜK")) -> YÜKSEK
A22: Kontroller yalnızca giriş verisini denetler; değerleri değiştirmez.

Sheet KARAR
A1: KARAR — Pazaryeri Net Kâr & Eksik Hakediş Yakalayıcı
A3: Karar Kapısı — Portföy Yönlendirme
A4: Genel kâr marjı, eksik hakediş durumu ve veri kalitesine göre üretilen portföy kararı.
A6: Toplam Net Kâr (TL) | B6: =HESAP!B20 -> 27802.457
A7: Genel Kâr Marjı | B7: =HESAP!B21 -> 0.15004267
A8: Toplam Hakediş Farkı (TL) | B8: =HESAP!B24 -> 6541.2
A9: Eksik Hakediş Kalem Sayısı | B9: =HESAP!B25 -> 2
A11: KARAR | B11: =IF(COUNTA(tblKalem[Ürün Adı])=0,"VERİ YOK",IF(OR(COUNTIF(tblKalem[Birim Satış Fiyatı (TL)],"<0")>0,COUNTIF(tblKalem[Birim Ürün Maliyeti (TL)],"<0")>0),"DURDUR",IF(HESAP!B14<=0,"VERİ YOK",IF(AND(COUNTIF(tblKalem[Durum],"EKSİK HAKEDİŞ")>0,HESAP!B24>0),"İNCELE",IF(HESAP!B21>=PazaryeriNetKarMarjiHedef,"GÜÇLÜ",IF(HESAP!B21>=PazaryeriNetKarMarjiKritik,"NORMAL","İNCELE")))))) -> İNCELE
A12: Gerekçe | B12: =IF(COUNTIF(tblKalem[Birim Satış Fiyatı (TL)],"<0")>0,"Negatif satış fiyatı tespit edildi; veriler düzeltilmeli.",IF(COUNTIF(tblKalem[Birim Ürün Maliyeti (TL)],"<0")>0,"Negatif ürün maliyeti tespit edildi; veriler düzeltilmeli.",IF(HESAP!B14<=0,"Satış kaydı bulunmuyor; portföy kararı üretilemiyor.",IF(AND(COUNTIF(tblKalem[Durum],"EKSİK HAKEDİŞ")>0,HESAP!B24>0),"Eksik hakediş tespit edildi; pazaryerinden fark tutarı talep edilmelidir.",IF(HESAP!B21>=PazaryeriNetKarMarjiHedef,"Genel marj hedefin üzerinde; portföy güçlü, büyütmeye devam edin.",IF(HESAP!B21>=PazaryeriNetKarMarjiKritik,"Genel marj sınırın üzerinde; portföy normal, maliyet kalemlerini izleyin.","Genel marj kritik altında; fiyat veya komisyon yapısı yeniden değerlendirilmeli.")))))) -> Eksik hakediş tespit edildi; pazaryerinden fark tutarı talep edilmelidir.
A14: Önerilen Aksiyonlar
A15: Aksiyon 1 | B15: =PazaryeriAksiyon1_ACIKLAMA -> Eksik hakediş tespit edildi; pazaryeri müşteri hizmetlerine fark dökümünü ileterek tutarın iadesini talep edin.
A16: Aksiyon 2 | B16: =PazaryeriAksiyon2_ACIKLAMA -> Genel marj hedefin üzerinde; satışı artırmak için kâr marjı yüksek kalemlerin reklam bütçesini öne çekin.
A17: Aksiyon 3 | B17: =PazaryeriAksiyon3_ACIKLAMA -> Marj kritik altında; komisyon yüksek pazaryerlerinde fiyat/komisyon yapısını yeniden müzakere edin veya portföyü gözden geçirin.
A19: Karar yalnızca giriş verisi ve AYARLAR'daki oran/eşiklerden türetilir.

Sheet PANO
A1: PANO — Pazaryeri Net Kâr & Eksik Hakediş Yakalayıcı
A3: Yönetim Paneli | B3: Toplam Satış (TL) | C3: Toplam NET KÂR (TL) | D3: Genel Kâr Marjı | E3: Toplam Beklenen Hakediş (TL) | F3: Toplam Hakediş Farkı (TL) | G3: Eksik Kalem Sayısı | H3: Kalite Skoru
B4: =HESAP!B14 -> 185297 | C4: =HESAP!B20 -> 27802.457 | D4: =HESAP!B21 -> 0.15004267 | E4: =HESAP!B23 -> 124956.36 | F4: =HESAP!B24 -> 6541.2 | G4: =HESAP!B25 -> 2 | H4: =KONTROLLER!B19 -> 95
A6: Karar | B6: =KARAR!B11 -> İNCELE | D6: En İyi Pazaryeri | E6: =HESAP!B27 -> N11 | G6: En İyi Pazaryeri Marjı | H6: =HESAP!B28 -> 38700
A10: Pazaryeri | B10: Toplam Satış (TL) | C10: NET KÂR (TL) | D10: KÂR MARJI | E10: Beklenen Hakediş (TL)
A11: Trendyol Satış | B11: =HESAP!C6 -> 49457 | C11: =HESAP!I6 -> 6429.149 | D11: =HESAP!J6 -> 24728.5 | E11: =HESAP!K6 -> 34529.76
A12: Hepsiburada Satış | B12: =HESAP!C7 -> 32940 | C12: =HESAP!I7 -> 5231.472 | D12: =HESAP!J7 -> 32940 | E12: =HESAP!K7 -> 22399.2
A13: Amazon Satış | B13: =HESAP!C8 -> 64200 | C13: =HESAP!I8 -> 7264.536 | D13: =HESAP!J8 -> 32100 | E13: =HESAP!K8 -> 39776.4
A14: N11 Satış | B14: =HESAP!C9 -> 38700 | C14: =HESAP!I9 -> 8877.3 | D14: =HESAP!J9 -> 38700 | E14: =HESAP!K9 -> 28251
A15: Diğer Satış | B15: =HESAP!C10 -> 0 | C15: =HESAP!I10 -> 0 | D15: =HESAP!J10 -> 0 | E15: =HESAP!K10 -> 0
G20: Kalem Sırası | H20: NET KÂR (TL) | I20: Hakediş Farkı (TL)
G21: 1 | H21: =HESAP!B31 -> 4460.525 | I21: =HESAP!D31 -> 0
G22: 2 | H22: =HESAP!B32 -> 5231.472 | I22: =HESAP!D32 -> 5899.2
G23: 3 | H23: =HESAP!B33 -> 1968.624 | I23: =HESAP!D33 -> 0
G24: 4 | H24: =HESAP!B34 -> 5509.536 | I24: =HESAP!D34 -> 0
G25: 5 | H25: =HESAP!B35 -> 8877.3 | I25: =HESAP!D35 -> 0
G26: 6 | H26: =HESAP!B36 -> 1755 | I26: =HESAP!D36 -> 642
G27: 7 | H27: =HESAP!B37 -> 0 | I27: =HESAP!D37 -> 0
G28: 8 | H28: =HESAP!B38 -> 0 | I28: =HESAP!D38 -> 0
G29: 9 | H29: =HESAP!B39 -> 0 | I29: =HESAP!D39 -> 0
G30: 10 | H30: =HESAP!B40 -> 0 | I30: =HESAP!D40 -> 0
G31: 11 | H31: =HESAP!B41 -> 0 | I31: =HESAP!D41 -> 0
G32: 12 | H32: =HESAP!B42 -> 0 | I32: =HESAP!D42 -> 0
A34: Durum | B34: Adet
A35: EKSİK HAKEDİŞ | B35: =IFERROR(COUNTIF(tblKalem[Durum],"EKSİK HAKEDİŞ"),0) -> 2
A36: DOĞRU | B36: =IFERROR(COUNTIF(tblKalem[Durum],"DOĞRU"),0) -> 2
A37: BEKLİYOR | B37: =IFERROR(COUNTIF(tblKalem[Durum],"BEKLİYOR"),0) -> 2
A40: Ortalama NET KÂR | B40: =HESAP!B44 -> 2317
A41: Gelecek Dönem NET KÂR Tahmini | B41: =HESAP!B45 -> 0
A42: NET KÂR Std Sapması | B42: =HESAP!B46 -> 0
A43: Alt Tahmin Sınırı | B43: =HESAP!B47 -> 2317
A44: Üst Tahmin Sınırı | B44: =HESAP!B48 -> 2317
E46: Senaryo | F46: Net Kâr (TL)
E47: İyimser | F47: =SENARYO_DUYARLILIK!C7 -> 33699.78
E48: Baz | F48: =SENARYO_DUYARLILIK!C8 -> 27802.457
E49: Kötümser | F49: =SENARYO_DUYARLILIK!C9 -> 21905.134
E50: Kritik | F50: =SENARYO_DUYARLILIK!C10 -> 16007.811
A52: Paneldeki tüm göstergeler canlı formüllerden beslenir.

Sheet SENARYO_DUYARLILIK
A1: SENARYO DUYARLILIK — Pazaryeri Net Kâr & Eksik Hakediş Yakalayıcı
A3: Senaryo ve Duyarlılık Analizi
A4: Farklı satış fiyatı çarpanı senaryolarında net kâr bant aralığı; ardından hangi değişkenin net kârı en çok etkilediğini gösteren tornado analizi.
A6: Senaryo | B6: Satış Fiyatı Çarpanı | C6: Net Kâr (TL) | D6: Durum
A7: İYİMSER | B7: =AYARLAR!$B$18 -> 0.05 | C7: =IFERROR(PazaryeriToplamNetKar+PazaryeriToplamSatis*B7*(1-PazaryeriOrtKesintiOrani),0) -> 33699.78 | D7: =IF(C7>=PazaryeriToplamNetKar,"AVANTAJLI","DEĞERLENDİR") -> AVANTAJLI
A8: BAZ | B8: =AYARLAR!$B$19 -> 0 | C8: =IFERROR(PazaryeriToplamNetKar+PazaryeriToplamSatis*B8*(1-PazaryeriOrtKesintiOrani),0) -> 27802.457 | D8: =IF(C8>=PazaryeriToplamNetKar,"AVANTAJLI","DEĞERLENDİR") -> AVANTAJLI
A9: KÖTÜMSER | B9: =AYARLAR!$B$20 -> -0.05 | C9: =IFERROR(PazaryeriToplamNetKar+PazaryeriToplamSatis*B9*(1-PazaryeriOrtKesintiOrani),0) -> 21905.134 | D9: =IF(C9>=PazaryeriToplamNetKar,"AVANTAJLI","DEĞERLENDİR") -> DEĞERLENDİR
A10: KRİTİK | B10: =AYARLAR!$B$21 -> -0.1 | C10: =IFERROR(PazaryeriToplamNetKar+PazaryeriToplamSatis*B10*(1-PazaryeriOrtKesintiOrani),0) -> 16007.811 | D10: =IF(C10>=PazaryeriToplamNetKar,"AVANTAJLI","DEĞERLENDİR") -> DEĞERLENDİR
A11: Senaryo Bant Genişliği (İyi − Kritik) | C11: =C7-C10 -> 17691.969
A13: Tornado: Net Kâra Etki
A14: Komisyon Oranı +1 puan Etkisi | B14: =IFERROR(ABS(PazaryeriToplamSatis*PazaryeriTornadoKomisyonOran),0) -> 1852.97
A15: Satış Fiyatı −%5 Etkisi | B15: =IFERROR(ABS(PazaryeriToplamSatis*AYARLAR!$B$29*(1-PazaryeriOrtKesintiOrani)),0) -> 5897.3228
A17: En Etkili Değişken | B17: =IF(B14>=B15,"Komisyon","Satış Fiyatı") -> Satış Fiyatı
A19: Senaryo çarpanları ve tornado adımları AYARLAR'dan türetilir.

Sheet RAPOR
A1: PAZARYERİ NET KÂR VE EKSİK HAKEDİŞ — YÖNETİCİ ÖZETİ
A2: =_xlfn.CONCAT("Rapor Tarihi: ",TEXT(PazaryeriRaporTarihi,"dd.mm.yyyy")," | Hazırlayan: ",PazaryeriRaporHazirlayan," | Sürüm: ",PazaryeriDosyaSurumu) -> Rapor Tarihi: 10.08.2026 | Hazırlayan: Pazaryeri Operasyon Müdürü | Sürüm: 1.0.0
A4: Karar | B4: =KARAR!B11 -> İNCELE
A6: Toplam Satış (TL) | B6: =HESAP!B14 -> 185297
A7: Toplam Maliyet (TL) | B7: =HESAP!B19 -> 157494.54
A8: Toplam Net Kâr (TL) | B8: =HESAP!B20 -> 27802.457
A9: Genel Kâr Marjı | B9: =HESAP!B21 -> 0.15004267
A10: Toplam Beklenen Hakediş (TL) | B10: =HESAP!B23 -> 124956.36
A11: Toplam Hakediş Farkı (TL) | B11: =HESAP!B24 -> 6541.2
A12: Eksik Hakediş Kalem Sayısı | B12: =HESAP!B25 -> 2
A13: En İyi Pazaryeri | B13: =HESAP!B27 -> N11
A14: Kalite Skoru | B14: =KONTROLLER!B19 -> 95
A16: Varsayımlar ve Önemli Notlar
A17: • Beklenen hakediş, satış bedelinden komisyon, kargo/operasyon ve reklam kesintileri düşüldükten sonra pazaryerinin ödemesi gereken tutardır.
A18: • Eksik hakediş tespiti, gerçek hakediş (pazaryerinden gelen ödeme) ile beklenen tutarın farkının eşikleri aşmasıyla üretilir; gerçek hakediş girilmeyen kalemler BEKLİYOR işaretlenir.
A19: • Net kâr; satıştan ürün maliyeti, komisyon, kargo, reklam, iade maliyeti ve ek giderler düşülerek hesaplanır.
A20: • Senaryo ve tornado analizi satış fiyatı ve komisyon değişimlerinin kâra etkisini gösterir; çarpanlar AYARLAR'dadır.
A21: • Bu dosya karar destek aracıdır; vergi ve muhasebe hesabı mali müşavir görüşü yerine geçmez.
A22: • Demo veriler gerçek müşteri verisi değildir; kullanımdan önce temizlenmelidir.
A24: Önerilen Aksiyonlar
A25: =PazaryeriAksiyon1_ACIKLAMA -> Eksik hakediş tespit edildi; pazaryeri müşteri hizmetlerine fark dökümünü ileterek tutarın iadesini talep edin.
A26: =PazaryeriAksiyon2_ACIKLAMA -> Genel marj hedefin üzerinde; satışı artırmak için kâr marjı yüksek kalemlerin reklam bütçesini öne çekin.
A27: =PazaryeriAksiyon3_ACIKLAMA -> Marj kritik altında; komisyon yüksek pazaryerlerinde fiyat/komisyon yapısını yeniden müzakere edin veya portföyü gözden geçirin.
A29: Bu rapor karar destek amaçlıdır; mali tavsiye niteliği taşımaz.

Sheet ORNEK_VERI
A1: ORNEK VERI — Pazaryeri Net Kâr & Eksik Hakediş Yakalayıcı
A3: Örnek Veri (Demo)
A4: Gerçek girişlere başlamadan önce demo veri ile ürünü deneyin. Bu satırlar örnektir; gerçek verilerle değiştirin.
A5: Kalem Kodu | B5: Ürün Adı | C5: Pazaryeri | D5: Birim Satış Fiyatı (TL) | E5: Miktar (Adet) | F5: Birim Ürün Maliyeti (TL) | G5: Komisyon Oranı | H5: Kargo/Operasyon Oranı | I5: Reklam Oranı | J5: İade Oranı | K5: Birim Ek Gider (TL) | L5: Beklenen Hakediş (TL) | M5: NET KÂR (TL) | N5: Açıklama
A6: P-1001 | B6: Kulaklık Bluetooth | C6: Trendyol | D6: 899 | E6: 25 | F6: 420 | G6: 0.18 | H6: 0.04 | I6: 0.06 | J6: 0.05 | K6: 12 | L6: =IF($E6="",0,$D6*$E6*(1-$G6-$H6-$I6)) -> 16182 | M6: =IF($E6="",0,$D6*$E6-($F6*$E6+$G6*$D6*$E6+$H6*$D6*$E6+$I6*$D6*$E6+$J6*$D6*$E6*(1-$G6)+$K6*$E6)) -> 4460.525 | N6: =IF($B6="","",CONCATENATE("Örnek kalem: ",$B6)) -> Örnek kalem: Kulaklık Bluetooth
A7: P-1002 | B7: Powerbank 20.000mAh | C7: Hepsiburada | D7: 549 | E7: 60 | F7: 260 | G7: 0.22 | H7: 0.05 | I7: 0.05 | J7: 0.04 | K7: 9 | L7: =IF($E7="",0,$D7*$E7*(1-$G7-$H7-$I7)) -> 22399.2 | M7: =IF($E7="",0,$D7*$E7-($F7*$E7+$G7*$D7*$E7+$H7*$D7*$E7+$I7*$D7*$E7+$J7*$D7*$E7*(1-$G7)+$K7*$E7)) -> 5231.472 | N7: =IF($B7="","",CONCATENATE("Örnek kalem: ",$B7)) -> Örnek kalem: Powerbank 20.000mAh
A8: P-1003 | B8: Akıllı Saat | C8: Trendyol | D8: 1499 | E8: 18 | F8: 820 | G8: 0.2 | H8: 0.04 | I8: 0.08 | J8: 0.06 | K8: 18 | L8: =IF($E8="",0,$D8*$E8*(1-$G8-$H8-$I8)) -> 18347.76 | M8: =IF($E8="",0,$D8*$E8-($F8*$E8+$G8*$D8*$E8+$H8*$D8*$E8+$I8*$D8*$E8+$J8*$D8*$E8*(1-$G8)+$K8*$E8)) -> 1968.624 | N8: =IF($B8="","",CONCATENATE("Örnek kalem: ",$B8)) -> Örnek kalem: Akıllı Saat
A9: P-1004 | B9: Şarj Aleti 65W | C9: Amazon | D9: 349 | E9: 120 | F9: 160 | G9: 0.24 | H9: 0.06 | I9: 0.07 | J9: 0.03 | K9: 6 | L9: =IF($E9="",0,$D9*$E9*(1-$G9-$H9-$I9)) -> 26384.4 | M9: =IF($E9="",0,$D9*$E9-($F9*$E9+$G9*$D9*$E9+$H9*$D9*$E9+$I9*$D9*$E9+$J9*$D9*$E9*(1-$G9)+$K9*$E9)) -> 5509.536 | N9: =IF($B9="","",CONCATENATE("Örnek kalem: ",$B9)) -> Örnek kalem: Şarj Aleti 65W
A10: P-1005 | B10: Kablo USB-C | C10: N11 | D10: 129 | E10: 300 | F10: 55 | G10: 0.15 | H10: 0.08 | I10: 0.04 | J10: 0.06 | K10: 3 | L10: =IF($E10="",0,$D10*$E10*(1-$G10-$H10-$I10)) -> 28251 | M10: =IF($E10="",0,$D10*$E10-($F10*$E10+$G10*$D10*$E10+$H10*$D10*$E10+$I10*$D10*$E10+$J10*$D10*$E10*(1-$G10)+$K10*$E10)) -> 8877.3 | N10: =IF($B10="","",CONCATENATE("Örnek kalem: ",$B10)) -> Örnek kalem: Kablo USB-C
A11: P-1006 | B11: Mouse Kablosuz | C11: Amazon | D11: 279 | E11: 80 | F11: 130 | G11: 0.25 | H11: 0.06 | I11: 0.09 | J11: 0.05 | K11: 5 | L11: =IF($E11="",0,$D11*$E11*(1-$G11-$H11-$I11)) -> 13392 | M11: =IF($E11="",0,$D11*$E11-($F11*$E11+$G11*$D11*$E11+$H11*$D11*$E11+$I11*$D11*$E11+$J11*$D11*$E11*(1-$G11)+$K11*$E11)) -> 1755 | N11: =IF($B11="","",CONCATENATE("Örnek kalem: ",$B11)) -> Örnek kalem: Mouse Kablosuz
L12: =IF($E12="",0,$D12*$E12*(1-$G12-$H12-$I12)) -> 0 | M12: =IF($E12="",0,$D12*$E12-($F12*$E12+$G12*$D12*$E12+$H12*$D12*$E12+$I12*$D12*$E12+$J12*$D12*$E12*(1-$G12)+$K12*$E12)) -> 0 | N12: =IF($B12="","",CONCATENATE("Örnek kalem: ",$B12))
L13: =IF($E13="",0,$D13*$E13*(1-$G13-$H13-$I13)) -> 0 | M13: =IF($E13="",0,$D13*$E13-($F13*$E13+$G13*$D13*$E13+$H13*$D13*$E13+$I13*$D13*$E13+$J13*$D13*$E13*(1-$G13)+$K13*$E13)) -> 0 | N13: =IF($B13="","",CONCATENATE("Örnek kalem: ",$B13))
L14: =IF($E14="",0,$D14*$E14*(1-$G14-$H14-$I14)) -> 0 | M14: =IF($E14="",0,$D14*$E14-($F14*$E14+$G14*$D14*$E14+$H14*$D14*$E14+$I14*$D14*$E14+$J14*$D14*$E14*(1-$G14)+$K14*$E14)) -> 0 | N14: =IF($B14="","",CONCATENATE("Örnek kalem: ",$B14))
L15: =IF($E15="",0,$D15*$E15*(1-$G15-$H15-$I15)) -> 0 | M15: =IF($E15="",0,$D15*$E15-($F15*$E15+$G15*$D15*$E15+$H15*$D15*$E15+$I15*$D15*$E15+$J15*$D15*$E15*(1-$G15)+$K15*$E15)) -> 0 | N15: =IF($B15="","",CONCATENATE("Örnek kalem: ",$B15))
L16: =IF($E16="",0,$D16*$E16*(1-$G16-$H16-$I16)) -> 0 | M16: =IF($E16="",0,$D16*$E16-($F16*$E16+$G16*$D16*$E16+$H16*$D16*$E16+$I16*$D16*$E16+$J16*$D16*$E16*(1-$G16)+$K16*$E16)) -> 0 | N16: =IF($B16="","",CONCATENATE("Örnek kalem: ",$B16))
L17: =IF($E17="",0,$D17*$E17*(1-$G17-$H17-$I17)) -> 0 | M17: =IF($E17="",0,$D17*$E17-($F17*$E17+$G17*$D17*$E17+$H17*$D17*$E17+$I17*$D17*$E17+$J17*$D17*$E17*(1-$G17)+$K17*$E17)) -> 0 | N17: =IF($B17="","",CONCATENATE("Örnek kalem: ",$B17))
L18: =IF($E18="",0,$D18*$E18*(1-$G18-$H18-$I18)) -> 0 | M18: =IF($E18="",0,$D18*$E18-($F18*$E18+$G18*$D18*$E18+$H18*$D18*$E18+$I18*$D18*$E18+$J18*$D18*$E18*(1-$G18)+$K18*$E18)) -> 0 | N18: =IF($B18="","",CONCATENATE("Örnek kalem: ",$B18))
L19: =IF($E19="",0,$D19*$E19*(1-$G19-$H19-$I19)) -> 0 | M19: =IF($E19="",0,$D19*$E19-($F19*$E19+$G19*$D19*$E19+$H19*$D19*$E19+$I19*$D19*$E19+$J19*$D19*$E19*(1-$G19)+$K19*$E19)) -> 0 | N19: =IF($B19="","",CONCATENATE("Örnek kalem: ",$B19))
L20: =IF($E20="",0,$D20*$E20*(1-$G20-$H20-$I20)) -> 0 | M20: =IF($E20="",0,$D20*$E20-($F20*$E20+$G20*$D20*$E20+$H20*$D20*$E20+$I20*$D20*$E20+$J20*$D20*$E20*(1-$G20)+$K20*$E20)) -> 0 | N20: =IF($B20="","",CONCATENATE("Örnek kalem: ",$B20))
L21: =IF($E21="",0,$D21*$E21*(1-$G21-$H21-$I21)) -> 0 | M21: =IF($E21="",0,$D21*$E21-($F21*$E21+$G21*$D21*$E21+$H21*$D21*$E21+$I21*$D21*$E21+$J21*$D21*$E21*(1-$G21)+$K21*$E21)) -> 0 | N21: =IF($B21="","",CONCATENATE("Örnek kalem: ",$B21))
L22: =IF($E22="",0,$D22*$E22*(1-$G22-$H22-$I22)) -> 0 | M22: =IF($E22="",0,$D22*$E22-($F22*$E22+$G22*$D22*$E22+$H22*$D22*$E22+$I22*$D22*$E22+$J22*$D22*$E22*(1-$G22)+$K22*$E22)) -> 0 | N22: =IF($B22="","",CONCATENATE("Örnek kalem: ",$B22))
L23: =IF($E23="",0,$D23*$E23*(1-$G23-$H23-$I23)) -> 0 | M23: =IF($E23="",0,$D23*$E23-($F23*$E23+$G23*$D23*$E23+$H23*$D23*$E23+$I23*$D23*$E23+$J23*$D23*$E23*(1-$G23)+$K23*$E23)) -> 0 | N23: =IF($B23="","",CONCATENATE("Örnek kalem: ",$B23))
... L1004: =IF($E1004="",0,$D1004*$E1004*(1-$G1004-$H1004-$I1004)) -> 0 | M1004: =IF($E1004="",0,$D1004*$E1004-($F1004*$E1004+$G1004*$D1004*$E1004+$H1004*$D1004*$E1004+$I1004*$D1004*$E1004+$J1004*$D1004*$E1004*(1-$G1004)+$K1004*$E1004)) -> 0 | N1004: =IF($B1004="","",CONCATENATE("Örnek kalem: ",$B1004))
A1006: Demo veriler rapor sonuçlarını örnekler; satın alma sonrası silinerek gerçek veriler girilir.

Sheet DEGISIKLIK_KAYDI
A1: DEGISIKLIK KAYDI — Pazaryeri Net Kâr & Eksik Hakediş Yakalayıcı
A3: Değişiklik Kaydı
A4: Tarih | B4: Sürüm | C4: Değişiklik | D4: Neden | E4: Yapan
A5: 10.08.2026 | B5: 1.0.0 | C5: İlk üretim | D5: Ürünün yayına hazırlanması | E5: ExcelArşiv

Sheet LISTELER
A1: LISTELER — Pazaryeri Net Kâr & Eksik Hakediş Yakalayıcı
A3: Bağlı Listeler
A4: Bu sayfadaki listeler açılır menüleri besler; yeni seçenek eklemek için sarı hücrelere yazın.
A6: Pazaryerleri
A7: Trendyol
A8: Hepsiburada
A9: Amazon
A10: N11
A11: Diğer

Sheet AYARLAR
A1: AYARLAR — Pazaryeri Net Kâr & Eksik Hakediş Yakalayıcı
A3: Sistem Ayarları ve Oranlar
A4: Tüm sabitler bu sayfadadır. Eşikler, senaryo çarpanları ve oranları güncelleyin; değişen her değer tüm hesaplamalara anında yansır.
A6: anahtar | B6: deger | C6: birim | D6: alt | E6: ust | F6: aciklama | G6: kaynak | H6: yururluk_tarihi | I6: dogrulama_tarihi
A7: PazaryeriFirmaUnvan | B7: Örnek Firma A.Ş. | C7: Metin | F7: Firma unvanı rapor başlığında görünür. | G7: Kullanıcı | H7: 46244 | I7: 46244
A8: PazaryeriRaporTarihi | B8: 46244 | C8: Tarih | F8: Raporun dayanak tarihi. | G8: Kullanıcı | H8: 46244 | I8: 46244
A9: PazaryeriRaporHazirlayan | B9: Pazaryeri Operasyon Müdürü | C9: Metin | F9: Raporu hazırlayan kişi. | G9: Kullanıcı | H9: 46244 | I9: 46244
A10: PazaryeriDosyaSurumu | B10: 1.0.0 | C10: Metin | F10: Dosya sürümü. | G10: Kullanıcı | H10: 46244 | I10: 46244
A11: PazaryeriEksikHakedisEsik | B11: 0.01 | C11: Oran | D11: 0 | E11: 1 | F11: Fark oranı eşiği; üzerindeki farklar eksik hakediş sayılır. | G11: Varsayım | H11: 46244 | I11: 46244
A12: PazaryeriEksikHakedisTutarEsik | B12: 50 | C12: TL | D12: 0 | E12: 1000000000 | F12: Fark tutarının ihmal edilmeyeceği asgari TL eşiği. | G12: Varsayım | H12: 46244 | I12: 46244
A13: PazaryeriNetKarMarjiHedef | B13: 0.1 | C13: Oran | D13: 0 | E13: 1 | F13: GÜÇLÜ kararı için genel marj hedefi. | G13: Varsayım | H13: 46244 | I13: 46244
A14: PazaryeriNetKarMarjiKritik | B14: 0 | C14: Oran | D14: -1 | E14: 1 | F14: Marjın altına inmesi durumunda İNCELE kararı üretilir. | G14: Varsayım | H14: 46244 | I14: 46244
A15: PazaryeriKargoVarsayilanOran | B15: 0.05 | C15: Oran | D15: 0 | E15: 1 | F15: Kargo/operasyon oranı varsayılanı (kalem girişinde öneri). | G15: Varsayım | H15: 46244 | I15: 46244
A16: PazaryeriReklamVarsayilanOran | B16: 0.05 | C16: Oran | D16: 0 | E16: 1 | F16: Reklam oranı varsayılanı. | G16: Varsayım | H16: 46244 | I16: 46244
A17: PazaryeriIadeVarsayilanOran | B17: 0.05 | C17: Oran | D17: 0 | E17: 1 | F17: İade oranı varsayılanı. | G17: Varsayım | H17: 46244 | I17: 46244
A18: PazaryeriSenIyiSatis | B18: 0.05 | C18: Oran | D18: -0.5 | E18: 0.5 | F18: İyimser senaryo satış fiyatı çarpanı. | G18: Varsayım | H18: 46244 | I18: 46244
A19: PazaryeriSenBazSatis | B19: 0 | C19: Oran | D19: -0.5 | E19: 0.5 | F19: Baz senaryo satış fiyatı çarpanı. | G19: Varsayım | H19: 46244 | I19: 46244
A20: PazaryeriSenKotuSatis | B20: -0.05 | C20: Oran | D20: -0.5 | E20: 0.5 | F20: Kötümser senaryo satış fiyatı çarpanı. | G20: Varsayım | H20: 46244 | I20: 46244
A21: PazaryeriSenKritikSatis | B21: -0.1 | C21: Oran | D21: -0.5 | E21: 0.5 | F21: Kritik senaryo satış fiyatı çarpanı. | G21: Varsayım | H21: 46244 | I21: 46244
A22: PazaryeriTahminCarpan | B22: 1.645 | C22: Çarpan | D22: 0 | E22: 10 | F22: Tahmin güven bandı çarpanı (%90 normal dağılım). | G22: Varsayım | H22: 46244 | I22: 46244
... A30: PazaryeriYuksekToplamSatisEsik | B30: 1000000 | C30: TL | D30: 0 | E30: 100000000000 | F30: Yüksek toplam satış kontrol eşiği. | G30: Varsayım | H30: 46244 | I30: 46244
A31: PazaryeriAksiyon1_ACIKLAMA | B31: Eksik hakediş tespit edildi; pazaryeri müşteri hizmetlerine fark dökümünü ileterek tutarın iadesini talep edin. | C31: Metin | F31: İNCELE kararında gösterilen ilk öneri. | G31: Varsayım | H31: 46244 | I31: 46244
A32: PazaryeriAksiyon2_ACIKLAMA | B32: Genel marj hedefin üzerinde; satışı artırmak için kâr marjı yüksek kalemlerin reklam bütçesini öne çekin. | C32: Metin | F32: GÜÇLÜ kararında gösterilen ikinci öneri. | G32: Varsayım | H32: 46244 | I32: 46244
A33: PazaryeriAksiyon3_ACIKLAMA | B33: Marj kritik altında; komisyon yüksek pazaryerlerinde fiyat/komisyon yapısını yeniden müzakere edin veya portföyü gözden geçirin. | C33: Metin | F33: İNCELE/NORMAL kararında gösterilen üçüncü öneri. | G33: Varsayım | H33: 46244 | I33: 46244
A35: PazaryeriPanelSatir_1 | B35: 1 | C35: Satır | F35: HESAP/PANO'daki kalem bazlı grafiğin tablodaki veri satırı (1. veri). | G35: Kullanıcı | H35: 46244 | I35: 46244
A36: PazaryeriPanelSatir_2 | B36: 2 | C36: Satır | F36: HESAP/PANO'daki kalem bazlı grafiğin tablodaki veri satırı (2. veri). | G36: Kullanıcı | H36: 46244 | I36: 46244
A37: PazaryeriPanelSatir_3 | B37: 3 | C37: Satır | F37: HESAP/PANO'daki kalem bazlı grafiğin tablodaki veri satırı (3. veri). | G37: Kullanıcı | H37: 46244 | I37: 46244
A38: PazaryeriPanelSatir_4 | B38: 4 | C38: Satır | F38: HESAP/PANO'daki kalem bazlı grafiğin tablodaki veri satırı (4. veri). | G38: Kullanıcı | H38: 46244 | I38: 46244
A39: PazaryeriPanelSatir_5 | B39: 5 | C39: Satır | F39: HESAP/PANO'daki kalem bazlı grafiğin tablodaki veri satırı (5. veri). | G39: Kullanıcı | H39: 46244 | I39: 46244
A40: PazaryeriPanelSatir_6 | B40: 6 | C40: Satır | F40: HESAP/PANO'daki kalem bazlı grafiğin tablodaki veri satırı (6. veri). | G40: Kullanıcı | H40: 46244 | I40: 46244
A41: PazaryeriPanelSatir_7 | B41: 7 | C41: Satır | F41: HESAP/PANO'daki kalem bazlı grafiğin tablodaki veri satırı (7. veri). | G41: Kullanıcı | H41: 46244 | I41: 46244
A42: PazaryeriPanelSatir_8 | B42: 8 | C42: Satır | F42: HESAP/PANO'daki kalem bazlı grafiğin tablodaki veri satırı (8. veri). | G42: Kullanıcı | H42: 46244 | I42: 46244
A43: PazaryeriPanelSatir_9 | B43: 9 | C43: Satır | F43: HESAP/PANO'daki kalem bazlı grafiğin tablodaki veri satırı (9. veri). | G43: Kullanıcı | H43: 46244 | I43: 46244
A44: PazaryeriPanelSatir_10 | B44: 10 | C44: Satır | F44: HESAP/PANO'daki kalem bazlı grafiğin tablodaki veri satırı (10. veri). | G44: Kullanıcı | H44: 46244 | I44: 46244
A45: PazaryeriPanelSatir_11 | B45: 11 | C45: Satır | F45: HESAP/PANO'daki kalem bazlı grafiğin tablodaki veri satırı (11. veri). | G45: Kullanıcı | H45: 46244 | I45: 46244
A46: PazaryeriPanelSatir_12 | B46: 12 | C46: Satır | F46: HESAP/PANO'daki kalem bazlı grafiğin tablodaki veri satırı (12. veri). | G46: Kullanıcı | H46: 46244 | I46: 46244

Sheet KILAVUZ
A1: KILAVUZ — Pazaryeri Net Kâr & Eksik Hakediş Yakalayıcı
A3: Kullanım Kılavuzu
A5: Veri girişi | B5: KALEM_LISTESI sayfasında sarı hücrelere satış kalemlerinizi girin. Satış fiyatı, miktar, ürün maliyeti, komisyon/kargo/reklam/iade oranları ve ek gider doldurulunca net kâr ve marj otomatik hesaplanır.
A6: Eksik hakediş yakalama | B6: Her kalem için pazaryerinden gelen gerçek ödemeyi 'Gerçek Hakediş' sütununa girin. Beklenen hakedişten fark, eşiklerin üzerindeyse kalem 'EKSİK HAKEDİŞ' olarak işaretlenir.
A7: Eksik hakediş mutabakatı | B7: Beklenen hakediş; satış tutarından komisyon, kargo/operasyon ve reklam tutarları düşülerek hesaplanır. İade maliyeti mutabakata doğrudan girmez; kâr ve marjda etkilidir. Gerçek hakedişi KDV hariç girin; fark, AYARLAR'daki eşikleri aşınca EKSİK HAKEDİŞ işaretlenir.
A8: Veri kalite skoru | B8: KONTROLLER sayfası zorunlu giriş kolonlarının doluluk oranını ölçer ve 0-100 puan üretir. Düşük skorda PANO'daki tüm çıktılara DÜŞÜK GÜVEN uyarısı basılır; karar kalitesini artırmak için eksik alanları doldurun.
A9: Karar ve aksiyon | B9: KARAR sayfası marj ve eksik hakediş durumuna göre GÜÇLÜ/NORMAL/İNCELE kararını gerekçesiyle üretir ve önerilen aksiyonları gösterir.
A10: Oranlar ve senaryolar | B10: AYARLAR sayfasından marj hedefleri, eksik hakediş eşikleri, senaryo ve tornado çarpanlarını güncelleyin; PANO ve SENARYO_DUYARLILIK anında güncellenir.
A11: Güven ve karar kalitesi | B11: Veri kalite skoru girişlerin tamlığını ölçer. Kalem girişi yokken karar VERİ YOK; negatif girişte DURDUR üretir. Verileriniz cihazınızdan çıkmaz; dosya tamamen çevrimdışıdır.
A12: Uyumluluk | B12: Excel 2016-365 (Windows ve Mac), LibreOffice ve Google Sheets ile uyumludur. Makro içermez; formüller ayrıştırıcı ile denetlenmiştir.
A13: Karar kuralları | B13: KARAR sayfasındaki sonuç şu kurallarla üretilir: (1) kalem girişi yoksa VERİ YOK; (2) negatif satış fiyatı veya maliyet varsa DURDUR; (3) genel kâr marjı hedefin üzerindeyse ve eksik hakediş yoksa GÜÇLÜ; (4) eksik hakediş tespit edilmişse veya marj kritik eşiğin altındaysa İNCELE; (5) diğer durumlarda NORMAL. Gerekçe, kararın altında makine tarafından üretilir ve hangi kuralın tetiklendiğini açıklar.
